{
  size: [8, 8, 9],
  entities: [],
  blocks: [
    {
      pos: [2, 2, 1],
      state: 0
    },
    {
      pos: [3, 2, 1],
      state: 0
    },
    {
      pos: [4, 2, 1],
      state: 0
    },
    {
      pos: [5, 2, 1],
      state: 0
    },
    {
      pos: [6, 2, 1],
      state: 0
    },
    {
      pos: [2, 3, 1],
      state: 1
    },
    {
      pos: [3, 3, 1],
      state: 2
    },
    {
      pos: [4, 3, 1],
      state: 2
    },
    {
      pos: [5, 3, 1],
      state: 2
    },
    {
      pos: [6, 3, 1],
      state: 1
    },
    {
      pos: [2, 4, 1],
      state: 1
    },
    {
      pos: [3, 4, 1],
      state: 2
    },
    {
      pos: [4, 4, 1],
      state: 2
    },
    {
      pos: [5, 4, 1],
      state: 2
    },
    {
      pos: [6, 4, 1],
      state: 1
    },
    {
      pos: [2, 5, 1],
      state: 1
    },
    {
      pos: [3, 5, 1],
      state: 2
    },
    {
      pos: [4, 5, 1],
      state: 2
    },
    {
      pos: [5, 5, 1],
      state: 2
    },
    {
      pos: [6, 5, 1],
      state: 1
    },
    {
      pos: [2, 6, 1],
      state: 3
    },
    {
      pos: [3, 6, 1],
      state: 3
    },
    {
      pos: [4, 6, 1],
      state: 3
    },
    {
      pos: [5, 6, 1],
      state: 3
    },
    {
      pos: [6, 6, 1],
      state: 3
    },
    {
      pos: [3, 2, 2],
      state: 0
    },
    {
      pos: [4, 2, 2],
      state: 0
    },
    {
      pos: [5, 2, 2],
      state: 0
    },
    {
      pos: [6, 2, 2],
      state: 0
    },
    {
      pos: [3, 3, 2],
      state: 4
    },
    {
      pos: [4, 3, 2],
      state: 1
    },
    {
      pos: [5, 3, 2],
      state: 5
    },
    {
      pos: [6, 3, 2],
      state: 4
    },
    {
      pos: [3, 4, 2],
      state: 4
    },
    {
      pos: [6, 4, 2],
      state: 4
    },
    {
      pos: [3, 5, 2],
      state: 4
    },
    {
      pos: [6, 5, 2],
      state: 4
    },
    {
      pos: [2, 6, 2],
      state: 3
    },
    {
      pos: [3, 6, 2],
      state: 3
    },
    {
      pos: [6, 6, 2],
      state: 3
    },
    {
      pos: [3, 7, 2],
      state: 3
    },
    {
      pos: [4, 7, 2],
      state: 3
    },
    {
      pos: [5, 7, 2],
      state: 3
    },
    {
      pos: [1, 0, 3],
      state: 3
    },
    {
      pos: [3, 2, 3],
      state: 0
    },
    {
      pos: [4, 2, 3],
      state: 0
    },
    {
      pos: [5, 2, 3],
      state: 0
    },
    {
      pos: [6, 2, 3],
      state: 0
    },
    {
      pos: [3, 3, 3],
      state: 4
    },
    {
      pos: [6, 3, 3],
      state: 4
    },
    {
      pos: [3, 4, 3],
      state: 4
    },
    {
      pos: [3, 5, 3],
      state: 4
    },
    {
      pos: [6, 5, 3],
      state: 4
    },
    {
      pos: [2, 6, 3],
      state: 3
    },
    {
      pos: [3, 6, 3],
      state: 3
    },
    {
      pos: [6, 6, 3],
      state: 3
    },
    {
      pos: [3, 7, 3],
      state: 3
    },
    {
      pos: [4, 7, 3],
      state: 3
    },
    {
      pos: [5, 7, 3],
      state: 3
    },
    {
      pos: [1, 0, 4],
      state: 3
    },
    {
      pos: [2, 1, 4],
      state: 3
    },
    {
      pos: [3, 2, 4],
      state: 0
    },
    {
      pos: [4, 2, 4],
      state: 0
    },
    {
      pos: [5, 2, 4],
      state: 0
    },
    {
      pos: [6, 2, 4],
      state: 0
    },
    {
      pos: [6, 3, 4],
      state: 4
    },
    {
      pos: [6, 4, 4],
      state: 4
    },
    {
      pos: [3, 5, 4],
      state: 4
    },
    {
      pos: [6, 5, 4],
      state: 4
    },
    {
      pos: [2, 6, 4],
      state: 3
    },
    {
      pos: [3, 6, 4],
      state: 3
    },
    {
      pos: [6, 6, 4],
      state: 3
    },
    {
      pos: [3, 7, 4],
      state: 3
    },
    {
      pos: [4, 7, 4],
      state: 3
    },
    {
      pos: [5, 7, 4],
      state: 3
    },
    {
      pos: [1, 0, 5],
      state: 3
    },
    {
      pos: [3, 2, 5],
      state: 0
    },
    {
      pos: [4, 2, 5],
      state: 0
    },
    {
      pos: [5, 2, 5],
      state: 0
    },
    {
      pos: [6, 2, 5],
      state: 0
    },
    {
      pos: [3, 3, 5],
      state: 4
    },
    {
      pos: [6, 3, 5],
      state: 4
    },
    {
      pos: [3, 4, 5],
      state: 4
    },
    {
      pos: [3, 5, 5],
      state: 4
    },
    {
      pos: [6, 5, 5],
      state: 4
    },
    {
      pos: [2, 6, 5],
      state: 3
    },
    {
      pos: [3, 6, 5],
      state: 3
    },
    {
      pos: [6, 6, 5],
      state: 3
    },
    {
      pos: [3, 7, 5],
      state: 3
    },
    {
      pos: [4, 7, 5],
      state: 3
    },
    {
      pos: [5, 7, 5],
      state: 3
    },
    {
      pos: [3, 2, 6],
      state: 0
    },
    {
      pos: [4, 2, 6],
      state: 0
    },
    {
      pos: [5, 2, 6],
      state: 0
    },
    {
      pos: [6, 2, 6],
      state: 0
    },
    {
      pos: [3, 3, 6],
      state: 4
    },
    {
      pos: [5, 3, 6],
      state: 1
    },
    {
      pos: [6, 3, 6],
      state: 4
    },
    {
      pos: [3, 4, 6],
      state: 4
    },
    {
      pos: [6, 4, 6],
      state: 4
    },
    {
      pos: [3, 5, 6],
      state: 4
    },
    {
      pos: [6, 5, 6],
      state: 4
    },
    {
      pos: [2, 6, 6],
      state: 3
    },
    {
      pos: [3, 6, 6],
      state: 3
    },
    {
      pos: [6, 6, 6],
      state: 3
    },
    {
      pos: [3, 7, 6],
      state: 3
    },
    {
      pos: [4, 7, 6],
      state: 3
    },
    {
      pos: [5, 7, 6],
      state: 3
    },
    {
      pos: [2, 2, 7],
      state: 0
    },
    {
      pos: [3, 2, 7],
      state: 0
    },
    {
      pos: [4, 2, 7],
      state: 0
    },
    {
      pos: [5, 2, 7],
      state: 0
    },
    {
      pos: [6, 2, 7],
      state: 0
    },
    {
      pos: [2, 3, 7],
      state: 1
    },
    {
      pos: [3, 3, 7],
      state: 2
    },
    {
      pos: [4, 3, 7],
      state: 2
    },
    {
      pos: [5, 3, 7],
      state: 2
    },
    {
      pos: [6, 3, 7],
      state: 1
    },
    {
      pos: [2, 4, 7],
      state: 1
    },
    {
      pos: [3, 4, 7],
      state: 2
    },
    {
      pos: [4, 4, 7],
      state: 2
    },
    {
      pos: [5, 4, 7],
      state: 2
    },
    {
      pos: [6, 4, 7],
      state: 1
    },
    {
      pos: [2, 5, 7],
      state: 1
    },
    {
      pos: [3, 5, 7],
      state: 2
    },
    {
      pos: [4, 5, 7],
      state: 2
    },
    {
      pos: [5, 5, 7],
      state: 2
    },
    {
      pos: [6, 5, 7],
      state: 1
    },
    {
      pos: [2, 6, 7],
      state: 3
    },
    {
      pos: [3, 6, 7],
      state: 3
    },
    {
      pos: [4, 6, 7],
      state: 3
    },
    {
      pos: [5, 6, 7],
      state: 3
    },
    {
      pos: [6, 6, 7],
      state: 3
    },
    {
      nbt: {
        id: "minecraft:banner",
        Patterns: []
      },
      pos: [3, 3, 0],
      state: 6
    },
    {
      nbt: {
        id: "minecraft:banner",
        Patterns: []
      },
      pos: [4, 3, 0],
      state: 6
    },
    {
      nbt: {
        id: "minecraft:banner",
        Patterns: []
      },
      pos: [5, 3, 0],
      state: 6
    },
    {
      nbt: {
        id: "minecraft:banner",
        Patterns: []
      },
      pos: [2, 5, 3],
      state: 7
    },
    {
      nbt: {
        target_pool: "minecraft:empty",
        final_state: "minecraft:acacia_stairs[facing=east]",
        id: "minecraft:jigsaw",
        attachement_type: "minecraft:building_entrance"
      },
      pos: [0, 0, 4],
      state: 8
    },
    {
      nbt: {
        id: "minecraft:banner",
        Patterns: []
      },
      pos: [2, 5, 5],
      state: 7
    },
    {
      nbt: {
        LootTable: "minecraft:chests/village/village_cartographer",
        Items: [],
        id: "minecraft:chest",
        Lock: "",
        LootTableSeed: 0L
      },
      pos: [4, 3, 6],
      state: 9
    },
    {
      nbt: {
        id: "minecraft:banner",
        Patterns: []
      },
      pos: [3, 3, 8],
      state: 10
    },
    {
      nbt: {
        id: "minecraft:banner",
        Patterns: []
      },
      pos: [4, 3, 8],
      state: 10
    },
    {
      nbt: {
        id: "minecraft:banner",
        Patterns: []
      },
      pos: [5, 3, 8],
      state: 10
    },
    {
      pos: [0, 0, 0],
      state: 11
    },
    {
      pos: [1, 0, 0],
      state: 11
    },
    {
      pos: [2, 0, 0],
      state: 12
    },
    {
      pos: [3, 0, 0],
      state: 12
    },
    {
      pos: [4, 0, 0],
      state: 12
    },
    {
      pos: [5, 0, 0],
      state: 12
    },
    {
      pos: [6, 0, 0],
      state: 11
    },
    {
      pos: [7, 0, 0],
      state: 11
    },
    {
      pos: [0, 1, 0],
      state: 11
    },
    {
      pos: [1, 1, 0],
      state: 11
    },
    {
      pos: [2, 1, 0],
      state: 11
    },
    {
      pos: [3, 1, 0],
      state: 11
    },
    {
      pos: [4, 1, 0],
      state: 11
    },
    {
      pos: [5, 1, 0],
      state: 11
    },
    {
      pos: [6, 1, 0],
      state: 11
    },
    {
      pos: [7, 1, 0],
      state: 11
    },
    {
      pos: [0, 2, 0],
      state: 11
    },
    {
      pos: [1, 2, 0],
      state: 11
    },
    {
      pos: [2, 2, 0],
      state: 11
    },
    {
      pos: [3, 2, 0],
      state: 11
    },
    {
      pos: [4, 2, 0],
      state: 11
    },
    {
      pos: [5, 2, 0],
      state: 11
    },
    {
      pos: [6, 2, 0],
      state: 11
    },
    {
      pos: [7, 2, 0],
      state: 11
    },
    {
      pos: [0, 3, 0],
      state: 11
    },
    {
      pos: [1, 3, 0],
      state: 11
    },
    {
      pos: [2, 3, 0],
      state: 11
    },
    {
      pos: [6, 3, 0],
      state: 11
    },
    {
      pos: [7, 3, 0],
      state: 11
    },
    {
      pos: [0, 4, 0],
      state: 11
    },
    {
      pos: [1, 4, 0],
      state: 11
    },
    {
      pos: [2, 4, 0],
      state: 11
    },
    {
      pos: [3, 4, 0],
      state: 11
    },
    {
      pos: [4, 4, 0],
      state: 11
    },
    {
      pos: [5, 4, 0],
      state: 11
    },
    {
      pos: [6, 4, 0],
      state: 11
    },
    {
      pos: [7, 4, 0],
      state: 11
    },
    {
      pos: [0, 5, 0],
      state: 11
    },
    {
      pos: [1, 5, 0],
      state: 11
    },
    {
      pos: [2, 5, 0],
      state: 11
    },
    {
      pos: [3, 5, 0],
      state: 11
    },
    {
      pos: [4, 5, 0],
      state: 11
    },
    {
      pos: [5, 5, 0],
      state: 11
    },
    {
      pos: [6, 5, 0],
      state: 11
    },
    {
      pos: [7, 5, 0],
      state: 11
    },
    {
      pos: [0, 6, 0],
      state: 11
    },
    {
      pos: [1, 6, 0],
      state: 13
    },
    {
      pos: [2, 6, 0],
      state: 14
    },
    {
      pos: [3, 6, 0],
      state: 14
    },
    {
      pos: [4, 6, 0],
      state: 14
    },
    {
      pos: [5, 6, 0],
      state: 14
    },
    {
      pos: [6, 6, 0],
      state: 14
    },
    {
      pos: [7, 6, 0],
      state: 15
    },
    {
      pos: [0, 7, 0],
      state: 11
    },
    {
      pos: [1, 7, 0],
      state: 11
    },
    {
      pos: [2, 7, 0],
      state: 11
    },
    {
      pos: [3, 7, 0],
      state: 11
    },
    {
      pos: [4, 7, 0],
      state: 11
    },
    {
      pos: [5, 7, 0],
      state: 11
    },
    {
      pos: [6, 7, 0],
      state: 11
    },
    {
      pos: [7, 7, 0],
      state: 11
    },
    {
      pos: [0, 0, 1],
      state: 12
    },
    {
      pos: [1, 0, 1],
      state: 12
    },
    {
      pos: [2, 0, 1],
      state: 16
    },
    {
      pos: [3, 0, 1],
      state: 11
    },
    {
      pos: [4, 0, 1],
      state: 16
    },
    {
      pos: [5, 0, 1],
      state: 12
    },
    {
      pos: [6, 0, 1],
      state: 16
    },
    {
      pos: [7, 0, 1],
      state: 11
    },
    {
      pos: [0, 1, 1],
      state: 11
    },
    {
      pos: [1, 1, 1],
      state: 11
    },
    {
      pos: [2, 1, 1],
      state: 16
    },
    {
      pos: [3, 1, 1],
      state: 11
    },
    {
      pos: [4, 1, 1],
      state: 16
    },
    {
      pos: [5, 1, 1],
      state: 11
    },
    {
      pos: [6, 1, 1],
      state: 16
    },
    {
      pos: [7, 1, 1],
      state: 11
    },
    {
      pos: [0, 2, 1],
      state: 11
    },
    {
      pos: [1, 2, 1],
      state: 11
    },
    {
      pos: [7, 2, 1],
      state: 11
    },
    {
      pos: [0, 3, 1],
      state: 11
    },
    {
      pos: [1, 3, 1],
      state: 11
    },
    {
      pos: [7, 3, 1],
      state: 11
    },
    {
      pos: [0, 4, 1],
      state: 11
    },
    {
      pos: [1, 4, 1],
      state: 11
    },
    {
      pos: [7, 4, 1],
      state: 11
    },
    {
      pos: [0, 5, 1],
      state: 11
    },
    {
      pos: [1, 5, 1],
      state: 11
    },
    {
      pos: [7, 5, 1],
      state: 11
    },
    {
      pos: [0, 6, 1],
      state: 11
    },
    {
      pos: [1, 6, 1],
      state: 17
    },
    {
      pos: [7, 6, 1],
      state: 18
    },
    {
      pos: [0, 7, 1],
      state: 11
    },
    {
      pos: [1, 7, 1],
      state: 11
    },
    {
      pos: [2, 7, 1],
      state: 13
    },
    {
      pos: [3, 7, 1],
      state: 14
    },
    {
      pos: [4, 7, 1],
      state: 14
    },
    {
      pos: [5, 7, 1],
      state: 14
    },
    {
      pos: [6, 7, 1],
      state: 19
    },
    {
      pos: [7, 7, 1],
      state: 11
    },
    {
      pos: [0, 0, 2],
      state: 12
    },
    {
      pos: [1, 0, 2],
      state: 11
    },
    {
      pos: [2, 0, 2],
      state: 11
    },
    {
      pos: [3, 0, 2],
      state: 12
    },
    {
      pos: [4, 0, 2],
      state: 11
    },
    {
      pos: [5, 0, 2],
      state: 11
    },
    {
      pos: [6, 0, 2],
      state: 12
    },
    {
      pos: [7, 0, 2],
      state: 11
    },
    {
      pos: [0, 1, 2],
      state: 11
    },
    {
      pos: [1, 1, 2],
      state: 11
    },
    {
      pos: [2, 1, 2],
      state: 11
    },
    {
      pos: [3, 1, 2],
      state: 11
    },
    {
      pos: [4, 1, 2],
      state: 11
    },
    {
      pos: [5, 1, 2],
      state: 11
    },
    {
      pos: [6, 1, 2],
      state: 11
    },
    {
      pos: [7, 1, 2],
      state: 11
    },
    {
      pos: [0, 2, 2],
      state: 11
    },
    {
      pos: [1, 2, 2],
      state: 11
    },
    {
      pos: [2, 2, 2],
      state: 20
    },
    {
      pos: [7, 2, 2],
      state: 11
    },
    {
      pos: [0, 3, 2],
      state: 11
    },
    {
      pos: [1, 3, 2],
      state: 11
    },
    {
      pos: [2, 3, 2],
      state: 11
    },
    {
      pos: [7, 3, 2],
      state: 11
    },
    {
      pos: [0, 4, 2],
      state: 11
    },
    {
      pos: [1, 4, 2],
      state: 11
    },
    {
      pos: [2, 4, 2],
      state: 11
    },
    {
      pos: [4, 4, 2],
      state: 21
    },
    {
      pos: [5, 4, 2],
      state: 11
    },
    {
      pos: [7, 4, 2],
      state: 11
    },
    {
      pos: [0, 5, 2],
      state: 11
    },
    {
      pos: [1, 5, 2],
      state: 11
    },
    {
      pos: [2, 5, 2],
      state: 11
    },
    {
      pos: [4, 5, 2],
      state: 11
    },
    {
      pos: [5, 5, 2],
      state: 11
    },
    {
      pos: [7, 5, 2],
      state: 11
    },
    {
      pos: [0, 6, 2],
      state: 11
    },
    {
      pos: [1, 6, 2],
      state: 17
    },
    {
      pos: [4, 6, 2],
      state: 11
    },
    {
      pos: [5, 6, 2],
      state: 11
    },
    {
      pos: [7, 6, 2],
      state: 18
    },
    {
      pos: [0, 7, 2],
      state: 11
    },
    {
      pos: [1, 7, 2],
      state: 11
    },
    {
      pos: [2, 7, 2],
      state: 17
    },
    {
      pos: [6, 7, 2],
      state: 18
    },
    {
      pos: [7, 7, 2],
      state: 11
    },
    {
      pos: [0, 0, 3],
      state: 17
    },
    {
      pos: [2, 0, 3],
      state: 22
    },
    {
      pos: [3, 0, 3],
      state: 12
    },
    {
      pos: [4, 0, 3],
      state: 11
    },
    {
      pos: [5, 0, 3],
      state: 11
    },
    {
      pos: [6, 0, 3],
      state: 16
    },
    {
      pos: [7, 0, 3],
      state: 12
    },
    {
      pos: [0, 1, 3],
      state: 11
    },
    {
      pos: [1, 1, 3],
      state: 17
    },
    {
      pos: [2, 1, 3],
      state: 23
    },
    {
      pos: [3, 1, 3],
      state: 11
    },
    {
      pos: [4, 1, 3],
      state: 11
    },
    {
      pos: [5, 1, 3],
      state: 11
    },
    {
      pos: [6, 1, 3],
      state: 16
    },
    {
      pos: [7, 1, 3],
      state: 11
    },
    {
      pos: [0, 2, 3],
      state: 11
    },
    {
      pos: [1, 2, 3],
      state: 11
    },
    {
      pos: [2, 2, 3],
      state: 20
    },
    {
      pos: [7, 2, 3],
      state: 11
    },
    {
      pos: [0, 3, 3],
      state: 11
    },
    {
      pos: [1, 3, 3],
      state: 11
    },
    {
      pos: [2, 3, 3],
      state: 11
    },
    {
      pos: [4, 3, 3],
      state: 11
    },
    {
      pos: [5, 3, 3],
      state: 11
    },
    {
      pos: [7, 3, 3],
      state: 11
    },
    {
      pos: [0, 4, 3],
      state: 11
    },
    {
      pos: [1, 4, 3],
      state: 11
    },
    {
      pos: [2, 4, 3],
      state: 11
    },
    {
      pos: [4, 4, 3],
      state: 11
    },
    {
      pos: [5, 4, 3],
      state: 11
    },
    {
      pos: [6, 4, 3],
      state: 24
    },
    {
      pos: [7, 4, 3],
      state: 11
    },
    {
      pos: [0, 5, 3],
      state: 11
    },
    {
      pos: [1, 5, 3],
      state: 11
    },
    {
      pos: [4, 5, 3],
      state: 11
    },
    {
      pos: [5, 5, 3],
      state: 11
    },
    {
      pos: [7, 5, 3],
      state: 11
    },
    {
      pos: [0, 6, 3],
      state: 11
    },
    {
      pos: [1, 6, 3],
      state: 17
    },
    {
      pos: [4, 6, 3],
      state: 11
    },
    {
      pos: [5, 6, 3],
      state: 11
    },
    {
      pos: [7, 6, 3],
      state: 18
    },
    {
      pos: [0, 7, 3],
      state: 11
    },
    {
      pos: [1, 7, 3],
      state: 11
    },
    {
      pos: [2, 7, 3],
      state: 17
    },
    {
      pos: [6, 7, 3],
      state: 18
    },
    {
      pos: [7, 7, 3],
      state: 11
    },
    {
      pos: [2, 0, 4],
      state: 11
    },
    {
      pos: [3, 0, 4],
      state: 12
    },
    {
      pos: [4, 0, 4],
      state: 11
    },
    {
      pos: [5, 0, 4],
      state: 11
    },
    {
      pos: [6, 0, 4],
      state: 12
    },
    {
      pos: [7, 0, 4],
      state: 11
    },
    {
      pos: [0, 1, 4],
      state: 11
    },
    {
      pos: [1, 1, 4],
      state: 17
    },
    {
      pos: [3, 1, 4],
      state: 11
    },
    {
      pos: [4, 1, 4],
      state: 11
    },
    {
      pos: [5, 1, 4],
      state: 11
    },
    {
      pos: [6, 1, 4],
      state: 11
    },
    {
      pos: [7, 1, 4],
      state: 11
    },
    {
      pos: [0, 2, 4],
      state: 11
    },
    {
      pos: [1, 2, 4],
      state: 11
    },
    {
      pos: [2, 2, 4],
      state: 20
    },
    {
      pos: [7, 2, 4],
      state: 11
    },
    {
      pos: [0, 3, 4],
      state: 11
    },
    {
      pos: [1, 3, 4],
      state: 11
    },
    {
      pos: [2, 3, 4],
      state: 11
    },
    {
      pos: [3, 3, 4],
      state: 25
    },
    {
      pos: [4, 3, 4],
      state: 11
    },
    {
      pos: [5, 3, 4],
      state: 11
    },
    {
      pos: [7, 3, 4],
      state: 11
    },
    {
      pos: [0, 4, 4],
      state: 11
    },
    {
      pos: [1, 4, 4],
      state: 11
    },
    {
      pos: [2, 4, 4],
      state: 11
    },
    {
      pos: [3, 4, 4],
      state: 26
    },
    {
      pos: [4, 4, 4],
      state: 11
    },
    {
      pos: [5, 4, 4],
      state: 11
    },
    {
      pos: [7, 4, 4],
      state: 11
    },
    {
      pos: [0, 5, 4],
      state: 11
    },
    {
      pos: [1, 5, 4],
      state: 11
    },
    {
      pos: [2, 5, 4],
      state: 27
    },
    {
      pos: [4, 5, 4],
      state: 11
    },
    {
      pos: [5, 5, 4],
      state: 11
    },
    {
      pos: [7, 5, 4],
      state: 11
    },
    {
      pos: [0, 6, 4],
      state: 11
    },
    {
      pos: [1, 6, 4],
      state: 17
    },
    {
      pos: [4, 6, 4],
      state: 11
    },
    {
      pos: [5, 6, 4],
      state: 11
    },
    {
      pos: [7, 6, 4],
      state: 18
    },
    {
      pos: [0, 7, 4],
      state: 11
    },
    {
      pos: [1, 7, 4],
      state: 11
    },
    {
      pos: [2, 7, 4],
      state: 17
    },
    {
      pos: [6, 7, 4],
      state: 18
    },
    {
      pos: [7, 7, 4],
      state: 11
    },
    {
      pos: [0, 0, 5],
      state: 17
    },
    {
      pos: [2, 0, 5],
      state: 22
    },
    {
      pos: [3, 0, 5],
      state: 11
    },
    {
      pos: [4, 0, 5],
      state: 11
    },
    {
      pos: [5, 0, 5],
      state: 11
    },
    {
      pos: [6, 0, 5],
      state: 16
    },
    {
      pos: [7, 0, 5],
      state: 12
    },
    {
      pos: [0, 1, 5],
      state: 11
    },
    {
      pos: [1, 1, 5],
      state: 17
    },
    {
      pos: [2, 1, 5],
      state: 28
    },
    {
      pos: [3, 1, 5],
      state: 11
    },
    {
      pos: [4, 1, 5],
      state: 11
    },
    {
      pos: [5, 1, 5],
      state: 11
    },
    {
      pos: [6, 1, 5],
      state: 16
    },
    {
      pos: [7, 1, 5],
      state: 11
    },
    {
      pos: [0, 2, 5],
      state: 11
    },
    {
      pos: [1, 2, 5],
      state: 11
    },
    {
      pos: [2, 2, 5],
      state: 20
    },
    {
      pos: [7, 2, 5],
      state: 11
    },
    {
      pos: [0, 3, 5],
      state: 11
    },
    {
      pos: [1, 3, 5],
      state: 11
    },
    {
      pos: [2, 3, 5],
      state: 11
    },
    {
      pos: [4, 3, 5],
      state: 11
    },
    {
      pos: [5, 3, 5],
      state: 11
    },
    {
      pos: [7, 3, 5],
      state: 11
    },
    {
      pos: [0, 4, 5],
      state: 11
    },
    {
      pos: [1, 4, 5],
      state: 11
    },
    {
      pos: [2, 4, 5],
      state: 11
    },
    {
      pos: [4, 4, 5],
      state: 11
    },
    {
      pos: [5, 4, 5],
      state: 11
    },
    {
      pos: [6, 4, 5],
      state: 24
    },
    {
      pos: [7, 4, 5],
      state: 11
    },
    {
      pos: [0, 5, 5],
      state: 11
    },
    {
      pos: [1, 5, 5],
      state: 11
    },
    {
      pos: [4, 5, 5],
      state: 11
    },
    {
      pos: [5, 5, 5],
      state: 11
    },
    {
      pos: [7, 5, 5],
      state: 11
    },
    {
      pos: [0, 6, 5],
      state: 11
    },
    {
      pos: [1, 6, 5],
      state: 17
    },
    {
      pos: [4, 6, 5],
      state: 11
    },
    {
      pos: [5, 6, 5],
      state: 11
    },
    {
      pos: [7, 6, 5],
      state: 18
    },
    {
      pos: [0, 7, 5],
      state: 11
    },
    {
      pos: [1, 7, 5],
      state: 11
    },
    {
      pos: [2, 7, 5],
      state: 17
    },
    {
      pos: [6, 7, 5],
      state: 18
    },
    {
      pos: [7, 7, 5],
      state: 11
    },
    {
      pos: [0, 0, 6],
      state: 12
    },
    {
      pos: [1, 0, 6],
      state: 12
    },
    {
      pos: [2, 0, 6],
      state: 12
    },
    {
      pos: [3, 0, 6],
      state: 12
    },
    {
      pos: [4, 0, 6],
      state: 12
    },
    {
      pos: [5, 0, 6],
      state: 11
    },
    {
      pos: [6, 0, 6],
      state: 11
    },
    {
      pos: [7, 0, 6],
      state: 12
    },
    {
      pos: [0, 1, 6],
      state: 11
    },
    {
      pos: [1, 1, 6],
      state: 11
    },
    {
      pos: [2, 1, 6],
      state: 11
    },
    {
      pos: [3, 1, 6],
      state: 11
    },
    {
      pos: [4, 1, 6],
      state: 11
    },
    {
      pos: [5, 1, 6],
      state: 11
    },
    {
      pos: [6, 1, 6],
      state: 11
    },
    {
      pos: [7, 1, 6],
      state: 11
    },
    {
      pos: [0, 2, 6],
      state: 11
    },
    {
      pos: [1, 2, 6],
      state: 11
    },
    {
      pos: [2, 2, 6],
      state: 20
    },
    {
      pos: [7, 2, 6],
      state: 11
    },
    {
      pos: [0, 3, 6],
      state: 11
    },
    {
      pos: [1, 3, 6],
      state: 11
    },
    {
      pos: [2, 3, 6],
      state: 11
    },
    {
      pos: [7, 3, 6],
      state: 11
    },
    {
      pos: [0, 4, 6],
      state: 11
    },
    {
      pos: [1, 4, 6],
      state: 11
    },
    {
      pos: [2, 4, 6],
      state: 11
    },
    {
      pos: [4, 4, 6],
      state: 11
    },
    {
      pos: [5, 4, 6],
      state: 21
    },
    {
      pos: [7, 4, 6],
      state: 11
    },
    {
      pos: [0, 5, 6],
      state: 11
    },
    {
      pos: [1, 5, 6],
      state: 11
    },
    {
      pos: [2, 5, 6],
      state: 11
    },
    {
      pos: [4, 5, 6],
      state: 11
    },
    {
      pos: [5, 5, 6],
      state: 11
    },
    {
      pos: [7, 5, 6],
      state: 11
    },
    {
      pos: [0, 6, 6],
      state: 11
    },
    {
      pos: [1, 6, 6],
      state: 17
    },
    {
      pos: [4, 6, 6],
      state: 11
    },
    {
      pos: [5, 6, 6],
      state: 11
    },
    {
      pos: [7, 6, 6],
      state: 18
    },
    {
      pos: [0, 7, 6],
      state: 11
    },
    {
      pos: [1, 7, 6],
      state: 11
    },
    {
      pos: [2, 7, 6],
      state: 17
    },
    {
      pos: [6, 7, 6],
      state: 18
    },
    {
      pos: [7, 7, 6],
      state: 11
    },
    {
      pos: [0, 0, 7],
      state: 11
    },
    {
      pos: [1, 0, 7],
      state: 11
    },
    {
      pos: [2, 0, 7],
      state: 16
    },
    {
      pos: [3, 0, 7],
      state: 12
    },
    {
      pos: [4, 0, 7],
      state: 16
    },
    {
      pos: [5, 0, 7],
      state: 11
    },
    {
      pos: [6, 0, 7],
      state: 16
    },
    {
      pos: [7, 0, 7],
      state: 12
    },
    {
      pos: [0, 1, 7],
      state: 11
    },
    {
      pos: [1, 1, 7],
      state: 11
    },
    {
      pos: [2, 1, 7],
      state: 16
    },
    {
      pos: [3, 1, 7],
      state: 11
    },
    {
      pos: [4, 1, 7],
      state: 16
    },
    {
      pos: [5, 1, 7],
      state: 11
    },
    {
      pos: [6, 1, 7],
      state: 16
    },
    {
      pos: [7, 1, 7],
      state: 11
    },
    {
      pos: [0, 2, 7],
      state: 11
    },
    {
      pos: [1, 2, 7],
      state: 11
    },
    {
      pos: [7, 2, 7],
      state: 11
    },
    {
      pos: [0, 3, 7],
      state: 11
    },
    {
      pos: [1, 3, 7],
      state: 11
    },
    {
      pos: [7, 3, 7],
      state: 11
    },
    {
      pos: [0, 4, 7],
      state: 11
    },
    {
      pos: [1, 4, 7],
      state: 11
    },
    {
      pos: [7, 4, 7],
      state: 11
    },
    {
      pos: [0, 5, 7],
      state: 11
    },
    {
      pos: [1, 5, 7],
      state: 11
    },
    {
      pos: [7, 5, 7],
      state: 11
    },
    {
      pos: [0, 6, 7],
      state: 11
    },
    {
      pos: [1, 6, 7],
      state: 17
    },
    {
      pos: [7, 6, 7],
      state: 18
    },
    {
      pos: [0, 7, 7],
      state: 11
    },
    {
      pos: [1, 7, 7],
      state: 11
    },
    {
      pos: [2, 7, 7],
      state: 29
    },
    {
      pos: [3, 7, 7],
      state: 30
    },
    {
      pos: [4, 7, 7],
      state: 30
    },
    {
      pos: [5, 7, 7],
      state: 30
    },
    {
      pos: [6, 7, 7],
      state: 31
    },
    {
      pos: [7, 7, 7],
      state: 11
    },
    {
      pos: [0, 0, 8],
      state: 11
    },
    {
      pos: [1, 0, 8],
      state: 11
    },
    {
      pos: [2, 0, 8],
      state: 11
    },
    {
      pos: [3, 0, 8],
      state: 12
    },
    {
      pos: [4, 0, 8],
      state: 11
    },
    {
      pos: [5, 0, 8],
      state: 11
    },
    {
      pos: [6, 0, 8],
      state: 11
    },
    {
      pos: [7, 0, 8],
      state: 11
    },
    {
      pos: [0, 1, 8],
      state: 11
    },
    {
      pos: [1, 1, 8],
      state: 11
    },
    {
      pos: [2, 1, 8],
      state: 11
    },
    {
      pos: [3, 1, 8],
      state: 11
    },
    {
      pos: [4, 1, 8],
      state: 11
    },
    {
      pos: [5, 1, 8],
      state: 11
    },
    {
      pos: [6, 1, 8],
      state: 11
    },
    {
      pos: [7, 1, 8],
      state: 11
    },
    {
      pos: [0, 2, 8],
      state: 11
    },
    {
      pos: [1, 2, 8],
      state: 11
    },
    {
      pos: [2, 2, 8],
      state: 11
    },
    {
      pos: [3, 2, 8],
      state: 11
    },
    {
      pos: [4, 2, 8],
      state: 11
    },
    {
      pos: [5, 2, 8],
      state: 11
    },
    {
      pos: [6, 2, 8],
      state: 11
    },
    {
      pos: [7, 2, 8],
      state: 11
    },
    {
      pos: [0, 3, 8],
      state: 11
    },
    {
      pos: [1, 3, 8],
      state: 11
    },
    {
      pos: [2, 3, 8],
      state: 11
    },
    {
      pos: [6, 3, 8],
      state: 11
    },
    {
      pos: [7, 3, 8],
      state: 11
    },
    {
      pos: [0, 4, 8],
      state: 11
    },
    {
      pos: [1, 4, 8],
      state: 11
    },
    {
      pos: [2, 4, 8],
      state: 11
    },
    {
      pos: [3, 4, 8],
      state: 11
    },
    {
      pos: [4, 4, 8],
      state: 11
    },
    {
      pos: [5, 4, 8],
      state: 11
    },
    {
      pos: [6, 4, 8],
      state: 11
    },
    {
      pos: [7, 4, 8],
      state: 11
    },
    {
      pos: [0, 5, 8],
      state: 11
    },
    {
      pos: [1, 5, 8],
      state: 11
    },
    {
      pos: [2, 5, 8],
      state: 11
    },
    {
      pos: [3, 5, 8],
      state: 11
    },
    {
      pos: [4, 5, 8],
      state: 11
    },
    {
      pos: [5, 5, 8],
      state: 11
    },
    {
      pos: [6, 5, 8],
      state: 11
    },
    {
      pos: [7, 5, 8],
      state: 11
    },
    {
      pos: [0, 6, 8],
      state: 11
    },
    {
      pos: [1, 6, 8],
      state: 32
    },
    {
      pos: [2, 6, 8],
      state: 30
    },
    {
      pos: [3, 6, 8],
      state: 30
    },
    {
      pos: [4, 6, 8],
      state: 30
    },
    {
      pos: [5, 6, 8],
      state: 30
    },
    {
      pos: [6, 6, 8],
      state: 30
    },
    {
      pos: [7, 6, 8],
      state: 33
    },
    {
      pos: [0, 7, 8],
      state: 11
    },
    {
      pos: [1, 7, 8],
      state: 11
    },
    {
      pos: [2, 7, 8],
      state: 11
    },
    {
      pos: [3, 7, 8],
      state: 11
    },
    {
      pos: [4, 7, 8],
      state: 11
    },
    {
      pos: [5, 7, 8],
      state: 11
    },
    {
      pos: [6, 7, 8],
      state: 11
    },
    {
      pos: [7, 7, 8],
      state: 11
    }
  ],
  palette: [
    {
      Properties: {
        waterlogged: "false",
        type: "double"
      },
      Name: "minecraft:acacia_slab"
    },
    {
      Properties: {
        axis: "y"
      },
      Name: "minecraft:acacia_wood"
    },
    {
      Properties: {
        axis: "z"
      },
      Name: "minecraft:acacia_log"
    },
    {
      Name: "minecraft:acacia_planks"
    },
    {
      Properties: {
        axis: "x"
      },
      Name: "minecraft:acacia_log"
    },
    {
      Name: "minecraft:cartography_table"
    },
    {
      Properties: {
        facing: "north"
      },
      Name: "minecraft:brown_wall_banner"
    },
    {
      Properties: {
        facing: "west"
      },
      Name: "minecraft:brown_wall_banner"
    },
    {
      Properties: {
        facing: "west"
      },
      Name: "minecraft:jigsaw"
    },
    {
      Properties: {
        waterlogged: "false",
        facing: "north",
        type: "single"
      },
      Name: "minecraft:chest"
    },
    {
      Properties: {
        facing: "south"
      },
      Name: "minecraft:brown_wall_banner"
    },
    {
      Name: "minecraft:air"
    },
    {
      Name: "minecraft:grass"
    },
    {
      Properties: {
        half: "bottom",
        waterlogged: "false",
        shape: "outer_right",
        facing: "east"
      },
      Name: "minecraft:acacia_stairs"
    },
    {
      Properties: {
        half: "bottom",
        waterlogged: "false",
        shape: "straight",
        facing: "south"
      },
      Name: "minecraft:acacia_stairs"
    },
    {
      Properties: {
        half: "bottom",
        waterlogged: "false",
        shape: "outer_left",
        facing: "west"
      },
      Name: "minecraft:acacia_stairs"
    },
    {
      Properties: {
        east: "false",
        waterlogged: "false",
        south: "false",
        north: "false",
        west: "false"
      },
      Name: "minecraft:acacia_fence"
    },
    {
      Properties: {
        half: "bottom",
        waterlogged: "false",
        shape: "straight",
        facing: "east"
      },
      Name: "minecraft:acacia_stairs"
    },
    {
      Properties: {
        half: "bottom",
        waterlogged: "false",
        shape: "straight",
        facing: "west"
      },
      Name: "minecraft:acacia_stairs"
    },
    {
      Properties: {
        half: "bottom",
        waterlogged: "false",
        shape: "outer_right",
        facing: "south"
      },
      Name: "minecraft:acacia_stairs"
    },
    {
      Properties: {
        waterlogged: "false",
        type: "bottom"
      },
      Name: "minecraft:acacia_slab"
    },
    {
      Name: "minecraft:torch"
    },
    {
      Properties: {
        east: "false",
        waterlogged: "false",
        south: "false",
        north: "false",
        west: "true"
      },
      Name: "minecraft:acacia_fence"
    },
    {
      Properties: {
        east: "false",
        waterlogged: "false",
        south: "true",
        north: "false",
        west: "true"
      },
      Name: "minecraft:acacia_fence"
    },
    {
      Properties: {
        east: "false",
        waterlogged: "false",
        south: "true",
        north: "true",
        west: "false"
      },
      Name: "minecraft:glass_pane"
    },
    {
      Properties: {
        hinge: "right",
        half: "lower",
        powered: "false",
        facing: "east",
        open: "false"
      },
      Name: "minecraft:acacia_door"
    },
    {
      Properties: {
        hinge: "right",
        half: "upper",
        powered: "false",
        facing: "east",
        open: "false"
      },
      Name: "minecraft:acacia_door"
    },
    {
      Properties: {
        facing: "west"
      },
      Name: "minecraft:wall_torch"
    },
    {
      Properties: {
        east: "false",
        waterlogged: "false",
        south: "false",
        north: "true",
        west: "true"
      },
      Name: "minecraft:acacia_fence"
    },
    {
      Properties: {
        half: "bottom",
        waterlogged: "false",
        shape: "outer_right",
        facing: "north"
      },
      Name: "minecraft:acacia_stairs"
    },
    {
      Properties: {
        half: "bottom",
        waterlogged: "false",
        shape: "straight",
        facing: "north"
      },
      Name: "minecraft:acacia_stairs"
    },
    {
      Properties: {
        half: "bottom",
        waterlogged: "false",
        shape: "outer_right",
        facing: "west"
      },
      Name: "minecraft:acacia_stairs"
    },
    {
      Properties: {
        half: "bottom",
        waterlogged: "false",
        shape: "outer_left",
        facing: "east"
      },
      Name: "minecraft:acacia_stairs"
    },
    {
      Properties: {
        half: "bottom",
        waterlogged: "false",
        shape: "outer_left",
        facing: "north"
      },
      Name: "minecraft:acacia_stairs"
    }
  ],
  DataVersion: 1910
}