{
  size: [7, 3, 9],
  entities: [],
  blocks: [
    {
      pos: [3, 0, 0],
      state: 0
    },
    {
      pos: [2, 0, 1],
      state: 0
    },
    {
      pos: [3, 0, 1],
      state: 0
    },
    {
      pos: [4, 0, 1],
      state: 0
    },
    {
      pos: [5, 0, 1],
      state: 0
    },
    {
      pos: [3, 1, 1],
      state: 0
    },
    {
      pos: [5, 0, 2],
      state: 0
    },
    {
      pos: [6, 0, 2],
      state: 0
    },
    {
      pos: [6, 0, 3],
      state: 0
    },
    {
      pos: [0, 0, 4],
      state: 0
    },
    {
      pos: [3, 0, 4],
      state: 0
    },
    {
      pos: [6, 0, 4],
      state: 0
    },
    {
      pos: [1, 0, 5],
      state: 0
    },
    {
      pos: [6, 0, 5],
      state: 0
    },
    {
      pos: [0, 0, 6],
      state: 0
    },
    {
      pos: [1, 0, 6],
      state: 0
    },
    {
      pos: [5, 0, 6],
      state: 0
    },
    {
      pos: [1, 1, 6],
      state: 0
    },
    {
      pos: [5, 1, 6],
      state: 0
    },
    {
      pos: [3, 0, 7],
      state: 0
    },
    {
      pos: [4, 0, 7],
      state: 0
    },
    {
      pos: [5, 0, 7],
      state: 0
    },
    {
      pos: [1, 0, 8],
      state: 0
    },
    {
      pos: [2, 0, 8],
      state: 0
    },
    {
      pos: [3, 0, 8],
      state: 0
    },
    {
      nbt: {
        target_pool: "minecraft:empty",
        final_state: "minecraft:snow_block",
        id: "minecraft:jigsaw",
        attachement_type: "minecraft:building_entrance"
      },
      pos: [0, 0, 3],
      state: 1
    },
    {
      pos: [0, 0, 0],
      state: 2
    },
    {
      pos: [1, 0, 0],
      state: 2
    },
    {
      pos: [2, 0, 0],
      state: 2
    },
    {
      pos: [4, 0, 0],
      state: 2
    },
    {
      pos: [5, 0, 0],
      state: 2
    },
    {
      pos: [6, 0, 0],
      state: 2
    },
    {
      pos: [0, 1, 0],
      state: 3
    },
    {
      pos: [1, 1, 0],
      state: 3
    },
    {
      pos: [2, 1, 0],
      state: 3
    },
    {
      pos: [3, 1, 0],
      state: 3
    },
    {
      pos: [4, 1, 0],
      state: 3
    },
    {
      pos: [5, 1, 0],
      state: 3
    },
    {
      pos: [6, 1, 0],
      state: 3
    },
    {
      pos: [0, 2, 0],
      state: 3
    },
    {
      pos: [1, 2, 0],
      state: 3
    },
    {
      pos: [2, 2, 0],
      state: 3
    },
    {
      pos: [3, 2, 0],
      state: 3
    },
    {
      pos: [4, 2, 0],
      state: 3
    },
    {
      pos: [5, 2, 0],
      state: 3
    },
    {
      pos: [6, 2, 0],
      state: 3
    },
    {
      pos: [0, 0, 1],
      state: 2
    },
    {
      pos: [1, 0, 1],
      state: 4
    },
    {
      pos: [6, 0, 1],
      state: 2
    },
    {
      pos: [0, 1, 1],
      state: 3
    },
    {
      pos: [1, 1, 1],
      state: 3
    },
    {
      pos: [2, 1, 1],
      state: 5
    },
    {
      pos: [4, 1, 1],
      state: 3
    },
    {
      pos: [5, 1, 1],
      state: 3
    },
    {
      pos: [6, 1, 1],
      state: 3
    },
    {
      pos: [0, 2, 1],
      state: 3
    },
    {
      pos: [1, 2, 1],
      state: 3
    },
    {
      pos: [2, 2, 1],
      state: 3
    },
    {
      pos: [3, 2, 1],
      state: 3
    },
    {
      pos: [4, 2, 1],
      state: 3
    },
    {
      pos: [5, 2, 1],
      state: 3
    },
    {
      pos: [6, 2, 1],
      state: 3
    },
    {
      pos: [0, 0, 2],
      state: 6
    },
    {
      pos: [1, 0, 2],
      state: 7
    },
    {
      pos: [2, 0, 2],
      state: 7
    },
    {
      pos: [3, 0, 2],
      state: 7
    },
    {
      pos: [4, 0, 2],
      state: 8
    },
    {
      pos: [0, 1, 2],
      state: 3
    },
    {
      pos: [1, 1, 2],
      state: 9
    },
    {
      pos: [2, 1, 2],
      state: 10
    },
    {
      pos: [3, 1, 2],
      state: 9
    },
    {
      pos: [4, 1, 2],
      state: 9
    },
    {
      pos: [5, 1, 2],
      state: 5
    },
    {
      pos: [6, 1, 2],
      state: 3
    },
    {
      pos: [0, 2, 2],
      state: 3
    },
    {
      pos: [1, 2, 2],
      state: 3
    },
    {
      pos: [2, 2, 2],
      state: 3
    },
    {
      pos: [3, 2, 2],
      state: 3
    },
    {
      pos: [4, 2, 2],
      state: 3
    },
    {
      pos: [5, 2, 2],
      state: 3
    },
    {
      pos: [6, 2, 2],
      state: 3
    },
    {
      pos: [1, 0, 3],
      state: 7
    },
    {
      pos: [2, 0, 3],
      state: 11
    },
    {
      pos: [3, 0, 3],
      state: 12
    },
    {
      pos: [4, 0, 3],
      state: 7
    },
    {
      pos: [5, 0, 3],
      state: 8
    },
    {
      pos: [0, 1, 3],
      state: 3
    },
    {
      pos: [1, 1, 3],
      state: 9
    },
    {
      pos: [2, 1, 3],
      state: 9
    },
    {
      pos: [3, 1, 3],
      state: 3
    },
    {
      pos: [4, 1, 3],
      state: 9
    },
    {
      pos: [5, 1, 3],
      state: 9
    },
    {
      pos: [6, 1, 3],
      state: 3
    },
    {
      pos: [0, 2, 3],
      state: 3
    },
    {
      pos: [1, 2, 3],
      state: 3
    },
    {
      pos: [2, 2, 3],
      state: 3
    },
    {
      pos: [3, 2, 3],
      state: 3
    },
    {
      pos: [4, 2, 3],
      state: 3
    },
    {
      pos: [5, 2, 3],
      state: 3
    },
    {
      pos: [6, 2, 3],
      state: 3
    },
    {
      pos: [1, 0, 4],
      state: 8
    },
    {
      pos: [2, 0, 4],
      state: 8
    },
    {
      pos: [4, 0, 4],
      state: 7
    },
    {
      pos: [5, 0, 4],
      state: 7
    },
    {
      pos: [0, 1, 4],
      state: 3
    },
    {
      pos: [1, 1, 4],
      state: 9
    },
    {
      pos: [2, 1, 4],
      state: 9
    },
    {
      pos: [3, 1, 4],
      state: 13
    },
    {
      pos: [4, 1, 4],
      state: 9
    },
    {
      pos: [5, 1, 4],
      state: 9
    },
    {
      pos: [6, 1, 4],
      state: 3
    },
    {
      pos: [0, 2, 4],
      state: 3
    },
    {
      pos: [1, 2, 4],
      state: 3
    },
    {
      pos: [2, 2, 4],
      state: 3
    },
    {
      pos: [3, 2, 4],
      state: 3
    },
    {
      pos: [4, 2, 4],
      state: 3
    },
    {
      pos: [5, 2, 4],
      state: 3
    },
    {
      pos: [6, 2, 4],
      state: 3
    },
    {
      pos: [0, 0, 5],
      state: 14
    },
    {
      pos: [2, 0, 5],
      state: 7
    },
    {
      pos: [3, 0, 5],
      state: 12
    },
    {
      pos: [4, 0, 5],
      state: 7
    },
    {
      pos: [5, 0, 5],
      state: 8
    },
    {
      pos: [0, 1, 5],
      state: 3
    },
    {
      pos: [1, 1, 5],
      state: 3
    },
    {
      pos: [2, 1, 5],
      state: 9
    },
    {
      pos: [3, 1, 5],
      state: 3
    },
    {
      pos: [4, 1, 5],
      state: 9
    },
    {
      pos: [5, 1, 5],
      state: 9
    },
    {
      pos: [6, 1, 5],
      state: 3
    },
    {
      pos: [0, 2, 5],
      state: 3
    },
    {
      pos: [1, 2, 5],
      state: 3
    },
    {
      pos: [2, 2, 5],
      state: 3
    },
    {
      pos: [3, 2, 5],
      state: 3
    },
    {
      pos: [4, 2, 5],
      state: 3
    },
    {
      pos: [5, 2, 5],
      state: 3
    },
    {
      pos: [6, 2, 5],
      state: 3
    },
    {
      pos: [2, 0, 6],
      state: 7
    },
    {
      pos: [3, 0, 6],
      state: 7
    },
    {
      pos: [4, 0, 6],
      state: 7
    },
    {
      pos: [6, 0, 6],
      state: 14
    },
    {
      pos: [0, 1, 6],
      state: 2
    },
    {
      pos: [2, 1, 6],
      state: 9
    },
    {
      pos: [3, 1, 6],
      state: 9
    },
    {
      pos: [4, 1, 6],
      state: 9
    },
    {
      pos: [6, 1, 6],
      state: 3
    },
    {
      pos: [0, 2, 6],
      state: 3
    },
    {
      pos: [1, 2, 6],
      state: 3
    },
    {
      pos: [2, 2, 6],
      state: 3
    },
    {
      pos: [3, 2, 6],
      state: 3
    },
    {
      pos: [4, 2, 6],
      state: 3
    },
    {
      pos: [5, 2, 6],
      state: 3
    },
    {
      pos: [6, 2, 6],
      state: 3
    },
    {
      pos: [0, 0, 7],
      state: 2
    },
    {
      pos: [1, 0, 7],
      state: 14
    },
    {
      pos: [2, 0, 7],
      state: 8
    },
    {
      pos: [6, 0, 7],
      state: 2
    },
    {
      pos: [0, 1, 7],
      state: 3
    },
    {
      pos: [1, 1, 7],
      state: 3
    },
    {
      pos: [2, 1, 7],
      state: 9
    },
    {
      pos: [3, 1, 7],
      state: 3
    },
    {
      pos: [4, 1, 7],
      state: 3
    },
    {
      pos: [5, 1, 7],
      state: 3
    },
    {
      pos: [6, 1, 7],
      state: 3
    },
    {
      pos: [0, 2, 7],
      state: 3
    },
    {
      pos: [1, 2, 7],
      state: 3
    },
    {
      pos: [2, 2, 7],
      state: 3
    },
    {
      pos: [3, 2, 7],
      state: 3
    },
    {
      pos: [4, 2, 7],
      state: 3
    },
    {
      pos: [5, 2, 7],
      state: 3
    },
    {
      pos: [6, 2, 7],
      state: 3
    },
    {
      pos: [0, 0, 8],
      state: 2
    },
    {
      pos: [4, 0, 8],
      state: 4
    },
    {
      pos: [5, 0, 8],
      state: 2
    },
    {
      pos: [6, 0, 8],
      state: 2
    },
    {
      pos: [0, 1, 8],
      state: 3
    },
    {
      pos: [1, 1, 8],
      state: 3
    },
    {
      pos: [2, 1, 8],
      state: 3
    },
    {
      pos: [3, 1, 8],
      state: 3
    },
    {
      pos: [4, 1, 8],
      state: 3
    },
    {
      pos: [5, 1, 8],
      state: 3
    },
    {
      pos: [6, 1, 8],
      state: 3
    },
    {
      pos: [0, 2, 8],
      state: 3
    },
    {
      pos: [1, 2, 8],
      state: 3
    },
    {
      pos: [2, 2, 8],
      state: 3
    },
    {
      pos: [3, 2, 8],
      state: 3
    },
    {
      pos: [4, 2, 8],
      state: 3
    },
    {
      pos: [5, 2, 8],
      state: 3
    },
    {
      pos: [6, 2, 8],
      state: 3
    }
  ],
  palette: [
    {
      Name: "minecraft:snow_block"
    },
    {
      Properties: {
        facing: "west"
      },
      Name: "minecraft:jigsaw"
    },
    {
      Properties: {
        layers: "1"
      },
      Name: "minecraft:snow"
    },
    {
      Name: "minecraft:air"
    },
    {
      Properties: {
        layers: "5"
      },
      Name: "minecraft:snow"
    },
    {
      Properties: {
        layers: "2"
      },
      Name: "minecraft:snow"
    },
    {
      Properties: {
        half: "bottom",
        waterlogged: "false",
        shape: "straight",
        facing: "east"
      },
      Name: "minecraft:spruce_stairs"
    },
    {
      Properties: {
        moisture: "7"
      },
      Name: "minecraft:farmland"
    },
    {
      Properties: {
        moisture: "0"
      },
      Name: "minecraft:farmland"
    },
    {
      Properties: {
        age: "0"
      },
      Name: "minecraft:potatoes"
    },
    {
      Properties: {
        age: "1"
      },
      Name: "minecraft:potatoes"
    },
    {
      Properties: {
        moisture: "6"
      },
      Name: "minecraft:farmland"
    },
    {
      Properties: {
        level: "0"
      },
      Name: "minecraft:water"
    },
    {
      Properties: {
        hanging: "false"
      },
      Name: "minecraft:lantern"
    },
    {
      Properties: {
        layers: "4"
      },
      Name: "minecraft:snow"
    }
  ],
  DataVersion: 1913
}