{
  size: [7, 10, 11],
  entities: [],
  blocks: [
    {
      pos: [0, 6, 0],
      state: 0
    },
    {
      pos: [6, 6, 0],
      state: 0
    },
    {
      pos: [1, 7, 0],
      state: 0
    },
    {
      pos: [5, 7, 0],
      state: 0
    },
    {
      pos: [2, 8, 0],
      state: 0
    },
    {
      pos: [4, 8, 0],
      state: 0
    },
    {
      pos: [3, 9, 0],
      state: 0
    },
    {
      pos: [1, 0, 1],
      state: 1
    },
    {
      pos: [2, 0, 1],
      state: 2
    },
    {
      pos: [3, 0, 1],
      state: 2
    },
    {
      pos: [4, 0, 1],
      state: 2
    },
    {
      pos: [5, 0, 1],
      state: 1
    },
    {
      pos: [1, 1, 1],
      state: 1
    },
    {
      pos: [2, 1, 1],
      state: 2
    },
    {
      pos: [4, 1, 1],
      state: 2
    },
    {
      pos: [5, 1, 1],
      state: 1
    },
    {
      pos: [1, 2, 1],
      state: 1
    },
    {
      pos: [2, 2, 1],
      state: 2
    },
    {
      pos: [3, 2, 1],
      state: 2
    },
    {
      pos: [4, 2, 1],
      state: 2
    },
    {
      pos: [5, 2, 1],
      state: 1
    },
    {
      pos: [1, 3, 1],
      state: 1
    },
    {
      pos: [2, 3, 1],
      state: 1
    },
    {
      pos: [3, 3, 1],
      state: 1
    },
    {
      pos: [4, 3, 1],
      state: 1
    },
    {
      pos: [5, 3, 1],
      state: 1
    },
    {
      pos: [1, 4, 1],
      state: 1
    },
    {
      pos: [2, 4, 1],
      state: 0
    },
    {
      pos: [3, 4, 1],
      state: 0
    },
    {
      pos: [4, 4, 1],
      state: 0
    },
    {
      pos: [5, 4, 1],
      state: 1
    },
    {
      pos: [1, 5, 1],
      state: 1
    },
    {
      pos: [2, 5, 1],
      state: 0
    },
    {
      pos: [4, 5, 1],
      state: 0
    },
    {
      pos: [5, 5, 1],
      state: 1
    },
    {
      pos: [0, 6, 1],
      state: 0
    },
    {
      pos: [1, 6, 1],
      state: 1
    },
    {
      pos: [2, 6, 1],
      state: 0
    },
    {
      pos: [3, 6, 1],
      state: 0
    },
    {
      pos: [4, 6, 1],
      state: 0
    },
    {
      pos: [5, 6, 1],
      state: 1
    },
    {
      pos: [6, 6, 1],
      state: 0
    },
    {
      pos: [1, 7, 1],
      state: 0
    },
    {
      pos: [2, 7, 1],
      state: 0
    },
    {
      pos: [3, 7, 1],
      state: 0
    },
    {
      pos: [4, 7, 1],
      state: 0
    },
    {
      pos: [5, 7, 1],
      state: 0
    },
    {
      pos: [2, 8, 1],
      state: 0
    },
    {
      pos: [3, 8, 1],
      state: 0
    },
    {
      pos: [4, 8, 1],
      state: 0
    },
    {
      pos: [3, 9, 1],
      state: 0
    },
    {
      pos: [1, 0, 2],
      state: 2
    },
    {
      pos: [5, 0, 2],
      state: 2
    },
    {
      pos: [1, 1, 2],
      state: 2
    },
    {
      pos: [5, 1, 2],
      state: 2
    },
    {
      pos: [1, 2, 2],
      state: 2
    },
    {
      pos: [4, 2, 2],
      state: 2
    },
    {
      pos: [5, 2, 2],
      state: 2
    },
    {
      pos: [1, 3, 2],
      state: 3
    },
    {
      pos: [2, 3, 2],
      state: 0
    },
    {
      pos: [4, 3, 2],
      state: 0
    },
    {
      pos: [5, 3, 2],
      state: 1
    },
    {
      pos: [1, 4, 2],
      state: 0
    },
    {
      pos: [5, 4, 2],
      state: 0
    },
    {
      pos: [1, 5, 2],
      state: 0
    },
    {
      pos: [5, 5, 2],
      state: 0
    },
    {
      pos: [0, 6, 2],
      state: 0
    },
    {
      pos: [1, 6, 2],
      state: 0
    },
    {
      pos: [5, 6, 2],
      state: 0
    },
    {
      pos: [6, 6, 2],
      state: 0
    },
    {
      pos: [1, 7, 2],
      state: 0
    },
    {
      pos: [5, 7, 2],
      state: 0
    },
    {
      pos: [2, 8, 2],
      state: 0
    },
    {
      pos: [4, 8, 2],
      state: 0
    },
    {
      pos: [3, 9, 2],
      state: 0
    },
    {
      pos: [1, 0, 3],
      state: 2
    },
    {
      pos: [5, 0, 3],
      state: 2
    },
    {
      pos: [1, 2, 3],
      state: 2
    },
    {
      pos: [4, 2, 3],
      state: 2
    },
    {
      pos: [5, 2, 3],
      state: 2
    },
    {
      pos: [1, 3, 3],
      state: 3
    },
    {
      pos: [2, 3, 3],
      state: 0
    },
    {
      pos: [3, 3, 3],
      state: 0
    },
    {
      pos: [5, 3, 3],
      state: 1
    },
    {
      pos: [1, 4, 3],
      state: 0
    },
    {
      pos: [5, 4, 3],
      state: 0
    },
    {
      pos: [0, 6, 3],
      state: 0
    },
    {
      pos: [1, 6, 3],
      state: 0
    },
    {
      pos: [5, 6, 3],
      state: 0
    },
    {
      pos: [6, 6, 3],
      state: 0
    },
    {
      pos: [1, 7, 3],
      state: 0
    },
    {
      pos: [5, 7, 3],
      state: 0
    },
    {
      pos: [2, 8, 3],
      state: 0
    },
    {
      pos: [4, 8, 3],
      state: 0
    },
    {
      pos: [3, 9, 3],
      state: 0
    },
    {
      pos: [1, 0, 4],
      state: 2
    },
    {
      pos: [4, 0, 4],
      state: 2
    },
    {
      pos: [5, 0, 4],
      state: 2
    },
    {
      pos: [1, 1, 4],
      state: 2
    },
    {
      pos: [4, 1, 4],
      state: 2
    },
    {
      pos: [5, 1, 4],
      state: 2
    },
    {
      pos: [1, 2, 4],
      state: 2
    },
    {
      pos: [5, 2, 4],
      state: 2
    },
    {
      pos: [1, 3, 4],
      state: 3
    },
    {
      pos: [2, 3, 4],
      state: 0
    },
    {
      pos: [3, 3, 4],
      state: 0
    },
    {
      pos: [5, 3, 4],
      state: 1
    },
    {
      pos: [1, 4, 4],
      state: 0
    },
    {
      pos: [5, 4, 4],
      state: 0
    },
    {
      pos: [1, 5, 4],
      state: 0
    },
    {
      pos: [5, 5, 4],
      state: 0
    },
    {
      pos: [0, 6, 4],
      state: 0
    },
    {
      pos: [1, 6, 4],
      state: 0
    },
    {
      pos: [5, 6, 4],
      state: 0
    },
    {
      pos: [6, 6, 4],
      state: 0
    },
    {
      pos: [1, 7, 4],
      state: 0
    },
    {
      pos: [5, 7, 4],
      state: 0
    },
    {
      pos: [2, 8, 4],
      state: 0
    },
    {
      pos: [4, 8, 4],
      state: 0
    },
    {
      pos: [3, 9, 4],
      state: 0
    },
    {
      pos: [4, 0, 5],
      state: 2
    },
    {
      pos: [5, 0, 5],
      state: 1
    },
    {
      pos: [5, 1, 5],
      state: 1
    },
    {
      pos: [1, 2, 5],
      state: 2
    },
    {
      pos: [5, 2, 5],
      state: 1
    },
    {
      pos: [1, 3, 5],
      state: 3
    },
    {
      pos: [2, 3, 5],
      state: 0
    },
    {
      pos: [3, 3, 5],
      state: 0
    },
    {
      pos: [5, 3, 5],
      state: 1
    },
    {
      pos: [1, 4, 5],
      state: 1
    },
    {
      pos: [5, 4, 5],
      state: 1
    },
    {
      pos: [1, 5, 5],
      state: 1
    },
    {
      pos: [5, 5, 5],
      state: 1
    },
    {
      pos: [0, 6, 5],
      state: 0
    },
    {
      pos: [1, 6, 5],
      state: 1
    },
    {
      pos: [5, 6, 5],
      state: 1
    },
    {
      pos: [6, 6, 5],
      state: 0
    },
    {
      pos: [1, 7, 5],
      state: 0
    },
    {
      pos: [5, 7, 5],
      state: 0
    },
    {
      pos: [2, 8, 5],
      state: 0
    },
    {
      pos: [4, 8, 5],
      state: 0
    },
    {
      pos: [3, 9, 5],
      state: 0
    },
    {
      pos: [1, 0, 6],
      state: 2
    },
    {
      pos: [5, 0, 6],
      state: 2
    },
    {
      pos: [1, 1, 6],
      state: 2
    },
    {
      pos: [5, 1, 6],
      state: 2
    },
    {
      pos: [1, 2, 6],
      state: 2
    },
    {
      pos: [5, 2, 6],
      state: 2
    },
    {
      pos: [1, 3, 6],
      state: 3
    },
    {
      pos: [2, 3, 6],
      state: 0
    },
    {
      pos: [3, 3, 6],
      state: 0
    },
    {
      pos: [5, 3, 6],
      state: 1
    },
    {
      pos: [1, 4, 6],
      state: 0
    },
    {
      pos: [5, 4, 6],
      state: 0
    },
    {
      pos: [1, 5, 6],
      state: 0
    },
    {
      pos: [5, 5, 6],
      state: 0
    },
    {
      pos: [0, 6, 6],
      state: 0
    },
    {
      pos: [1, 6, 6],
      state: 0
    },
    {
      pos: [5, 6, 6],
      state: 0
    },
    {
      pos: [6, 6, 6],
      state: 0
    },
    {
      pos: [1, 7, 6],
      state: 0
    },
    {
      pos: [5, 7, 6],
      state: 0
    },
    {
      pos: [2, 8, 6],
      state: 0
    },
    {
      pos: [4, 8, 6],
      state: 0
    },
    {
      pos: [3, 9, 6],
      state: 0
    },
    {
      pos: [1, 0, 7],
      state: 2
    },
    {
      pos: [5, 0, 7],
      state: 2
    },
    {
      pos: [1, 2, 7],
      state: 2
    },
    {
      pos: [5, 2, 7],
      state: 2
    },
    {
      pos: [1, 3, 7],
      state: 3
    },
    {
      pos: [2, 3, 7],
      state: 0
    },
    {
      pos: [3, 3, 7],
      state: 0
    },
    {
      pos: [4, 3, 7],
      state: 0
    },
    {
      pos: [5, 3, 7],
      state: 1
    },
    {
      pos: [1, 4, 7],
      state: 0
    },
    {
      pos: [5, 4, 7],
      state: 0
    },
    {
      pos: [0, 6, 7],
      state: 0
    },
    {
      pos: [1, 6, 7],
      state: 0
    },
    {
      pos: [5, 6, 7],
      state: 0
    },
    {
      pos: [6, 6, 7],
      state: 0
    },
    {
      pos: [1, 7, 7],
      state: 0
    },
    {
      pos: [5, 7, 7],
      state: 0
    },
    {
      pos: [2, 8, 7],
      state: 0
    },
    {
      pos: [4, 8, 7],
      state: 0
    },
    {
      pos: [3, 9, 7],
      state: 0
    },
    {
      pos: [1, 0, 8],
      state: 2
    },
    {
      pos: [5, 0, 8],
      state: 2
    },
    {
      pos: [1, 1, 8],
      state: 2
    },
    {
      pos: [5, 1, 8],
      state: 2
    },
    {
      pos: [1, 2, 8],
      state: 2
    },
    {
      pos: [5, 2, 8],
      state: 2
    },
    {
      pos: [1, 3, 8],
      state: 3
    },
    {
      pos: [2, 3, 8],
      state: 0
    },
    {
      pos: [4, 3, 8],
      state: 0
    },
    {
      pos: [5, 3, 8],
      state: 1
    },
    {
      pos: [1, 4, 8],
      state: 0
    },
    {
      pos: [5, 4, 8],
      state: 0
    },
    {
      pos: [1, 5, 8],
      state: 0
    },
    {
      pos: [5, 5, 8],
      state: 0
    },
    {
      pos: [0, 6, 8],
      state: 0
    },
    {
      pos: [1, 6, 8],
      state: 0
    },
    {
      pos: [5, 6, 8],
      state: 0
    },
    {
      pos: [6, 6, 8],
      state: 0
    },
    {
      pos: [1, 7, 8],
      state: 0
    },
    {
      pos: [5, 7, 8],
      state: 0
    },
    {
      pos: [2, 8, 8],
      state: 0
    },
    {
      pos: [4, 8, 8],
      state: 0
    },
    {
      pos: [3, 9, 8],
      state: 0
    },
    {
      pos: [1, 0, 9],
      state: 1
    },
    {
      pos: [2, 0, 9],
      state: 2
    },
    {
      pos: [3, 0, 9],
      state: 2
    },
    {
      pos: [4, 0, 9],
      state: 2
    },
    {
      pos: [5, 0, 9],
      state: 1
    },
    {
      pos: [1, 1, 9],
      state: 1
    },
    {
      pos: [2, 1, 9],
      state: 2
    },
    {
      pos: [4, 1, 9],
      state: 2
    },
    {
      pos: [5, 1, 9],
      state: 1
    },
    {
      pos: [1, 2, 9],
      state: 1
    },
    {
      pos: [2, 2, 9],
      state: 2
    },
    {
      pos: [3, 2, 9],
      state: 2
    },
    {
      pos: [4, 2, 9],
      state: 2
    },
    {
      pos: [5, 2, 9],
      state: 1
    },
    {
      pos: [1, 3, 9],
      state: 1
    },
    {
      pos: [2, 3, 9],
      state: 4
    },
    {
      pos: [3, 3, 9],
      state: 4
    },
    {
      pos: [4, 3, 9],
      state: 4
    },
    {
      pos: [5, 3, 9],
      state: 1
    },
    {
      pos: [1, 4, 9],
      state: 1
    },
    {
      pos: [2, 4, 9],
      state: 0
    },
    {
      pos: [3, 4, 9],
      state: 0
    },
    {
      pos: [4, 4, 9],
      state: 0
    },
    {
      pos: [5, 4, 9],
      state: 1
    },
    {
      pos: [1, 5, 9],
      state: 1
    },
    {
      pos: [2, 5, 9],
      state: 0
    },
    {
      pos: [4, 5, 9],
      state: 0
    },
    {
      pos: [5, 5, 9],
      state: 1
    },
    {
      pos: [0, 6, 9],
      state: 0
    },
    {
      pos: [1, 6, 9],
      state: 1
    },
    {
      pos: [2, 6, 9],
      state: 0
    },
    {
      pos: [3, 6, 9],
      state: 0
    },
    {
      pos: [4, 6, 9],
      state: 0
    },
    {
      pos: [5, 6, 9],
      state: 1
    },
    {
      pos: [6, 6, 9],
      state: 0
    },
    {
      pos: [1, 7, 9],
      state: 0
    },
    {
      pos: [2, 7, 9],
      state: 0
    },
    {
      pos: [3, 7, 9],
      state: 0
    },
    {
      pos: [4, 7, 9],
      state: 0
    },
    {
      pos: [5, 7, 9],
      state: 0
    },
    {
      pos: [2, 8, 9],
      state: 0
    },
    {
      pos: [3, 8, 9],
      state: 0
    },
    {
      pos: [4, 8, 9],
      state: 0
    },
    {
      pos: [3, 9, 9],
      state: 0
    },
    {
      pos: [0, 6, 10],
      state: 0
    },
    {
      pos: [6, 6, 10],
      state: 0
    },
    {
      pos: [1, 7, 10],
      state: 0
    },
    {
      pos: [5, 7, 10],
      state: 0
    },
    {
      pos: [2, 8, 10],
      state: 0
    },
    {
      pos: [4, 8, 10],
      state: 0
    },
    {
      pos: [3, 9, 10],
      state: 0
    },
    {
      nbt: {
        id: "minecraft:bed"
      },
      pos: [3, 0, 2],
      state: 5
    },
    {
      nbt: {
        id: "minecraft:bed"
      },
      pos: [4, 0, 2],
      state: 6
    },
    {
      nbt: {
        target_pool: "minecraft:village/plains/villagers",
        final_state: "minecraft:oak_planks",
        id: "minecraft:jigsaw",
        attachement_type: "minecraft:bottom"
      },
      pos: [3, 3, 2],
      state: 7
    },
    {
      nbt: {
        id: "minecraft:bed"
      },
      pos: [2, 4, 2],
      state: 8
    },
    {
      nbt: {
        id: "minecraft:bed"
      },
      pos: [2, 4, 3],
      state: 9
    },
    {
      nbt: {
        target_pool: "minecraft:village/plains/streets",
        final_state: "minecraft:air",
        id: "minecraft:jigsaw",
        attachement_type: "minecraft:building_entrance"
      },
      pos: [0, 0, 5],
      state: 10
    },
    {
      nbt: {
        id: "minecraft:bed"
      },
      pos: [2, 0, 7],
      state: 11
    },
    {
      nbt: {
        id: "minecraft:bed"
      },
      pos: [2, 4, 7],
      state: 11
    },
    {
      nbt: {
        id: "minecraft:bed"
      },
      pos: [2, 0, 8],
      state: 12
    },
    {
      nbt: {
        target_pool: "minecraft:village/plains/villagers",
        final_state: "minecraft:oak_planks",
        id: "minecraft:jigsaw",
        attachement_type: "minecraft:bottom"
      },
      pos: [3, 3, 8],
      state: 7
    },
    {
      nbt: {
        id: "minecraft:bed"
      },
      pos: [2, 4, 8],
      state: 12
    },
    {
      nbt: {
        LootTable: "minecraft:chests/village/village_plains_house",
        id: "minecraft:chest",
        Lock: "",
        LootTableSeed: 0L
      },
      pos: [4, 4, 8],
      state: 13
    },
    {
      pos: [0, 0, 0],
      state: 14
    },
    {
      pos: [1, 0, 0],
      state: 14
    },
    {
      pos: [2, 0, 0],
      state: 14
    },
    {
      pos: [3, 0, 0],
      state: 14
    },
    {
      pos: [4, 0, 0],
      state: 14
    },
    {
      pos: [5, 0, 0],
      state: 14
    },
    {
      pos: [6, 0, 0],
      state: 14
    },
    {
      pos: [0, 1, 0],
      state: 14
    },
    {
      pos: [1, 1, 0],
      state: 14
    },
    {
      pos: [2, 1, 0],
      state: 14
    },
    {
      pos: [3, 1, 0],
      state: 14
    },
    {
      pos: [4, 1, 0],
      state: 14
    },
    {
      pos: [5, 1, 0],
      state: 14
    },
    {
      pos: [6, 1, 0],
      state: 14
    },
    {
      pos: [0, 2, 0],
      state: 14
    },
    {
      pos: [1, 2, 0],
      state: 14
    },
    {
      pos: [2, 2, 0],
      state: 14
    },
    {
      pos: [3, 2, 0],
      state: 14
    },
    {
      pos: [4, 2, 0],
      state: 14
    },
    {
      pos: [5, 2, 0],
      state: 14
    },
    {
      pos: [6, 2, 0],
      state: 14
    },
    {
      pos: [0, 3, 0],
      state: 14
    },
    {
      pos: [1, 3, 0],
      state: 14
    },
    {
      pos: [2, 3, 0],
      state: 14
    },
    {
      pos: [3, 3, 0],
      state: 14
    },
    {
      pos: [4, 3, 0],
      state: 14
    },
    {
      pos: [5, 3, 0],
      state: 14
    },
    {
      pos: [6, 3, 0],
      state: 14
    },
    {
      pos: [0, 4, 0],
      state: 14
    },
    {
      pos: [1, 4, 0],
      state: 14
    },
    {
      pos: [2, 4, 0],
      state: 14
    },
    {
      pos: [3, 4, 0],
      state: 14
    },
    {
      pos: [4, 4, 0],
      state: 14
    },
    {
      pos: [5, 4, 0],
      state: 14
    },
    {
      pos: [6, 4, 0],
      state: 14
    },
    {
      pos: [0, 5, 0],
      state: 14
    },
    {
      pos: [1, 5, 0],
      state: 14
    },
    {
      pos: [2, 5, 0],
      state: 14
    },
    {
      pos: [3, 5, 0],
      state: 14
    },
    {
      pos: [4, 5, 0],
      state: 14
    },
    {
      pos: [5, 5, 0],
      state: 14
    },
    {
      pos: [6, 5, 0],
      state: 14
    },
    {
      pos: [1, 6, 0],
      state: 14
    },
    {
      pos: [2, 6, 0],
      state: 14
    },
    {
      pos: [3, 6, 0],
      state: 14
    },
    {
      pos: [4, 6, 0],
      state: 14
    },
    {
      pos: [5, 6, 0],
      state: 14
    },
    {
      pos: [0, 7, 0],
      state: 14
    },
    {
      pos: [2, 7, 0],
      state: 14
    },
    {
      pos: [3, 7, 0],
      state: 14
    },
    {
      pos: [4, 7, 0],
      state: 14
    },
    {
      pos: [6, 7, 0],
      state: 14
    },
    {
      pos: [0, 8, 0],
      state: 14
    },
    {
      pos: [1, 8, 0],
      state: 14
    },
    {
      pos: [3, 8, 0],
      state: 14
    },
    {
      pos: [5, 8, 0],
      state: 14
    },
    {
      pos: [6, 8, 0],
      state: 14
    },
    {
      pos: [0, 9, 0],
      state: 14
    },
    {
      pos: [1, 9, 0],
      state: 14
    },
    {
      pos: [2, 9, 0],
      state: 14
    },
    {
      pos: [4, 9, 0],
      state: 14
    },
    {
      pos: [5, 9, 0],
      state: 14
    },
    {
      pos: [6, 9, 0],
      state: 14
    },
    {
      pos: [0, 0, 1],
      state: 14
    },
    {
      pos: [6, 0, 1],
      state: 14
    },
    {
      pos: [0, 1, 1],
      state: 14
    },
    {
      pos: [3, 1, 1],
      state: 15
    },
    {
      pos: [6, 1, 1],
      state: 14
    },
    {
      pos: [0, 2, 1],
      state: 14
    },
    {
      pos: [6, 2, 1],
      state: 14
    },
    {
      pos: [0, 3, 1],
      state: 14
    },
    {
      pos: [6, 3, 1],
      state: 14
    },
    {
      pos: [0, 4, 1],
      state: 14
    },
    {
      pos: [6, 4, 1],
      state: 14
    },
    {
      pos: [0, 5, 1],
      state: 14
    },
    {
      pos: [3, 5, 1],
      state: 15
    },
    {
      pos: [6, 5, 1],
      state: 14
    },
    {
      pos: [0, 7, 1],
      state: 14
    },
    {
      pos: [6, 7, 1],
      state: 14
    },
    {
      pos: [0, 8, 1],
      state: 14
    },
    {
      pos: [1, 8, 1],
      state: 14
    },
    {
      pos: [5, 8, 1],
      state: 14
    },
    {
      pos: [6, 8, 1],
      state: 14
    },
    {
      pos: [0, 9, 1],
      state: 14
    },
    {
      pos: [1, 9, 1],
      state: 14
    },
    {
      pos: [2, 9, 1],
      state: 14
    },
    {
      pos: [4, 9, 1],
      state: 14
    },
    {
      pos: [5, 9, 1],
      state: 14
    },
    {
      pos: [6, 9, 1],
      state: 14
    },
    {
      pos: [0, 0, 2],
      state: 14
    },
    {
      pos: [2, 0, 2],
      state: 14
    },
    {
      pos: [6, 0, 2],
      state: 14
    },
    {
      pos: [0, 1, 2],
      state: 14
    },
    {
      pos: [2, 1, 2],
      state: 14
    },
    {
      pos: [3, 1, 2],
      state: 14
    },
    {
      pos: [4, 1, 2],
      state: 14
    },
    {
      pos: [6, 1, 2],
      state: 14
    },
    {
      pos: [0, 2, 2],
      state: 14
    },
    {
      pos: [2, 2, 2],
      state: 14
    },
    {
      pos: [3, 2, 2],
      state: 16
    },
    {
      pos: [6, 2, 2],
      state: 14
    },
    {
      pos: [0, 3, 2],
      state: 14
    },
    {
      pos: [6, 3, 2],
      state: 14
    },
    {
      pos: [0, 4, 2],
      state: 14
    },
    {
      pos: [3, 4, 2],
      state: 14
    },
    {
      pos: [4, 4, 2],
      state: 14
    },
    {
      pos: [6, 4, 2],
      state: 14
    },
    {
      pos: [0, 5, 2],
      state: 14
    },
    {
      pos: [2, 5, 2],
      state: 14
    },
    {
      pos: [3, 5, 2],
      state: 14
    },
    {
      pos: [4, 5, 2],
      state: 14
    },
    {
      pos: [6, 5, 2],
      state: 14
    },
    {
      pos: [2, 6, 2],
      state: 14
    },
    {
      pos: [3, 6, 2],
      state: 16
    },
    {
      pos: [4, 6, 2],
      state: 14
    },
    {
      pos: [0, 7, 2],
      state: 14
    },
    {
      pos: [2, 7, 2],
      state: 14
    },
    {
      pos: [3, 7, 2],
      state: 14
    },
    {
      pos: [4, 7, 2],
      state: 14
    },
    {
      pos: [6, 7, 2],
      state: 14
    },
    {
      pos: [0, 8, 2],
      state: 14
    },
    {
      pos: [1, 8, 2],
      state: 14
    },
    {
      pos: [3, 8, 2],
      state: 14
    },
    {
      pos: [5, 8, 2],
      state: 14
    },
    {
      pos: [6, 8, 2],
      state: 14
    },
    {
      pos: [0, 9, 2],
      state: 14
    },
    {
      pos: [1, 9, 2],
      state: 14
    },
    {
      pos: [2, 9, 2],
      state: 14
    },
    {
      pos: [4, 9, 2],
      state: 14
    },
    {
      pos: [5, 9, 2],
      state: 14
    },
    {
      pos: [6, 9, 2],
      state: 14
    },
    {
      pos: [0, 0, 3],
      state: 14
    },
    {
      pos: [2, 0, 3],
      state: 14
    },
    {
      pos: [3, 0, 3],
      state: 14
    },
    {
      pos: [4, 0, 3],
      state: 14
    },
    {
      pos: [6, 0, 3],
      state: 14
    },
    {
      pos: [0, 1, 3],
      state: 14
    },
    {
      pos: [1, 1, 3],
      state: 17
    },
    {
      pos: [2, 1, 3],
      state: 14
    },
    {
      pos: [3, 1, 3],
      state: 14
    },
    {
      pos: [4, 1, 3],
      state: 14
    },
    {
      pos: [5, 1, 3],
      state: 17
    },
    {
      pos: [6, 1, 3],
      state: 14
    },
    {
      pos: [0, 2, 3],
      state: 14
    },
    {
      pos: [2, 2, 3],
      state: 14
    },
    {
      pos: [3, 2, 3],
      state: 14
    },
    {
      pos: [6, 2, 3],
      state: 14
    },
    {
      pos: [0, 3, 3],
      state: 14
    },
    {
      pos: [4, 3, 3],
      state: 18
    },
    {
      pos: [6, 3, 3],
      state: 14
    },
    {
      pos: [0, 4, 3],
      state: 14
    },
    {
      pos: [3, 4, 3],
      state: 14
    },
    {
      pos: [4, 4, 3],
      state: 14
    },
    {
      pos: [6, 4, 3],
      state: 14
    },
    {
      pos: [0, 5, 3],
      state: 14
    },
    {
      pos: [1, 5, 3],
      state: 17
    },
    {
      pos: [2, 5, 3],
      state: 14
    },
    {
      pos: [3, 5, 3],
      state: 14
    },
    {
      pos: [4, 5, 3],
      state: 14
    },
    {
      pos: [5, 5, 3],
      state: 17
    },
    {
      pos: [6, 5, 3],
      state: 14
    },
    {
      pos: [2, 6, 3],
      state: 14
    },
    {
      pos: [3, 6, 3],
      state: 14
    },
    {
      pos: [4, 6, 3],
      state: 14
    },
    {
      pos: [0, 7, 3],
      state: 14
    },
    {
      pos: [2, 7, 3],
      state: 14
    },
    {
      pos: [3, 7, 3],
      state: 14
    },
    {
      pos: [4, 7, 3],
      state: 14
    },
    {
      pos: [6, 7, 3],
      state: 14
    },
    {
      pos: [0, 8, 3],
      state: 14
    },
    {
      pos: [1, 8, 3],
      state: 14
    },
    {
      pos: [3, 8, 3],
      state: 14
    },
    {
      pos: [5, 8, 3],
      state: 14
    },
    {
      pos: [6, 8, 3],
      state: 14
    },
    {
      pos: [0, 9, 3],
      state: 14
    },
    {
      pos: [1, 9, 3],
      state: 14
    },
    {
      pos: [2, 9, 3],
      state: 14
    },
    {
      pos: [4, 9, 3],
      state: 14
    },
    {
      pos: [5, 9, 3],
      state: 14
    },
    {
      pos: [6, 9, 3],
      state: 14
    },
    {
      pos: [0, 0, 4],
      state: 14
    },
    {
      pos: [2, 0, 4],
      state: 14
    },
    {
      pos: [3, 0, 4],
      state: 14
    },
    {
      pos: [6, 0, 4],
      state: 14
    },
    {
      pos: [0, 1, 4],
      state: 14
    },
    {
      pos: [2, 1, 4],
      state: 14
    },
    {
      pos: [3, 1, 4],
      state: 14
    },
    {
      pos: [6, 1, 4],
      state: 14
    },
    {
      pos: [0, 2, 4],
      state: 14
    },
    {
      pos: [2, 2, 4],
      state: 14
    },
    {
      pos: [3, 2, 4],
      state: 14
    },
    {
      pos: [4, 2, 4],
      state: 18
    },
    {
      pos: [6, 2, 4],
      state: 14
    },
    {
      pos: [0, 3, 4],
      state: 14
    },
    {
      pos: [4, 3, 4],
      state: 14
    },
    {
      pos: [6, 3, 4],
      state: 14
    },
    {
      pos: [0, 4, 4],
      state: 14
    },
    {
      pos: [2, 4, 4],
      state: 14
    },
    {
      pos: [3, 4, 4],
      state: 14
    },
    {
      pos: [4, 4, 4],
      state: 14
    },
    {
      pos: [6, 4, 4],
      state: 14
    },
    {
      pos: [0, 5, 4],
      state: 14
    },
    {
      pos: [2, 5, 4],
      state: 14
    },
    {
      pos: [3, 5, 4],
      state: 14
    },
    {
      pos: [4, 5, 4],
      state: 14
    },
    {
      pos: [6, 5, 4],
      state: 14
    },
    {
      pos: [2, 6, 4],
      state: 14
    },
    {
      pos: [3, 6, 4],
      state: 14
    },
    {
      pos: [4, 6, 4],
      state: 14
    },
    {
      pos: [0, 7, 4],
      state: 14
    },
    {
      pos: [2, 7, 4],
      state: 14
    },
    {
      pos: [3, 7, 4],
      state: 14
    },
    {
      pos: [4, 7, 4],
      state: 14
    },
    {
      pos: [6, 7, 4],
      state: 14
    },
    {
      pos: [0, 8, 4],
      state: 14
    },
    {
      pos: [1, 8, 4],
      state: 14
    },
    {
      pos: [3, 8, 4],
      state: 14
    },
    {
      pos: [5, 8, 4],
      state: 14
    },
    {
      pos: [6, 8, 4],
      state: 14
    },
    {
      pos: [0, 9, 4],
      state: 14
    },
    {
      pos: [1, 9, 4],
      state: 14
    },
    {
      pos: [2, 9, 4],
      state: 14
    },
    {
      pos: [4, 9, 4],
      state: 14
    },
    {
      pos: [5, 9, 4],
      state: 14
    },
    {
      pos: [6, 9, 4],
      state: 14
    },
    {
      pos: [1, 0, 5],
      state: 19
    },
    {
      pos: [2, 0, 5],
      state: 14
    },
    {
      pos: [3, 0, 5],
      state: 14
    },
    {
      pos: [6, 0, 5],
      state: 14
    },
    {
      pos: [0, 1, 5],
      state: 14
    },
    {
      pos: [1, 1, 5],
      state: 20
    },
    {
      pos: [2, 1, 5],
      state: 14
    },
    {
      pos: [3, 1, 5],
      state: 14
    },
    {
      pos: [4, 1, 5],
      state: 18
    },
    {
      pos: [6, 1, 5],
      state: 14
    },
    {
      pos: [0, 2, 5],
      state: 14
    },
    {
      pos: [2, 2, 5],
      state: 14
    },
    {
      pos: [3, 2, 5],
      state: 14
    },
    {
      pos: [4, 2, 5],
      state: 14
    },
    {
      pos: [6, 2, 5],
      state: 14
    },
    {
      pos: [0, 3, 5],
      state: 14
    },
    {
      pos: [4, 3, 5],
      state: 14
    },
    {
      pos: [6, 3, 5],
      state: 14
    },
    {
      pos: [0, 4, 5],
      state: 14
    },
    {
      pos: [2, 4, 5],
      state: 14
    },
    {
      pos: [3, 4, 5],
      state: 14
    },
    {
      pos: [4, 4, 5],
      state: 14
    },
    {
      pos: [6, 4, 5],
      state: 14
    },
    {
      pos: [0, 5, 5],
      state: 14
    },
    {
      pos: [2, 5, 5],
      state: 14
    },
    {
      pos: [3, 5, 5],
      state: 14
    },
    {
      pos: [4, 5, 5],
      state: 21
    },
    {
      pos: [6, 5, 5],
      state: 14
    },
    {
      pos: [2, 6, 5],
      state: 14
    },
    {
      pos: [3, 6, 5],
      state: 14
    },
    {
      pos: [4, 6, 5],
      state: 14
    },
    {
      pos: [0, 7, 5],
      state: 14
    },
    {
      pos: [2, 7, 5],
      state: 14
    },
    {
      pos: [3, 7, 5],
      state: 14
    },
    {
      pos: [4, 7, 5],
      state: 14
    },
    {
      pos: [6, 7, 5],
      state: 14
    },
    {
      pos: [0, 8, 5],
      state: 14
    },
    {
      pos: [1, 8, 5],
      state: 14
    },
    {
      pos: [3, 8, 5],
      state: 14
    },
    {
      pos: [5, 8, 5],
      state: 14
    },
    {
      pos: [6, 8, 5],
      state: 14
    },
    {
      pos: [0, 9, 5],
      state: 14
    },
    {
      pos: [1, 9, 5],
      state: 14
    },
    {
      pos: [2, 9, 5],
      state: 14
    },
    {
      pos: [4, 9, 5],
      state: 14
    },
    {
      pos: [5, 9, 5],
      state: 14
    },
    {
      pos: [6, 9, 5],
      state: 14
    },
    {
      pos: [0, 0, 6],
      state: 14
    },
    {
      pos: [2, 0, 6],
      state: 14
    },
    {
      pos: [3, 0, 6],
      state: 14
    },
    {
      pos: [4, 0, 6],
      state: 18
    },
    {
      pos: [6, 0, 6],
      state: 14
    },
    {
      pos: [0, 1, 6],
      state: 14
    },
    {
      pos: [2, 1, 6],
      state: 14
    },
    {
      pos: [3, 1, 6],
      state: 14
    },
    {
      pos: [4, 1, 6],
      state: 14
    },
    {
      pos: [6, 1, 6],
      state: 14
    },
    {
      pos: [0, 2, 6],
      state: 14
    },
    {
      pos: [2, 2, 6],
      state: 14
    },
    {
      pos: [3, 2, 6],
      state: 14
    },
    {
      pos: [4, 2, 6],
      state: 14
    },
    {
      pos: [6, 2, 6],
      state: 14
    },
    {
      pos: [0, 3, 6],
      state: 14
    },
    {
      pos: [4, 3, 6],
      state: 14
    },
    {
      pos: [6, 3, 6],
      state: 14
    },
    {
      pos: [0, 4, 6],
      state: 14
    },
    {
      pos: [2, 4, 6],
      state: 14
    },
    {
      pos: [3, 4, 6],
      state: 14
    },
    {
      pos: [4, 4, 6],
      state: 14
    },
    {
      pos: [6, 4, 6],
      state: 14
    },
    {
      pos: [0, 5, 6],
      state: 14
    },
    {
      pos: [2, 5, 6],
      state: 14
    },
    {
      pos: [3, 5, 6],
      state: 14
    },
    {
      pos: [4, 5, 6],
      state: 14
    },
    {
      pos: [6, 5, 6],
      state: 14
    },
    {
      pos: [2, 6, 6],
      state: 14
    },
    {
      pos: [3, 6, 6],
      state: 14
    },
    {
      pos: [4, 6, 6],
      state: 14
    },
    {
      pos: [0, 7, 6],
      state: 14
    },
    {
      pos: [2, 7, 6],
      state: 14
    },
    {
      pos: [3, 7, 6],
      state: 14
    },
    {
      pos: [4, 7, 6],
      state: 14
    },
    {
      pos: [6, 7, 6],
      state: 14
    },
    {
      pos: [0, 8, 6],
      state: 14
    },
    {
      pos: [1, 8, 6],
      state: 14
    },
    {
      pos: [3, 8, 6],
      state: 14
    },
    {
      pos: [5, 8, 6],
      state: 14
    },
    {
      pos: [6, 8, 6],
      state: 14
    },
    {
      pos: [0, 9, 6],
      state: 14
    },
    {
      pos: [1, 9, 6],
      state: 14
    },
    {
      pos: [2, 9, 6],
      state: 14
    },
    {
      pos: [4, 9, 6],
      state: 14
    },
    {
      pos: [5, 9, 6],
      state: 14
    },
    {
      pos: [6, 9, 6],
      state: 14
    },
    {
      pos: [0, 0, 7],
      state: 14
    },
    {
      pos: [3, 0, 7],
      state: 14
    },
    {
      pos: [4, 0, 7],
      state: 14
    },
    {
      pos: [6, 0, 7],
      state: 14
    },
    {
      pos: [0, 1, 7],
      state: 14
    },
    {
      pos: [1, 1, 7],
      state: 17
    },
    {
      pos: [2, 1, 7],
      state: 14
    },
    {
      pos: [3, 1, 7],
      state: 14
    },
    {
      pos: [4, 1, 7],
      state: 14
    },
    {
      pos: [5, 1, 7],
      state: 17
    },
    {
      pos: [6, 1, 7],
      state: 14
    },
    {
      pos: [0, 2, 7],
      state: 14
    },
    {
      pos: [2, 2, 7],
      state: 14
    },
    {
      pos: [3, 2, 7],
      state: 14
    },
    {
      pos: [4, 2, 7],
      state: 14
    },
    {
      pos: [6, 2, 7],
      state: 14
    },
    {
      pos: [0, 3, 7],
      state: 14
    },
    {
      pos: [6, 3, 7],
      state: 14
    },
    {
      pos: [0, 4, 7],
      state: 14
    },
    {
      pos: [3, 4, 7],
      state: 14
    },
    {
      pos: [4, 4, 7],
      state: 14
    },
    {
      pos: [6, 4, 7],
      state: 14
    },
    {
      pos: [0, 5, 7],
      state: 14
    },
    {
      pos: [1, 5, 7],
      state: 17
    },
    {
      pos: [2, 5, 7],
      state: 14
    },
    {
      pos: [3, 5, 7],
      state: 14
    },
    {
      pos: [4, 5, 7],
      state: 14
    },
    {
      pos: [5, 5, 7],
      state: 17
    },
    {
      pos: [6, 5, 7],
      state: 14
    },
    {
      pos: [2, 6, 7],
      state: 14
    },
    {
      pos: [3, 6, 7],
      state: 14
    },
    {
      pos: [4, 6, 7],
      state: 14
    },
    {
      pos: [0, 7, 7],
      state: 14
    },
    {
      pos: [2, 7, 7],
      state: 14
    },
    {
      pos: [3, 7, 7],
      state: 14
    },
    {
      pos: [4, 7, 7],
      state: 14
    },
    {
      pos: [6, 7, 7],
      state: 14
    },
    {
      pos: [0, 8, 7],
      state: 14
    },
    {
      pos: [1, 8, 7],
      state: 14
    },
    {
      pos: [3, 8, 7],
      state: 14
    },
    {
      pos: [5, 8, 7],
      state: 14
    },
    {
      pos: [6, 8, 7],
      state: 14
    },
    {
      pos: [0, 9, 7],
      state: 14
    },
    {
      pos: [1, 9, 7],
      state: 14
    },
    {
      pos: [2, 9, 7],
      state: 14
    },
    {
      pos: [4, 9, 7],
      state: 14
    },
    {
      pos: [5, 9, 7],
      state: 14
    },
    {
      pos: [6, 9, 7],
      state: 14
    },
    {
      pos: [0, 0, 8],
      state: 14
    },
    {
      pos: [3, 0, 8],
      state: 14
    },
    {
      pos: [4, 0, 8],
      state: 14
    },
    {
      pos: [6, 0, 8],
      state: 14
    },
    {
      pos: [0, 1, 8],
      state: 14
    },
    {
      pos: [2, 1, 8],
      state: 14
    },
    {
      pos: [3, 1, 8],
      state: 14
    },
    {
      pos: [4, 1, 8],
      state: 14
    },
    {
      pos: [6, 1, 8],
      state: 14
    },
    {
      pos: [0, 2, 8],
      state: 14
    },
    {
      pos: [2, 2, 8],
      state: 14
    },
    {
      pos: [3, 2, 8],
      state: 22
    },
    {
      pos: [4, 2, 8],
      state: 14
    },
    {
      pos: [6, 2, 8],
      state: 14
    },
    {
      pos: [0, 3, 8],
      state: 14
    },
    {
      pos: [6, 3, 8],
      state: 14
    },
    {
      pos: [0, 4, 8],
      state: 14
    },
    {
      pos: [3, 4, 8],
      state: 14
    },
    {
      pos: [6, 4, 8],
      state: 14
    },
    {
      pos: [0, 5, 8],
      state: 14
    },
    {
      pos: [2, 5, 8],
      state: 14
    },
    {
      pos: [3, 5, 8],
      state: 14
    },
    {
      pos: [4, 5, 8],
      state: 14
    },
    {
      pos: [6, 5, 8],
      state: 14
    },
    {
      pos: [2, 6, 8],
      state: 14
    },
    {
      pos: [3, 6, 8],
      state: 22
    },
    {
      pos: [4, 6, 8],
      state: 14
    },
    {
      pos: [0, 7, 8],
      state: 14
    },
    {
      pos: [2, 7, 8],
      state: 14
    },
    {
      pos: [3, 7, 8],
      state: 14
    },
    {
      pos: [4, 7, 8],
      state: 14
    },
    {
      pos: [6, 7, 8],
      state: 14
    },
    {
      pos: [0, 8, 8],
      state: 14
    },
    {
      pos: [1, 8, 8],
      state: 14
    },
    {
      pos: [3, 8, 8],
      state: 14
    },
    {
      pos: [5, 8, 8],
      state: 14
    },
    {
      pos: [6, 8, 8],
      state: 14
    },
    {
      pos: [0, 9, 8],
      state: 14
    },
    {
      pos: [1, 9, 8],
      state: 14
    },
    {
      pos: [2, 9, 8],
      state: 14
    },
    {
      pos: [4, 9, 8],
      state: 14
    },
    {
      pos: [5, 9, 8],
      state: 14
    },
    {
      pos: [6, 9, 8],
      state: 14
    },
    {
      pos: [0, 0, 9],
      state: 14
    },
    {
      pos: [6, 0, 9],
      state: 14
    },
    {
      pos: [0, 1, 9],
      state: 14
    },
    {
      pos: [3, 1, 9],
      state: 15
    },
    {
      pos: [6, 1, 9],
      state: 14
    },
    {
      pos: [0, 2, 9],
      state: 14
    },
    {
      pos: [6, 2, 9],
      state: 14
    },
    {
      pos: [0, 3, 9],
      state: 14
    },
    {
      pos: [6, 3, 9],
      state: 14
    },
    {
      pos: [0, 4, 9],
      state: 14
    },
    {
      pos: [6, 4, 9],
      state: 14
    },
    {
      pos: [0, 5, 9],
      state: 14
    },
    {
      pos: [3, 5, 9],
      state: 15
    },
    {
      pos: [6, 5, 9],
      state: 14
    },
    {
      pos: [0, 7, 9],
      state: 14
    },
    {
      pos: [6, 7, 9],
      state: 14
    },
    {
      pos: [0, 8, 9],
      state: 14
    },
    {
      pos: [1, 8, 9],
      state: 14
    },
    {
      pos: [5, 8, 9],
      state: 14
    },
    {
      pos: [6, 8, 9],
      state: 14
    },
    {
      pos: [0, 9, 9],
      state: 14
    },
    {
      pos: [1, 9, 9],
      state: 14
    },
    {
      pos: [2, 9, 9],
      state: 14
    },
    {
      pos: [4, 9, 9],
      state: 14
    },
    {
      pos: [5, 9, 9],
      state: 14
    },
    {
      pos: [6, 9, 9],
      state: 14
    },
    {
      pos: [0, 0, 10],
      state: 14
    },
    {
      pos: [1, 0, 10],
      state: 14
    },
    {
      pos: [2, 0, 10],
      state: 14
    },
    {
      pos: [3, 0, 10],
      state: 14
    },
    {
      pos: [4, 0, 10],
      state: 14
    },
    {
      pos: [5, 0, 10],
      state: 14
    },
    {
      pos: [6, 0, 10],
      state: 14
    },
    {
      pos: [0, 1, 10],
      state: 14
    },
    {
      pos: [1, 1, 10],
      state: 14
    },
    {
      pos: [2, 1, 10],
      state: 14
    },
    {
      pos: [3, 1, 10],
      state: 14
    },
    {
      pos: [4, 1, 10],
      state: 14
    },
    {
      pos: [5, 1, 10],
      state: 14
    },
    {
      pos: [6, 1, 10],
      state: 14
    },
    {
      pos: [0, 2, 10],
      state: 14
    },
    {
      pos: [1, 2, 10],
      state: 14
    },
    {
      pos: [2, 2, 10],
      state: 14
    },
    {
      pos: [3, 2, 10],
      state: 14
    },
    {
      pos: [4, 2, 10],
      state: 14
    },
    {
      pos: [5, 2, 10],
      state: 14
    },
    {
      pos: [6, 2, 10],
      state: 14
    },
    {
      pos: [0, 3, 10],
      state: 14
    },
    {
      pos: [1, 3, 10],
      state: 14
    },
    {
      pos: [2, 3, 10],
      state: 14
    },
    {
      pos: [3, 3, 10],
      state: 14
    },
    {
      pos: [4, 3, 10],
      state: 14
    },
    {
      pos: [5, 3, 10],
      state: 14
    },
    {
      pos: [6, 3, 10],
      state: 14
    },
    {
      pos: [0, 4, 10],
      state: 14
    },
    {
      pos: [1, 4, 10],
      state: 14
    },
    {
      pos: [2, 4, 10],
      state: 14
    },
    {
      pos: [3, 4, 10],
      state: 14
    },
    {
      pos: [4, 4, 10],
      state: 14
    },
    {
      pos: [5, 4, 10],
      state: 14
    },
    {
      pos: [6, 4, 10],
      state: 14
    },
    {
      pos: [0, 5, 10],
      state: 14
    },
    {
      pos: [1, 5, 10],
      state: 14
    },
    {
      pos: [2, 5, 10],
      state: 14
    },
    {
      pos: [3, 5, 10],
      state: 14
    },
    {
      pos: [4, 5, 10],
      state: 14
    },
    {
      pos: [5, 5, 10],
      state: 14
    },
    {
      pos: [6, 5, 10],
      state: 14
    },
    {
      pos: [1, 6, 10],
      state: 14
    },
    {
      pos: [2, 6, 10],
      state: 14
    },
    {
      pos: [3, 6, 10],
      state: 14
    },
    {
      pos: [4, 6, 10],
      state: 14
    },
    {
      pos: [5, 6, 10],
      state: 14
    },
    {
      pos: [0, 7, 10],
      state: 14
    },
    {
      pos: [2, 7, 10],
      state: 14
    },
    {
      pos: [3, 7, 10],
      state: 14
    },
    {
      pos: [4, 7, 10],
      state: 14
    },
    {
      pos: [6, 7, 10],
      state: 14
    },
    {
      pos: [0, 8, 10],
      state: 14
    },
    {
      pos: [1, 8, 10],
      state: 14
    },
    {
      pos: [3, 8, 10],
      state: 14
    },
    {
      pos: [5, 8, 10],
      state: 14
    },
    {
      pos: [6, 8, 10],
      state: 14
    },
    {
      pos: [0, 9, 10],
      state: 14
    },
    {
      pos: [1, 9, 10],
      state: 14
    },
    {
      pos: [2, 9, 10],
      state: 14
    },
    {
      pos: [4, 9, 10],
      state: 14
    },
    {
      pos: [5, 9, 10],
      state: 14
    },
    {
      pos: [6, 9, 10],
      state: 14
    }
  ],
  palette: [
    {
      Name: "minecraft:oak_planks"
    },
    {
      Properties: {
        axis: "y"
      },
      Name: "minecraft:oak_log"
    },
    {
      Name: "minecraft:cobblestone"
    },
    {
      Properties: {
        axis: "z"
      },
      Name: "minecraft:oak_log"
    },
    {
      Properties: {
        axis: "x"
      },
      Name: "minecraft:oak_log"
    },
    {
      Properties: {
        part: "foot",
        facing: "east",
        occupied: "false"
      },
      Name: "minecraft:white_bed"
    },
    {
      Properties: {
        part: "head",
        facing: "east",
        occupied: "false"
      },
      Name: "minecraft:white_bed"
    },
    {
      Properties: {
        facing: "up"
      },
      Name: "minecraft:jigsaw"
    },
    {
      Properties: {
        part: "head",
        facing: "north",
        occupied: "false"
      },
      Name: "minecraft:white_bed"
    },
    {
      Properties: {
        part: "foot",
        facing: "north",
        occupied: "false"
      },
      Name: "minecraft:white_bed"
    },
    {
      Properties: {
        facing: "west"
      },
      Name: "minecraft:jigsaw"
    },
    {
      Properties: {
        part: "foot",
        facing: "south",
        occupied: "false"
      },
      Name: "minecraft:white_bed"
    },
    {
      Properties: {
        part: "head",
        facing: "south",
        occupied: "false"
      },
      Name: "minecraft:white_bed"
    },
    {
      Properties: {
        waterlogged: "false",
        facing: "north",
        type: "single"
      },
      Name: "minecraft:chest"
    },
    {
      Name: "minecraft:air"
    },
    {
      Properties: {
        east: "true",
        waterlogged: "false",
        south: "false",
        north: "false",
        west: "true"
      },
      Name: "minecraft:glass_pane"
    },
    {
      Properties: {
        facing: "south"
      },
      Name: "minecraft:wall_torch"
    },
    {
      Properties: {
        east: "false",
        waterlogged: "false",
        south: "true",
        north: "true",
        west: "false"
      },
      Name: "minecraft:glass_pane"
    },
    {
      Properties: {
        half: "bottom",
        waterlogged: "false",
        shape: "straight",
        facing: "north"
      },
      Name: "minecraft:cobblestone_stairs"
    },
    {
      Properties: {
        hinge: "left",
        half: "lower",
        powered: "false",
        facing: "east",
        open: "false"
      },
      Name: "minecraft:oak_door"
    },
    {
      Properties: {
        hinge: "left",
        half: "upper",
        powered: "false",
        facing: "east",
        open: "false"
      },
      Name: "minecraft:oak_door"
    },
    {
      Properties: {
        facing: "west"
      },
      Name: "minecraft:wall_torch"
    },
    {
      Properties: {
        facing: "north"
      },
      Name: "minecraft:wall_torch"
    }
  ],
  DataVersion: 1910
}