{
  size: [10, 8, 12],
  entities: [],
  blocks: [
    {
      pos: [0, 0, 0],
      state: 0
    },
    {
      pos: [1, 0, 0],
      state: 0
    },
    {
      pos: [2, 0, 0],
      state: 0
    },
    {
      pos: [3, 0, 0],
      state: 0
    },
    {
      pos: [4, 0, 0],
      state: 1
    },
    {
      pos: [5, 0, 0],
      state: 1
    },
    {
      pos: [6, 0, 0],
      state: 2
    },
    {
      pos: [7, 0, 0],
      state: 2
    },
    {
      pos: [8, 0, 0],
      state: 2
    },
    {
      pos: [9, 0, 0],
      state: 0
    },
    {
      pos: [1, 1, 0],
      state: 3
    },
    {
      pos: [2, 1, 0],
      state: 3
    },
    {
      pos: [3, 1, 0],
      state: 3
    },
    {
      pos: [4, 1, 0],
      state: 3
    },
    {
      pos: [5, 1, 0],
      state: 3
    },
    {
      pos: [6, 1, 0],
      state: 3
    },
    {
      pos: [7, 1, 0],
      state: 3
    },
    {
      pos: [8, 1, 0],
      state: 3
    },
    {
      pos: [9, 1, 0],
      state: 0
    },
    {
      pos: [0, 0, 1],
      state: 3
    },
    {
      pos: [1, 0, 1],
      state: 0
    },
    {
      pos: [2, 0, 1],
      state: 0
    },
    {
      pos: [3, 0, 1],
      state: 2
    },
    {
      pos: [4, 0, 1],
      state: 2
    },
    {
      pos: [5, 0, 1],
      state: 2
    },
    {
      pos: [6, 0, 1],
      state: 2
    },
    {
      pos: [7, 0, 1],
      state: 2
    },
    {
      pos: [8, 0, 1],
      state: 2
    },
    {
      pos: [9, 0, 1],
      state: 2
    },
    {
      pos: [1, 1, 1],
      state: 3
    },
    {
      pos: [7, 1, 1],
      state: 0
    },
    {
      pos: [8, 1, 1],
      state: 0
    },
    {
      pos: [9, 1, 1],
      state: 3
    },
    {
      pos: [0, 0, 2],
      state: 0
    },
    {
      pos: [1, 0, 2],
      state: 0
    },
    {
      pos: [2, 0, 2],
      state: 0
    },
    {
      pos: [3, 0, 2],
      state: 0
    },
    {
      pos: [4, 0, 2],
      state: 2
    },
    {
      pos: [5, 0, 2],
      state: 2
    },
    {
      pos: [6, 0, 2],
      state: 2
    },
    {
      pos: [7, 0, 2],
      state: 2
    },
    {
      pos: [8, 0, 2],
      state: 2
    },
    {
      pos: [9, 0, 2],
      state: 1
    },
    {
      pos: [0, 1, 2],
      state: 3
    },
    {
      pos: [4, 1, 2],
      state: 4
    },
    {
      pos: [8, 1, 2],
      state: 3
    },
    {
      pos: [9, 1, 2],
      state: 3
    },
    {
      pos: [0, 0, 3],
      state: 0
    },
    {
      pos: [1, 0, 3],
      state: 0
    },
    {
      pos: [2, 0, 3],
      state: 0
    },
    {
      pos: [3, 0, 3],
      state: 0
    },
    {
      pos: [4, 0, 3],
      state: 2
    },
    {
      pos: [5, 0, 3],
      state: 2
    },
    {
      pos: [6, 0, 3],
      state: 2
    },
    {
      pos: [7, 0, 3],
      state: 2
    },
    {
      pos: [8, 0, 3],
      state: 2
    },
    {
      pos: [9, 0, 3],
      state: 1
    },
    {
      pos: [0, 1, 3],
      state: 3
    },
    {
      pos: [4, 1, 3],
      state: 4
    },
    {
      pos: [9, 1, 3],
      state: 3
    },
    {
      pos: [1, 4, 3],
      state: 5
    },
    {
      pos: [7, 4, 3],
      state: 5
    },
    {
      pos: [2, 5, 3],
      state: 5
    },
    {
      pos: [6, 5, 3],
      state: 5
    },
    {
      pos: [3, 6, 3],
      state: 5
    },
    {
      pos: [5, 6, 3],
      state: 5
    },
    {
      pos: [4, 7, 3],
      state: 5
    },
    {
      pos: [0, 0, 4],
      state: 3
    },
    {
      pos: [1, 0, 4],
      state: 0
    },
    {
      pos: [2, 0, 4],
      state: 0
    },
    {
      pos: [3, 0, 4],
      state: 0
    },
    {
      pos: [4, 0, 4],
      state: 0
    },
    {
      pos: [5, 0, 4],
      state: 0
    },
    {
      pos: [6, 0, 4],
      state: 2
    },
    {
      pos: [7, 0, 4],
      state: 3
    },
    {
      pos: [8, 0, 4],
      state: 3
    },
    {
      pos: [9, 0, 4],
      state: 1
    },
    {
      pos: [1, 1, 4],
      state: 3
    },
    {
      pos: [2, 1, 4],
      state: 6
    },
    {
      pos: [4, 1, 4],
      state: 4
    },
    {
      pos: [6, 1, 4],
      state: 6
    },
    {
      pos: [9, 1, 4],
      state: 0
    },
    {
      pos: [2, 2, 4],
      state: 6
    },
    {
      pos: [6, 2, 4],
      state: 6
    },
    {
      pos: [2, 3, 4],
      state: 6
    },
    {
      pos: [6, 3, 4],
      state: 6
    },
    {
      pos: [1, 4, 4],
      state: 5
    },
    {
      pos: [2, 4, 4],
      state: 6
    },
    {
      pos: [6, 4, 4],
      state: 6
    },
    {
      pos: [7, 4, 4],
      state: 5
    },
    {
      pos: [2, 5, 4],
      state: 5
    },
    {
      pos: [3, 5, 4],
      state: 7
    },
    {
      pos: [4, 5, 4],
      state: 7
    },
    {
      pos: [5, 5, 4],
      state: 7
    },
    {
      pos: [6, 5, 4],
      state: 5
    },
    {
      pos: [3, 6, 4],
      state: 5
    },
    {
      pos: [5, 6, 4],
      state: 5
    },
    {
      pos: [4, 7, 4],
      state: 5
    },
    {
      pos: [0, 0, 5],
      state: 0
    },
    {
      pos: [1, 0, 5],
      state: 0
    },
    {
      pos: [2, 0, 5],
      state: 0
    },
    {
      pos: [3, 0, 5],
      state: 0
    },
    {
      pos: [4, 0, 5],
      state: 0
    },
    {
      pos: [5, 0, 5],
      state: 8
    },
    {
      pos: [6, 0, 5],
      state: 8
    },
    {
      pos: [7, 0, 5],
      state: 1
    },
    {
      pos: [8, 0, 5],
      state: 3
    },
    {
      pos: [9, 0, 5],
      state: 1
    },
    {
      pos: [1, 1, 5],
      state: 0
    },
    {
      pos: [2, 1, 5],
      state: 0
    },
    {
      pos: [3, 1, 5],
      state: 9
    },
    {
      pos: [4, 1, 5],
      state: 9
    },
    {
      pos: [5, 1, 5],
      state: 9
    },
    {
      pos: [6, 1, 5],
      state: 9
    },
    {
      pos: [7, 1, 5],
      state: 6
    },
    {
      pos: [9, 1, 5],
      state: 3
    },
    {
      pos: [1, 2, 5],
      state: 6
    },
    {
      pos: [2, 2, 5],
      state: 9
    },
    {
      pos: [3, 2, 5],
      state: 9
    },
    {
      pos: [5, 2, 5],
      state: 9
    },
    {
      pos: [6, 2, 5],
      state: 9
    },
    {
      pos: [7, 2, 5],
      state: 6
    },
    {
      pos: [1, 3, 5],
      state: 6
    },
    {
      pos: [2, 3, 5],
      state: 9
    },
    {
      pos: [3, 3, 5],
      state: 9
    },
    {
      pos: [5, 3, 5],
      state: 9
    },
    {
      pos: [6, 3, 5],
      state: 9
    },
    {
      pos: [7, 3, 5],
      state: 6
    },
    {
      pos: [1, 4, 5],
      state: 5
    },
    {
      pos: [2, 4, 5],
      state: 9
    },
    {
      pos: [3, 4, 5],
      state: 9
    },
    {
      pos: [4, 4, 5],
      state: 9
    },
    {
      pos: [5, 4, 5],
      state: 9
    },
    {
      pos: [6, 4, 5],
      state: 9
    },
    {
      pos: [7, 4, 5],
      state: 5
    },
    {
      pos: [2, 5, 5],
      state: 5
    },
    {
      pos: [3, 5, 5],
      state: 9
    },
    {
      pos: [4, 5, 5],
      state: 9
    },
    {
      pos: [5, 5, 5],
      state: 9
    },
    {
      pos: [6, 5, 5],
      state: 5
    },
    {
      pos: [3, 6, 5],
      state: 5
    },
    {
      pos: [4, 6, 5],
      state: 9
    },
    {
      pos: [5, 6, 5],
      state: 5
    },
    {
      pos: [4, 7, 5],
      state: 5
    },
    {
      pos: [0, 0, 6],
      state: 0
    },
    {
      pos: [1, 0, 6],
      state: 0
    },
    {
      pos: [2, 0, 6],
      state: 0
    },
    {
      pos: [3, 0, 6],
      state: 0
    },
    {
      pos: [4, 0, 6],
      state: 0
    },
    {
      pos: [5, 0, 6],
      state: 0
    },
    {
      pos: [6, 0, 6],
      state: 8
    },
    {
      pos: [7, 0, 6],
      state: 3
    },
    {
      pos: [8, 0, 6],
      state: 3
    },
    {
      pos: [9, 0, 6],
      state: 1
    },
    {
      pos: [0, 1, 6],
      state: 3
    },
    {
      pos: [1, 1, 6],
      state: 0
    },
    {
      pos: [2, 1, 6],
      state: 0
    },
    {
      pos: [3, 1, 6],
      state: 9
    },
    {
      pos: [4, 1, 6],
      state: 9
    },
    {
      pos: [5, 1, 6],
      state: 9
    },
    {
      pos: [6, 1, 6],
      state: 0
    },
    {
      pos: [9, 1, 6],
      state: 3
    },
    {
      pos: [2, 2, 6],
      state: 9
    },
    {
      pos: [6, 2, 6],
      state: 9
    },
    {
      pos: [2, 3, 6],
      state: 9
    },
    {
      pos: [6, 3, 6],
      state: 9
    },
    {
      pos: [1, 4, 6],
      state: 5
    },
    {
      pos: [2, 4, 6],
      state: 9
    },
    {
      pos: [6, 4, 6],
      state: 9
    },
    {
      pos: [7, 4, 6],
      state: 5
    },
    {
      pos: [2, 5, 6],
      state: 5
    },
    {
      pos: [6, 5, 6],
      state: 5
    },
    {
      pos: [3, 6, 6],
      state: 5
    },
    {
      pos: [5, 6, 6],
      state: 5
    },
    {
      pos: [4, 7, 6],
      state: 5
    },
    {
      pos: [0, 0, 7],
      state: 0
    },
    {
      pos: [1, 0, 7],
      state: 0
    },
    {
      pos: [2, 0, 7],
      state: 0
    },
    {
      pos: [3, 0, 7],
      state: 0
    },
    {
      pos: [4, 0, 7],
      state: 0
    },
    {
      pos: [5, 0, 7],
      state: 0
    },
    {
      pos: [6, 0, 7],
      state: 0
    },
    {
      pos: [7, 0, 7],
      state: 8
    },
    {
      pos: [8, 0, 7],
      state: 1
    },
    {
      pos: [9, 0, 7],
      state: 1
    },
    {
      pos: [1, 1, 7],
      state: 0
    },
    {
      pos: [2, 1, 7],
      state: 0
    },
    {
      pos: [3, 1, 7],
      state: 4
    },
    {
      pos: [4, 1, 7],
      state: 4
    },
    {
      pos: [5, 1, 7],
      state: 4
    },
    {
      pos: [6, 1, 7],
      state: 0
    },
    {
      pos: [7, 1, 7],
      state: 3
    },
    {
      pos: [8, 1, 7],
      state: 3
    },
    {
      pos: [9, 1, 7],
      state: 3
    },
    {
      pos: [2, 2, 7],
      state: 9
    },
    {
      pos: [6, 2, 7],
      state: 9
    },
    {
      pos: [2, 3, 7],
      state: 9
    },
    {
      pos: [6, 3, 7],
      state: 9
    },
    {
      pos: [1, 4, 7],
      state: 5
    },
    {
      pos: [2, 4, 7],
      state: 9
    },
    {
      pos: [6, 4, 7],
      state: 9
    },
    {
      pos: [7, 4, 7],
      state: 5
    },
    {
      pos: [2, 5, 7],
      state: 5
    },
    {
      pos: [6, 5, 7],
      state: 5
    },
    {
      pos: [3, 6, 7],
      state: 5
    },
    {
      pos: [5, 6, 7],
      state: 5
    },
    {
      pos: [4, 7, 7],
      state: 5
    },
    {
      pos: [0, 0, 8],
      state: 0
    },
    {
      pos: [1, 0, 8],
      state: 0
    },
    {
      pos: [2, 0, 8],
      state: 0
    },
    {
      pos: [3, 0, 8],
      state: 0
    },
    {
      pos: [4, 0, 8],
      state: 0
    },
    {
      pos: [5, 0, 8],
      state: 0
    },
    {
      pos: [6, 0, 8],
      state: 0
    },
    {
      pos: [7, 0, 8],
      state: 0
    },
    {
      pos: [8, 0, 8],
      state: 0
    },
    {
      pos: [9, 0, 8],
      state: 0
    },
    {
      pos: [0, 1, 8],
      state: 3
    },
    {
      pos: [2, 1, 8],
      state: 0
    },
    {
      pos: [3, 1, 8],
      state: 9
    },
    {
      pos: [4, 1, 8],
      state: 9
    },
    {
      pos: [5, 1, 8],
      state: 9
    },
    {
      pos: [6, 1, 8],
      state: 0
    },
    {
      pos: [2, 2, 8],
      state: 9
    },
    {
      pos: [6, 2, 8],
      state: 9
    },
    {
      pos: [2, 3, 8],
      state: 9
    },
    {
      pos: [6, 3, 8],
      state: 9
    },
    {
      pos: [1, 4, 8],
      state: 5
    },
    {
      pos: [2, 4, 8],
      state: 9
    },
    {
      pos: [6, 4, 8],
      state: 9
    },
    {
      pos: [7, 4, 8],
      state: 5
    },
    {
      pos: [2, 5, 8],
      state: 5
    },
    {
      pos: [6, 5, 8],
      state: 5
    },
    {
      pos: [3, 6, 8],
      state: 5
    },
    {
      pos: [5, 6, 8],
      state: 5
    },
    {
      pos: [4, 7, 8],
      state: 5
    },
    {
      pos: [0, 0, 9],
      state: 3
    },
    {
      pos: [1, 0, 9],
      state: 0
    },
    {
      pos: [2, 0, 9],
      state: 0
    },
    {
      pos: [3, 0, 9],
      state: 0
    },
    {
      pos: [4, 0, 9],
      state: 0
    },
    {
      pos: [5, 0, 9],
      state: 0
    },
    {
      pos: [6, 0, 9],
      state: 0
    },
    {
      pos: [7, 0, 9],
      state: 0
    },
    {
      pos: [8, 0, 9],
      state: 0
    },
    {
      pos: [9, 0, 9],
      state: 0
    },
    {
      pos: [1, 1, 9],
      state: 0
    },
    {
      pos: [2, 1, 9],
      state: 0
    },
    {
      pos: [3, 1, 9],
      state: 0
    },
    {
      pos: [4, 1, 9],
      state: 9
    },
    {
      pos: [5, 1, 9],
      state: 0
    },
    {
      pos: [6, 1, 9],
      state: 0
    },
    {
      pos: [7, 1, 9],
      state: 0
    },
    {
      pos: [1, 2, 9],
      state: 6
    },
    {
      pos: [2, 2, 9],
      state: 9
    },
    {
      pos: [3, 2, 9],
      state: 9
    },
    {
      pos: [5, 2, 9],
      state: 9
    },
    {
      pos: [6, 2, 9],
      state: 9
    },
    {
      pos: [7, 2, 9],
      state: 6
    },
    {
      pos: [1, 3, 9],
      state: 6
    },
    {
      pos: [2, 3, 9],
      state: 9
    },
    {
      pos: [3, 3, 9],
      state: 9
    },
    {
      pos: [5, 3, 9],
      state: 9
    },
    {
      pos: [6, 3, 9],
      state: 9
    },
    {
      pos: [7, 3, 9],
      state: 6
    },
    {
      pos: [1, 4, 9],
      state: 5
    },
    {
      pos: [2, 4, 9],
      state: 9
    },
    {
      pos: [3, 4, 9],
      state: 9
    },
    {
      pos: [4, 4, 9],
      state: 9
    },
    {
      pos: [5, 4, 9],
      state: 9
    },
    {
      pos: [6, 4, 9],
      state: 9
    },
    {
      pos: [7, 4, 9],
      state: 5
    },
    {
      pos: [2, 5, 9],
      state: 5
    },
    {
      pos: [3, 5, 9],
      state: 9
    },
    {
      pos: [5, 5, 9],
      state: 9
    },
    {
      pos: [6, 5, 9],
      state: 5
    },
    {
      pos: [3, 6, 9],
      state: 5
    },
    {
      pos: [4, 6, 9],
      state: 9
    },
    {
      pos: [5, 6, 9],
      state: 5
    },
    {
      pos: [4, 7, 9],
      state: 5
    },
    {
      pos: [0, 0, 10],
      state: 3
    },
    {
      pos: [1, 0, 10],
      state: 0
    },
    {
      pos: [2, 0, 10],
      state: 0
    },
    {
      pos: [3, 0, 10],
      state: 0
    },
    {
      pos: [4, 0, 10],
      state: 3
    },
    {
      pos: [5, 0, 10],
      state: 0
    },
    {
      pos: [6, 0, 10],
      state: 0
    },
    {
      pos: [7, 0, 10],
      state: 0
    },
    {
      pos: [8, 0, 10],
      state: 0
    },
    {
      pos: [9, 0, 10],
      state: 0
    },
    {
      pos: [1, 1, 10],
      state: 3
    },
    {
      pos: [2, 1, 10],
      state: 0
    },
    {
      pos: [3, 1, 10],
      state: 3
    },
    {
      pos: [6, 1, 10],
      state: 0
    },
    {
      pos: [2, 2, 10],
      state: 6
    },
    {
      pos: [6, 2, 10],
      state: 6
    },
    {
      pos: [2, 3, 10],
      state: 6
    },
    {
      pos: [6, 3, 10],
      state: 6
    },
    {
      pos: [1, 4, 10],
      state: 5
    },
    {
      pos: [2, 4, 10],
      state: 6
    },
    {
      pos: [6, 4, 10],
      state: 6
    },
    {
      pos: [7, 4, 10],
      state: 5
    },
    {
      pos: [2, 5, 10],
      state: 5
    },
    {
      pos: [6, 5, 10],
      state: 5
    },
    {
      pos: [3, 6, 10],
      state: 5
    },
    {
      pos: [5, 6, 10],
      state: 5
    },
    {
      pos: [4, 7, 10],
      state: 5
    },
    {
      pos: [0, 0, 11],
      state: 0
    },
    {
      pos: [1, 0, 11],
      state: 0
    },
    {
      pos: [2, 0, 11],
      state: 3
    },
    {
      pos: [3, 0, 11],
      state: 0
    },
    {
      pos: [4, 0, 11],
      state: 3
    },
    {
      pos: [5, 0, 11],
      state: 0
    },
    {
      pos: [6, 0, 11],
      state: 0
    },
    {
      pos: [7, 0, 11],
      state: 0
    },
    {
      pos: [8, 0, 11],
      state: 0
    },
    {
      pos: [9, 0, 11],
      state: 0
    },
    {
      pos: [6, 1, 11],
      state: 3
    },
    {
      pos: [1, 4, 11],
      state: 5
    },
    {
      pos: [7, 4, 11],
      state: 5
    },
    {
      pos: [2, 5, 11],
      state: 5
    },
    {
      pos: [6, 5, 11],
      state: 5
    },
    {
      pos: [3, 6, 11],
      state: 5
    },
    {
      pos: [5, 6, 11],
      state: 5
    },
    {
      pos: [4, 7, 11],
      state: 5
    },
    {
      nbt: {
        target_pool: "minecraft:village/taiga/decor",
        final_state: "minecraft:grass_block",
        id: "minecraft:jigsaw",
        attachement_type: "minecraft:bottom"
      },
      pos: [0, 1, 0],
      state: 10
    },
    {
      nbt: {
        Items: [],
        id: "minecraft:barrel",
        Lock: ""
      },
      pos: [9, 2, 0],
      state: 11
    },
    {
      nbt: {
        Items: [],
        id: "minecraft:barrel",
        Lock: ""
      },
      pos: [7, 2, 1],
      state: 12
    },
    {
      nbt: {
        Items: [],
        id: "minecraft:barrel",
        Lock: ""
      },
      pos: [8, 2, 1],
      state: 13
    },
    {
      nbt: {
        Items: [],
        id: "minecraft:barrel",
        Lock: ""
      },
      pos: [8, 3, 1],
      state: 14
    },
    {
      nbt: {
        Items: [],
        id: "minecraft:barrel",
        Lock: ""
      },
      pos: [9, 2, 4],
      state: 13
    },
    {
      nbt: {
        target_pool: "minecraft:village/common/cats",
        final_state: "minecraft:grass_block",
        id: "minecraft:jigsaw",
        attachement_type: "minecraft:bottom"
      },
      pos: [0, 1, 5],
      state: 10
    },
    {
      nbt: {
        Items: [],
        id: "minecraft:barrel",
        Lock: ""
      },
      pos: [1, 2, 6],
      state: 13
    },
    {
      nbt: {
        Items: [],
        id: "minecraft:barrel",
        Lock: ""
      },
      pos: [1, 3, 6],
      state: 15
    },
    {
      nbt: {
        Items: [],
        id: "minecraft:barrel",
        Lock: ""
      },
      pos: [1, 2, 7],
      state: 12
    },
    {
      nbt: {
        target_pool: "minecraft:village/common/cats",
        final_state: "minecraft:grass_block",
        id: "minecraft:jigsaw",
        attachement_type: "minecraft:bottom"
      },
      pos: [5, 1, 11],
      state: 10
    },
    {
      nbt: {
        target_pool: "minecraft:village/taiga/decor",
        final_state: "minecraft:grass_block",
        id: "minecraft:jigsaw",
        attachement_type: "minecraft:bottom"
      },
      pos: [9, 1, 11],
      state: 10
    },
    {
      nbt: {
        target_pool: "minecraft:empty",
        final_state: "minecraft:air",
        id: "minecraft:jigsaw",
        attachement_type: "minecraft:building_entrance"
      },
      pos: [4, 2, 11],
      state: 16
    },
    {
      pos: [0, 2, 0],
      state: 17
    },
    {
      pos: [1, 2, 0],
      state: 17
    },
    {
      pos: [2, 2, 0],
      state: 17
    },
    {
      pos: [3, 2, 0],
      state: 17
    },
    {
      pos: [4, 2, 0],
      state: 17
    },
    {
      pos: [5, 2, 0],
      state: 17
    },
    {
      pos: [6, 2, 0],
      state: 17
    },
    {
      pos: [7, 2, 0],
      state: 17
    },
    {
      pos: [8, 2, 0],
      state: 17
    },
    {
      pos: [0, 3, 0],
      state: 17
    },
    {
      pos: [1, 3, 0],
      state: 17
    },
    {
      pos: [2, 3, 0],
      state: 17
    },
    {
      pos: [3, 3, 0],
      state: 17
    },
    {
      pos: [4, 3, 0],
      state: 17
    },
    {
      pos: [5, 3, 0],
      state: 17
    },
    {
      pos: [6, 3, 0],
      state: 17
    },
    {
      pos: [7, 3, 0],
      state: 17
    },
    {
      pos: [8, 3, 0],
      state: 17
    },
    {
      pos: [9, 3, 0],
      state: 17
    },
    {
      pos: [0, 4, 0],
      state: 17
    },
    {
      pos: [1, 4, 0],
      state: 17
    },
    {
      pos: [2, 4, 0],
      state: 17
    },
    {
      pos: [3, 4, 0],
      state: 17
    },
    {
      pos: [4, 4, 0],
      state: 17
    },
    {
      pos: [5, 4, 0],
      state: 17
    },
    {
      pos: [6, 4, 0],
      state: 17
    },
    {
      pos: [7, 4, 0],
      state: 17
    },
    {
      pos: [8, 4, 0],
      state: 17
    },
    {
      pos: [9, 4, 0],
      state: 17
    },
    {
      pos: [0, 5, 0],
      state: 17
    },
    {
      pos: [1, 5, 0],
      state: 17
    },
    {
      pos: [2, 5, 0],
      state: 17
    },
    {
      pos: [3, 5, 0],
      state: 17
    },
    {
      pos: [4, 5, 0],
      state: 17
    },
    {
      pos: [5, 5, 0],
      state: 17
    },
    {
      pos: [6, 5, 0],
      state: 17
    },
    {
      pos: [7, 5, 0],
      state: 17
    },
    {
      pos: [8, 5, 0],
      state: 17
    },
    {
      pos: [9, 5, 0],
      state: 17
    },
    {
      pos: [0, 6, 0],
      state: 17
    },
    {
      pos: [1, 6, 0],
      state: 17
    },
    {
      pos: [2, 6, 0],
      state: 17
    },
    {
      pos: [3, 6, 0],
      state: 17
    },
    {
      pos: [4, 6, 0],
      state: 17
    },
    {
      pos: [5, 6, 0],
      state: 17
    },
    {
      pos: [6, 6, 0],
      state: 17
    },
    {
      pos: [7, 6, 0],
      state: 17
    },
    {
      pos: [8, 6, 0],
      state: 17
    },
    {
      pos: [9, 6, 0],
      state: 17
    },
    {
      pos: [0, 7, 0],
      state: 17
    },
    {
      pos: [1, 7, 0],
      state: 17
    },
    {
      pos: [2, 7, 0],
      state: 17
    },
    {
      pos: [3, 7, 0],
      state: 17
    },
    {
      pos: [4, 7, 0],
      state: 17
    },
    {
      pos: [5, 7, 0],
      state: 17
    },
    {
      pos: [6, 7, 0],
      state: 17
    },
    {
      pos: [7, 7, 0],
      state: 17
    },
    {
      pos: [8, 7, 0],
      state: 17
    },
    {
      pos: [9, 7, 0],
      state: 17
    },
    {
      pos: [2, 1, 1],
      state: 18
    },
    {
      pos: [3, 1, 1],
      state: 18
    },
    {
      pos: [4, 1, 1],
      state: 18
    },
    {
      pos: [5, 1, 1],
      state: 18
    },
    {
      pos: [6, 1, 1],
      state: 18
    },
    {
      pos: [0, 2, 1],
      state: 17
    },
    {
      pos: [1, 2, 1],
      state: 19
    },
    {
      pos: [2, 2, 1],
      state: 17
    },
    {
      pos: [3, 2, 1],
      state: 17
    },
    {
      pos: [4, 2, 1],
      state: 17
    },
    {
      pos: [5, 2, 1],
      state: 17
    },
    {
      pos: [6, 2, 1],
      state: 17
    },
    {
      pos: [9, 2, 1],
      state: 17
    },
    {
      pos: [0, 3, 1],
      state: 17
    },
    {
      pos: [1, 3, 1],
      state: 20
    },
    {
      pos: [2, 3, 1],
      state: 17
    },
    {
      pos: [3, 3, 1],
      state: 17
    },
    {
      pos: [4, 3, 1],
      state: 17
    },
    {
      pos: [5, 3, 1],
      state: 17
    },
    {
      pos: [6, 3, 1],
      state: 17
    },
    {
      pos: [7, 3, 1],
      state: 17
    },
    {
      pos: [9, 3, 1],
      state: 17
    },
    {
      pos: [0, 4, 1],
      state: 17
    },
    {
      pos: [1, 4, 1],
      state: 17
    },
    {
      pos: [2, 4, 1],
      state: 17
    },
    {
      pos: [3, 4, 1],
      state: 17
    },
    {
      pos: [4, 4, 1],
      state: 17
    },
    {
      pos: [5, 4, 1],
      state: 17
    },
    {
      pos: [6, 4, 1],
      state: 17
    },
    {
      pos: [7, 4, 1],
      state: 17
    },
    {
      pos: [8, 4, 1],
      state: 17
    },
    {
      pos: [9, 4, 1],
      state: 17
    },
    {
      pos: [0, 5, 1],
      state: 17
    },
    {
      pos: [1, 5, 1],
      state: 17
    },
    {
      pos: [2, 5, 1],
      state: 17
    },
    {
      pos: [3, 5, 1],
      state: 17
    },
    {
      pos: [4, 5, 1],
      state: 17
    },
    {
      pos: [5, 5, 1],
      state: 17
    },
    {
      pos: [6, 5, 1],
      state: 17
    },
    {
      pos: [7, 5, 1],
      state: 17
    },
    {
      pos: [8, 5, 1],
      state: 17
    },
    {
      pos: [9, 5, 1],
      state: 17
    },
    {
      pos: [0, 6, 1],
      state: 17
    },
    {
      pos: [1, 6, 1],
      state: 17
    },
    {
      pos: [2, 6, 1],
      state: 17
    },
    {
      pos: [3, 6, 1],
      state: 17
    },
    {
      pos: [4, 6, 1],
      state: 17
    },
    {
      pos: [5, 6, 1],
      state: 17
    },
    {
      pos: [6, 6, 1],
      state: 17
    },
    {
      pos: [7, 6, 1],
      state: 17
    },
    {
      pos: [8, 6, 1],
      state: 17
    },
    {
      pos: [9, 6, 1],
      state: 17
    },
    {
      pos: [0, 7, 1],
      state: 17
    },
    {
      pos: [1, 7, 1],
      state: 17
    },
    {
      pos: [2, 7, 1],
      state: 17
    },
    {
      pos: [3, 7, 1],
      state: 17
    },
    {
      pos: [4, 7, 1],
      state: 17
    },
    {
      pos: [5, 7, 1],
      state: 17
    },
    {
      pos: [6, 7, 1],
      state: 17
    },
    {
      pos: [7, 7, 1],
      state: 17
    },
    {
      pos: [8, 7, 1],
      state: 17
    },
    {
      pos: [9, 7, 1],
      state: 17
    },
    {
      pos: [1, 1, 2],
      state: 18
    },
    {
      pos: [2, 1, 2],
      state: 18
    },
    {
      pos: [3, 1, 2],
      state: 18
    },
    {
      pos: [5, 1, 2],
      state: 18
    },
    {
      pos: [6, 1, 2],
      state: 18
    },
    {
      pos: [7, 1, 2],
      state: 18
    },
    {
      pos: [0, 2, 2],
      state: 17
    },
    {
      pos: [1, 2, 2],
      state: 17
    },
    {
      pos: [2, 2, 2],
      state: 17
    },
    {
      pos: [3, 2, 2],
      state: 17
    },
    {
      pos: [4, 2, 2],
      state: 17
    },
    {
      pos: [5, 2, 2],
      state: 17
    },
    {
      pos: [6, 2, 2],
      state: 17
    },
    {
      pos: [7, 2, 2],
      state: 17
    },
    {
      pos: [8, 2, 2],
      state: 17
    },
    {
      pos: [9, 2, 2],
      state: 17
    },
    {
      pos: [0, 3, 2],
      state: 17
    },
    {
      pos: [1, 3, 2],
      state: 17
    },
    {
      pos: [2, 3, 2],
      state: 17
    },
    {
      pos: [3, 3, 2],
      state: 17
    },
    {
      pos: [4, 3, 2],
      state: 17
    },
    {
      pos: [5, 3, 2],
      state: 17
    },
    {
      pos: [6, 3, 2],
      state: 17
    },
    {
      pos: [7, 3, 2],
      state: 17
    },
    {
      pos: [8, 3, 2],
      state: 17
    },
    {
      pos: [9, 3, 2],
      state: 17
    },
    {
      pos: [0, 4, 2],
      state: 17
    },
    {
      pos: [1, 4, 2],
      state: 17
    },
    {
      pos: [2, 4, 2],
      state: 17
    },
    {
      pos: [3, 4, 2],
      state: 17
    },
    {
      pos: [4, 4, 2],
      state: 17
    },
    {
      pos: [5, 4, 2],
      state: 17
    },
    {
      pos: [6, 4, 2],
      state: 17
    },
    {
      pos: [7, 4, 2],
      state: 17
    },
    {
      pos: [8, 4, 2],
      state: 17
    },
    {
      pos: [9, 4, 2],
      state: 17
    },
    {
      pos: [0, 5, 2],
      state: 17
    },
    {
      pos: [1, 5, 2],
      state: 17
    },
    {
      pos: [2, 5, 2],
      state: 17
    },
    {
      pos: [3, 5, 2],
      state: 17
    },
    {
      pos: [4, 5, 2],
      state: 17
    },
    {
      pos: [5, 5, 2],
      state: 17
    },
    {
      pos: [6, 5, 2],
      state: 17
    },
    {
      pos: [7, 5, 2],
      state: 17
    },
    {
      pos: [8, 5, 2],
      state: 17
    },
    {
      pos: [9, 5, 2],
      state: 17
    },
    {
      pos: [0, 6, 2],
      state: 17
    },
    {
      pos: [1, 6, 2],
      state: 17
    },
    {
      pos: [2, 6, 2],
      state: 17
    },
    {
      pos: [3, 6, 2],
      state: 17
    },
    {
      pos: [4, 6, 2],
      state: 17
    },
    {
      pos: [5, 6, 2],
      state: 17
    },
    {
      pos: [6, 6, 2],
      state: 17
    },
    {
      pos: [7, 6, 2],
      state: 17
    },
    {
      pos: [8, 6, 2],
      state: 17
    },
    {
      pos: [9, 6, 2],
      state: 17
    },
    {
      pos: [0, 7, 2],
      state: 17
    },
    {
      pos: [1, 7, 2],
      state: 17
    },
    {
      pos: [2, 7, 2],
      state: 17
    },
    {
      pos: [3, 7, 2],
      state: 17
    },
    {
      pos: [4, 7, 2],
      state: 17
    },
    {
      pos: [5, 7, 2],
      state: 17
    },
    {
      pos: [6, 7, 2],
      state: 17
    },
    {
      pos: [7, 7, 2],
      state: 17
    },
    {
      pos: [8, 7, 2],
      state: 17
    },
    {
      pos: [9, 7, 2],
      state: 17
    },
    {
      pos: [1, 1, 3],
      state: 18
    },
    {
      pos: [2, 1, 3],
      state: 18
    },
    {
      pos: [3, 1, 3],
      state: 18
    },
    {
      pos: [5, 1, 3],
      state: 18
    },
    {
      pos: [6, 1, 3],
      state: 18
    },
    {
      pos: [7, 1, 3],
      state: 18
    },
    {
      pos: [8, 1, 3],
      state: 18
    },
    {
      pos: [0, 2, 3],
      state: 17
    },
    {
      pos: [1, 2, 3],
      state: 17
    },
    {
      pos: [2, 2, 3],
      state: 17
    },
    {
      pos: [3, 2, 3],
      state: 17
    },
    {
      pos: [4, 2, 3],
      state: 17
    },
    {
      pos: [5, 2, 3],
      state: 17
    },
    {
      pos: [6, 2, 3],
      state: 17
    },
    {
      pos: [7, 2, 3],
      state: 17
    },
    {
      pos: [8, 2, 3],
      state: 17
    },
    {
      pos: [9, 2, 3],
      state: 17
    },
    {
      pos: [0, 3, 3],
      state: 17
    },
    {
      pos: [1, 3, 3],
      state: 17
    },
    {
      pos: [2, 3, 3],
      state: 17
    },
    {
      pos: [3, 3, 3],
      state: 17
    },
    {
      pos: [4, 3, 3],
      state: 17
    },
    {
      pos: [5, 3, 3],
      state: 17
    },
    {
      pos: [6, 3, 3],
      state: 17
    },
    {
      pos: [7, 3, 3],
      state: 17
    },
    {
      pos: [8, 3, 3],
      state: 17
    },
    {
      pos: [9, 3, 3],
      state: 17
    },
    {
      pos: [0, 4, 3],
      state: 17
    },
    {
      pos: [2, 4, 3],
      state: 17
    },
    {
      pos: [3, 4, 3],
      state: 17
    },
    {
      pos: [4, 4, 3],
      state: 17
    },
    {
      pos: [5, 4, 3],
      state: 17
    },
    {
      pos: [6, 4, 3],
      state: 17
    },
    {
      pos: [8, 4, 3],
      state: 17
    },
    {
      pos: [9, 4, 3],
      state: 17
    },
    {
      pos: [0, 5, 3],
      state: 17
    },
    {
      pos: [1, 5, 3],
      state: 17
    },
    {
      pos: [3, 5, 3],
      state: 17
    },
    {
      pos: [4, 5, 3],
      state: 17
    },
    {
      pos: [5, 5, 3],
      state: 17
    },
    {
      pos: [7, 5, 3],
      state: 17
    },
    {
      pos: [8, 5, 3],
      state: 17
    },
    {
      pos: [9, 5, 3],
      state: 17
    },
    {
      pos: [0, 6, 3],
      state: 17
    },
    {
      pos: [1, 6, 3],
      state: 17
    },
    {
      pos: [2, 6, 3],
      state: 17
    },
    {
      pos: [4, 6, 3],
      state: 17
    },
    {
      pos: [6, 6, 3],
      state: 17
    },
    {
      pos: [7, 6, 3],
      state: 17
    },
    {
      pos: [8, 6, 3],
      state: 17
    },
    {
      pos: [9, 6, 3],
      state: 17
    },
    {
      pos: [0, 7, 3],
      state: 17
    },
    {
      pos: [1, 7, 3],
      state: 17
    },
    {
      pos: [2, 7, 3],
      state: 17
    },
    {
      pos: [3, 7, 3],
      state: 17
    },
    {
      pos: [5, 7, 3],
      state: 17
    },
    {
      pos: [6, 7, 3],
      state: 17
    },
    {
      pos: [7, 7, 3],
      state: 17
    },
    {
      pos: [8, 7, 3],
      state: 17
    },
    {
      pos: [9, 7, 3],
      state: 17
    },
    {
      pos: [3, 1, 4],
      state: 18
    },
    {
      pos: [5, 1, 4],
      state: 18
    },
    {
      pos: [7, 1, 4],
      state: 18
    },
    {
      pos: [8, 1, 4],
      state: 18
    },
    {
      pos: [0, 2, 4],
      state: 17
    },
    {
      pos: [1, 2, 4],
      state: 17
    },
    {
      pos: [3, 2, 4],
      state: 21
    },
    {
      pos: [4, 2, 4],
      state: 17
    },
    {
      pos: [5, 2, 4],
      state: 22
    },
    {
      pos: [7, 2, 4],
      state: 17
    },
    {
      pos: [8, 2, 4],
      state: 17
    },
    {
      pos: [0, 3, 4],
      state: 17
    },
    {
      pos: [1, 3, 4],
      state: 17
    },
    {
      pos: [3, 3, 4],
      state: 23
    },
    {
      pos: [4, 3, 4],
      state: 17
    },
    {
      pos: [5, 3, 4],
      state: 23
    },
    {
      pos: [7, 3, 4],
      state: 17
    },
    {
      pos: [8, 3, 4],
      state: 17
    },
    {
      pos: [9, 3, 4],
      state: 17
    },
    {
      pos: [0, 4, 4],
      state: 17
    },
    {
      pos: [3, 4, 4],
      state: 17
    },
    {
      pos: [4, 4, 4],
      state: 17
    },
    {
      pos: [5, 4, 4],
      state: 17
    },
    {
      pos: [8, 4, 4],
      state: 17
    },
    {
      pos: [9, 4, 4],
      state: 17
    },
    {
      pos: [0, 5, 4],
      state: 17
    },
    {
      pos: [1, 5, 4],
      state: 17
    },
    {
      pos: [7, 5, 4],
      state: 17
    },
    {
      pos: [8, 5, 4],
      state: 17
    },
    {
      pos: [9, 5, 4],
      state: 17
    },
    {
      pos: [0, 6, 4],
      state: 17
    },
    {
      pos: [1, 6, 4],
      state: 17
    },
    {
      pos: [2, 6, 4],
      state: 17
    },
    {
      pos: [4, 6, 4],
      state: 17
    },
    {
      pos: [6, 6, 4],
      state: 17
    },
    {
      pos: [7, 6, 4],
      state: 17
    },
    {
      pos: [8, 6, 4],
      state: 17
    },
    {
      pos: [9, 6, 4],
      state: 17
    },
    {
      pos: [0, 7, 4],
      state: 17
    },
    {
      pos: [1, 7, 4],
      state: 17
    },
    {
      pos: [2, 7, 4],
      state: 17
    },
    {
      pos: [3, 7, 4],
      state: 17
    },
    {
      pos: [5, 7, 4],
      state: 17
    },
    {
      pos: [6, 7, 4],
      state: 17
    },
    {
      pos: [7, 7, 4],
      state: 17
    },
    {
      pos: [8, 7, 4],
      state: 17
    },
    {
      pos: [9, 7, 4],
      state: 17
    },
    {
      pos: [8, 1, 5],
      state: 18
    },
    {
      pos: [0, 2, 5],
      state: 17
    },
    {
      pos: [4, 2, 5],
      state: 24
    },
    {
      pos: [8, 2, 5],
      state: 17
    },
    {
      pos: [9, 2, 5],
      state: 17
    },
    {
      pos: [0, 3, 5],
      state: 17
    },
    {
      pos: [4, 3, 5],
      state: 25
    },
    {
      pos: [8, 3, 5],
      state: 17
    },
    {
      pos: [9, 3, 5],
      state: 17
    },
    {
      pos: [0, 4, 5],
      state: 17
    },
    {
      pos: [8, 4, 5],
      state: 17
    },
    {
      pos: [9, 4, 5],
      state: 17
    },
    {
      pos: [0, 5, 5],
      state: 17
    },
    {
      pos: [1, 5, 5],
      state: 17
    },
    {
      pos: [7, 5, 5],
      state: 17
    },
    {
      pos: [8, 5, 5],
      state: 17
    },
    {
      pos: [9, 5, 5],
      state: 17
    },
    {
      pos: [0, 6, 5],
      state: 17
    },
    {
      pos: [1, 6, 5],
      state: 17
    },
    {
      pos: [2, 6, 5],
      state: 17
    },
    {
      pos: [6, 6, 5],
      state: 17
    },
    {
      pos: [7, 6, 5],
      state: 17
    },
    {
      pos: [8, 6, 5],
      state: 17
    },
    {
      pos: [9, 6, 5],
      state: 17
    },
    {
      pos: [0, 7, 5],
      state: 17
    },
    {
      pos: [1, 7, 5],
      state: 17
    },
    {
      pos: [2, 7, 5],
      state: 17
    },
    {
      pos: [3, 7, 5],
      state: 17
    },
    {
      pos: [5, 7, 5],
      state: 17
    },
    {
      pos: [6, 7, 5],
      state: 17
    },
    {
      pos: [7, 7, 5],
      state: 17
    },
    {
      pos: [8, 7, 5],
      state: 17
    },
    {
      pos: [9, 7, 5],
      state: 17
    },
    {
      pos: [7, 1, 6],
      state: 18
    },
    {
      pos: [8, 1, 6],
      state: 18
    },
    {
      pos: [0, 2, 6],
      state: 19
    },
    {
      pos: [3, 2, 6],
      state: 26
    },
    {
      pos: [4, 2, 6],
      state: 21
    },
    {
      pos: [5, 2, 6],
      state: 18
    },
    {
      pos: [7, 2, 6],
      state: 17
    },
    {
      pos: [8, 2, 6],
      state: 17
    },
    {
      pos: [9, 2, 6],
      state: 17
    },
    {
      pos: [0, 3, 6],
      state: 20
    },
    {
      pos: [3, 3, 6],
      state: 27
    },
    {
      pos: [4, 3, 6],
      state: 17
    },
    {
      pos: [5, 3, 6],
      state: 17
    },
    {
      pos: [7, 3, 6],
      state: 17
    },
    {
      pos: [8, 3, 6],
      state: 17
    },
    {
      pos: [9, 3, 6],
      state: 17
    },
    {
      pos: [0, 4, 6],
      state: 17
    },
    {
      pos: [3, 4, 6],
      state: 17
    },
    {
      pos: [4, 4, 6],
      state: 17
    },
    {
      pos: [5, 4, 6],
      state: 17
    },
    {
      pos: [8, 4, 6],
      state: 17
    },
    {
      pos: [9, 4, 6],
      state: 17
    },
    {
      pos: [0, 5, 6],
      state: 17
    },
    {
      pos: [1, 5, 6],
      state: 17
    },
    {
      pos: [3, 5, 6],
      state: 17
    },
    {
      pos: [4, 5, 6],
      state: 28
    },
    {
      pos: [5, 5, 6],
      state: 17
    },
    {
      pos: [7, 5, 6],
      state: 17
    },
    {
      pos: [8, 5, 6],
      state: 17
    },
    {
      pos: [9, 5, 6],
      state: 17
    },
    {
      pos: [0, 6, 6],
      state: 17
    },
    {
      pos: [1, 6, 6],
      state: 17
    },
    {
      pos: [2, 6, 6],
      state: 17
    },
    {
      pos: [4, 6, 6],
      state: 17
    },
    {
      pos: [6, 6, 6],
      state: 17
    },
    {
      pos: [7, 6, 6],
      state: 17
    },
    {
      pos: [8, 6, 6],
      state: 17
    },
    {
      pos: [9, 6, 6],
      state: 17
    },
    {
      pos: [0, 7, 6],
      state: 17
    },
    {
      pos: [1, 7, 6],
      state: 17
    },
    {
      pos: [2, 7, 6],
      state: 17
    },
    {
      pos: [3, 7, 6],
      state: 17
    },
    {
      pos: [5, 7, 6],
      state: 17
    },
    {
      pos: [6, 7, 6],
      state: 17
    },
    {
      pos: [7, 7, 6],
      state: 17
    },
    {
      pos: [8, 7, 6],
      state: 17
    },
    {
      pos: [9, 7, 6],
      state: 17
    },
    {
      pos: [0, 2, 7],
      state: 17
    },
    {
      pos: [3, 2, 7],
      state: 17
    },
    {
      pos: [4, 2, 7],
      state: 21
    },
    {
      pos: [5, 2, 7],
      state: 18
    },
    {
      pos: [7, 2, 7],
      state: 17
    },
    {
      pos: [8, 2, 7],
      state: 17
    },
    {
      pos: [9, 2, 7],
      state: 17
    },
    {
      pos: [0, 3, 7],
      state: 17
    },
    {
      pos: [1, 3, 7],
      state: 17
    },
    {
      pos: [3, 3, 7],
      state: 17
    },
    {
      pos: [4, 3, 7],
      state: 17
    },
    {
      pos: [5, 3, 7],
      state: 17
    },
    {
      pos: [7, 3, 7],
      state: 17
    },
    {
      pos: [8, 3, 7],
      state: 17
    },
    {
      pos: [9, 3, 7],
      state: 17
    },
    {
      pos: [0, 4, 7],
      state: 17
    },
    {
      pos: [3, 4, 7],
      state: 17
    },
    {
      pos: [4, 4, 7],
      state: 17
    },
    {
      pos: [5, 4, 7],
      state: 17
    },
    {
      pos: [8, 4, 7],
      state: 17
    },
    {
      pos: [9, 4, 7],
      state: 17
    },
    {
      pos: [0, 5, 7],
      state: 17
    },
    {
      pos: [1, 5, 7],
      state: 17
    },
    {
      pos: [3, 5, 7],
      state: 17
    },
    {
      pos: [4, 5, 7],
      state: 17
    },
    {
      pos: [5, 5, 7],
      state: 17
    },
    {
      pos: [7, 5, 7],
      state: 17
    },
    {
      pos: [8, 5, 7],
      state: 17
    },
    {
      pos: [9, 5, 7],
      state: 17
    },
    {
      pos: [0, 6, 7],
      state: 17
    },
    {
      pos: [1, 6, 7],
      state: 17
    },
    {
      pos: [2, 6, 7],
      state: 17
    },
    {
      pos: [4, 6, 7],
      state: 17
    },
    {
      pos: [6, 6, 7],
      state: 17
    },
    {
      pos: [7, 6, 7],
      state: 17
    },
    {
      pos: [8, 6, 7],
      state: 17
    },
    {
      pos: [9, 6, 7],
      state: 17
    },
    {
      pos: [0, 7, 7],
      state: 17
    },
    {
      pos: [1, 7, 7],
      state: 17
    },
    {
      pos: [2, 7, 7],
      state: 17
    },
    {
      pos: [3, 7, 7],
      state: 17
    },
    {
      pos: [5, 7, 7],
      state: 17
    },
    {
      pos: [6, 7, 7],
      state: 17
    },
    {
      pos: [7, 7, 7],
      state: 17
    },
    {
      pos: [8, 7, 7],
      state: 17
    },
    {
      pos: [9, 7, 7],
      state: 17
    },
    {
      pos: [0, 2, 8],
      state: 29
    },
    {
      pos: [1, 2, 8],
      state: 17
    },
    {
      pos: [3, 2, 8],
      state: 17
    },
    {
      pos: [4, 2, 8],
      state: 21
    },
    {
      pos: [5, 2, 8],
      state: 18
    },
    {
      pos: [7, 2, 8],
      state: 17
    },
    {
      pos: [8, 2, 8],
      state: 17
    },
    {
      pos: [9, 2, 8],
      state: 17
    },
    {
      pos: [0, 3, 8],
      state: 17
    },
    {
      pos: [1, 3, 8],
      state: 17
    },
    {
      pos: [3, 3, 8],
      state: 23
    },
    {
      pos: [4, 3, 8],
      state: 17
    },
    {
      pos: [5, 3, 8],
      state: 23
    },
    {
      pos: [7, 3, 8],
      state: 17
    },
    {
      pos: [8, 3, 8],
      state: 17
    },
    {
      pos: [9, 3, 8],
      state: 17
    },
    {
      pos: [0, 4, 8],
      state: 17
    },
    {
      pos: [3, 4, 8],
      state: 17
    },
    {
      pos: [4, 4, 8],
      state: 17
    },
    {
      pos: [5, 4, 8],
      state: 17
    },
    {
      pos: [8, 4, 8],
      state: 17
    },
    {
      pos: [9, 4, 8],
      state: 17
    },
    {
      pos: [0, 5, 8],
      state: 17
    },
    {
      pos: [1, 5, 8],
      state: 17
    },
    {
      pos: [3, 5, 8],
      state: 17
    },
    {
      pos: [4, 5, 8],
      state: 17
    },
    {
      pos: [5, 5, 8],
      state: 17
    },
    {
      pos: [7, 5, 8],
      state: 17
    },
    {
      pos: [8, 5, 8],
      state: 17
    },
    {
      pos: [9, 5, 8],
      state: 17
    },
    {
      pos: [0, 6, 8],
      state: 17
    },
    {
      pos: [1, 6, 8],
      state: 17
    },
    {
      pos: [2, 6, 8],
      state: 17
    },
    {
      pos: [4, 6, 8],
      state: 17
    },
    {
      pos: [6, 6, 8],
      state: 17
    },
    {
      pos: [7, 6, 8],
      state: 17
    },
    {
      pos: [8, 6, 8],
      state: 17
    },
    {
      pos: [9, 6, 8],
      state: 17
    },
    {
      pos: [0, 7, 8],
      state: 17
    },
    {
      pos: [1, 7, 8],
      state: 17
    },
    {
      pos: [2, 7, 8],
      state: 17
    },
    {
      pos: [3, 7, 8],
      state: 17
    },
    {
      pos: [5, 7, 8],
      state: 17
    },
    {
      pos: [6, 7, 8],
      state: 17
    },
    {
      pos: [7, 7, 8],
      state: 17
    },
    {
      pos: [8, 7, 8],
      state: 17
    },
    {
      pos: [9, 7, 8],
      state: 17
    },
    {
      pos: [0, 2, 9],
      state: 17
    },
    {
      pos: [4, 2, 9],
      state: 30
    },
    {
      pos: [8, 2, 9],
      state: 17
    },
    {
      pos: [9, 2, 9],
      state: 17
    },
    {
      pos: [0, 3, 9],
      state: 17
    },
    {
      pos: [4, 3, 9],
      state: 31
    },
    {
      pos: [8, 3, 9],
      state: 17
    },
    {
      pos: [9, 3, 9],
      state: 17
    },
    {
      pos: [0, 4, 9],
      state: 17
    },
    {
      pos: [8, 4, 9],
      state: 17
    },
    {
      pos: [9, 4, 9],
      state: 17
    },
    {
      pos: [0, 5, 9],
      state: 17
    },
    {
      pos: [1, 5, 9],
      state: 17
    },
    {
      pos: [4, 5, 9],
      state: 32
    },
    {
      pos: [7, 5, 9],
      state: 17
    },
    {
      pos: [8, 5, 9],
      state: 17
    },
    {
      pos: [9, 5, 9],
      state: 17
    },
    {
      pos: [0, 6, 9],
      state: 17
    },
    {
      pos: [1, 6, 9],
      state: 17
    },
    {
      pos: [2, 6, 9],
      state: 17
    },
    {
      pos: [6, 6, 9],
      state: 17
    },
    {
      pos: [7, 6, 9],
      state: 17
    },
    {
      pos: [8, 6, 9],
      state: 17
    },
    {
      pos: [9, 6, 9],
      state: 17
    },
    {
      pos: [0, 7, 9],
      state: 17
    },
    {
      pos: [1, 7, 9],
      state: 17
    },
    {
      pos: [2, 7, 9],
      state: 17
    },
    {
      pos: [3, 7, 9],
      state: 17
    },
    {
      pos: [5, 7, 9],
      state: 17
    },
    {
      pos: [6, 7, 9],
      state: 17
    },
    {
      pos: [7, 7, 9],
      state: 17
    },
    {
      pos: [8, 7, 9],
      state: 17
    },
    {
      pos: [9, 7, 9],
      state: 17
    },
    {
      pos: [4, 1, 10],
      state: 33
    },
    {
      pos: [0, 2, 10],
      state: 17
    },
    {
      pos: [1, 2, 10],
      state: 19
    },
    {
      pos: [3, 2, 10],
      state: 34
    },
    {
      pos: [4, 2, 10],
      state: 17
    },
    {
      pos: [5, 2, 10],
      state: 17
    },
    {
      pos: [7, 2, 10],
      state: 17
    },
    {
      pos: [8, 2, 10],
      state: 17
    },
    {
      pos: [9, 2, 10],
      state: 17
    },
    {
      pos: [0, 3, 10],
      state: 17
    },
    {
      pos: [1, 3, 10],
      state: 20
    },
    {
      pos: [3, 3, 10],
      state: 28
    },
    {
      pos: [4, 3, 10],
      state: 17
    },
    {
      pos: [5, 3, 10],
      state: 28
    },
    {
      pos: [7, 3, 10],
      state: 17
    },
    {
      pos: [8, 3, 10],
      state: 17
    },
    {
      pos: [9, 3, 10],
      state: 17
    },
    {
      pos: [0, 4, 10],
      state: 17
    },
    {
      pos: [3, 4, 10],
      state: 17
    },
    {
      pos: [4, 4, 10],
      state: 17
    },
    {
      pos: [5, 4, 10],
      state: 17
    },
    {
      pos: [8, 4, 10],
      state: 17
    },
    {
      pos: [9, 4, 10],
      state: 17
    },
    {
      pos: [0, 5, 10],
      state: 17
    },
    {
      pos: [1, 5, 10],
      state: 17
    },
    {
      pos: [3, 5, 10],
      state: 17
    },
    {
      pos: [4, 5, 10],
      state: 17
    },
    {
      pos: [5, 5, 10],
      state: 17
    },
    {
      pos: [7, 5, 10],
      state: 17
    },
    {
      pos: [8, 5, 10],
      state: 17
    },
    {
      pos: [9, 5, 10],
      state: 17
    },
    {
      pos: [0, 6, 10],
      state: 17
    },
    {
      pos: [1, 6, 10],
      state: 17
    },
    {
      pos: [2, 6, 10],
      state: 17
    },
    {
      pos: [4, 6, 10],
      state: 17
    },
    {
      pos: [6, 6, 10],
      state: 17
    },
    {
      pos: [7, 6, 10],
      state: 17
    },
    {
      pos: [8, 6, 10],
      state: 17
    },
    {
      pos: [9, 6, 10],
      state: 17
    },
    {
      pos: [0, 7, 10],
      state: 17
    },
    {
      pos: [1, 7, 10],
      state: 17
    },
    {
      pos: [2, 7, 10],
      state: 17
    },
    {
      pos: [3, 7, 10],
      state: 17
    },
    {
      pos: [5, 7, 10],
      state: 17
    },
    {
      pos: [6, 7, 10],
      state: 17
    },
    {
      pos: [7, 7, 10],
      state: 17
    },
    {
      pos: [8, 7, 10],
      state: 17
    },
    {
      pos: [9, 7, 10],
      state: 17
    },
    {
      pos: [4, 1, 11],
      state: 33
    },
    {
      pos: [0, 2, 11],
      state: 17
    },
    {
      pos: [1, 2, 11],
      state: 17
    },
    {
      pos: [2, 2, 11],
      state: 17
    },
    {
      pos: [3, 2, 11],
      state: 17
    },
    {
      pos: [5, 2, 11],
      state: 17
    },
    {
      pos: [6, 2, 11],
      state: 19
    },
    {
      pos: [7, 2, 11],
      state: 17
    },
    {
      pos: [8, 2, 11],
      state: 17
    },
    {
      pos: [9, 2, 11],
      state: 17
    },
    {
      pos: [0, 3, 11],
      state: 17
    },
    {
      pos: [1, 3, 11],
      state: 17
    },
    {
      pos: [2, 3, 11],
      state: 17
    },
    {
      pos: [3, 3, 11],
      state: 17
    },
    {
      pos: [4, 3, 11],
      state: 17
    },
    {
      pos: [5, 3, 11],
      state: 17
    },
    {
      pos: [6, 3, 11],
      state: 20
    },
    {
      pos: [7, 3, 11],
      state: 17
    },
    {
      pos: [8, 3, 11],
      state: 17
    },
    {
      pos: [9, 3, 11],
      state: 17
    },
    {
      pos: [0, 4, 11],
      state: 17
    },
    {
      pos: [2, 4, 11],
      state: 17
    },
    {
      pos: [3, 4, 11],
      state: 17
    },
    {
      pos: [4, 4, 11],
      state: 17
    },
    {
      pos: [5, 4, 11],
      state: 17
    },
    {
      pos: [6, 4, 11],
      state: 17
    },
    {
      pos: [8, 4, 11],
      state: 17
    },
    {
      pos: [9, 4, 11],
      state: 17
    },
    {
      pos: [0, 5, 11],
      state: 17
    },
    {
      pos: [1, 5, 11],
      state: 17
    },
    {
      pos: [3, 5, 11],
      state: 17
    },
    {
      pos: [4, 5, 11],
      state: 17
    },
    {
      pos: [5, 5, 11],
      state: 17
    },
    {
      pos: [7, 5, 11],
      state: 17
    },
    {
      pos: [8, 5, 11],
      state: 17
    },
    {
      pos: [9, 5, 11],
      state: 17
    },
    {
      pos: [0, 6, 11],
      state: 17
    },
    {
      pos: [1, 6, 11],
      state: 17
    },
    {
      pos: [2, 6, 11],
      state: 17
    },
    {
      pos: [4, 6, 11],
      state: 17
    },
    {
      pos: [6, 6, 11],
      state: 17
    },
    {
      pos: [7, 6, 11],
      state: 17
    },
    {
      pos: [8, 6, 11],
      state: 17
    },
    {
      pos: [9, 6, 11],
      state: 17
    },
    {
      pos: [0, 7, 11],
      state: 17
    },
    {
      pos: [1, 7, 11],
      state: 17
    },
    {
      pos: [2, 7, 11],
      state: 17
    },
    {
      pos: [3, 7, 11],
      state: 17
    },
    {
      pos: [5, 7, 11],
      state: 17
    },
    {
      pos: [6, 7, 11],
      state: 17
    },
    {
      pos: [7, 7, 11],
      state: 17
    },
    {
      pos: [8, 7, 11],
      state: 17
    },
    {
      pos: [9, 7, 11],
      state: 17
    }
  ],
  palette: [
    {
      Name: "minecraft:dirt"
    },
    {
      Name: "minecraft:sand"
    },
    {
      Name: "minecraft:gravel"
    },
    {
      Properties: {
        snowy: "false"
      },
      Name: "minecraft:grass_block"
    },
    {
      Name: "minecraft:spruce_planks"
    },
    {
      Properties: {
        axis: "z"
      },
      Name: "minecraft:spruce_log"
    },
    {
      Properties: {
        axis: "y"
      },
      Name: "minecraft:spruce_log"
    },
    {
      Properties: {
        axis: "x"
      },
      Name: "minecraft:spruce_log"
    },
    {
      Name: "minecraft:clay"
    },
    {
      Name: "minecraft:cobblestone"
    },
    {
      Properties: {
        facing: "up"
      },
      Name: "minecraft:jigsaw"
    },
    {
      Properties: {
        facing: "east"
      },
      Name: "minecraft:barrel"
    },
    {
      Properties: {
        facing: "west"
      },
      Name: "minecraft:barrel"
    },
    {
      Properties: {
        facing: "up"
      },
      Name: "minecraft:barrel"
    },
    {
      Properties: {
        facing: "north"
      },
      Name: "minecraft:barrel"
    },
    {
      Properties: {
        facing: "down"
      },
      Name: "minecraft:barrel"
    },
    {
      Properties: {
        facing: "south"
      },
      Name: "minecraft:jigsaw"
    },
    {
      Name: "minecraft:air"
    },
    {
      Properties: {
        level: "0"
      },
      Name: "minecraft:water"
    },
    {
      Properties: {
        half: "lower"
      },
      Name: "minecraft:large_fern"
    },
    {
      Properties: {
        half: "upper"
      },
      Name: "minecraft:large_fern"
    },
    {
      Properties: {
        half: "bottom",
        waterlogged: "false",
        powered: "false",
        facing: "west",
        open: "true"
      },
      Name: "minecraft:spruce_trapdoor"
    },
    {
      Properties: {
        half: "bottom",
        waterlogged: "false",
        powered: "false",
        facing: "east",
        open: "true"
      },
      Name: "minecraft:spruce_trapdoor"
    },
    {
      Properties: {
        facing: "north"
      },
      Name: "minecraft:wall_torch"
    },
    {
      Properties: {
        hinge: "left",
        half: "lower",
        powered: "false",
        facing: "east",
        open: "true"
      },
      Name: "minecraft:spruce_door"
    },
    {
      Properties: {
        hinge: "left",
        half: "upper",
        powered: "false",
        facing: "east",
        open: "true"
      },
      Name: "minecraft:spruce_door"
    },
    {
      Properties: {
        east: "false",
        waterlogged: "false",
        south: "false",
        north: "true",
        west: "true"
      },
      Name: "minecraft:spruce_fence"
    },
    {
      Properties: {
        half: "bottom",
        waterlogged: "false",
        powered: "false",
        facing: "east",
        open: "false"
      },
      Name: "minecraft:spruce_trapdoor"
    },
    {
      Properties: {
        facing: "south"
      },
      Name: "minecraft:wall_torch"
    },
    {
      Name: "minecraft:fern"
    },
    {
      Properties: {
        hinge: "right",
        half: "lower",
        powered: "false",
        facing: "north",
        open: "false"
      },
      Name: "minecraft:spruce_door"
    },
    {
      Properties: {
        hinge: "right",
        half: "upper",
        powered: "false",
        facing: "north",
        open: "false"
      },
      Name: "minecraft:spruce_door"
    },
    {
      Properties: {
        east: "true",
        waterlogged: "false",
        south: "false",
        north: "false",
        west: "true"
      },
      Name: "minecraft:spruce_fence"
    },
    {
      Name: "minecraft:grass_path"
    },
    {
      Name: "minecraft:poppy"
    }
  ],
  DataVersion: 1915
}