{
  size: [7, 9, 7],
  entities: [],
  blocks: [
    {
      pos: [2, 0, 0],
      state: 0
    },
    {
      pos: [3, 0, 0],
      state: 1
    },
    {
      pos: [4, 0, 0],
      state: 0
    },
    {
      pos: [1, 0, 1],
      state: 1
    },
    {
      pos: [2, 0, 1],
      state: 1
    },
    {
      pos: [3, 0, 1],
      state: 1
    },
    {
      pos: [4, 0, 1],
      state: 1
    },
    {
      pos: [5, 0, 1],
      state: 1
    },
    {
      pos: [1, 1, 1],
      state: 1
    },
    {
      pos: [2, 1, 1],
      state: 1
    },
    {
      pos: [3, 1, 1],
      state: 1
    },
    {
      pos: [4, 1, 1],
      state: 1
    },
    {
      pos: [5, 1, 1],
      state: 1
    },
    {
      pos: [1, 2, 1],
      state: 2
    },
    {
      pos: [2, 2, 1],
      state: 3
    },
    {
      pos: [3, 2, 1],
      state: 3
    },
    {
      pos: [4, 2, 1],
      state: 3
    },
    {
      pos: [5, 2, 1],
      state: 2
    },
    {
      pos: [1, 3, 1],
      state: 2
    },
    {
      pos: [2, 3, 1],
      state: 3
    },
    {
      pos: [3, 3, 1],
      state: 3
    },
    {
      pos: [4, 3, 1],
      state: 3
    },
    {
      pos: [5, 3, 1],
      state: 2
    },
    {
      pos: [1, 4, 1],
      state: 2
    },
    {
      pos: [2, 4, 1],
      state: 3
    },
    {
      pos: [4, 4, 1],
      state: 3
    },
    {
      pos: [5, 4, 1],
      state: 2
    },
    {
      pos: [1, 5, 1],
      state: 2
    },
    {
      pos: [2, 5, 1],
      state: 3
    },
    {
      pos: [3, 5, 1],
      state: 3
    },
    {
      pos: [4, 5, 1],
      state: 3
    },
    {
      pos: [5, 5, 1],
      state: 2
    },
    {
      pos: [1, 6, 1],
      state: 2
    },
    {
      pos: [2, 6, 1],
      state: 3
    },
    {
      pos: [3, 6, 1],
      state: 3
    },
    {
      pos: [4, 6, 1],
      state: 3
    },
    {
      pos: [5, 6, 1],
      state: 2
    },
    {
      pos: [2, 7, 1],
      state: 4
    },
    {
      pos: [4, 7, 1],
      state: 4
    },
    {
      pos: [0, 0, 2],
      state: 1
    },
    {
      pos: [1, 0, 2],
      state: 1
    },
    {
      pos: [2, 0, 2],
      state: 1
    },
    {
      pos: [3, 0, 2],
      state: 1
    },
    {
      pos: [4, 0, 2],
      state: 1
    },
    {
      pos: [5, 0, 2],
      state: 1
    },
    {
      pos: [6, 0, 2],
      state: 0
    },
    {
      pos: [0, 1, 2],
      state: 0
    },
    {
      pos: [1, 1, 2],
      state: 1
    },
    {
      pos: [2, 1, 2],
      state: 1
    },
    {
      pos: [3, 1, 2],
      state: 1
    },
    {
      pos: [4, 1, 2],
      state: 1
    },
    {
      pos: [5, 1, 2],
      state: 1
    },
    {
      pos: [1, 2, 2],
      state: 3
    },
    {
      pos: [2, 2, 2],
      state: 4
    },
    {
      pos: [3, 2, 2],
      state: 4
    },
    {
      pos: [4, 2, 2],
      state: 4
    },
    {
      pos: [5, 2, 2],
      state: 3
    },
    {
      pos: [1, 3, 2],
      state: 3
    },
    {
      pos: [5, 3, 2],
      state: 3
    },
    {
      pos: [1, 4, 2],
      state: 3
    },
    {
      pos: [5, 4, 2],
      state: 3
    },
    {
      pos: [1, 5, 2],
      state: 3
    },
    {
      pos: [5, 5, 2],
      state: 3
    },
    {
      pos: [1, 6, 2],
      state: 5
    },
    {
      pos: [5, 6, 2],
      state: 5
    },
    {
      pos: [1, 7, 2],
      state: 3
    },
    {
      pos: [5, 7, 2],
      state: 3
    },
    {
      pos: [2, 8, 2],
      state: 4
    },
    {
      pos: [3, 8, 2],
      state: 4
    },
    {
      pos: [4, 8, 2],
      state: 4
    },
    {
      pos: [0, 0, 3],
      state: 1
    },
    {
      pos: [1, 0, 3],
      state: 1
    },
    {
      pos: [2, 0, 3],
      state: 1
    },
    {
      pos: [3, 0, 3],
      state: 1
    },
    {
      pos: [4, 0, 3],
      state: 1
    },
    {
      pos: [5, 0, 3],
      state: 1
    },
    {
      pos: [6, 0, 3],
      state: 1
    },
    {
      pos: [0, 1, 3],
      state: 1
    },
    {
      pos: [1, 1, 3],
      state: 1
    },
    {
      pos: [2, 1, 3],
      state: 1
    },
    {
      pos: [3, 1, 3],
      state: 1
    },
    {
      pos: [4, 1, 3],
      state: 1
    },
    {
      pos: [5, 1, 3],
      state: 1
    },
    {
      pos: [1, 2, 3],
      state: 3
    },
    {
      pos: [2, 2, 3],
      state: 4
    },
    {
      pos: [4, 2, 3],
      state: 4
    },
    {
      pos: [5, 2, 3],
      state: 3
    },
    {
      pos: [5, 3, 3],
      state: 3
    },
    {
      pos: [1, 5, 3],
      state: 3
    },
    {
      pos: [5, 5, 3],
      state: 3
    },
    {
      pos: [1, 6, 3],
      state: 5
    },
    {
      pos: [5, 6, 3],
      state: 5
    },
    {
      pos: [1, 7, 3],
      state: 3
    },
    {
      pos: [5, 7, 3],
      state: 3
    },
    {
      pos: [0, 8, 3],
      state: 6
    },
    {
      pos: [1, 8, 3],
      state: 4
    },
    {
      pos: [2, 8, 3],
      state: 4
    },
    {
      pos: [3, 8, 3],
      state: 4
    },
    {
      pos: [4, 8, 3],
      state: 4
    },
    {
      pos: [5, 8, 3],
      state: 4
    },
    {
      pos: [6, 8, 3],
      state: 4
    },
    {
      pos: [0, 0, 4],
      state: 1
    },
    {
      pos: [1, 0, 4],
      state: 1
    },
    {
      pos: [2, 0, 4],
      state: 1
    },
    {
      pos: [3, 0, 4],
      state: 1
    },
    {
      pos: [4, 0, 4],
      state: 1
    },
    {
      pos: [5, 0, 4],
      state: 1
    },
    {
      pos: [6, 0, 4],
      state: 0
    },
    {
      pos: [0, 1, 4],
      state: 0
    },
    {
      pos: [1, 1, 4],
      state: 1
    },
    {
      pos: [2, 1, 4],
      state: 1
    },
    {
      pos: [3, 1, 4],
      state: 1
    },
    {
      pos: [4, 1, 4],
      state: 1
    },
    {
      pos: [5, 1, 4],
      state: 1
    },
    {
      pos: [1, 2, 4],
      state: 3
    },
    {
      pos: [2, 2, 4],
      state: 4
    },
    {
      pos: [3, 2, 4],
      state: 4
    },
    {
      pos: [4, 2, 4],
      state: 4
    },
    {
      pos: [5, 2, 4],
      state: 3
    },
    {
      pos: [1, 3, 4],
      state: 3
    },
    {
      pos: [5, 3, 4],
      state: 3
    },
    {
      pos: [1, 4, 4],
      state: 3
    },
    {
      pos: [5, 4, 4],
      state: 3
    },
    {
      pos: [1, 5, 4],
      state: 3
    },
    {
      pos: [5, 5, 4],
      state: 3
    },
    {
      pos: [1, 6, 4],
      state: 5
    },
    {
      pos: [5, 6, 4],
      state: 5
    },
    {
      pos: [1, 7, 4],
      state: 3
    },
    {
      pos: [5, 7, 4],
      state: 3
    },
    {
      pos: [2, 8, 4],
      state: 4
    },
    {
      pos: [3, 8, 4],
      state: 4
    },
    {
      pos: [4, 8, 4],
      state: 4
    },
    {
      pos: [1, 0, 5],
      state: 1
    },
    {
      pos: [2, 0, 5],
      state: 1
    },
    {
      pos: [3, 0, 5],
      state: 1
    },
    {
      pos: [4, 0, 5],
      state: 1
    },
    {
      pos: [5, 0, 5],
      state: 1
    },
    {
      pos: [1, 1, 5],
      state: 1
    },
    {
      pos: [2, 1, 5],
      state: 1
    },
    {
      pos: [3, 1, 5],
      state: 1
    },
    {
      pos: [4, 1, 5],
      state: 1
    },
    {
      pos: [5, 1, 5],
      state: 1
    },
    {
      pos: [1, 2, 5],
      state: 2
    },
    {
      pos: [2, 2, 5],
      state: 3
    },
    {
      pos: [3, 2, 5],
      state: 3
    },
    {
      pos: [4, 2, 5],
      state: 3
    },
    {
      pos: [5, 2, 5],
      state: 2
    },
    {
      pos: [1, 3, 5],
      state: 2
    },
    {
      pos: [2, 3, 5],
      state: 3
    },
    {
      pos: [3, 3, 5],
      state: 3
    },
    {
      pos: [4, 3, 5],
      state: 3
    },
    {
      pos: [5, 3, 5],
      state: 2
    },
    {
      pos: [1, 4, 5],
      state: 2
    },
    {
      pos: [2, 4, 5],
      state: 3
    },
    {
      pos: [4, 4, 5],
      state: 3
    },
    {
      pos: [5, 4, 5],
      state: 2
    },
    {
      pos: [1, 5, 5],
      state: 2
    },
    {
      pos: [2, 5, 5],
      state: 3
    },
    {
      pos: [3, 5, 5],
      state: 3
    },
    {
      pos: [4, 5, 5],
      state: 3
    },
    {
      pos: [5, 5, 5],
      state: 2
    },
    {
      pos: [1, 6, 5],
      state: 2
    },
    {
      pos: [2, 6, 5],
      state: 3
    },
    {
      pos: [3, 6, 5],
      state: 3
    },
    {
      pos: [4, 6, 5],
      state: 3
    },
    {
      pos: [5, 6, 5],
      state: 2
    },
    {
      pos: [2, 7, 5],
      state: 4
    },
    {
      pos: [4, 7, 5],
      state: 4
    },
    {
      pos: [2, 0, 6],
      state: 0
    },
    {
      pos: [3, 0, 6],
      state: 1
    },
    {
      pos: [4, 0, 6],
      state: 0
    },
    {
      nbt: {
        id: "minecraft:bed"
      },
      pos: [3, 3, 2],
      state: 7
    },
    {
      nbt: {
        id: "minecraft:bed"
      },
      pos: [4, 3, 2],
      state: 8
    },
    {
      nbt: {
        target_pool: "minecraft:village/plains/streets",
        final_state: "minecraft:cobblestone_stairs[facing=east,half=bottom,shape=straight,waterlogged=false]",
        id: "minecraft:jigsaw",
        attachement_type: "minecraft:building_entrance"
      },
      pos: [0, 2, 3],
      state: 9
    },
    {
      nbt: {
        target_pool: "minecraft:village/plains/villagers",
        final_state: "minecraft:oak_planks",
        id: "minecraft:jigsaw",
        attachement_type: "minecraft:bottom"
      },
      pos: [3, 2, 3],
      state: 10
    },
    {
      pos: [2, 1, 0],
      state: 11
    },
    {
      pos: [3, 1, 0],
      state: 12
    },
    {
      pos: [4, 1, 0],
      state: 11
    },
    {
      pos: [0, 2, 0],
      state: 13
    },
    {
      pos: [1, 2, 0],
      state: 13
    },
    {
      pos: [2, 2, 0],
      state: 14
    },
    {
      pos: [3, 2, 0],
      state: 13
    },
    {
      pos: [4, 2, 0],
      state: 14
    },
    {
      pos: [5, 2, 0],
      state: 13
    },
    {
      pos: [6, 2, 0],
      state: 13
    },
    {
      pos: [0, 3, 0],
      state: 13
    },
    {
      pos: [1, 3, 0],
      state: 13
    },
    {
      pos: [2, 3, 0],
      state: 13
    },
    {
      pos: [3, 3, 0],
      state: 13
    },
    {
      pos: [4, 3, 0],
      state: 13
    },
    {
      pos: [5, 3, 0],
      state: 13
    },
    {
      pos: [6, 3, 0],
      state: 13
    },
    {
      pos: [0, 4, 0],
      state: 13
    },
    {
      pos: [1, 4, 0],
      state: 13
    },
    {
      pos: [2, 4, 0],
      state: 13
    },
    {
      pos: [3, 4, 0],
      state: 13
    },
    {
      pos: [4, 4, 0],
      state: 13
    },
    {
      pos: [5, 4, 0],
      state: 13
    },
    {
      pos: [6, 4, 0],
      state: 13
    },
    {
      pos: [0, 5, 0],
      state: 13
    },
    {
      pos: [1, 5, 0],
      state: 13
    },
    {
      pos: [2, 5, 0],
      state: 13
    },
    {
      pos: [3, 5, 0],
      state: 13
    },
    {
      pos: [4, 5, 0],
      state: 13
    },
    {
      pos: [5, 5, 0],
      state: 13
    },
    {
      pos: [6, 5, 0],
      state: 13
    },
    {
      pos: [0, 6, 0],
      state: 15
    },
    {
      pos: [1, 6, 0],
      state: 15
    },
    {
      pos: [2, 6, 0],
      state: 15
    },
    {
      pos: [3, 6, 0],
      state: 15
    },
    {
      pos: [4, 6, 0],
      state: 15
    },
    {
      pos: [5, 6, 0],
      state: 15
    },
    {
      pos: [6, 6, 0],
      state: 15
    },
    {
      pos: [0, 7, 0],
      state: 13
    },
    {
      pos: [1, 7, 0],
      state: 13
    },
    {
      pos: [2, 7, 0],
      state: 13
    },
    {
      pos: [3, 7, 0],
      state: 13
    },
    {
      pos: [4, 7, 0],
      state: 13
    },
    {
      pos: [5, 7, 0],
      state: 13
    },
    {
      pos: [6, 7, 0],
      state: 13
    },
    {
      pos: [0, 8, 0],
      state: 13
    },
    {
      pos: [1, 8, 0],
      state: 13
    },
    {
      pos: [2, 8, 0],
      state: 13
    },
    {
      pos: [3, 8, 0],
      state: 13
    },
    {
      pos: [4, 8, 0],
      state: 13
    },
    {
      pos: [5, 8, 0],
      state: 13
    },
    {
      pos: [6, 8, 0],
      state: 13
    },
    {
      pos: [0, 2, 1],
      state: 13
    },
    {
      pos: [6, 2, 1],
      state: 13
    },
    {
      pos: [0, 3, 1],
      state: 13
    },
    {
      pos: [6, 3, 1],
      state: 13
    },
    {
      pos: [0, 4, 1],
      state: 13
    },
    {
      pos: [3, 4, 1],
      state: 16
    },
    {
      pos: [6, 4, 1],
      state: 13
    },
    {
      pos: [0, 5, 1],
      state: 13
    },
    {
      pos: [6, 5, 1],
      state: 13
    },
    {
      pos: [0, 6, 1],
      state: 17
    },
    {
      pos: [6, 6, 1],
      state: 17
    },
    {
      pos: [0, 7, 1],
      state: 15
    },
    {
      pos: [1, 7, 1],
      state: 15
    },
    {
      pos: [3, 7, 1],
      state: 16
    },
    {
      pos: [5, 7, 1],
      state: 15
    },
    {
      pos: [6, 7, 1],
      state: 15
    },
    {
      pos: [0, 8, 1],
      state: 13
    },
    {
      pos: [1, 8, 1],
      state: 13
    },
    {
      pos: [2, 8, 1],
      state: 18
    },
    {
      pos: [3, 8, 1],
      state: 15
    },
    {
      pos: [4, 8, 1],
      state: 19
    },
    {
      pos: [5, 8, 1],
      state: 13
    },
    {
      pos: [6, 8, 1],
      state: 13
    },
    {
      pos: [6, 1, 2],
      state: 11
    },
    {
      pos: [0, 2, 2],
      state: 20
    },
    {
      pos: [6, 2, 2],
      state: 14
    },
    {
      pos: [0, 3, 2],
      state: 13
    },
    {
      pos: [2, 3, 2],
      state: 13
    },
    {
      pos: [6, 3, 2],
      state: 13
    },
    {
      pos: [0, 4, 2],
      state: 13
    },
    {
      pos: [2, 4, 2],
      state: 13
    },
    {
      pos: [3, 4, 2],
      state: 13
    },
    {
      pos: [4, 4, 2],
      state: 13
    },
    {
      pos: [6, 4, 2],
      state: 13
    },
    {
      pos: [0, 5, 2],
      state: 13
    },
    {
      pos: [2, 5, 2],
      state: 13
    },
    {
      pos: [3, 5, 2],
      state: 13
    },
    {
      pos: [4, 5, 2],
      state: 13
    },
    {
      pos: [6, 5, 2],
      state: 13
    },
    {
      pos: [0, 6, 2],
      state: 13
    },
    {
      pos: [2, 6, 2],
      state: 13
    },
    {
      pos: [3, 6, 2],
      state: 13
    },
    {
      pos: [4, 6, 2],
      state: 13
    },
    {
      pos: [6, 6, 2],
      state: 13
    },
    {
      pos: [0, 7, 2],
      state: 17
    },
    {
      pos: [2, 7, 2],
      state: 13
    },
    {
      pos: [3, 7, 2],
      state: 13
    },
    {
      pos: [4, 7, 2],
      state: 13
    },
    {
      pos: [6, 7, 2],
      state: 17
    },
    {
      pos: [0, 8, 2],
      state: 15
    },
    {
      pos: [1, 8, 2],
      state: 15
    },
    {
      pos: [5, 8, 2],
      state: 15
    },
    {
      pos: [6, 8, 2],
      state: 15
    },
    {
      pos: [6, 1, 3],
      state: 12
    },
    {
      pos: [6, 2, 3],
      state: 13
    },
    {
      pos: [0, 3, 3],
      state: 13
    },
    {
      pos: [1, 3, 3],
      state: 21
    },
    {
      pos: [2, 3, 3],
      state: 13
    },
    {
      pos: [3, 3, 3],
      state: 13
    },
    {
      pos: [4, 3, 3],
      state: 13
    },
    {
      pos: [6, 3, 3],
      state: 13
    },
    {
      pos: [0, 4, 3],
      state: 13
    },
    {
      pos: [1, 4, 3],
      state: 22
    },
    {
      pos: [2, 4, 3],
      state: 13
    },
    {
      pos: [3, 4, 3],
      state: 13
    },
    {
      pos: [4, 4, 3],
      state: 13
    },
    {
      pos: [5, 4, 3],
      state: 23
    },
    {
      pos: [6, 4, 3],
      state: 13
    },
    {
      pos: [0, 5, 3],
      state: 13
    },
    {
      pos: [2, 5, 3],
      state: 13
    },
    {
      pos: [3, 5, 3],
      state: 13
    },
    {
      pos: [4, 5, 3],
      state: 13
    },
    {
      pos: [6, 5, 3],
      state: 13
    },
    {
      pos: [0, 6, 3],
      state: 13
    },
    {
      pos: [2, 6, 3],
      state: 13
    },
    {
      pos: [3, 6, 3],
      state: 13
    },
    {
      pos: [4, 6, 3],
      state: 24
    },
    {
      pos: [6, 6, 3],
      state: 13
    },
    {
      pos: [0, 7, 3],
      state: 13
    },
    {
      pos: [2, 7, 3],
      state: 13
    },
    {
      pos: [3, 7, 3],
      state: 13
    },
    {
      pos: [4, 7, 3],
      state: 13
    },
    {
      pos: [6, 7, 3],
      state: 13
    },
    {
      pos: [6, 1, 4],
      state: 11
    },
    {
      pos: [0, 2, 4],
      state: 25
    },
    {
      pos: [6, 2, 4],
      state: 14
    },
    {
      pos: [0, 3, 4],
      state: 13
    },
    {
      pos: [2, 3, 4],
      state: 13
    },
    {
      pos: [3, 3, 4],
      state: 13
    },
    {
      pos: [4, 3, 4],
      state: 26
    },
    {
      pos: [6, 3, 4],
      state: 13
    },
    {
      pos: [0, 4, 4],
      state: 13
    },
    {
      pos: [2, 4, 4],
      state: 13
    },
    {
      pos: [3, 4, 4],
      state: 13
    },
    {
      pos: [4, 4, 4],
      state: 13
    },
    {
      pos: [6, 4, 4],
      state: 13
    },
    {
      pos: [0, 5, 4],
      state: 13
    },
    {
      pos: [2, 5, 4],
      state: 13
    },
    {
      pos: [3, 5, 4],
      state: 13
    },
    {
      pos: [4, 5, 4],
      state: 13
    },
    {
      pos: [6, 5, 4],
      state: 13
    },
    {
      pos: [0, 6, 4],
      state: 13
    },
    {
      pos: [2, 6, 4],
      state: 13
    },
    {
      pos: [3, 6, 4],
      state: 13
    },
    {
      pos: [4, 6, 4],
      state: 13
    },
    {
      pos: [6, 6, 4],
      state: 13
    },
    {
      pos: [0, 7, 4],
      state: 27
    },
    {
      pos: [2, 7, 4],
      state: 13
    },
    {
      pos: [3, 7, 4],
      state: 13
    },
    {
      pos: [4, 7, 4],
      state: 13
    },
    {
      pos: [6, 7, 4],
      state: 27
    },
    {
      pos: [0, 8, 4],
      state: 28
    },
    {
      pos: [1, 8, 4],
      state: 28
    },
    {
      pos: [5, 8, 4],
      state: 28
    },
    {
      pos: [6, 8, 4],
      state: 28
    },
    {
      pos: [0, 2, 5],
      state: 13
    },
    {
      pos: [6, 2, 5],
      state: 13
    },
    {
      pos: [0, 3, 5],
      state: 13
    },
    {
      pos: [6, 3, 5],
      state: 13
    },
    {
      pos: [0, 4, 5],
      state: 13
    },
    {
      pos: [3, 4, 5],
      state: 16
    },
    {
      pos: [6, 4, 5],
      state: 13
    },
    {
      pos: [0, 5, 5],
      state: 13
    },
    {
      pos: [6, 5, 5],
      state: 13
    },
    {
      pos: [0, 6, 5],
      state: 27
    },
    {
      pos: [6, 6, 5],
      state: 27
    },
    {
      pos: [0, 7, 5],
      state: 28
    },
    {
      pos: [1, 7, 5],
      state: 28
    },
    {
      pos: [3, 7, 5],
      state: 16
    },
    {
      pos: [5, 7, 5],
      state: 28
    },
    {
      pos: [6, 7, 5],
      state: 28
    },
    {
      pos: [0, 8, 5],
      state: 13
    },
    {
      pos: [1, 8, 5],
      state: 13
    },
    {
      pos: [2, 8, 5],
      state: 29
    },
    {
      pos: [3, 8, 5],
      state: 28
    },
    {
      pos: [4, 8, 5],
      state: 30
    },
    {
      pos: [5, 8, 5],
      state: 13
    },
    {
      pos: [6, 8, 5],
      state: 13
    },
    {
      pos: [2, 1, 6],
      state: 11
    },
    {
      pos: [3, 1, 6],
      state: 12
    },
    {
      pos: [4, 1, 6],
      state: 11
    },
    {
      pos: [0, 2, 6],
      state: 13
    },
    {
      pos: [1, 2, 6],
      state: 13
    },
    {
      pos: [2, 2, 6],
      state: 14
    },
    {
      pos: [3, 2, 6],
      state: 13
    },
    {
      pos: [4, 2, 6],
      state: 14
    },
    {
      pos: [5, 2, 6],
      state: 13
    },
    {
      pos: [6, 2, 6],
      state: 13
    },
    {
      pos: [0, 3, 6],
      state: 13
    },
    {
      pos: [1, 3, 6],
      state: 13
    },
    {
      pos: [2, 3, 6],
      state: 13
    },
    {
      pos: [3, 3, 6],
      state: 13
    },
    {
      pos: [4, 3, 6],
      state: 13
    },
    {
      pos: [5, 3, 6],
      state: 13
    },
    {
      pos: [6, 3, 6],
      state: 13
    },
    {
      pos: [0, 4, 6],
      state: 13
    },
    {
      pos: [1, 4, 6],
      state: 13
    },
    {
      pos: [2, 4, 6],
      state: 13
    },
    {
      pos: [3, 4, 6],
      state: 13
    },
    {
      pos: [4, 4, 6],
      state: 13
    },
    {
      pos: [5, 4, 6],
      state: 13
    },
    {
      pos: [6, 4, 6],
      state: 13
    },
    {
      pos: [0, 5, 6],
      state: 13
    },
    {
      pos: [1, 5, 6],
      state: 13
    },
    {
      pos: [2, 5, 6],
      state: 13
    },
    {
      pos: [3, 5, 6],
      state: 13
    },
    {
      pos: [4, 5, 6],
      state: 13
    },
    {
      pos: [5, 5, 6],
      state: 13
    },
    {
      pos: [6, 5, 6],
      state: 13
    },
    {
      pos: [0, 6, 6],
      state: 28
    },
    {
      pos: [1, 6, 6],
      state: 28
    },
    {
      pos: [2, 6, 6],
      state: 28
    },
    {
      pos: [3, 6, 6],
      state: 28
    },
    {
      pos: [4, 6, 6],
      state: 28
    },
    {
      pos: [5, 6, 6],
      state: 28
    },
    {
      pos: [6, 6, 6],
      state: 28
    },
    {
      pos: [0, 7, 6],
      state: 13
    },
    {
      pos: [1, 7, 6],
      state: 13
    },
    {
      pos: [2, 7, 6],
      state: 13
    },
    {
      pos: [3, 7, 6],
      state: 13
    },
    {
      pos: [4, 7, 6],
      state: 13
    },
    {
      pos: [5, 7, 6],
      state: 13
    },
    {
      pos: [6, 7, 6],
      state: 13
    },
    {
      pos: [0, 8, 6],
      state: 13
    },
    {
      pos: [1, 8, 6],
      state: 13
    },
    {
      pos: [2, 8, 6],
      state: 13
    },
    {
      pos: [3, 8, 6],
      state: 13
    },
    {
      pos: [4, 8, 6],
      state: 13
    },
    {
      pos: [5, 8, 6],
      state: 13
    },
    {
      pos: [6, 8, 6],
      state: 13
    }
  ],
  palette: [
    {
      Properties: {
        snowy: "false"
      },
      Name: "minecraft:grass_block"
    },
    {
      Name: "minecraft:dirt"
    },
    {
      Properties: {
        axis: "y"
      },
      Name: "minecraft:oak_log"
    },
    {
      Name: "minecraft:cobblestone"
    },
    {
      Name: "minecraft:oak_planks"
    },
    {
      Properties: {
        axis: "z"
      },
      Name: "minecraft:oak_log"
    },
    {
      Properties: {
        waterlogged: "false",
        type: "double"
      },
      Name: "minecraft:oak_slab"
    },
    {
      Properties: {
        part: "foot",
        facing: "east",
        occupied: "false"
      },
      Name: "minecraft:white_bed"
    },
    {
      Properties: {
        part: "head",
        facing: "east",
        occupied: "false"
      },
      Name: "minecraft:white_bed"
    },
    {
      Properties: {
        facing: "west"
      },
      Name: "minecraft:jigsaw"
    },
    {
      Properties: {
        facing: "up"
      },
      Name: "minecraft:jigsaw"
    },
    {
      Properties: {
        moisture: "7"
      },
      Name: "minecraft:farmland"
    },
    {
      Properties: {
        level: "0"
      },
      Name: "minecraft:water"
    },
    {
      Name: "minecraft:air"
    },
    {
      Properties: {
        age: "7"
      },
      Name: "minecraft:wheat"
    },
    {
      Properties: {
        half: "bottom",
        waterlogged: "false",
        shape: "straight",
        facing: "south"
      },
      Name: "minecraft:oak_stairs"
    },
    {
      Properties: {
        east: "true",
        waterlogged: "false",
        south: "false",
        north: "false",
        west: "true"
      },
      Name: "minecraft:glass_pane"
    },
    {
      Properties: {
        half: "top",
        waterlogged: "false",
        shape: "straight",
        facing: "north"
      },
      Name: "minecraft:oak_stairs"
    },
    {
      Properties: {
        half: "bottom",
        waterlogged: "false",
        shape: "outer_right",
        facing: "east"
      },
      Name: "minecraft:oak_stairs"
    },
    {
      Properties: {
        half: "bottom",
        waterlogged: "false",
        shape: "outer_left",
        facing: "west"
      },
      Name: "minecraft:oak_stairs"
    },
    {
      Properties: {
        half: "bottom",
        waterlogged: "false",
        shape: "straight",
        facing: "south"
      },
      Name: "minecraft:cobblestone_stairs"
    },
    {
      Properties: {
        hinge: "right",
        half: "lower",
        powered: "false",
        facing: "east",
        open: "false"
      },
      Name: "minecraft:oak_door"
    },
    {
      Properties: {
        hinge: "right",
        half: "upper",
        powered: "false",
        facing: "east",
        open: "false"
      },
      Name: "minecraft:oak_door"
    },
    {
      Properties: {
        east: "false",
        waterlogged: "false",
        south: "true",
        north: "true",
        west: "false"
      },
      Name: "minecraft:glass_pane"
    },
    {
      Properties: {
        facing: "west"
      },
      Name: "minecraft:wall_torch"
    },
    {
      Properties: {
        half: "bottom",
        waterlogged: "false",
        shape: "straight",
        facing: "north"
      },
      Name: "minecraft:cobblestone_stairs"
    },
    {
      Properties: {
        half: "bottom",
        waterlogged: "false",
        shape: "straight",
        facing: "east"
      },
      Name: "minecraft:oak_stairs"
    },
    {
      Properties: {
        half: "top",
        waterlogged: "false",
        shape: "straight",
        facing: "south"
      },
      Name: "minecraft:oak_stairs"
    },
    {
      Properties: {
        half: "bottom",
        waterlogged: "false",
        shape: "straight",
        facing: "north"
      },
      Name: "minecraft:oak_stairs"
    },
    {
      Properties: {
        half: "bottom",
        waterlogged: "false",
        shape: "outer_left",
        facing: "east"
      },
      Name: "minecraft:oak_stairs"
    },
    {
      Properties: {
        half: "bottom",
        waterlogged: "false",
        shape: "outer_right",
        facing: "west"
      },
      Name: "minecraft:oak_stairs"
    }
  ],
  DataVersion: 1910
}