{
  size: [7, 4, 5],
  entities: [],
  blocks: [
    {
      pos: [1, 0, 0],
      state: 0
    },
    {
      pos: [2, 0, 0],
      state: 0
    },
    {
      pos: [3, 0, 0],
      state: 0
    },
    {
      pos: [4, 0, 0],
      state: 0
    },
    {
      pos: [1, 1, 0],
      state: 0
    },
    {
      pos: [2, 1, 0],
      state: 0
    },
    {
      pos: [3, 1, 0],
      state: 0
    },
    {
      pos: [4, 1, 0],
      state: 0
    },
    {
      pos: [2, 2, 0],
      state: 0
    },
    {
      pos: [3, 2, 0],
      state: 0
    },
    {
      pos: [0, 0, 1],
      state: 1
    },
    {
      pos: [5, 0, 1],
      state: 1
    },
    {
      pos: [0, 1, 1],
      state: 1
    },
    {
      pos: [5, 1, 1],
      state: 1
    },
    {
      pos: [1, 2, 1],
      state: 1
    },
    {
      pos: [4, 2, 1],
      state: 1
    },
    {
      pos: [2, 3, 1],
      state: 0
    },
    {
      pos: [3, 3, 1],
      state: 0
    },
    {
      pos: [6, 0, 2],
      state: 1
    },
    {
      pos: [6, 1, 2],
      state: 1
    },
    {
      pos: [0, 2, 2],
      state: 0
    },
    {
      pos: [5, 2, 2],
      state: 0
    },
    {
      pos: [1, 3, 2],
      state: 0
    },
    {
      pos: [2, 3, 2],
      state: 0
    },
    {
      pos: [3, 3, 2],
      state: 0
    },
    {
      pos: [4, 3, 2],
      state: 0
    },
    {
      pos: [0, 0, 3],
      state: 1
    },
    {
      pos: [5, 0, 3],
      state: 1
    },
    {
      pos: [0, 1, 3],
      state: 1
    },
    {
      pos: [5, 1, 3],
      state: 1
    },
    {
      pos: [1, 2, 3],
      state: 1
    },
    {
      pos: [4, 2, 3],
      state: 1
    },
    {
      pos: [2, 3, 3],
      state: 0
    },
    {
      pos: [3, 3, 3],
      state: 0
    },
    {
      pos: [1, 0, 4],
      state: 0
    },
    {
      pos: [2, 0, 4],
      state: 0
    },
    {
      pos: [3, 0, 4],
      state: 0
    },
    {
      pos: [4, 0, 4],
      state: 0
    },
    {
      pos: [1, 1, 4],
      state: 0
    },
    {
      pos: [2, 1, 4],
      state: 0
    },
    {
      pos: [3, 1, 4],
      state: 0
    },
    {
      pos: [4, 1, 4],
      state: 0
    },
    {
      pos: [2, 2, 4],
      state: 0
    },
    {
      pos: [3, 2, 4],
      state: 0
    },
    {
      nbt: {
        id: "minecraft:bed"
      },
      pos: [3, 0, 1],
      state: 2
    },
    {
      nbt: {
        id: "minecraft:bed"
      },
      pos: [4, 0, 1],
      state: 3
    },
    {
      nbt: {
        LootTable: "minecraft:chests/village/village_snowy_house",
        Items: [],
        id: "minecraft:chest",
        Lock: "",
        LootTableSeed: 0L
      },
      pos: [4, 0, 3],
      state: 4
    },
    {
      pos: [0, 0, 0],
      state: 5
    },
    {
      pos: [5, 0, 0],
      state: 6
    },
    {
      pos: [6, 0, 0],
      state: 6
    },
    {
      pos: [0, 1, 0],
      state: 5
    },
    {
      pos: [5, 1, 0],
      state: 5
    },
    {
      pos: [6, 1, 0],
      state: 5
    },
    {
      pos: [0, 2, 0],
      state: 5
    },
    {
      pos: [1, 2, 0],
      state: 5
    },
    {
      pos: [4, 2, 0],
      state: 5
    },
    {
      pos: [5, 2, 0],
      state: 5
    },
    {
      pos: [6, 2, 0],
      state: 5
    },
    {
      pos: [0, 3, 0],
      state: 5
    },
    {
      pos: [1, 3, 0],
      state: 5
    },
    {
      pos: [2, 3, 0],
      state: 5
    },
    {
      pos: [3, 3, 0],
      state: 5
    },
    {
      pos: [4, 3, 0],
      state: 5
    },
    {
      pos: [5, 3, 0],
      state: 5
    },
    {
      pos: [6, 3, 0],
      state: 5
    },
    {
      pos: [1, 0, 1],
      state: 5
    },
    {
      pos: [2, 0, 1],
      state: 5
    },
    {
      pos: [6, 0, 1],
      state: 6
    },
    {
      pos: [1, 1, 1],
      state: 5
    },
    {
      pos: [2, 1, 1],
      state: 5
    },
    {
      pos: [3, 1, 1],
      state: 5
    },
    {
      pos: [4, 1, 1],
      state: 5
    },
    {
      pos: [6, 1, 1],
      state: 5
    },
    {
      pos: [0, 2, 1],
      state: 5
    },
    {
      pos: [2, 2, 1],
      state: 5
    },
    {
      pos: [3, 2, 1],
      state: 5
    },
    {
      pos: [5, 2, 1],
      state: 5
    },
    {
      pos: [6, 2, 1],
      state: 5
    },
    {
      pos: [0, 3, 1],
      state: 5
    },
    {
      pos: [1, 3, 1],
      state: 5
    },
    {
      pos: [4, 3, 1],
      state: 5
    },
    {
      pos: [5, 3, 1],
      state: 5
    },
    {
      pos: [6, 3, 1],
      state: 5
    },
    {
      pos: [0, 0, 2],
      state: 7
    },
    {
      pos: [1, 0, 2],
      state: 5
    },
    {
      pos: [2, 0, 2],
      state: 5
    },
    {
      pos: [3, 0, 2],
      state: 5
    },
    {
      pos: [4, 0, 2],
      state: 5
    },
    {
      pos: [5, 0, 2],
      state: 5
    },
    {
      pos: [0, 1, 2],
      state: 8
    },
    {
      pos: [1, 1, 2],
      state: 5
    },
    {
      pos: [2, 1, 2],
      state: 5
    },
    {
      pos: [3, 1, 2],
      state: 5
    },
    {
      pos: [4, 1, 2],
      state: 5
    },
    {
      pos: [5, 1, 2],
      state: 9
    },
    {
      pos: [1, 2, 2],
      state: 10
    },
    {
      pos: [2, 2, 2],
      state: 5
    },
    {
      pos: [3, 2, 2],
      state: 5
    },
    {
      pos: [4, 2, 2],
      state: 5
    },
    {
      pos: [6, 2, 2],
      state: 5
    },
    {
      pos: [0, 3, 2],
      state: 5
    },
    {
      pos: [5, 3, 2],
      state: 5
    },
    {
      pos: [6, 3, 2],
      state: 5
    },
    {
      pos: [1, 0, 3],
      state: 5
    },
    {
      pos: [2, 0, 3],
      state: 5
    },
    {
      pos: [3, 0, 3],
      state: 5
    },
    {
      pos: [6, 0, 3],
      state: 6
    },
    {
      pos: [1, 1, 3],
      state: 5
    },
    {
      pos: [2, 1, 3],
      state: 5
    },
    {
      pos: [3, 1, 3],
      state: 5
    },
    {
      pos: [4, 1, 3],
      state: 5
    },
    {
      pos: [6, 1, 3],
      state: 5
    },
    {
      pos: [0, 2, 3],
      state: 5
    },
    {
      pos: [2, 2, 3],
      state: 5
    },
    {
      pos: [3, 2, 3],
      state: 5
    },
    {
      pos: [5, 2, 3],
      state: 5
    },
    {
      pos: [6, 2, 3],
      state: 5
    },
    {
      pos: [0, 3, 3],
      state: 5
    },
    {
      pos: [1, 3, 3],
      state: 5
    },
    {
      pos: [4, 3, 3],
      state: 5
    },
    {
      pos: [5, 3, 3],
      state: 5
    },
    {
      pos: [6, 3, 3],
      state: 5
    },
    {
      pos: [0, 0, 4],
      state: 5
    },
    {
      pos: [5, 0, 4],
      state: 6
    },
    {
      pos: [6, 0, 4],
      state: 6
    },
    {
      pos: [0, 1, 4],
      state: 5
    },
    {
      pos: [5, 1, 4],
      state: 5
    },
    {
      pos: [6, 1, 4],
      state: 5
    },
    {
      pos: [0, 2, 4],
      state: 5
    },
    {
      pos: [1, 2, 4],
      state: 5
    },
    {
      pos: [4, 2, 4],
      state: 5
    },
    {
      pos: [5, 2, 4],
      state: 5
    },
    {
      pos: [6, 2, 4],
      state: 5
    },
    {
      pos: [0, 3, 4],
      state: 5
    },
    {
      pos: [1, 3, 4],
      state: 5
    },
    {
      pos: [2, 3, 4],
      state: 5
    },
    {
      pos: [3, 3, 4],
      state: 5
    },
    {
      pos: [4, 3, 4],
      state: 5
    },
    {
      pos: [5, 3, 4],
      state: 5
    },
    {
      pos: [6, 3, 4],
      state: 5
    }
  ],
  palette: [
    {
      Name: "minecraft:snow_block"
    },
    {
      Name: "minecraft:blue_ice"
    },
    {
      Properties: {
        part: "foot",
        facing: "east",
        occupied: "false"
      },
      Name: "minecraft:red_bed"
    },
    {
      Properties: {
        part: "head",
        facing: "east",
        occupied: "false"
      },
      Name: "minecraft:red_bed"
    },
    {
      Properties: {
        waterlogged: "false",
        facing: "west",
        type: "single"
      },
      Name: "minecraft:chest"
    },
    {
      Name: "minecraft:air"
    },
    {
      Properties: {
        layers: "1"
      },
      Name: "minecraft:snow"
    },
    {
      Properties: {
        hinge: "right",
        half: "lower",
        powered: "false",
        facing: "west",
        open: "false"
      },
      Name: "minecraft:spruce_door"
    },
    {
      Properties: {
        hinge: "right",
        half: "upper",
        powered: "false",
        facing: "west",
        open: "false"
      },
      Name: "minecraft:spruce_door"
    },
    {
      Properties: {
        facing: "west"
      },
      Name: "minecraft:wall_torch"
    },
    {
      Properties: {
        facing: "east"
      },
      Name: "minecraft:wall_torch"
    }
  ],
  DataVersion: 1910
}