{
  size: [10, 7, 10],
  entities: [],
  blocks: [
    {
      pos: [5, 0, 0],
      state: 0
    },
    {
      pos: [3, 1, 2],
      state: 1
    },
    {
      pos: [4, 1, 2],
      state: 1
    },
    {
      pos: [5, 1, 2],
      state: 1
    },
    {
      pos: [6, 1, 2],
      state: 1
    },
    {
      pos: [7, 1, 2],
      state: 1
    },
    {
      pos: [3, 0, 3],
      state: 1
    },
    {
      pos: [4, 0, 3],
      state: 1
    },
    {
      pos: [5, 0, 3],
      state: 1
    },
    {
      pos: [2, 1, 3],
      state: 1
    },
    {
      pos: [3, 1, 3],
      state: 1
    },
    {
      pos: [4, 1, 3],
      state: 1
    },
    {
      pos: [5, 1, 3],
      state: 1
    },
    {
      pos: [6, 1, 3],
      state: 1
    },
    {
      pos: [7, 1, 3],
      state: 1
    },
    {
      pos: [3, 2, 3],
      state: 1
    },
    {
      pos: [4, 2, 3],
      state: 1
    },
    {
      pos: [5, 2, 3],
      state: 1
    },
    {
      pos: [6, 2, 3],
      state: 1
    },
    {
      pos: [3, 5, 3],
      state: 1
    },
    {
      pos: [4, 5, 3],
      state: 1
    },
    {
      pos: [5, 5, 3],
      state: 1
    },
    {
      pos: [6, 5, 3],
      state: 1
    },
    {
      pos: [3, 0, 4],
      state: 1
    },
    {
      pos: [6, 0, 4],
      state: 1
    },
    {
      pos: [3, 1, 4],
      state: 1
    },
    {
      pos: [6, 1, 4],
      state: 1
    },
    {
      pos: [7, 1, 4],
      state: 1
    },
    {
      pos: [3, 2, 4],
      state: 1
    },
    {
      pos: [6, 2, 4],
      state: 1
    },
    {
      pos: [3, 5, 4],
      state: 1
    },
    {
      pos: [4, 5, 4],
      state: 1
    },
    {
      pos: [5, 5, 4],
      state: 1
    },
    {
      pos: [6, 5, 4],
      state: 1
    },
    {
      pos: [3, 0, 5],
      state: 1
    },
    {
      pos: [6, 0, 5],
      state: 1
    },
    {
      pos: [2, 1, 5],
      state: 1
    },
    {
      pos: [3, 1, 5],
      state: 1
    },
    {
      pos: [6, 1, 5],
      state: 1
    },
    {
      pos: [7, 1, 5],
      state: 1
    },
    {
      pos: [3, 2, 5],
      state: 1
    },
    {
      pos: [6, 2, 5],
      state: 1
    },
    {
      pos: [3, 5, 5],
      state: 1
    },
    {
      pos: [4, 5, 5],
      state: 1
    },
    {
      pos: [5, 5, 5],
      state: 1
    },
    {
      pos: [6, 5, 5],
      state: 1
    },
    {
      pos: [3, 0, 6],
      state: 1
    },
    {
      pos: [4, 0, 6],
      state: 1
    },
    {
      pos: [5, 0, 6],
      state: 1
    },
    {
      pos: [6, 0, 6],
      state: 1
    },
    {
      pos: [2, 1, 6],
      state: 1
    },
    {
      pos: [3, 1, 6],
      state: 1
    },
    {
      pos: [4, 1, 6],
      state: 1
    },
    {
      pos: [5, 1, 6],
      state: 1
    },
    {
      pos: [6, 1, 6],
      state: 1
    },
    {
      pos: [7, 1, 6],
      state: 1
    },
    {
      pos: [3, 2, 6],
      state: 1
    },
    {
      pos: [4, 2, 6],
      state: 1
    },
    {
      pos: [5, 2, 6],
      state: 1
    },
    {
      pos: [6, 2, 6],
      state: 1
    },
    {
      pos: [3, 5, 6],
      state: 1
    },
    {
      pos: [4, 5, 6],
      state: 1
    },
    {
      pos: [5, 5, 6],
      state: 1
    },
    {
      pos: [6, 5, 6],
      state: 1
    },
    {
      pos: [2, 1, 7],
      state: 1
    },
    {
      pos: [3, 1, 7],
      state: 1
    },
    {
      pos: [4, 1, 7],
      state: 1
    },
    {
      pos: [6, 1, 7],
      state: 1
    },
    {
      pos: [7, 1, 7],
      state: 1
    },
    {
      nbt: {
        target_pool: "minecraft:village/plains/streets",
        final_state: "minecraft:air",
        id: "minecraft:jigsaw",
        attachement_type: "minecraft:street"
      },
      pos: [5, 1, 0],
      state: 2
    },
    {
      nbt: {
        target_pool: "minecraft:village/common/cats",
        final_state: "minecraft:cobblestone",
        id: "minecraft:jigsaw",
        attachement_type: "minecraft:bottom"
      },
      pos: [2, 1, 2],
      state: 3
    },
    {
      nbt: {
        target_pool: "minecraft:village/common/well_bottoms",
        final_state: "minecraft:cobblestone",
        id: "minecraft:jigsaw",
        attachement_type: "minecraft:bottom"
      },
      pos: [6, 0, 3],
      state: 4
    },
    {
      nbt: {
        target_pool: "minecraft:village/plains/streets",
        final_state: "minecraft:air",
        id: "minecraft:jigsaw",
        attachement_type: "minecraft:street"
      },
      pos: [0, 1, 4],
      state: 5
    },
    {
      nbt: {
        target_pool: "minecraft:village/common/cats",
        final_state: "minecraft:cobblestone",
        id: "minecraft:jigsaw",
        attachement_type: "minecraft:bottom"
      },
      pos: [2, 1, 4],
      state: 3
    },
    {
      nbt: {
        target_pool: "minecraft:village/plains/streets",
        final_state: "minecraft:air",
        id: "minecraft:jigsaw",
        attachement_type: "minecraft:street"
      },
      pos: [9, 1, 5],
      state: 6
    },
    {
      nbt: {
        target_pool: "minecraft:village/common/cats",
        final_state: "minecraft:cobblestone",
        id: "minecraft:jigsaw",
        attachement_type: "minecraft:bottom"
      },
      pos: [5, 1, 7],
      state: 3
    },
    {
      nbt: {
        target_pool: "minecraft:village/plains/streets",
        final_state: "minecraft:air",
        id: "minecraft:jigsaw",
        attachement_type: "minecraft:street"
      },
      pos: [4, 1, 9],
      state: 7
    },
    {
      pos: [0, 0, 0],
      state: 8
    },
    {
      pos: [1, 0, 0],
      state: 8
    },
    {
      pos: [2, 0, 0],
      state: 8
    },
    {
      pos: [3, 0, 0],
      state: 8
    },
    {
      pos: [4, 0, 0],
      state: 9
    },
    {
      pos: [6, 0, 0],
      state: 8
    },
    {
      pos: [7, 0, 0],
      state: 8
    },
    {
      pos: [8, 0, 0],
      state: 8
    },
    {
      pos: [9, 0, 0],
      state: 8
    },
    {
      pos: [0, 0, 1],
      state: 8
    },
    {
      pos: [1, 0, 1],
      state: 9
    },
    {
      pos: [2, 0, 1],
      state: 9
    },
    {
      pos: [3, 0, 1],
      state: 9
    },
    {
      pos: [4, 0, 1],
      state: 9
    },
    {
      pos: [5, 0, 1],
      state: 9
    },
    {
      pos: [6, 0, 1],
      state: 9
    },
    {
      pos: [7, 0, 1],
      state: 9
    },
    {
      pos: [8, 0, 1],
      state: 9
    },
    {
      pos: [9, 0, 1],
      state: 8
    },
    {
      pos: [0, 0, 2],
      state: 8
    },
    {
      pos: [1, 0, 2],
      state: 9
    },
    {
      pos: [2, 0, 2],
      state: 9
    },
    {
      pos: [3, 0, 2],
      state: 9
    },
    {
      pos: [4, 0, 2],
      state: 9
    },
    {
      pos: [5, 0, 2],
      state: 9
    },
    {
      pos: [6, 0, 2],
      state: 9
    },
    {
      pos: [7, 0, 2],
      state: 9
    },
    {
      pos: [8, 0, 2],
      state: 9
    },
    {
      pos: [9, 0, 2],
      state: 8
    },
    {
      pos: [0, 0, 3],
      state: 8
    },
    {
      pos: [1, 0, 3],
      state: 9
    },
    {
      pos: [2, 0, 3],
      state: 9
    },
    {
      pos: [7, 0, 3],
      state: 9
    },
    {
      pos: [8, 0, 3],
      state: 9
    },
    {
      pos: [9, 0, 3],
      state: 8
    },
    {
      pos: [3, 3, 3],
      state: 10
    },
    {
      pos: [6, 3, 3],
      state: 10
    },
    {
      pos: [3, 4, 3],
      state: 10
    },
    {
      pos: [6, 4, 3],
      state: 10
    },
    {
      pos: [0, 0, 4],
      state: 9
    },
    {
      pos: [1, 0, 4],
      state: 9
    },
    {
      pos: [2, 0, 4],
      state: 9
    },
    {
      pos: [4, 0, 4],
      state: 11
    },
    {
      pos: [5, 0, 4],
      state: 11
    },
    {
      pos: [7, 0, 4],
      state: 9
    },
    {
      pos: [8, 0, 4],
      state: 9
    },
    {
      pos: [9, 0, 4],
      state: 9
    },
    {
      pos: [4, 1, 4],
      state: 11
    },
    {
      pos: [5, 1, 4],
      state: 11
    },
    {
      pos: [0, 0, 5],
      state: 9
    },
    {
      pos: [1, 0, 5],
      state: 9
    },
    {
      pos: [2, 0, 5],
      state: 9
    },
    {
      pos: [4, 0, 5],
      state: 11
    },
    {
      pos: [5, 0, 5],
      state: 11
    },
    {
      pos: [7, 0, 5],
      state: 9
    },
    {
      pos: [8, 0, 5],
      state: 9
    },
    {
      pos: [9, 0, 5],
      state: 9
    },
    {
      pos: [4, 1, 5],
      state: 11
    },
    {
      pos: [5, 1, 5],
      state: 11
    },
    {
      pos: [0, 0, 6],
      state: 8
    },
    {
      pos: [1, 0, 6],
      state: 9
    },
    {
      pos: [2, 0, 6],
      state: 9
    },
    {
      pos: [7, 0, 6],
      state: 9
    },
    {
      pos: [8, 0, 6],
      state: 9
    },
    {
      pos: [9, 0, 6],
      state: 8
    },
    {
      pos: [3, 3, 6],
      state: 10
    },
    {
      pos: [6, 3, 6],
      state: 10
    },
    {
      pos: [3, 4, 6],
      state: 10
    },
    {
      pos: [6, 4, 6],
      state: 10
    },
    {
      pos: [0, 0, 7],
      state: 8
    },
    {
      pos: [1, 0, 7],
      state: 9
    },
    {
      pos: [2, 0, 7],
      state: 9
    },
    {
      pos: [3, 0, 7],
      state: 9
    },
    {
      pos: [4, 0, 7],
      state: 9
    },
    {
      pos: [5, 0, 7],
      state: 9
    },
    {
      pos: [6, 0, 7],
      state: 9
    },
    {
      pos: [7, 0, 7],
      state: 9
    },
    {
      pos: [8, 0, 7],
      state: 9
    },
    {
      pos: [9, 0, 7],
      state: 8
    },
    {
      pos: [0, 0, 8],
      state: 8
    },
    {
      pos: [1, 0, 8],
      state: 9
    },
    {
      pos: [2, 0, 8],
      state: 9
    },
    {
      pos: [3, 0, 8],
      state: 9
    },
    {
      pos: [4, 0, 8],
      state: 9
    },
    {
      pos: [5, 0, 8],
      state: 9
    },
    {
      pos: [6, 0, 8],
      state: 9
    },
    {
      pos: [7, 0, 8],
      state: 9
    },
    {
      pos: [8, 0, 8],
      state: 9
    },
    {
      pos: [9, 0, 8],
      state: 8
    },
    {
      pos: [0, 0, 9],
      state: 8
    },
    {
      pos: [1, 0, 9],
      state: 8
    },
    {
      pos: [2, 0, 9],
      state: 8
    },
    {
      pos: [3, 0, 9],
      state: 8
    },
    {
      pos: [4, 0, 9],
      state: 9
    },
    {
      pos: [5, 0, 9],
      state: 9
    },
    {
      pos: [6, 0, 9],
      state: 8
    },
    {
      pos: [7, 0, 9],
      state: 8
    },
    {
      pos: [8, 0, 9],
      state: 8
    },
    {
      pos: [9, 0, 9],
      state: 8
    }
  ],
  palette: [
    {
      Name: "minecraft:dirt"
    },
    {
      Name: "minecraft:cobblestone"
    },
    {
      Properties: {
        facing: "north"
      },
      Name: "minecraft:jigsaw"
    },
    {
      Properties: {
        facing: "up"
      },
      Name: "minecraft:jigsaw"
    },
    {
      Properties: {
        facing: "down"
      },
      Name: "minecraft:jigsaw"
    },
    {
      Properties: {
        facing: "west"
      },
      Name: "minecraft:jigsaw"
    },
    {
      Properties: {
        facing: "east"
      },
      Name: "minecraft:jigsaw"
    },
    {
      Properties: {
        facing: "south"
      },
      Name: "minecraft:jigsaw"
    },
    {
      Name: "minecraft:air"
    },
    {
      Name: "minecraft:grass_path"
    },
    {
      Properties: {
        east: "false",
        waterlogged: "false",
        south: "false",
        north: "false",
        west: "false"
      },
      Name: "minecraft:oak_fence"
    },
    {
      Properties: {
        level: "0"
      },
      Name: "minecraft:water"
    }
  ],
  DataVersion: 1916
}