{
  size: [6, 7, 7],
  entities: [],
  blocks: [
    {
      pos: [2, 0, 1],
      state: 0
    },
    {
      pos: [3, 0, 1],
      state: 0
    },
    {
      pos: [2, 1, 1],
      state: 1
    },
    {
      pos: [3, 1, 1],
      state: 1
    },
    {
      pos: [2, 2, 1],
      state: 2
    },
    {
      pos: [3, 2, 1],
      state: 2
    },
    {
      pos: [2, 3, 1],
      state: 1
    },
    {
      pos: [3, 3, 1],
      state: 1
    },
    {
      pos: [1, 4, 1],
      state: 3
    },
    {
      pos: [2, 4, 1],
      state: 3
    },
    {
      pos: [3, 4, 1],
      state: 3
    },
    {
      pos: [4, 4, 1],
      state: 3
    },
    {
      pos: [1, 0, 2],
      state: 0
    },
    {
      pos: [2, 0, 2],
      state: 4
    },
    {
      pos: [3, 0, 2],
      state: 4
    },
    {
      pos: [4, 0, 2],
      state: 0
    },
    {
      pos: [1, 1, 2],
      state: 1
    },
    {
      pos: [4, 1, 2],
      state: 1
    },
    {
      pos: [1, 2, 2],
      state: 2
    },
    {
      pos: [4, 2, 2],
      state: 2
    },
    {
      pos: [1, 3, 2],
      state: 1
    },
    {
      pos: [4, 3, 2],
      state: 1
    },
    {
      pos: [1, 4, 2],
      state: 3
    },
    {
      pos: [4, 4, 2],
      state: 3
    },
    {
      pos: [2, 5, 2],
      state: 3
    },
    {
      pos: [3, 5, 2],
      state: 3
    },
    {
      pos: [1, 0, 3],
      state: 4
    },
    {
      pos: [2, 0, 3],
      state: 5
    },
    {
      pos: [4, 0, 3],
      state: 0
    },
    {
      pos: [4, 1, 3],
      state: 1
    },
    {
      pos: [1, 3, 3],
      state: 1
    },
    {
      pos: [4, 3, 3],
      state: 1
    },
    {
      pos: [1, 4, 3],
      state: 3
    },
    {
      pos: [4, 4, 3],
      state: 3
    },
    {
      pos: [2, 5, 3],
      state: 3
    },
    {
      pos: [3, 5, 3],
      state: 3
    },
    {
      pos: [1, 0, 4],
      state: 0
    },
    {
      pos: [2, 0, 4],
      state: 4
    },
    {
      pos: [3, 0, 4],
      state: 4
    },
    {
      pos: [4, 0, 4],
      state: 0
    },
    {
      pos: [1, 1, 4],
      state: 1
    },
    {
      pos: [4, 1, 4],
      state: 1
    },
    {
      pos: [1, 2, 4],
      state: 2
    },
    {
      pos: [4, 2, 4],
      state: 2
    },
    {
      pos: [1, 3, 4],
      state: 1
    },
    {
      pos: [4, 3, 4],
      state: 1
    },
    {
      pos: [1, 4, 4],
      state: 3
    },
    {
      pos: [4, 4, 4],
      state: 3
    },
    {
      pos: [2, 5, 4],
      state: 3
    },
    {
      pos: [3, 5, 4],
      state: 3
    },
    {
      pos: [2, 0, 5],
      state: 0
    },
    {
      pos: [3, 0, 5],
      state: 0
    },
    {
      pos: [2, 1, 5],
      state: 1
    },
    {
      pos: [3, 1, 5],
      state: 1
    },
    {
      pos: [2, 2, 5],
      state: 2
    },
    {
      pos: [3, 2, 5],
      state: 2
    },
    {
      pos: [2, 3, 5],
      state: 1
    },
    {
      pos: [3, 3, 5],
      state: 1
    },
    {
      pos: [1, 4, 5],
      state: 3
    },
    {
      pos: [2, 4, 5],
      state: 3
    },
    {
      pos: [3, 4, 5],
      state: 3
    },
    {
      pos: [4, 4, 5],
      state: 3
    },
    {
      nbt: {
        target_pool: "minecraft:village/savanna/decor",
        final_state: "minecraft:grass_block",
        id: "minecraft:jigsaw",
        attachement_type: "minecraft:bottom"
      },
      pos: [0, 0, 0],
      state: 6
    },
    {
      nbt: {
        id: "minecraft:bed"
      },
      pos: [2, 1, 2],
      state: 7
    },
    {
      nbt: {
        id: "minecraft:bed"
      },
      pos: [3, 1, 2],
      state: 8
    },
    {
      nbt: {
        target_pool: "minecraft:village/savanna/villagers",
        final_state: "minecraft:acacia_log",
        id: "minecraft:jigsaw",
        attachement_type: "minecraft:bottom"
      },
      pos: [3, 0, 3],
      state: 6
    },
    {
      pos: [0, 1, 0],
      state: 9
    },
    {
      pos: [1, 1, 0],
      state: 9
    },
    {
      pos: [2, 1, 0],
      state: 9
    },
    {
      pos: [3, 1, 0],
      state: 9
    },
    {
      pos: [4, 1, 0],
      state: 9
    },
    {
      pos: [5, 1, 0],
      state: 9
    },
    {
      pos: [0, 2, 0],
      state: 9
    },
    {
      pos: [1, 2, 0],
      state: 9
    },
    {
      pos: [2, 2, 0],
      state: 9
    },
    {
      pos: [3, 2, 0],
      state: 9
    },
    {
      pos: [4, 2, 0],
      state: 9
    },
    {
      pos: [5, 2, 0],
      state: 9
    },
    {
      pos: [0, 3, 0],
      state: 9
    },
    {
      pos: [1, 3, 0],
      state: 9
    },
    {
      pos: [2, 3, 0],
      state: 9
    },
    {
      pos: [3, 3, 0],
      state: 9
    },
    {
      pos: [4, 3, 0],
      state: 9
    },
    {
      pos: [5, 3, 0],
      state: 9
    },
    {
      pos: [0, 4, 0],
      state: 9
    },
    {
      pos: [1, 4, 0],
      state: 10
    },
    {
      pos: [2, 4, 0],
      state: 10
    },
    {
      pos: [3, 4, 0],
      state: 10
    },
    {
      pos: [4, 4, 0],
      state: 10
    },
    {
      pos: [5, 4, 0],
      state: 9
    },
    {
      pos: [0, 5, 0],
      state: 9
    },
    {
      pos: [1, 5, 0],
      state: 9
    },
    {
      pos: [2, 5, 0],
      state: 9
    },
    {
      pos: [3, 5, 0],
      state: 9
    },
    {
      pos: [4, 5, 0],
      state: 9
    },
    {
      pos: [5, 5, 0],
      state: 9
    },
    {
      pos: [0, 6, 0],
      state: 9
    },
    {
      pos: [1, 6, 0],
      state: 9
    },
    {
      pos: [2, 6, 0],
      state: 9
    },
    {
      pos: [3, 6, 0],
      state: 9
    },
    {
      pos: [4, 6, 0],
      state: 9
    },
    {
      pos: [5, 6, 0],
      state: 9
    },
    {
      pos: [0, 1, 1],
      state: 9
    },
    {
      pos: [1, 1, 1],
      state: 9
    },
    {
      pos: [4, 1, 1],
      state: 9
    },
    {
      pos: [5, 1, 1],
      state: 9
    },
    {
      pos: [0, 2, 1],
      state: 9
    },
    {
      pos: [1, 2, 1],
      state: 9
    },
    {
      pos: [4, 2, 1],
      state: 9
    },
    {
      pos: [5, 2, 1],
      state: 9
    },
    {
      pos: [0, 3, 1],
      state: 9
    },
    {
      pos: [1, 3, 1],
      state: 9
    },
    {
      pos: [4, 3, 1],
      state: 9
    },
    {
      pos: [5, 3, 1],
      state: 9
    },
    {
      pos: [0, 4, 1],
      state: 11
    },
    {
      pos: [5, 4, 1],
      state: 12
    },
    {
      pos: [0, 5, 1],
      state: 9
    },
    {
      pos: [1, 5, 1],
      state: 13
    },
    {
      pos: [2, 5, 1],
      state: 10
    },
    {
      pos: [3, 5, 1],
      state: 10
    },
    {
      pos: [4, 5, 1],
      state: 14
    },
    {
      pos: [5, 5, 1],
      state: 9
    },
    {
      pos: [0, 6, 1],
      state: 9
    },
    {
      pos: [1, 6, 1],
      state: 9
    },
    {
      pos: [2, 6, 1],
      state: 9
    },
    {
      pos: [3, 6, 1],
      state: 9
    },
    {
      pos: [4, 6, 1],
      state: 9
    },
    {
      pos: [5, 6, 1],
      state: 9
    },
    {
      pos: [0, 1, 2],
      state: 9
    },
    {
      pos: [0, 2, 2],
      state: 9
    },
    {
      pos: [2, 2, 2],
      state: 9
    },
    {
      pos: [3, 2, 2],
      state: 9
    },
    {
      pos: [5, 2, 2],
      state: 9
    },
    {
      pos: [0, 3, 2],
      state: 9
    },
    {
      pos: [2, 3, 2],
      state: 9
    },
    {
      pos: [3, 3, 2],
      state: 9
    },
    {
      pos: [5, 3, 2],
      state: 9
    },
    {
      pos: [0, 4, 2],
      state: 11
    },
    {
      pos: [2, 4, 2],
      state: 9
    },
    {
      pos: [3, 4, 2],
      state: 9
    },
    {
      pos: [5, 4, 2],
      state: 12
    },
    {
      pos: [0, 5, 2],
      state: 9
    },
    {
      pos: [1, 5, 2],
      state: 11
    },
    {
      pos: [4, 5, 2],
      state: 12
    },
    {
      pos: [5, 5, 2],
      state: 9
    },
    {
      pos: [0, 6, 2],
      state: 9
    },
    {
      pos: [1, 6, 2],
      state: 9
    },
    {
      pos: [2, 6, 2],
      state: 9
    },
    {
      pos: [3, 6, 2],
      state: 9
    },
    {
      pos: [4, 6, 2],
      state: 9
    },
    {
      pos: [5, 6, 2],
      state: 9
    },
    {
      pos: [0, 0, 3],
      state: 15
    },
    {
      pos: [0, 1, 3],
      state: 9
    },
    {
      pos: [1, 1, 3],
      state: 16
    },
    {
      pos: [2, 1, 3],
      state: 9
    },
    {
      pos: [3, 1, 3],
      state: 9
    },
    {
      pos: [5, 1, 3],
      state: 9
    },
    {
      pos: [0, 2, 3],
      state: 9
    },
    {
      pos: [1, 2, 3],
      state: 17
    },
    {
      pos: [2, 2, 3],
      state: 9
    },
    {
      pos: [3, 2, 3],
      state: 9
    },
    {
      pos: [4, 2, 3],
      state: 18
    },
    {
      pos: [5, 2, 3],
      state: 9
    },
    {
      pos: [0, 3, 3],
      state: 19
    },
    {
      pos: [2, 3, 3],
      state: 20
    },
    {
      pos: [3, 3, 3],
      state: 9
    },
    {
      pos: [5, 3, 3],
      state: 9
    },
    {
      pos: [0, 4, 3],
      state: 11
    },
    {
      pos: [2, 4, 3],
      state: 9
    },
    {
      pos: [3, 4, 3],
      state: 9
    },
    {
      pos: [5, 4, 3],
      state: 12
    },
    {
      pos: [0, 5, 3],
      state: 9
    },
    {
      pos: [1, 5, 3],
      state: 11
    },
    {
      pos: [4, 5, 3],
      state: 12
    },
    {
      pos: [5, 5, 3],
      state: 9
    },
    {
      pos: [0, 6, 3],
      state: 9
    },
    {
      pos: [1, 6, 3],
      state: 9
    },
    {
      pos: [2, 6, 3],
      state: 9
    },
    {
      pos: [3, 6, 3],
      state: 9
    },
    {
      pos: [4, 6, 3],
      state: 9
    },
    {
      pos: [5, 6, 3],
      state: 9
    },
    {
      pos: [0, 1, 4],
      state: 9
    },
    {
      pos: [2, 1, 4],
      state: 10
    },
    {
      pos: [3, 1, 4],
      state: 10
    },
    {
      pos: [5, 1, 4],
      state: 9
    },
    {
      pos: [0, 2, 4],
      state: 9
    },
    {
      pos: [2, 2, 4],
      state: 9
    },
    {
      pos: [3, 2, 4],
      state: 9
    },
    {
      pos: [5, 2, 4],
      state: 9
    },
    {
      pos: [0, 3, 4],
      state: 9
    },
    {
      pos: [2, 3, 4],
      state: 9
    },
    {
      pos: [3, 3, 4],
      state: 9
    },
    {
      pos: [5, 3, 4],
      state: 9
    },
    {
      pos: [0, 4, 4],
      state: 11
    },
    {
      pos: [2, 4, 4],
      state: 9
    },
    {
      pos: [3, 4, 4],
      state: 9
    },
    {
      pos: [5, 4, 4],
      state: 12
    },
    {
      pos: [0, 5, 4],
      state: 9
    },
    {
      pos: [1, 5, 4],
      state: 11
    },
    {
      pos: [4, 5, 4],
      state: 12
    },
    {
      pos: [5, 5, 4],
      state: 9
    },
    {
      pos: [0, 6, 4],
      state: 9
    },
    {
      pos: [1, 6, 4],
      state: 9
    },
    {
      pos: [2, 6, 4],
      state: 9
    },
    {
      pos: [3, 6, 4],
      state: 9
    },
    {
      pos: [4, 6, 4],
      state: 9
    },
    {
      pos: [5, 6, 4],
      state: 9
    },
    {
      pos: [0, 1, 5],
      state: 9
    },
    {
      pos: [1, 1, 5],
      state: 9
    },
    {
      pos: [4, 1, 5],
      state: 9
    },
    {
      pos: [5, 1, 5],
      state: 9
    },
    {
      pos: [0, 2, 5],
      state: 9
    },
    {
      pos: [1, 2, 5],
      state: 9
    },
    {
      pos: [4, 2, 5],
      state: 9
    },
    {
      pos: [5, 2, 5],
      state: 9
    },
    {
      pos: [0, 3, 5],
      state: 9
    },
    {
      pos: [1, 3, 5],
      state: 9
    },
    {
      pos: [4, 3, 5],
      state: 9
    },
    {
      pos: [5, 3, 5],
      state: 9
    },
    {
      pos: [0, 4, 5],
      state: 11
    },
    {
      pos: [5, 4, 5],
      state: 12
    },
    {
      pos: [0, 5, 5],
      state: 9
    },
    {
      pos: [1, 5, 5],
      state: 21
    },
    {
      pos: [2, 5, 5],
      state: 22
    },
    {
      pos: [3, 5, 5],
      state: 22
    },
    {
      pos: [4, 5, 5],
      state: 23
    },
    {
      pos: [5, 5, 5],
      state: 9
    },
    {
      pos: [0, 6, 5],
      state: 9
    },
    {
      pos: [1, 6, 5],
      state: 9
    },
    {
      pos: [2, 6, 5],
      state: 9
    },
    {
      pos: [3, 6, 5],
      state: 9
    },
    {
      pos: [4, 6, 5],
      state: 9
    },
    {
      pos: [5, 6, 5],
      state: 9
    },
    {
      pos: [0, 1, 6],
      state: 9
    },
    {
      pos: [1, 1, 6],
      state: 9
    },
    {
      pos: [2, 1, 6],
      state: 9
    },
    {
      pos: [3, 1, 6],
      state: 9
    },
    {
      pos: [4, 1, 6],
      state: 9
    },
    {
      pos: [5, 1, 6],
      state: 9
    },
    {
      pos: [0, 2, 6],
      state: 9
    },
    {
      pos: [1, 2, 6],
      state: 9
    },
    {
      pos: [2, 2, 6],
      state: 9
    },
    {
      pos: [3, 2, 6],
      state: 9
    },
    {
      pos: [4, 2, 6],
      state: 9
    },
    {
      pos: [5, 2, 6],
      state: 9
    },
    {
      pos: [0, 3, 6],
      state: 9
    },
    {
      pos: [1, 3, 6],
      state: 9
    },
    {
      pos: [2, 3, 6],
      state: 9
    },
    {
      pos: [3, 3, 6],
      state: 9
    },
    {
      pos: [4, 3, 6],
      state: 9
    },
    {
      pos: [5, 3, 6],
      state: 9
    },
    {
      pos: [0, 4, 6],
      state: 9
    },
    {
      pos: [1, 4, 6],
      state: 22
    },
    {
      pos: [2, 4, 6],
      state: 22
    },
    {
      pos: [3, 4, 6],
      state: 22
    },
    {
      pos: [4, 4, 6],
      state: 22
    },
    {
      pos: [5, 4, 6],
      state: 9
    },
    {
      pos: [0, 5, 6],
      state: 9
    },
    {
      pos: [1, 5, 6],
      state: 9
    },
    {
      pos: [2, 5, 6],
      state: 9
    },
    {
      pos: [3, 5, 6],
      state: 9
    },
    {
      pos: [4, 5, 6],
      state: 9
    },
    {
      pos: [5, 5, 6],
      state: 9
    },
    {
      pos: [0, 6, 6],
      state: 9
    },
    {
      pos: [1, 6, 6],
      state: 9
    },
    {
      pos: [2, 6, 6],
      state: 9
    },
    {
      pos: [3, 6, 6],
      state: 9
    },
    {
      pos: [4, 6, 6],
      state: 9
    },
    {
      pos: [5, 6, 6],
      state: 9
    }
  ],
  palette: [
    {
      Name: "minecraft:dirt"
    },
    {
      Name: "minecraft:yellow_terracotta"
    },
    {
      Properties: {
        axis: "y"
      },
      Name: "minecraft:acacia_wood"
    },
    {
      Name: "minecraft:acacia_planks"
    },
    {
      Properties: {
        axis: "x"
      },
      Name: "minecraft:acacia_log"
    },
    {
      Properties: {
        axis: "y"
      },
      Name: "minecraft:acacia_log"
    },
    {
      Properties: {
        facing: "up"
      },
      Name: "minecraft:jigsaw"
    },
    {
      Properties: {
        part: "foot",
        facing: "east",
        occupied: "false"
      },
      Name: "minecraft:orange_bed"
    },
    {
      Properties: {
        part: "head",
        facing: "east",
        occupied: "false"
      },
      Name: "minecraft:orange_bed"
    },
    {
      Name: "minecraft:air"
    },
    {
      Properties: {
        half: "bottom",
        waterlogged: "false",
        shape: "straight",
        facing: "south"
      },
      Name: "minecraft:acacia_stairs"
    },
    {
      Properties: {
        half: "bottom",
        waterlogged: "false",
        shape: "straight",
        facing: "east"
      },
      Name: "minecraft:acacia_stairs"
    },
    {
      Properties: {
        half: "bottom",
        waterlogged: "false",
        shape: "straight",
        facing: "west"
      },
      Name: "minecraft:acacia_stairs"
    },
    {
      Properties: {
        half: "bottom",
        waterlogged: "false",
        shape: "outer_left",
        facing: "south"
      },
      Name: "minecraft:acacia_stairs"
    },
    {
      Properties: {
        half: "bottom",
        waterlogged: "false",
        shape: "outer_right",
        facing: "south"
      },
      Name: "minecraft:acacia_stairs"
    },
    {
      Name: "minecraft:grass_path"
    },
    {
      Properties: {
        hinge: "right",
        half: "lower",
        powered: "false",
        facing: "west",
        open: "false"
      },
      Name: "minecraft:acacia_door"
    },
    {
      Properties: {
        hinge: "right",
        half: "upper",
        powered: "false",
        facing: "west",
        open: "false"
      },
      Name: "minecraft:acacia_door"
    },
    {
      Properties: {
        east: "false",
        waterlogged: "false",
        south: "true",
        north: "true",
        west: "false"
      },
      Name: "minecraft:glass_pane"
    },
    {
      Properties: {
        facing: "west"
      },
      Name: "minecraft:wall_torch"
    },
    {
      Properties: {
        facing: "east"
      },
      Name: "minecraft:wall_torch"
    },
    {
      Properties: {
        half: "bottom",
        waterlogged: "false",
        shape: "outer_right",
        facing: "north"
      },
      Name: "minecraft:acacia_stairs"
    },
    {
      Properties: {
        half: "bottom",
        waterlogged: "false",
        shape: "straight",
        facing: "north"
      },
      Name: "minecraft:acacia_stairs"
    },
    {
      Properties: {
        half: "bottom",
        waterlogged: "false",
        shape: "outer_right",
        facing: "west"
      },
      Name: "minecraft:acacia_stairs"
    }
  ],
  DataVersion: 1910
}