{
  size: [9, 7, 13],
  entities: [],
  blocks: [
    {
      pos: [5, 0, 1],
      state: 0
    },
    {
      pos: [6, 0, 1],
      state: 0
    },
    {
      pos: [5, 1, 1],
      state: 1
    },
    {
      pos: [6, 1, 1],
      state: 1
    },
    {
      pos: [5, 2, 1],
      state: 1
    },
    {
      pos: [6, 2, 1],
      state: 1
    },
    {
      pos: [5, 3, 1],
      state: 1
    },
    {
      pos: [6, 3, 1],
      state: 1
    },
    {
      pos: [5, 4, 1],
      state: 1
    },
    {
      pos: [6, 4, 1],
      state: 1
    },
    {
      pos: [4, 5, 1],
      state: 2
    },
    {
      pos: [5, 5, 1],
      state: 2
    },
    {
      pos: [6, 5, 1],
      state: 2
    },
    {
      pos: [7, 5, 1],
      state: 2
    },
    {
      pos: [2, 0, 2],
      state: 0
    },
    {
      pos: [3, 0, 2],
      state: 0
    },
    {
      pos: [4, 0, 2],
      state: 0
    },
    {
      pos: [5, 0, 2],
      state: 0
    },
    {
      pos: [6, 0, 2],
      state: 0
    },
    {
      pos: [7, 0, 2],
      state: 0
    },
    {
      pos: [2, 1, 2],
      state: 3
    },
    {
      pos: [3, 1, 2],
      state: 3
    },
    {
      pos: [4, 1, 2],
      state: 3
    },
    {
      pos: [5, 1, 2],
      state: 3
    },
    {
      pos: [6, 1, 2],
      state: 3
    },
    {
      pos: [7, 1, 2],
      state: 1
    },
    {
      pos: [2, 2, 2],
      state: 3
    },
    {
      pos: [3, 2, 2],
      state: 3
    },
    {
      pos: [4, 2, 2],
      state: 3
    },
    {
      pos: [7, 2, 2],
      state: 1
    },
    {
      pos: [4, 3, 2],
      state: 3
    },
    {
      pos: [7, 3, 2],
      state: 1
    },
    {
      pos: [4, 4, 2],
      state: 3
    },
    {
      pos: [7, 4, 2],
      state: 1
    },
    {
      pos: [4, 5, 2],
      state: 2
    },
    {
      pos: [7, 5, 2],
      state: 2
    },
    {
      pos: [5, 6, 2],
      state: 2
    },
    {
      pos: [6, 6, 2],
      state: 2
    },
    {
      pos: [2, 0, 3],
      state: 0
    },
    {
      pos: [3, 0, 3],
      state: 0
    },
    {
      pos: [4, 0, 3],
      state: 0
    },
    {
      pos: [5, 0, 3],
      state: 0
    },
    {
      pos: [6, 0, 3],
      state: 0
    },
    {
      pos: [7, 0, 3],
      state: 0
    },
    {
      pos: [2, 1, 3],
      state: 3
    },
    {
      pos: [3, 1, 3],
      state: 3
    },
    {
      pos: [4, 1, 3],
      state: 3
    },
    {
      pos: [5, 1, 3],
      state: 3
    },
    {
      pos: [6, 1, 3],
      state: 3
    },
    {
      pos: [7, 1, 3],
      state: 1
    },
    {
      pos: [2, 2, 3],
      state: 3
    },
    {
      pos: [4, 2, 3],
      state: 3
    },
    {
      pos: [7, 2, 3],
      state: 4
    },
    {
      pos: [4, 3, 3],
      state: 3
    },
    {
      pos: [7, 3, 3],
      state: 4
    },
    {
      pos: [4, 4, 3],
      state: 3
    },
    {
      pos: [7, 4, 3],
      state: 1
    },
    {
      pos: [4, 5, 3],
      state: 2
    },
    {
      pos: [7, 5, 3],
      state: 2
    },
    {
      pos: [5, 6, 3],
      state: 2
    },
    {
      pos: [6, 6, 3],
      state: 2
    },
    {
      pos: [0, 0, 4],
      state: 5
    },
    {
      pos: [1, 0, 4],
      state: 5
    },
    {
      pos: [2, 0, 4],
      state: 0
    },
    {
      pos: [3, 0, 4],
      state: 0
    },
    {
      pos: [4, 0, 4],
      state: 0
    },
    {
      pos: [5, 0, 4],
      state: 0
    },
    {
      pos: [6, 0, 4],
      state: 0
    },
    {
      pos: [7, 0, 4],
      state: 0
    },
    {
      pos: [2, 1, 4],
      state: 3
    },
    {
      pos: [3, 1, 4],
      state: 3
    },
    {
      pos: [4, 1, 4],
      state: 3
    },
    {
      pos: [5, 1, 4],
      state: 3
    },
    {
      pos: [6, 1, 4],
      state: 3
    },
    {
      pos: [7, 1, 4],
      state: 1
    },
    {
      pos: [2, 2, 4],
      state: 3
    },
    {
      pos: [3, 2, 4],
      state: 3
    },
    {
      pos: [4, 2, 4],
      state: 3
    },
    {
      pos: [7, 2, 4],
      state: 1
    },
    {
      pos: [4, 3, 4],
      state: 3
    },
    {
      pos: [4, 4, 4],
      state: 3
    },
    {
      pos: [7, 4, 4],
      state: 1
    },
    {
      pos: [4, 5, 4],
      state: 2
    },
    {
      pos: [7, 5, 4],
      state: 2
    },
    {
      pos: [5, 6, 4],
      state: 2
    },
    {
      pos: [6, 6, 4],
      state: 2
    },
    {
      pos: [0, 0, 5],
      state: 5
    },
    {
      pos: [1, 0, 5],
      state: 0
    },
    {
      pos: [2, 0, 5],
      state: 0
    },
    {
      pos: [3, 0, 5],
      state: 0
    },
    {
      pos: [4, 0, 5],
      state: 0
    },
    {
      pos: [5, 0, 5],
      state: 0
    },
    {
      pos: [6, 0, 5],
      state: 0
    },
    {
      pos: [7, 0, 5],
      state: 0
    },
    {
      pos: [1, 1, 5],
      state: 3
    },
    {
      pos: [2, 1, 5],
      state: 3
    },
    {
      pos: [3, 1, 5],
      state: 3
    },
    {
      pos: [4, 1, 5],
      state: 1
    },
    {
      pos: [5, 1, 5],
      state: 2
    },
    {
      pos: [6, 1, 5],
      state: 2
    },
    {
      pos: [7, 1, 5],
      state: 1
    },
    {
      pos: [4, 2, 5],
      state: 1
    },
    {
      pos: [7, 2, 5],
      state: 1
    },
    {
      pos: [4, 3, 5],
      state: 1
    },
    {
      pos: [7, 3, 5],
      state: 4
    },
    {
      pos: [4, 4, 5],
      state: 1
    },
    {
      pos: [7, 4, 5],
      state: 1
    },
    {
      pos: [4, 5, 5],
      state: 2
    },
    {
      pos: [7, 5, 5],
      state: 2
    },
    {
      pos: [5, 6, 5],
      state: 2
    },
    {
      pos: [6, 6, 5],
      state: 2
    },
    {
      pos: [0, 0, 6],
      state: 5
    },
    {
      pos: [1, 0, 6],
      state: 0
    },
    {
      pos: [2, 0, 6],
      state: 0
    },
    {
      pos: [3, 0, 6],
      state: 0
    },
    {
      pos: [4, 0, 6],
      state: 0
    },
    {
      pos: [5, 0, 6],
      state: 0
    },
    {
      pos: [6, 0, 6],
      state: 0
    },
    {
      pos: [7, 0, 6],
      state: 0
    },
    {
      pos: [1, 1, 6],
      state: 3
    },
    {
      pos: [2, 1, 6],
      state: 3
    },
    {
      pos: [3, 1, 6],
      state: 3
    },
    {
      pos: [4, 1, 6],
      state: 1
    },
    {
      pos: [5, 1, 6],
      state: 2
    },
    {
      pos: [6, 1, 6],
      state: 2
    },
    {
      pos: [7, 1, 6],
      state: 1
    },
    {
      pos: [7, 2, 6],
      state: 1
    },
    {
      pos: [7, 3, 6],
      state: 4
    },
    {
      pos: [4, 4, 6],
      state: 4
    },
    {
      pos: [7, 4, 6],
      state: 1
    },
    {
      pos: [4, 5, 6],
      state: 2
    },
    {
      pos: [7, 5, 6],
      state: 2
    },
    {
      pos: [5, 6, 6],
      state: 2
    },
    {
      pos: [6, 6, 6],
      state: 2
    },
    {
      pos: [0, 0, 7],
      state: 5
    },
    {
      pos: [1, 0, 7],
      state: 0
    },
    {
      pos: [2, 0, 7],
      state: 0
    },
    {
      pos: [3, 0, 7],
      state: 0
    },
    {
      pos: [4, 0, 7],
      state: 0
    },
    {
      pos: [5, 0, 7],
      state: 0
    },
    {
      pos: [6, 0, 7],
      state: 0
    },
    {
      pos: [7, 0, 7],
      state: 0
    },
    {
      pos: [1, 1, 7],
      state: 3
    },
    {
      pos: [2, 1, 7],
      state: 3
    },
    {
      pos: [3, 1, 7],
      state: 3
    },
    {
      pos: [4, 1, 7],
      state: 4
    },
    {
      pos: [5, 1, 7],
      state: 2
    },
    {
      pos: [6, 1, 7],
      state: 2
    },
    {
      pos: [7, 1, 7],
      state: 1
    },
    {
      pos: [4, 2, 7],
      state: 1
    },
    {
      pos: [7, 2, 7],
      state: 1
    },
    {
      pos: [4, 3, 7],
      state: 1
    },
    {
      pos: [7, 3, 7],
      state: 4
    },
    {
      pos: [4, 4, 7],
      state: 1
    },
    {
      pos: [7, 4, 7],
      state: 1
    },
    {
      pos: [4, 5, 7],
      state: 2
    },
    {
      pos: [7, 5, 7],
      state: 2
    },
    {
      pos: [5, 6, 7],
      state: 2
    },
    {
      pos: [6, 6, 7],
      state: 2
    },
    {
      pos: [0, 0, 8],
      state: 5
    },
    {
      pos: [1, 0, 8],
      state: 5
    },
    {
      pos: [2, 0, 8],
      state: 0
    },
    {
      pos: [3, 0, 8],
      state: 0
    },
    {
      pos: [4, 0, 8],
      state: 0
    },
    {
      pos: [5, 0, 8],
      state: 0
    },
    {
      pos: [6, 0, 8],
      state: 0
    },
    {
      pos: [7, 0, 8],
      state: 0
    },
    {
      pos: [2, 1, 8],
      state: 1
    },
    {
      pos: [3, 1, 8],
      state: 6
    },
    {
      pos: [4, 1, 8],
      state: 2
    },
    {
      pos: [5, 1, 8],
      state: 2
    },
    {
      pos: [6, 1, 8],
      state: 2
    },
    {
      pos: [7, 1, 8],
      state: 4
    },
    {
      pos: [2, 2, 8],
      state: 1
    },
    {
      pos: [3, 2, 8],
      state: 1
    },
    {
      pos: [7, 2, 8],
      state: 1
    },
    {
      pos: [2, 3, 8],
      state: 1
    },
    {
      pos: [3, 3, 8],
      state: 1
    },
    {
      pos: [2, 4, 8],
      state: 1
    },
    {
      pos: [3, 4, 8],
      state: 1
    },
    {
      pos: [7, 4, 8],
      state: 1
    },
    {
      pos: [1, 5, 8],
      state: 2
    },
    {
      pos: [2, 5, 8],
      state: 2
    },
    {
      pos: [3, 5, 8],
      state: 2
    },
    {
      pos: [4, 5, 8],
      state: 2
    },
    {
      pos: [7, 5, 8],
      state: 2
    },
    {
      pos: [5, 6, 8],
      state: 2
    },
    {
      pos: [6, 6, 8],
      state: 2
    },
    {
      pos: [1, 0, 9],
      state: 0
    },
    {
      pos: [2, 0, 9],
      state: 0
    },
    {
      pos: [3, 0, 9],
      state: 0
    },
    {
      pos: [4, 0, 9],
      state: 0
    },
    {
      pos: [5, 0, 9],
      state: 0
    },
    {
      pos: [6, 0, 9],
      state: 0
    },
    {
      pos: [7, 0, 9],
      state: 0
    },
    {
      pos: [1, 1, 9],
      state: 1
    },
    {
      pos: [2, 1, 9],
      state: 2
    },
    {
      pos: [3, 1, 9],
      state: 2
    },
    {
      pos: [4, 1, 9],
      state: 2
    },
    {
      pos: [5, 1, 9],
      state: 2
    },
    {
      pos: [6, 1, 9],
      state: 2
    },
    {
      pos: [7, 1, 9],
      state: 4
    },
    {
      pos: [1, 2, 9],
      state: 1
    },
    {
      pos: [7, 2, 9],
      state: 1
    },
    {
      pos: [1, 3, 9],
      state: 1
    },
    {
      pos: [7, 3, 9],
      state: 4
    },
    {
      pos: [1, 4, 9],
      state: 1
    },
    {
      pos: [7, 4, 9],
      state: 1
    },
    {
      pos: [1, 5, 9],
      state: 2
    },
    {
      pos: [7, 5, 9],
      state: 2
    },
    {
      pos: [2, 6, 9],
      state: 2
    },
    {
      pos: [3, 6, 9],
      state: 2
    },
    {
      pos: [4, 6, 9],
      state: 2
    },
    {
      pos: [5, 6, 9],
      state: 2
    },
    {
      pos: [6, 6, 9],
      state: 2
    },
    {
      pos: [1, 0, 10],
      state: 0
    },
    {
      pos: [2, 0, 10],
      state: 0
    },
    {
      pos: [3, 0, 10],
      state: 0
    },
    {
      pos: [4, 0, 10],
      state: 0
    },
    {
      pos: [5, 0, 10],
      state: 0
    },
    {
      pos: [6, 0, 10],
      state: 0
    },
    {
      pos: [7, 0, 10],
      state: 0
    },
    {
      pos: [1, 1, 10],
      state: 1
    },
    {
      pos: [2, 1, 10],
      state: 2
    },
    {
      pos: [3, 1, 10],
      state: 2
    },
    {
      pos: [4, 1, 10],
      state: 2
    },
    {
      pos: [5, 1, 10],
      state: 2
    },
    {
      pos: [6, 1, 10],
      state: 2
    },
    {
      pos: [7, 1, 10],
      state: 1
    },
    {
      pos: [1, 2, 10],
      state: 1
    },
    {
      pos: [7, 2, 10],
      state: 1
    },
    {
      pos: [1, 3, 10],
      state: 1
    },
    {
      pos: [7, 3, 10],
      state: 1
    },
    {
      pos: [1, 4, 10],
      state: 1
    },
    {
      pos: [7, 4, 10],
      state: 1
    },
    {
      pos: [1, 5, 10],
      state: 2
    },
    {
      pos: [7, 5, 10],
      state: 2
    },
    {
      pos: [2, 6, 10],
      state: 2
    },
    {
      pos: [3, 6, 10],
      state: 2
    },
    {
      pos: [4, 6, 10],
      state: 2
    },
    {
      pos: [5, 6, 10],
      state: 2
    },
    {
      pos: [6, 6, 10],
      state: 2
    },
    {
      pos: [2, 0, 11],
      state: 0
    },
    {
      pos: [3, 0, 11],
      state: 0
    },
    {
      pos: [4, 0, 11],
      state: 0
    },
    {
      pos: [5, 0, 11],
      state: 0
    },
    {
      pos: [6, 0, 11],
      state: 0
    },
    {
      pos: [2, 1, 11],
      state: 4
    },
    {
      pos: [3, 1, 11],
      state: 1
    },
    {
      pos: [4, 1, 11],
      state: 1
    },
    {
      pos: [5, 1, 11],
      state: 1
    },
    {
      pos: [6, 1, 11],
      state: 1
    },
    {
      pos: [2, 2, 11],
      state: 1
    },
    {
      pos: [3, 2, 11],
      state: 1
    },
    {
      pos: [4, 2, 11],
      state: 1
    },
    {
      pos: [5, 2, 11],
      state: 1
    },
    {
      pos: [6, 2, 11],
      state: 1
    },
    {
      pos: [2, 3, 11],
      state: 1
    },
    {
      pos: [3, 3, 11],
      state: 6
    },
    {
      pos: [5, 3, 11],
      state: 6
    },
    {
      pos: [6, 3, 11],
      state: 6
    },
    {
      pos: [2, 4, 11],
      state: 1
    },
    {
      pos: [3, 4, 11],
      state: 1
    },
    {
      pos: [4, 4, 11],
      state: 1
    },
    {
      pos: [5, 4, 11],
      state: 1
    },
    {
      pos: [6, 4, 11],
      state: 1
    },
    {
      pos: [1, 5, 11],
      state: 2
    },
    {
      pos: [2, 5, 11],
      state: 2
    },
    {
      pos: [3, 5, 11],
      state: 2
    },
    {
      pos: [4, 5, 11],
      state: 2
    },
    {
      pos: [5, 5, 11],
      state: 2
    },
    {
      pos: [6, 5, 11],
      state: 2
    },
    {
      pos: [7, 5, 11],
      state: 2
    },
    {
      nbt: {
        LootTable: "minecraft:chests/village/village_weaponsmith",
        Items: [],
        id: "minecraft:chest",
        Lock: "",
        LootTableSeed: 0L
      },
      pos: [2, 2, 9],
      state: 7
    },
    {
      pos: [8, 0, 0],
      state: 8
    },
    {
      pos: [0, 1, 0],
      state: 9
    },
    {
      pos: [1, 1, 0],
      state: 9
    },
    {
      pos: [2, 1, 0],
      state: 9
    },
    {
      pos: [4, 5, 0],
      state: 10
    },
    {
      pos: [5, 5, 0],
      state: 10
    },
    {
      pos: [6, 5, 0],
      state: 10
    },
    {
      pos: [7, 5, 0],
      state: 10
    },
    {
      pos: [8, 0, 1],
      state: 8
    },
    {
      pos: [3, 5, 1],
      state: 11
    },
    {
      pos: [8, 5, 1],
      state: 12
    },
    {
      pos: [4, 6, 1],
      state: 13
    },
    {
      pos: [5, 6, 1],
      state: 10
    },
    {
      pos: [6, 6, 1],
      state: 10
    },
    {
      pos: [7, 6, 1],
      state: 14
    },
    {
      pos: [8, 0, 2],
      state: 8
    },
    {
      pos: [2, 3, 2],
      state: 15
    },
    {
      pos: [3, 3, 2],
      state: 16
    },
    {
      pos: [2, 4, 2],
      state: 15
    },
    {
      pos: [3, 4, 2],
      state: 16
    },
    {
      pos: [2, 5, 2],
      state: 17
    },
    {
      pos: [3, 5, 2],
      state: 17
    },
    {
      pos: [8, 5, 2],
      state: 12
    },
    {
      pos: [4, 6, 2],
      state: 11
    },
    {
      pos: [7, 6, 2],
      state: 12
    },
    {
      pos: [8, 0, 3],
      state: 8
    },
    {
      pos: [3, 2, 3],
      state: 18
    },
    {
      pos: [5, 2, 3],
      state: 19
    },
    {
      pos: [2, 3, 3],
      state: 20
    },
    {
      pos: [2, 4, 3],
      state: 20
    },
    {
      pos: [2, 5, 3],
      state: 17
    },
    {
      pos: [3, 5, 3],
      state: 17
    },
    {
      pos: [8, 5, 3],
      state: 12
    },
    {
      pos: [4, 6, 3],
      state: 11
    },
    {
      pos: [7, 6, 3],
      state: 12
    },
    {
      pos: [8, 0, 4],
      state: 9
    },
    {
      pos: [0, 1, 4],
      state: 17
    },
    {
      pos: [1, 1, 4],
      state: 17
    },
    {
      pos: [2, 3, 4],
      state: 21
    },
    {
      pos: [7, 3, 4],
      state: 22
    },
    {
      pos: [2, 4, 4],
      state: 21
    },
    {
      pos: [6, 4, 4],
      state: 23
    },
    {
      pos: [2, 5, 4],
      state: 17
    },
    {
      pos: [3, 5, 4],
      state: 17
    },
    {
      pos: [8, 5, 4],
      state: 12
    },
    {
      pos: [4, 6, 4],
      state: 11
    },
    {
      pos: [7, 6, 4],
      state: 12
    },
    {
      pos: [0, 1, 5],
      state: 17
    },
    {
      pos: [3, 5, 5],
      state: 11
    },
    {
      pos: [8, 5, 5],
      state: 12
    },
    {
      pos: [4, 6, 5],
      state: 11
    },
    {
      pos: [7, 6, 5],
      state: 12
    },
    {
      pos: [0, 1, 6],
      state: 17
    },
    {
      pos: [2, 2, 6],
      state: 24
    },
    {
      pos: [4, 2, 6],
      state: 25
    },
    {
      pos: [4, 3, 6],
      state: 26
    },
    {
      pos: [3, 5, 6],
      state: 11
    },
    {
      pos: [8, 5, 6],
      state: 12
    },
    {
      pos: [4, 6, 6],
      state: 11
    },
    {
      pos: [7, 6, 6],
      state: 12
    },
    {
      pos: [0, 1, 7],
      state: 17
    },
    {
      pos: [1, 5, 7],
      state: 10
    },
    {
      pos: [2, 5, 7],
      state: 10
    },
    {
      pos: [3, 5, 7],
      state: 27
    },
    {
      pos: [8, 5, 7],
      state: 12
    },
    {
      pos: [4, 6, 7],
      state: 11
    },
    {
      pos: [7, 6, 7],
      state: 12
    },
    {
      pos: [0, 1, 8],
      state: 17
    },
    {
      pos: [1, 1, 8],
      state: 17
    },
    {
      pos: [6, 2, 8],
      state: 28
    },
    {
      pos: [1, 3, 8],
      state: 23
    },
    {
      pos: [7, 3, 8],
      state: 22
    },
    {
      pos: [6, 4, 8],
      state: 23
    },
    {
      pos: [0, 5, 8],
      state: 11
    },
    {
      pos: [8, 5, 8],
      state: 12
    },
    {
      pos: [1, 6, 8],
      state: 13
    },
    {
      pos: [2, 6, 8],
      state: 10
    },
    {
      pos: [3, 6, 8],
      state: 10
    },
    {
      pos: [4, 6, 8],
      state: 27
    },
    {
      pos: [7, 6, 8],
      state: 12
    },
    {
      pos: [6, 2, 9],
      state: 29
    },
    {
      pos: [6, 3, 9],
      state: 30
    },
    {
      pos: [2, 4, 9],
      state: 31
    },
    {
      pos: [0, 5, 9],
      state: 11
    },
    {
      pos: [8, 5, 9],
      state: 12
    },
    {
      pos: [1, 6, 9],
      state: 11
    },
    {
      pos: [7, 6, 9],
      state: 12
    },
    {
      pos: [6, 2, 10],
      state: 10
    },
    {
      pos: [0, 5, 10],
      state: 11
    },
    {
      pos: [8, 5, 10],
      state: 12
    },
    {
      pos: [1, 6, 10],
      state: 11
    },
    {
      pos: [7, 6, 10],
      state: 12
    },
    {
      pos: [4, 3, 11],
      state: 32
    },
    {
      pos: [0, 5, 11],
      state: 11
    },
    {
      pos: [8, 5, 11],
      state: 12
    },
    {
      pos: [1, 6, 11],
      state: 33
    },
    {
      pos: [2, 6, 11],
      state: 28
    },
    {
      pos: [3, 6, 11],
      state: 28
    },
    {
      pos: [4, 6, 11],
      state: 28
    },
    {
      pos: [5, 6, 11],
      state: 28
    },
    {
      pos: [6, 6, 11],
      state: 28
    },
    {
      pos: [7, 6, 11],
      state: 34
    },
    {
      pos: [1, 5, 12],
      state: 28
    },
    {
      pos: [2, 5, 12],
      state: 28
    },
    {
      pos: [3, 5, 12],
      state: 28
    },
    {
      pos: [4, 5, 12],
      state: 28
    },
    {
      pos: [5, 5, 12],
      state: 28
    },
    {
      pos: [6, 5, 12],
      state: 28
    },
    {
      pos: [7, 5, 12],
      state: 28
    }
  ],
  palette: [
    {
      Name: "minecraft:dirt"
    },
    {
      Properties: {
        axis: "y"
      },
      Name: "minecraft:acacia_wood"
    },
    {
      Name: "minecraft:acacia_planks"
    },
    {
      Name: "minecraft:smooth_stone"
    },
    {
      Properties: {
        axis: "z"
      },
      Name: "minecraft:acacia_wood"
    },
    {
      Properties: {
        snowy: "false"
      },
      Name: "minecraft:grass_block"
    },
    {
      Properties: {
        axis: "x"
      },
      Name: "minecraft:acacia_wood"
    },
    {
      Properties: {
        waterlogged: "false",
        facing: "east",
        type: "single"
      },
      Name: "minecraft:chest"
    },
    {
      Name: "minecraft:grass"
    },
    {
      Name: "minecraft:cave_air"
    },
    {
      Properties: {
        half: "bottom",
        waterlogged: "false",
        shape: "straight",
        facing: "south"
      },
      Name: "minecraft:acacia_stairs"
    },
    {
      Properties: {
        half: "bottom",
        waterlogged: "false",
        shape: "straight",
        facing: "east"
      },
      Name: "minecraft:acacia_stairs"
    },
    {
      Properties: {
        half: "bottom",
        waterlogged: "false",
        shape: "straight",
        facing: "west"
      },
      Name: "minecraft:acacia_stairs"
    },
    {
      Properties: {
        half: "bottom",
        waterlogged: "false",
        shape: "outer_left",
        facing: "south"
      },
      Name: "minecraft:acacia_stairs"
    },
    {
      Properties: {
        half: "bottom",
        waterlogged: "false",
        shape: "outer_right",
        facing: "south"
      },
      Name: "minecraft:acacia_stairs"
    },
    {
      Properties: {
        east: "true",
        waterlogged: "false",
        south: "true",
        north: "false",
        west: "false"
      },
      Name: "minecraft:iron_bars"
    },
    {
      Properties: {
        east: "true",
        waterlogged: "false",
        south: "false",
        north: "false",
        west: "true"
      },
      Name: "minecraft:iron_bars"
    },
    {
      Properties: {
        waterlogged: "false",
        type: "bottom"
      },
      Name: "minecraft:smooth_stone_slab"
    },
    {
      Properties: {
        level: "0"
      },
      Name: "minecraft:lava"
    },
    {
      Properties: {
        face: "wall",
        facing: "east"
      },
      Name: "minecraft:grindstone"
    },
    {
      Properties: {
        east: "false",
        waterlogged: "false",
        south: "true",
        north: "true",
        west: "false"
      },
      Name: "minecraft:iron_bars"
    },
    {
      Properties: {
        east: "false",
        waterlogged: "false",
        south: "false",
        north: "true",
        west: "false"
      },
      Name: "minecraft:iron_bars"
    },
    {
      Properties: {
        east: "false",
        waterlogged: "false",
        south: "true",
        north: "true",
        west: "false"
      },
      Name: "minecraft:glass_pane"
    },
    {
      Properties: {
        facing: "west"
      },
      Name: "minecraft:wall_torch"
    },
    {
      Properties: {
        face: "floor",
        facing: "east"
      },
      Name: "minecraft:grindstone"
    },
    {
      Properties: {
        hinge: "left",
        half: "lower",
        powered: "false",
        facing: "west",
        open: "false"
      },
      Name: "minecraft:acacia_door"
    },
    {
      Properties: {
        hinge: "left",
        half: "upper",
        powered: "false",
        facing: "west",
        open: "false"
      },
      Name: "minecraft:acacia_door"
    },
    {
      Properties: {
        half: "bottom",
        waterlogged: "false",
        shape: "inner_right",
        facing: "east"
      },
      Name: "minecraft:acacia_stairs"
    },
    {
      Properties: {
        half: "bottom",
        waterlogged: "false",
        shape: "straight",
        facing: "north"
      },
      Name: "minecraft:acacia_stairs"
    },
    {
      Properties: {
        east: "true",
        waterlogged: "false",
        south: "false",
        north: "false",
        west: "false"
      },
      Name: "minecraft:acacia_fence"
    },
    {
      Properties: {
        powered: "false"
      },
      Name: "minecraft:acacia_pressure_plate"
    },
    {
      Properties: {
        facing: "east"
      },
      Name: "minecraft:wall_torch"
    },
    {
      Properties: {
        east: "true",
        waterlogged: "false",
        south: "false",
        north: "false",
        west: "true"
      },
      Name: "minecraft:glass_pane"
    },
    {
      Properties: {
        half: "bottom",
        waterlogged: "false",
        shape: "outer_right",
        facing: "north"
      },
      Name: "minecraft:acacia_stairs"
    },
    {
      Properties: {
        half: "bottom",
        waterlogged: "false",
        shape: "outer_left",
        facing: "north"
      },
      Name: "minecraft:acacia_stairs"
    }
  ],
  DataVersion: 1915
}