{
  size: [9, 6, 9],
  entities: [],
  blocks: [
    {
      pos: [3, 0, 2],
      state: 0
    },
    {
      pos: [4, 0, 2],
      state: 0
    },
    {
      pos: [5, 0, 2],
      state: 0
    },
    {
      pos: [3, 1, 2],
      state: 1
    },
    {
      pos: [4, 1, 2],
      state: 1
    },
    {
      pos: [5, 1, 2],
      state: 1
    },
    {
      pos: [2, 0, 3],
      state: 0
    },
    {
      pos: [3, 0, 3],
      state: 0
    },
    {
      pos: [4, 0, 3],
      state: 1
    },
    {
      pos: [5, 0, 3],
      state: 0
    },
    {
      pos: [6, 0, 3],
      state: 0
    },
    {
      pos: [2, 1, 3],
      state: 1
    },
    {
      pos: [3, 1, 3],
      state: 1
    },
    {
      pos: [5, 1, 3],
      state: 1
    },
    {
      pos: [6, 1, 3],
      state: 1
    },
    {
      pos: [2, 0, 4],
      state: 0
    },
    {
      pos: [3, 0, 4],
      state: 1
    },
    {
      pos: [4, 0, 4],
      state: 1
    },
    {
      pos: [5, 0, 4],
      state: 1
    },
    {
      pos: [6, 0, 4],
      state: 0
    },
    {
      pos: [2, 1, 4],
      state: 1
    },
    {
      pos: [6, 1, 4],
      state: 1
    },
    {
      pos: [4, 4, 4],
      state: 2
    },
    {
      pos: [2, 0, 5],
      state: 0
    },
    {
      pos: [3, 0, 5],
      state: 3
    },
    {
      pos: [4, 0, 5],
      state: 1
    },
    {
      pos: [5, 0, 5],
      state: 0
    },
    {
      pos: [6, 0, 5],
      state: 0
    },
    {
      pos: [2, 1, 5],
      state: 4
    },
    {
      pos: [3, 1, 5],
      state: 1
    },
    {
      pos: [5, 1, 5],
      state: 1
    },
    {
      pos: [6, 1, 5],
      state: 1
    },
    {
      pos: [3, 0, 6],
      state: 0
    },
    {
      pos: [4, 0, 6],
      state: 0
    },
    {
      pos: [5, 0, 6],
      state: 0
    },
    {
      pos: [3, 1, 6],
      state: 1
    },
    {
      pos: [4, 1, 6],
      state: 1
    },
    {
      pos: [5, 1, 6],
      state: 1
    },
    {
      nbt: {
        target_pool: "minecraft:village/savanna/streets",
        final_state: "minecraft:air",
        id: "minecraft:jigsaw",
        attachement_type: "minecraft:street"
      },
      pos: [4, 1, 0],
      state: 5
    },
    {
      nbt: {
        target_pool: "minecraft:village/savanna/streets",
        final_state: "minecraft:air",
        id: "minecraft:jigsaw",
        attachement_type: "minecraft:street"
      },
      pos: [0, 1, 4],
      state: 6
    },
    {
      nbt: {
        target_pool: "minecraft:village/savanna/streets",
        final_state: "minecraft:air",
        id: "minecraft:jigsaw",
        attachement_type: "minecraft:street"
      },
      pos: [8, 1, 4],
      state: 7
    },
    {
      nbt: {
        id: "minecraft:bell"
      },
      pos: [4, 3, 4],
      state: 8
    },
    {
      nbt: {
        target_pool: "minecraft:village/savanna/streets",
        final_state: "minecraft:air",
        id: "minecraft:jigsaw",
        attachement_type: "minecraft:street"
      },
      pos: [4, 1, 8],
      state: 9
    },
    {
      pos: [3, 0, 0],
      state: 10
    },
    {
      pos: [4, 0, 0],
      state: 10
    },
    {
      pos: [5, 0, 0],
      state: 10
    },
    {
      pos: [1, 0, 1],
      state: 10
    },
    {
      pos: [2, 0, 1],
      state: 10
    },
    {
      pos: [3, 0, 1],
      state: 10
    },
    {
      pos: [4, 0, 1],
      state: 10
    },
    {
      pos: [5, 0, 1],
      state: 10
    },
    {
      pos: [6, 0, 1],
      state: 10
    },
    {
      pos: [7, 0, 1],
      state: 10
    },
    {
      pos: [1, 0, 2],
      state: 10
    },
    {
      pos: [2, 0, 2],
      state: 10
    },
    {
      pos: [6, 0, 2],
      state: 10
    },
    {
      pos: [7, 0, 2],
      state: 10
    },
    {
      pos: [4, 2, 2],
      state: 11
    },
    {
      pos: [0, 0, 3],
      state: 10
    },
    {
      pos: [1, 0, 3],
      state: 10
    },
    {
      pos: [7, 0, 3],
      state: 10
    },
    {
      pos: [8, 0, 3],
      state: 10
    },
    {
      pos: [4, 1, 3],
      state: 12
    },
    {
      pos: [3, 2, 3],
      state: 13
    },
    {
      pos: [5, 2, 3],
      state: 13
    },
    {
      pos: [3, 3, 3],
      state: 13
    },
    {
      pos: [5, 3, 3],
      state: 13
    },
    {
      pos: [3, 4, 3],
      state: 14
    },
    {
      pos: [4, 4, 3],
      state: 15
    },
    {
      pos: [5, 4, 3],
      state: 16
    },
    {
      pos: [0, 0, 4],
      state: 10
    },
    {
      pos: [1, 0, 4],
      state: 10
    },
    {
      pos: [7, 0, 4],
      state: 10
    },
    {
      pos: [8, 0, 4],
      state: 10
    },
    {
      pos: [3, 1, 4],
      state: 12
    },
    {
      pos: [4, 1, 4],
      state: 12
    },
    {
      pos: [5, 1, 4],
      state: 12
    },
    {
      pos: [2, 2, 4],
      state: 11
    },
    {
      pos: [6, 2, 4],
      state: 11
    },
    {
      pos: [3, 4, 4],
      state: 17
    },
    {
      pos: [5, 4, 4],
      state: 18
    },
    {
      pos: [0, 0, 5],
      state: 10
    },
    {
      pos: [1, 0, 5],
      state: 10
    },
    {
      pos: [7, 0, 5],
      state: 10
    },
    {
      pos: [8, 0, 5],
      state: 10
    },
    {
      pos: [4, 1, 5],
      state: 12
    },
    {
      pos: [3, 2, 5],
      state: 13
    },
    {
      pos: [5, 2, 5],
      state: 13
    },
    {
      pos: [3, 3, 5],
      state: 13
    },
    {
      pos: [5, 3, 5],
      state: 13
    },
    {
      pos: [3, 4, 5],
      state: 19
    },
    {
      pos: [4, 4, 5],
      state: 20
    },
    {
      pos: [5, 4, 5],
      state: 21
    },
    {
      pos: [1, 0, 6],
      state: 10
    },
    {
      pos: [2, 0, 6],
      state: 10
    },
    {
      pos: [6, 0, 6],
      state: 10
    },
    {
      pos: [7, 0, 6],
      state: 10
    },
    {
      pos: [4, 2, 6],
      state: 11
    },
    {
      pos: [1, 0, 7],
      state: 10
    },
    {
      pos: [2, 0, 7],
      state: 10
    },
    {
      pos: [3, 0, 7],
      state: 10
    },
    {
      pos: [4, 0, 7],
      state: 10
    },
    {
      pos: [5, 0, 7],
      state: 10
    },
    {
      pos: [6, 0, 7],
      state: 10
    },
    {
      pos: [7, 0, 7],
      state: 10
    },
    {
      pos: [3, 0, 8],
      state: 10
    },
    {
      pos: [4, 0, 8],
      state: 10
    },
    {
      pos: [5, 0, 8],
      state: 10
    }
  ],
  palette: [
    {
      Name: "minecraft:dirt"
    },
    {
      Properties: {
        axis: "y"
      },
      Name: "minecraft:acacia_wood"
    },
    {
      Properties: {
        waterlogged: "false",
        type: "double"
      },
      Name: "minecraft:acacia_slab"
    },
    {
      Properties: {
        snowy: "false"
      },
      Name: "minecraft:grass_block"
    },
    {
      Properties: {
        axis: "z"
      },
      Name: "minecraft:acacia_wood"
    },
    {
      Properties: {
        facing: "north"
      },
      Name: "minecraft:jigsaw"
    },
    {
      Properties: {
        facing: "west"
      },
      Name: "minecraft:jigsaw"
    },
    {
      Properties: {
        facing: "east"
      },
      Name: "minecraft:jigsaw"
    },
    {
      Properties: {
        face: "ceiling",
        facing: "north"
      },
      Name: "minecraft:bell"
    },
    {
      Properties: {
        facing: "south"
      },
      Name: "minecraft:jigsaw"
    },
    {
      Name: "minecraft:grass_path"
    },
    {
      Name: "minecraft:torch"
    },
    {
      Properties: {
        level: "0"
      },
      Name: "minecraft:water"
    },
    {
      Properties: {
        east: "false",
        waterlogged: "false",
        south: "false",
        north: "false",
        west: "false"
      },
      Name: "minecraft:acacia_fence"
    },
    {
      Properties: {
        half: "bottom",
        waterlogged: "false",
        shape: "outer_right",
        facing: "east"
      },
      Name: "minecraft:acacia_stairs"
    },
    {
      Properties: {
        half: "bottom",
        waterlogged: "false",
        shape: "straight",
        facing: "south"
      },
      Name: "minecraft:acacia_stairs"
    },
    {
      Properties: {
        half: "bottom",
        waterlogged: "false",
        shape: "outer_right",
        facing: "south"
      },
      Name: "minecraft:acacia_stairs"
    },
    {
      Properties: {
        half: "bottom",
        waterlogged: "false",
        shape: "straight",
        facing: "east"
      },
      Name: "minecraft:acacia_stairs"
    },
    {
      Properties: {
        half: "bottom",
        waterlogged: "false",
        shape: "straight",
        facing: "west"
      },
      Name: "minecraft:acacia_stairs"
    },
    {
      Properties: {
        half: "bottom",
        waterlogged: "false",
        shape: "outer_left",
        facing: "east"
      },
      Name: "minecraft:acacia_stairs"
    },
    {
      Properties: {
        half: "bottom",
        waterlogged: "false",
        shape: "straight",
        facing: "north"
      },
      Name: "minecraft:acacia_stairs"
    },
    {
      Properties: {
        half: "bottom",
        waterlogged: "false",
        shape: "outer_right",
        facing: "west"
      },
      Name: "minecraft:acacia_stairs"
    }
  ],
  DataVersion: 1915
}