{
  size: [11, 4, 13],
  entities: [],
  blocks: [
    {
      pos: [0, 0, 0],
      state: 0
    },
    {
      pos: [1, 0, 0],
      state: 0
    },
    {
      pos: [2, 0, 0],
      state: 0
    },
    {
      pos: [3, 0, 0],
      state: 0
    },
    {
      pos: [4, 0, 0],
      state: 0
    },
    {
      pos: [5, 0, 0],
      state: 0
    },
    {
      pos: [6, 0, 0],
      state: 0
    },
    {
      pos: [7, 0, 0],
      state: 0
    },
    {
      pos: [8, 0, 0],
      state: 0
    },
    {
      pos: [9, 0, 0],
      state: 0
    },
    {
      pos: [10, 0, 0],
      state: 0
    },
    {
      pos: [0, 0, 1],
      state: 0
    },
    {
      pos: [1, 0, 1],
      state: 0
    },
    {
      pos: [2, 0, 1],
      state: 0
    },
    {
      pos: [3, 0, 1],
      state: 0
    },
    {
      pos: [4, 0, 1],
      state: 0
    },
    {
      pos: [5, 0, 1],
      state: 0
    },
    {
      pos: [6, 0, 1],
      state: 0
    },
    {
      pos: [7, 0, 1],
      state: 0
    },
    {
      pos: [8, 0, 1],
      state: 0
    },
    {
      pos: [9, 0, 1],
      state: 0
    },
    {
      pos: [10, 0, 1],
      state: 0
    },
    {
      pos: [3, 1, 1],
      state: 0
    },
    {
      pos: [4, 1, 1],
      state: 0
    },
    {
      pos: [5, 1, 1],
      state: 0
    },
    {
      pos: [6, 1, 1],
      state: 0
    },
    {
      pos: [7, 1, 1],
      state: 0
    },
    {
      pos: [8, 1, 1],
      state: 0
    },
    {
      pos: [9, 1, 1],
      state: 0
    },
    {
      pos: [3, 2, 1],
      state: 1
    },
    {
      pos: [5, 2, 1],
      state: 2
    },
    {
      pos: [8, 2, 1],
      state: 3
    },
    {
      pos: [0, 0, 2],
      state: 0
    },
    {
      pos: [1, 0, 2],
      state: 0
    },
    {
      pos: [2, 0, 2],
      state: 0
    },
    {
      pos: [3, 0, 2],
      state: 0
    },
    {
      pos: [4, 0, 2],
      state: 0
    },
    {
      pos: [5, 0, 2],
      state: 0
    },
    {
      pos: [6, 0, 2],
      state: 0
    },
    {
      pos: [7, 0, 2],
      state: 0
    },
    {
      pos: [8, 0, 2],
      state: 0
    },
    {
      pos: [9, 0, 2],
      state: 0
    },
    {
      pos: [10, 0, 2],
      state: 0
    },
    {
      pos: [0, 1, 2],
      state: 0
    },
    {
      pos: [1, 1, 2],
      state: 0
    },
    {
      pos: [2, 1, 2],
      state: 0
    },
    {
      pos: [3, 1, 2],
      state: 0
    },
    {
      pos: [4, 1, 2],
      state: 0
    },
    {
      pos: [5, 1, 2],
      state: 0
    },
    {
      pos: [6, 1, 2],
      state: 0
    },
    {
      pos: [7, 1, 2],
      state: 0
    },
    {
      pos: [8, 1, 2],
      state: 3
    },
    {
      pos: [9, 1, 2],
      state: 0
    },
    {
      pos: [10, 1, 2],
      state: 0
    },
    {
      pos: [0, 2, 2],
      state: 1
    },
    {
      pos: [4, 2, 2],
      state: 1
    },
    {
      pos: [7, 2, 2],
      state: 3
    },
    {
      pos: [9, 2, 2],
      state: 3
    },
    {
      pos: [4, 3, 2],
      state: 2
    },
    {
      pos: [0, 0, 3],
      state: 0
    },
    {
      pos: [1, 0, 3],
      state: 0
    },
    {
      pos: [2, 0, 3],
      state: 0
    },
    {
      pos: [3, 0, 3],
      state: 0
    },
    {
      pos: [4, 0, 3],
      state: 0
    },
    {
      pos: [5, 0, 3],
      state: 0
    },
    {
      pos: [6, 0, 3],
      state: 0
    },
    {
      pos: [7, 0, 3],
      state: 0
    },
    {
      pos: [8, 0, 3],
      state: 0
    },
    {
      pos: [9, 0, 3],
      state: 0
    },
    {
      pos: [10, 0, 3],
      state: 0
    },
    {
      pos: [1, 1, 3],
      state: 0
    },
    {
      pos: [3, 1, 3],
      state: 0
    },
    {
      pos: [4, 1, 3],
      state: 0
    },
    {
      pos: [5, 1, 3],
      state: 0
    },
    {
      pos: [7, 1, 3],
      state: 0
    },
    {
      pos: [8, 1, 3],
      state: 3
    },
    {
      pos: [9, 1, 3],
      state: 0
    },
    {
      pos: [10, 1, 3],
      state: 0
    },
    {
      pos: [3, 2, 3],
      state: 4
    },
    {
      pos: [7, 2, 3],
      state: 3
    },
    {
      pos: [9, 2, 3],
      state: 3
    },
    {
      pos: [0, 0, 4],
      state: 0
    },
    {
      pos: [1, 0, 4],
      state: 0
    },
    {
      pos: [2, 0, 4],
      state: 0
    },
    {
      pos: [3, 0, 4],
      state: 0
    },
    {
      pos: [4, 0, 4],
      state: 0
    },
    {
      pos: [5, 0, 4],
      state: 0
    },
    {
      pos: [6, 0, 4],
      state: 0
    },
    {
      pos: [7, 0, 4],
      state: 0
    },
    {
      pos: [8, 0, 4],
      state: 0
    },
    {
      pos: [9, 0, 4],
      state: 0
    },
    {
      pos: [10, 0, 4],
      state: 0
    },
    {
      pos: [1, 1, 4],
      state: 0
    },
    {
      pos: [4, 1, 4],
      state: 0
    },
    {
      pos: [7, 1, 4],
      state: 0
    },
    {
      pos: [8, 1, 4],
      state: 3
    },
    {
      pos: [9, 1, 4],
      state: 0
    },
    {
      pos: [10, 1, 4],
      state: 0
    },
    {
      pos: [4, 2, 4],
      state: 1
    },
    {
      pos: [7, 2, 4],
      state: 3
    },
    {
      pos: [9, 2, 4],
      state: 3
    },
    {
      pos: [0, 0, 5],
      state: 0
    },
    {
      pos: [1, 0, 5],
      state: 0
    },
    {
      pos: [2, 0, 5],
      state: 0
    },
    {
      pos: [3, 0, 5],
      state: 0
    },
    {
      pos: [4, 0, 5],
      state: 0
    },
    {
      pos: [5, 0, 5],
      state: 0
    },
    {
      pos: [6, 0, 5],
      state: 0
    },
    {
      pos: [7, 0, 5],
      state: 0
    },
    {
      pos: [8, 0, 5],
      state: 0
    },
    {
      pos: [9, 0, 5],
      state: 0
    },
    {
      pos: [10, 0, 5],
      state: 0
    },
    {
      pos: [0, 1, 5],
      state: 0
    },
    {
      pos: [7, 1, 5],
      state: 0
    },
    {
      pos: [8, 1, 5],
      state: 0
    },
    {
      pos: [9, 1, 5],
      state: 0
    },
    {
      pos: [10, 1, 5],
      state: 0
    },
    {
      pos: [8, 2, 5],
      state: 3
    },
    {
      pos: [0, 0, 6],
      state: 0
    },
    {
      pos: [1, 0, 6],
      state: 0
    },
    {
      pos: [2, 0, 6],
      state: 0
    },
    {
      pos: [3, 0, 6],
      state: 0
    },
    {
      pos: [4, 0, 6],
      state: 0
    },
    {
      pos: [5, 0, 6],
      state: 0
    },
    {
      pos: [6, 0, 6],
      state: 0
    },
    {
      pos: [7, 0, 6],
      state: 0
    },
    {
      pos: [8, 0, 6],
      state: 0
    },
    {
      pos: [9, 0, 6],
      state: 0
    },
    {
      pos: [10, 0, 6],
      state: 0
    },
    {
      pos: [0, 1, 6],
      state: 0
    },
    {
      pos: [7, 1, 6],
      state: 0
    },
    {
      pos: [9, 1, 6],
      state: 0
    },
    {
      pos: [10, 1, 6],
      state: 0
    },
    {
      pos: [9, 2, 6],
      state: 4
    },
    {
      pos: [0, 0, 7],
      state: 0
    },
    {
      pos: [1, 0, 7],
      state: 0
    },
    {
      pos: [2, 0, 7],
      state: 0
    },
    {
      pos: [3, 0, 7],
      state: 0
    },
    {
      pos: [4, 0, 7],
      state: 0
    },
    {
      pos: [5, 0, 7],
      state: 0
    },
    {
      pos: [6, 0, 7],
      state: 0
    },
    {
      pos: [7, 0, 7],
      state: 0
    },
    {
      pos: [8, 0, 7],
      state: 0
    },
    {
      pos: [9, 0, 7],
      state: 0
    },
    {
      pos: [10, 0, 7],
      state: 0
    },
    {
      pos: [0, 1, 7],
      state: 0
    },
    {
      pos: [9, 1, 7],
      state: 0
    },
    {
      pos: [10, 1, 7],
      state: 0
    },
    {
      pos: [10, 2, 7],
      state: 2
    },
    {
      pos: [0, 0, 8],
      state: 0
    },
    {
      pos: [1, 0, 8],
      state: 0
    },
    {
      pos: [2, 0, 8],
      state: 0
    },
    {
      pos: [3, 0, 8],
      state: 0
    },
    {
      pos: [4, 0, 8],
      state: 0
    },
    {
      pos: [5, 0, 8],
      state: 0
    },
    {
      pos: [6, 0, 8],
      state: 0
    },
    {
      pos: [7, 0, 8],
      state: 0
    },
    {
      pos: [8, 0, 8],
      state: 0
    },
    {
      pos: [9, 0, 8],
      state: 0
    },
    {
      pos: [10, 0, 8],
      state: 0
    },
    {
      pos: [1, 1, 8],
      state: 0
    },
    {
      pos: [9, 1, 8],
      state: 0
    },
    {
      pos: [10, 1, 8],
      state: 0
    },
    {
      pos: [0, 0, 9],
      state: 0
    },
    {
      pos: [1, 0, 9],
      state: 0
    },
    {
      pos: [2, 0, 9],
      state: 0
    },
    {
      pos: [3, 0, 9],
      state: 0
    },
    {
      pos: [4, 0, 9],
      state: 0
    },
    {
      pos: [5, 0, 9],
      state: 0
    },
    {
      pos: [6, 0, 9],
      state: 0
    },
    {
      pos: [7, 0, 9],
      state: 0
    },
    {
      pos: [8, 0, 9],
      state: 0
    },
    {
      pos: [9, 0, 9],
      state: 0
    },
    {
      pos: [10, 0, 9],
      state: 0
    },
    {
      pos: [1, 1, 9],
      state: 0
    },
    {
      pos: [3, 1, 9],
      state: 0
    },
    {
      pos: [5, 1, 9],
      state: 0
    },
    {
      pos: [9, 1, 9],
      state: 0
    },
    {
      pos: [10, 1, 9],
      state: 0
    },
    {
      pos: [3, 2, 9],
      state: 1
    },
    {
      pos: [9, 2, 9],
      state: 1
    },
    {
      pos: [0, 0, 10],
      state: 0
    },
    {
      pos: [1, 0, 10],
      state: 0
    },
    {
      pos: [2, 0, 10],
      state: 0
    },
    {
      pos: [3, 0, 10],
      state: 0
    },
    {
      pos: [4, 0, 10],
      state: 0
    },
    {
      pos: [5, 0, 10],
      state: 0
    },
    {
      pos: [6, 0, 10],
      state: 0
    },
    {
      pos: [7, 0, 10],
      state: 0
    },
    {
      pos: [8, 0, 10],
      state: 0
    },
    {
      pos: [9, 0, 10],
      state: 0
    },
    {
      pos: [10, 0, 10],
      state: 0
    },
    {
      pos: [1, 1, 10],
      state: 0
    },
    {
      pos: [2, 1, 10],
      state: 0
    },
    {
      pos: [3, 1, 10],
      state: 0
    },
    {
      pos: [4, 1, 10],
      state: 0
    },
    {
      pos: [5, 1, 10],
      state: 0
    },
    {
      pos: [8, 1, 10],
      state: 0
    },
    {
      pos: [9, 1, 10],
      state: 0
    },
    {
      pos: [4, 2, 10],
      state: 4
    },
    {
      pos: [5, 2, 10],
      state: 2
    },
    {
      pos: [0, 0, 11],
      state: 0
    },
    {
      pos: [1, 0, 11],
      state: 0
    },
    {
      pos: [2, 0, 11],
      state: 0
    },
    {
      pos: [3, 0, 11],
      state: 0
    },
    {
      pos: [4, 0, 11],
      state: 0
    },
    {
      pos: [5, 0, 11],
      state: 0
    },
    {
      pos: [6, 0, 11],
      state: 0
    },
    {
      pos: [7, 0, 11],
      state: 0
    },
    {
      pos: [8, 0, 11],
      state: 0
    },
    {
      pos: [9, 0, 11],
      state: 0
    },
    {
      pos: [10, 0, 11],
      state: 0
    },
    {
      pos: [2, 1, 11],
      state: 0
    },
    {
      pos: [3, 1, 11],
      state: 0
    },
    {
      pos: [4, 1, 11],
      state: 0
    },
    {
      pos: [5, 1, 11],
      state: 0
    },
    {
      pos: [6, 1, 11],
      state: 0
    },
    {
      pos: [8, 1, 11],
      state: 0
    },
    {
      pos: [3, 2, 11],
      state: 2
    },
    {
      pos: [4, 2, 11],
      state: 2
    },
    {
      pos: [4, 3, 11],
      state: 1
    },
    {
      pos: [0, 0, 12],
      state: 0
    },
    {
      pos: [1, 0, 12],
      state: 0
    },
    {
      pos: [2, 0, 12],
      state: 0
    },
    {
      pos: [3, 0, 12],
      state: 0
    },
    {
      pos: [4, 0, 12],
      state: 0
    },
    {
      pos: [5, 0, 12],
      state: 0
    },
    {
      pos: [6, 0, 12],
      state: 0
    },
    {
      pos: [7, 0, 12],
      state: 0
    },
    {
      pos: [8, 0, 12],
      state: 0
    },
    {
      pos: [9, 0, 12],
      state: 0
    },
    {
      pos: [10, 0, 12],
      state: 0
    },
    {
      pos: [2, 1, 12],
      state: 0
    },
    {
      pos: [3, 1, 12],
      state: 0
    },
    {
      pos: [4, 1, 12],
      state: 0
    },
    {
      pos: [5, 1, 12],
      state: 0
    },
    {
      pos: [6, 1, 12],
      state: 0
    },
    {
      pos: [7, 1, 12],
      state: 0
    },
    {
      pos: [8, 1, 12],
      state: 0
    },
    {
      pos: [2, 2, 12],
      state: 4
    },
    {
      pos: [4, 2, 12],
      state: 1
    },
    {
      pos: [5, 2, 12],
      state: 2
    },
    {
      pos: [7, 2, 12],
      state: 1
    },
    {
      nbt: {
        target_pool: "minecraft:empty",
        final_state: "minecraft:air",
        id: "minecraft:jigsaw",
        attachement_type: "minecraft:building_entrance"
      },
      pos: [0, 2, 6],
      state: 5
    },
    {
      nbt: {
        target_pool: "minecraft:empty",
        final_state: "minecraft:air",
        id: "minecraft:jigsaw",
        attachement_type: "minecraft:empty"
      },
      pos: [0, 2, 7],
      state: 6
    },
    {
      pos: [0, 2, 0],
      state: 6
    },
    {
      pos: [1, 2, 0],
      state: 6
    },
    {
      pos: [2, 2, 0],
      state: 6
    },
    {
      pos: [3, 2, 0],
      state: 6
    },
    {
      pos: [4, 2, 0],
      state: 6
    },
    {
      pos: [5, 2, 0],
      state: 6
    },
    {
      pos: [6, 2, 0],
      state: 6
    },
    {
      pos: [7, 2, 0],
      state: 6
    },
    {
      pos: [8, 2, 0],
      state: 6
    },
    {
      pos: [9, 2, 0],
      state: 6
    },
    {
      pos: [10, 2, 0],
      state: 6
    },
    {
      pos: [0, 3, 0],
      state: 6
    },
    {
      pos: [1, 3, 0],
      state: 6
    },
    {
      pos: [2, 3, 0],
      state: 6
    },
    {
      pos: [3, 3, 0],
      state: 6
    },
    {
      pos: [4, 3, 0],
      state: 6
    },
    {
      pos: [5, 3, 0],
      state: 6
    },
    {
      pos: [6, 3, 0],
      state: 6
    },
    {
      pos: [7, 3, 0],
      state: 6
    },
    {
      pos: [8, 3, 0],
      state: 6
    },
    {
      pos: [9, 3, 0],
      state: 6
    },
    {
      pos: [10, 3, 0],
      state: 6
    },
    {
      pos: [0, 2, 1],
      state: 6
    },
    {
      pos: [1, 2, 1],
      state: 6
    },
    {
      pos: [2, 2, 1],
      state: 6
    },
    {
      pos: [4, 2, 1],
      state: 6
    },
    {
      pos: [6, 2, 1],
      state: 6
    },
    {
      pos: [7, 2, 1],
      state: 7
    },
    {
      pos: [9, 2, 1],
      state: 8
    },
    {
      pos: [10, 2, 1],
      state: 6
    },
    {
      pos: [0, 3, 1],
      state: 6
    },
    {
      pos: [1, 3, 1],
      state: 6
    },
    {
      pos: [2, 3, 1],
      state: 6
    },
    {
      pos: [3, 3, 1],
      state: 6
    },
    {
      pos: [4, 3, 1],
      state: 6
    },
    {
      pos: [5, 3, 1],
      state: 6
    },
    {
      pos: [6, 3, 1],
      state: 6
    },
    {
      pos: [7, 3, 1],
      state: 6
    },
    {
      pos: [8, 3, 1],
      state: 6
    },
    {
      pos: [9, 3, 1],
      state: 6
    },
    {
      pos: [10, 3, 1],
      state: 6
    },
    {
      pos: [1, 2, 2],
      state: 6
    },
    {
      pos: [2, 2, 2],
      state: 6
    },
    {
      pos: [3, 2, 2],
      state: 6
    },
    {
      pos: [5, 2, 2],
      state: 6
    },
    {
      pos: [6, 2, 2],
      state: 6
    },
    {
      pos: [8, 2, 2],
      state: 9
    },
    {
      pos: [10, 2, 2],
      state: 6
    },
    {
      pos: [0, 3, 2],
      state: 6
    },
    {
      pos: [1, 3, 2],
      state: 6
    },
    {
      pos: [2, 3, 2],
      state: 6
    },
    {
      pos: [3, 3, 2],
      state: 6
    },
    {
      pos: [5, 3, 2],
      state: 6
    },
    {
      pos: [6, 3, 2],
      state: 6
    },
    {
      pos: [7, 3, 2],
      state: 6
    },
    {
      pos: [8, 3, 2],
      state: 6
    },
    {
      pos: [9, 3, 2],
      state: 6
    },
    {
      pos: [10, 3, 2],
      state: 6
    },
    {
      pos: [2, 1, 3],
      state: 10
    },
    {
      pos: [6, 1, 3],
      state: 10
    },
    {
      pos: [0, 2, 3],
      state: 6
    },
    {
      pos: [1, 2, 3],
      state: 6
    },
    {
      pos: [2, 2, 3],
      state: 11
    },
    {
      pos: [4, 2, 3],
      state: 6
    },
    {
      pos: [5, 2, 3],
      state: 6
    },
    {
      pos: [6, 2, 3],
      state: 12
    },
    {
      pos: [8, 2, 3],
      state: 9
    },
    {
      pos: [10, 2, 3],
      state: 6
    },
    {
      pos: [0, 3, 3],
      state: 6
    },
    {
      pos: [1, 3, 3],
      state: 6
    },
    {
      pos: [2, 3, 3],
      state: 6
    },
    {
      pos: [3, 3, 3],
      state: 6
    },
    {
      pos: [4, 3, 3],
      state: 6
    },
    {
      pos: [5, 3, 3],
      state: 6
    },
    {
      pos: [6, 3, 3],
      state: 6
    },
    {
      pos: [7, 3, 3],
      state: 6
    },
    {
      pos: [8, 3, 3],
      state: 6
    },
    {
      pos: [9, 3, 3],
      state: 6
    },
    {
      pos: [10, 3, 3],
      state: 6
    },
    {
      pos: [2, 1, 4],
      state: 10
    },
    {
      pos: [3, 1, 4],
      state: 10
    },
    {
      pos: [5, 1, 4],
      state: 10
    },
    {
      pos: [6, 1, 4],
      state: 10
    },
    {
      pos: [0, 2, 4],
      state: 6
    },
    {
      pos: [1, 2, 4],
      state: 6
    },
    {
      pos: [2, 2, 4],
      state: 11
    },
    {
      pos: [3, 2, 4],
      state: 12
    },
    {
      pos: [5, 2, 4],
      state: 12
    },
    {
      pos: [6, 2, 4],
      state: 12
    },
    {
      pos: [8, 2, 4],
      state: 9
    },
    {
      pos: [10, 2, 4],
      state: 6
    },
    {
      pos: [0, 3, 4],
      state: 6
    },
    {
      pos: [1, 3, 4],
      state: 6
    },
    {
      pos: [2, 3, 4],
      state: 6
    },
    {
      pos: [3, 3, 4],
      state: 6
    },
    {
      pos: [4, 3, 4],
      state: 6
    },
    {
      pos: [5, 3, 4],
      state: 6
    },
    {
      pos: [6, 3, 4],
      state: 6
    },
    {
      pos: [7, 3, 4],
      state: 6
    },
    {
      pos: [8, 3, 4],
      state: 6
    },
    {
      pos: [9, 3, 4],
      state: 6
    },
    {
      pos: [10, 3, 4],
      state: 6
    },
    {
      pos: [1, 1, 5],
      state: 10
    },
    {
      pos: [2, 1, 5],
      state: 10
    },
    {
      pos: [3, 1, 5],
      state: 10
    },
    {
      pos: [4, 1, 5],
      state: 10
    },
    {
      pos: [5, 1, 5],
      state: 10
    },
    {
      pos: [6, 1, 5],
      state: 10
    },
    {
      pos: [0, 2, 5],
      state: 6
    },
    {
      pos: [1, 2, 5],
      state: 11
    },
    {
      pos: [2, 2, 5],
      state: 13
    },
    {
      pos: [3, 2, 5],
      state: 11
    },
    {
      pos: [4, 2, 5],
      state: 12
    },
    {
      pos: [5, 2, 5],
      state: 12
    },
    {
      pos: [6, 2, 5],
      state: 12
    },
    {
      pos: [7, 2, 5],
      state: 14
    },
    {
      pos: [9, 2, 5],
      state: 15
    },
    {
      pos: [10, 2, 5],
      state: 6
    },
    {
      pos: [0, 3, 5],
      state: 6
    },
    {
      pos: [1, 3, 5],
      state: 6
    },
    {
      pos: [2, 3, 5],
      state: 6
    },
    {
      pos: [3, 3, 5],
      state: 6
    },
    {
      pos: [4, 3, 5],
      state: 6
    },
    {
      pos: [5, 3, 5],
      state: 6
    },
    {
      pos: [6, 3, 5],
      state: 6
    },
    {
      pos: [7, 3, 5],
      state: 6
    },
    {
      pos: [8, 3, 5],
      state: 6
    },
    {
      pos: [9, 3, 5],
      state: 6
    },
    {
      pos: [10, 3, 5],
      state: 6
    },
    {
      pos: [1, 1, 6],
      state: 10
    },
    {
      pos: [2, 1, 6],
      state: 9
    },
    {
      pos: [3, 1, 6],
      state: 10
    },
    {
      pos: [4, 1, 6],
      state: 10
    },
    {
      pos: [5, 1, 6],
      state: 10
    },
    {
      pos: [6, 1, 6],
      state: 10
    },
    {
      pos: [8, 1, 6],
      state: 10
    },
    {
      pos: [1, 2, 6],
      state: 13
    },
    {
      pos: [2, 2, 6],
      state: 6
    },
    {
      pos: [3, 2, 6],
      state: 16
    },
    {
      pos: [4, 2, 6],
      state: 12
    },
    {
      pos: [5, 2, 6],
      state: 12
    },
    {
      pos: [6, 2, 6],
      state: 12
    },
    {
      pos: [7, 2, 6],
      state: 6
    },
    {
      pos: [8, 2, 6],
      state: 17
    },
    {
      pos: [10, 2, 6],
      state: 6
    },
    {
      pos: [0, 3, 6],
      state: 6
    },
    {
      pos: [1, 3, 6],
      state: 6
    },
    {
      pos: [2, 3, 6],
      state: 6
    },
    {
      pos: [3, 3, 6],
      state: 6
    },
    {
      pos: [4, 3, 6],
      state: 6
    },
    {
      pos: [5, 3, 6],
      state: 6
    },
    {
      pos: [6, 3, 6],
      state: 6
    },
    {
      pos: [7, 3, 6],
      state: 6
    },
    {
      pos: [8, 3, 6],
      state: 6
    },
    {
      pos: [9, 3, 6],
      state: 6
    },
    {
      pos: [10, 3, 6],
      state: 6
    },
    {
      pos: [1, 1, 7],
      state: 10
    },
    {
      pos: [2, 1, 7],
      state: 10
    },
    {
      pos: [3, 1, 7],
      state: 10
    },
    {
      pos: [4, 1, 7],
      state: 10
    },
    {
      pos: [5, 1, 7],
      state: 10
    },
    {
      pos: [6, 1, 7],
      state: 10
    },
    {
      pos: [7, 1, 7],
      state: 10
    },
    {
      pos: [8, 1, 7],
      state: 10
    },
    {
      pos: [1, 2, 7],
      state: 11
    },
    {
      pos: [2, 2, 7],
      state: 11
    },
    {
      pos: [3, 2, 7],
      state: 11
    },
    {
      pos: [4, 2, 7],
      state: 12
    },
    {
      pos: [5, 2, 7],
      state: 12
    },
    {
      pos: [6, 2, 7],
      state: 18
    },
    {
      pos: [7, 2, 7],
      state: 12
    },
    {
      pos: [8, 2, 7],
      state: 19
    },
    {
      pos: [9, 2, 7],
      state: 6
    },
    {
      pos: [0, 3, 7],
      state: 6
    },
    {
      pos: [1, 3, 7],
      state: 6
    },
    {
      pos: [2, 3, 7],
      state: 6
    },
    {
      pos: [3, 3, 7],
      state: 6
    },
    {
      pos: [4, 3, 7],
      state: 6
    },
    {
      pos: [5, 3, 7],
      state: 6
    },
    {
      pos: [6, 3, 7],
      state: 6
    },
    {
      pos: [7, 3, 7],
      state: 6
    },
    {
      pos: [8, 3, 7],
      state: 6
    },
    {
      pos: [9, 3, 7],
      state: 6
    },
    {
      pos: [10, 3, 7],
      state: 6
    },
    {
      pos: [2, 1, 8],
      state: 10
    },
    {
      pos: [3, 1, 8],
      state: 10
    },
    {
      pos: [4, 1, 8],
      state: 10
    },
    {
      pos: [5, 1, 8],
      state: 10
    },
    {
      pos: [6, 1, 8],
      state: 10
    },
    {
      pos: [7, 1, 8],
      state: 9
    },
    {
      pos: [8, 1, 8],
      state: 10
    },
    {
      pos: [0, 2, 8],
      state: 6
    },
    {
      pos: [1, 2, 8],
      state: 6
    },
    {
      pos: [2, 2, 8],
      state: 11
    },
    {
      pos: [3, 2, 8],
      state: 11
    },
    {
      pos: [4, 2, 8],
      state: 17
    },
    {
      pos: [5, 2, 8],
      state: 12
    },
    {
      pos: [6, 2, 8],
      state: 18
    },
    {
      pos: [7, 2, 8],
      state: 6
    },
    {
      pos: [8, 2, 8],
      state: 12
    },
    {
      pos: [9, 2, 8],
      state: 6
    },
    {
      pos: [10, 2, 8],
      state: 6
    },
    {
      pos: [0, 3, 8],
      state: 6
    },
    {
      pos: [1, 3, 8],
      state: 6
    },
    {
      pos: [2, 3, 8],
      state: 6
    },
    {
      pos: [3, 3, 8],
      state: 6
    },
    {
      pos: [4, 3, 8],
      state: 6
    },
    {
      pos: [5, 3, 8],
      state: 6
    },
    {
      pos: [6, 3, 8],
      state: 6
    },
    {
      pos: [7, 3, 8],
      state: 6
    },
    {
      pos: [8, 3, 8],
      state: 6
    },
    {
      pos: [9, 3, 8],
      state: 6
    },
    {
      pos: [10, 3, 8],
      state: 6
    },
    {
      pos: [2, 1, 9],
      state: 10
    },
    {
      pos: [4, 1, 9],
      state: 10
    },
    {
      pos: [6, 1, 9],
      state: 10
    },
    {
      pos: [7, 1, 9],
      state: 10
    },
    {
      pos: [8, 1, 9],
      state: 10
    },
    {
      pos: [0, 2, 9],
      state: 6
    },
    {
      pos: [1, 2, 9],
      state: 6
    },
    {
      pos: [2, 2, 9],
      state: 12
    },
    {
      pos: [4, 2, 9],
      state: 17
    },
    {
      pos: [5, 2, 9],
      state: 6
    },
    {
      pos: [6, 2, 9],
      state: 12
    },
    {
      pos: [7, 2, 9],
      state: 12
    },
    {
      pos: [8, 2, 9],
      state: 17
    },
    {
      pos: [10, 2, 9],
      state: 6
    },
    {
      pos: [0, 3, 9],
      state: 6
    },
    {
      pos: [1, 3, 9],
      state: 6
    },
    {
      pos: [2, 3, 9],
      state: 6
    },
    {
      pos: [3, 3, 9],
      state: 6
    },
    {
      pos: [4, 3, 9],
      state: 6
    },
    {
      pos: [5, 3, 9],
      state: 6
    },
    {
      pos: [6, 3, 9],
      state: 6
    },
    {
      pos: [7, 3, 9],
      state: 6
    },
    {
      pos: [8, 3, 9],
      state: 6
    },
    {
      pos: [9, 3, 9],
      state: 6
    },
    {
      pos: [10, 3, 9],
      state: 6
    },
    {
      pos: [6, 1, 10],
      state: 10
    },
    {
      pos: [7, 1, 10],
      state: 10
    },
    {
      pos: [0, 2, 10],
      state: 6
    },
    {
      pos: [1, 2, 10],
      state: 6
    },
    {
      pos: [2, 2, 10],
      state: 6
    },
    {
      pos: [3, 2, 10],
      state: 6
    },
    {
      pos: [6, 2, 10],
      state: 16
    },
    {
      pos: [7, 2, 10],
      state: 12
    },
    {
      pos: [8, 2, 10],
      state: 6
    },
    {
      pos: [9, 2, 10],
      state: 6
    },
    {
      pos: [10, 2, 10],
      state: 6
    },
    {
      pos: [0, 3, 10],
      state: 6
    },
    {
      pos: [1, 3, 10],
      state: 6
    },
    {
      pos: [2, 3, 10],
      state: 6
    },
    {
      pos: [3, 3, 10],
      state: 6
    },
    {
      pos: [4, 3, 10],
      state: 6
    },
    {
      pos: [5, 3, 10],
      state: 6
    },
    {
      pos: [6, 3, 10],
      state: 6
    },
    {
      pos: [7, 3, 10],
      state: 6
    },
    {
      pos: [8, 3, 10],
      state: 6
    },
    {
      pos: [9, 3, 10],
      state: 6
    },
    {
      pos: [10, 3, 10],
      state: 6
    },
    {
      pos: [7, 1, 11],
      state: 10
    },
    {
      pos: [0, 2, 11],
      state: 6
    },
    {
      pos: [1, 2, 11],
      state: 6
    },
    {
      pos: [2, 2, 11],
      state: 6
    },
    {
      pos: [5, 2, 11],
      state: 6
    },
    {
      pos: [6, 2, 11],
      state: 6
    },
    {
      pos: [7, 2, 11],
      state: 18
    },
    {
      pos: [8, 2, 11],
      state: 6
    },
    {
      pos: [9, 2, 11],
      state: 6
    },
    {
      pos: [10, 2, 11],
      state: 6
    },
    {
      pos: [0, 3, 11],
      state: 6
    },
    {
      pos: [1, 3, 11],
      state: 6
    },
    {
      pos: [2, 3, 11],
      state: 6
    },
    {
      pos: [3, 3, 11],
      state: 6
    },
    {
      pos: [5, 3, 11],
      state: 6
    },
    {
      pos: [6, 3, 11],
      state: 6
    },
    {
      pos: [7, 3, 11],
      state: 6
    },
    {
      pos: [8, 3, 11],
      state: 6
    },
    {
      pos: [9, 3, 11],
      state: 6
    },
    {
      pos: [10, 3, 11],
      state: 6
    },
    {
      pos: [0, 2, 12],
      state: 6
    },
    {
      pos: [1, 2, 12],
      state: 6
    },
    {
      pos: [3, 2, 12],
      state: 6
    },
    {
      pos: [6, 2, 12],
      state: 6
    },
    {
      pos: [8, 2, 12],
      state: 6
    },
    {
      pos: [9, 2, 12],
      state: 6
    },
    {
      pos: [10, 2, 12],
      state: 6
    },
    {
      pos: [0, 3, 12],
      state: 6
    },
    {
      pos: [1, 3, 12],
      state: 6
    },
    {
      pos: [2, 3, 12],
      state: 6
    },
    {
      pos: [3, 3, 12],
      state: 6
    },
    {
      pos: [4, 3, 12],
      state: 6
    },
    {
      pos: [5, 3, 12],
      state: 6
    },
    {
      pos: [6, 3, 12],
      state: 6
    },
    {
      pos: [7, 3, 12],
      state: 6
    },
    {
      pos: [8, 3, 12],
      state: 6
    },
    {
      pos: [9, 3, 12],
      state: 6
    },
    {
      pos: [10, 3, 12],
      state: 6
    }
  ],
  palette: [
    {
      Name: "minecraft:sand"
    },
    {
      Properties: {
        axis: "z"
      },
      Name: "minecraft:hay_block"
    },
    {
      Properties: {
        axis: "y"
      },
      Name: "minecraft:hay_block"
    },
    {
      Name: "minecraft:smooth_sandstone"
    },
    {
      Properties: {
        axis: "x"
      },
      Name: "minecraft:hay_block"
    },
    {
      Properties: {
        facing: "west"
      },
      Name: "minecraft:jigsaw"
    },
    {
      Name: "minecraft:air"
    },
    {
      Properties: {
        half: "bottom",
        waterlogged: "false",
        shape: "inner_left",
        facing: "south"
      },
      Name: "minecraft:smooth_sandstone_stairs"
    },
    {
      Properties: {
        half: "bottom",
        waterlogged: "false",
        shape: "inner_right",
        facing: "south"
      },
      Name: "minecraft:smooth_sandstone_stairs"
    },
    {
      Properties: {
        level: "0"
      },
      Name: "minecraft:water"
    },
    {
      Properties: {
        moisture: "7"
      },
      Name: "minecraft:farmland"
    },
    {
      Properties: {
        age: "0"
      },
      Name: "minecraft:wheat"
    },
    {
      Properties: {
        age: "7"
      },
      Name: "minecraft:wheat"
    },
    {
      Properties: {
        age: "1"
      },
      Name: "minecraft:wheat"
    },
    {
      Properties: {
        half: "bottom",
        waterlogged: "false",
        shape: "inner_left",
        facing: "east"
      },
      Name: "minecraft:smooth_sandstone_stairs"
    },
    {
      Properties: {
        half: "bottom",
        waterlogged: "false",
        shape: "inner_right",
        facing: "west"
      },
      Name: "minecraft:smooth_sandstone_stairs"
    },
    {
      Properties: {
        age: "2"
      },
      Name: "minecraft:wheat"
    },
    {
      Properties: {
        age: "6"
      },
      Name: "minecraft:wheat"
    },
    {
      Properties: {
        age: "5"
      },
      Name: "minecraft:wheat"
    },
    {
      Properties: {
        age: "3"
      },
      Name: "minecraft:wheat"
    }
  ],
  DataVersion: 1915
}