{
  size: [9, 7, 9],
  entities: [],
  blocks: [
    {
      pos: [0, 0, 0],
      state: 0
    },
    {
      pos: [3, 0, 0],
      state: 0
    },
    {
      pos: [4, 0, 0],
      state: 0
    },
    {
      pos: [5, 0, 0],
      state: 0
    },
    {
      pos: [1, 0, 1],
      state: 0
    },
    {
      pos: [2, 0, 1],
      state: 0
    },
    {
      pos: [3, 0, 1],
      state: 0
    },
    {
      pos: [4, 0, 1],
      state: 0
    },
    {
      pos: [5, 0, 1],
      state: 0
    },
    {
      pos: [6, 0, 1],
      state: 0
    },
    {
      pos: [7, 0, 1],
      state: 0
    },
    {
      pos: [1, 0, 2],
      state: 0
    },
    {
      pos: [7, 0, 2],
      state: 0
    },
    {
      pos: [2, 1, 2],
      state: 1
    },
    {
      pos: [3, 1, 2],
      state: 1
    },
    {
      pos: [4, 1, 2],
      state: 1
    },
    {
      pos: [5, 1, 2],
      state: 2
    },
    {
      pos: [6, 1, 2],
      state: 1
    },
    {
      pos: [2, 2, 2],
      state: 1
    },
    {
      pos: [3, 2, 2],
      state: 1
    },
    {
      pos: [4, 2, 2],
      state: 1
    },
    {
      pos: [5, 2, 2],
      state: 1
    },
    {
      pos: [6, 2, 2],
      state: 1
    },
    {
      pos: [2, 5, 2],
      state: 3
    },
    {
      pos: [6, 5, 2],
      state: 3
    },
    {
      pos: [3, 6, 2],
      state: 4
    },
    {
      pos: [4, 6, 2],
      state: 3
    },
    {
      pos: [5, 6, 2],
      state: 3
    },
    {
      pos: [0, 0, 3],
      state: 0
    },
    {
      pos: [1, 0, 3],
      state: 0
    },
    {
      pos: [3, 0, 3],
      state: 2
    },
    {
      pos: [4, 0, 3],
      state: 2
    },
    {
      pos: [5, 0, 3],
      state: 1
    },
    {
      pos: [7, 0, 3],
      state: 0
    },
    {
      pos: [8, 0, 3],
      state: 0
    },
    {
      pos: [2, 1, 3],
      state: 1
    },
    {
      pos: [6, 1, 3],
      state: 1
    },
    {
      pos: [2, 2, 3],
      state: 1
    },
    {
      pos: [6, 2, 3],
      state: 1
    },
    {
      pos: [2, 5, 3],
      state: 3
    },
    {
      pos: [6, 5, 3],
      state: 3
    },
    {
      pos: [3, 6, 3],
      state: 3
    },
    {
      pos: [4, 6, 3],
      state: 3
    },
    {
      pos: [5, 6, 3],
      state: 3
    },
    {
      pos: [0, 0, 4],
      state: 0
    },
    {
      pos: [1, 0, 4],
      state: 0
    },
    {
      pos: [3, 0, 4],
      state: 2
    },
    {
      pos: [4, 0, 4],
      state: 2
    },
    {
      pos: [5, 0, 4],
      state: 2
    },
    {
      pos: [7, 0, 4],
      state: 0
    },
    {
      pos: [8, 0, 4],
      state: 5
    },
    {
      pos: [2, 1, 4],
      state: 1
    },
    {
      pos: [6, 1, 4],
      state: 2
    },
    {
      pos: [2, 2, 4],
      state: 1
    },
    {
      pos: [6, 2, 4],
      state: 1
    },
    {
      pos: [2, 5, 4],
      state: 3
    },
    {
      pos: [6, 5, 4],
      state: 3
    },
    {
      pos: [3, 6, 4],
      state: 3
    },
    {
      pos: [4, 6, 4],
      state: 3
    },
    {
      pos: [5, 6, 4],
      state: 3
    },
    {
      pos: [0, 0, 5],
      state: 0
    },
    {
      pos: [3, 0, 5],
      state: 2
    },
    {
      pos: [4, 0, 5],
      state: 2
    },
    {
      pos: [5, 0, 5],
      state: 2
    },
    {
      pos: [7, 0, 5],
      state: 0
    },
    {
      pos: [8, 0, 5],
      state: 0
    },
    {
      pos: [2, 1, 5],
      state: 1
    },
    {
      pos: [6, 1, 5],
      state: 1
    },
    {
      pos: [2, 2, 5],
      state: 1
    },
    {
      pos: [6, 2, 5],
      state: 1
    },
    {
      pos: [2, 5, 5],
      state: 3
    },
    {
      pos: [6, 5, 5],
      state: 3
    },
    {
      pos: [3, 6, 5],
      state: 3
    },
    {
      pos: [4, 6, 5],
      state: 3
    },
    {
      pos: [5, 6, 5],
      state: 3
    },
    {
      pos: [1, 0, 6],
      state: 0
    },
    {
      pos: [7, 0, 6],
      state: 0
    },
    {
      pos: [2, 1, 6],
      state: 1
    },
    {
      pos: [3, 1, 6],
      state: 1
    },
    {
      pos: [4, 1, 6],
      state: 1
    },
    {
      pos: [5, 1, 6],
      state: 1
    },
    {
      pos: [6, 1, 6],
      state: 1
    },
    {
      pos: [2, 2, 6],
      state: 1
    },
    {
      pos: [3, 2, 6],
      state: 1
    },
    {
      pos: [4, 2, 6],
      state: 1
    },
    {
      pos: [5, 2, 6],
      state: 1
    },
    {
      pos: [6, 2, 6],
      state: 1
    },
    {
      pos: [2, 5, 6],
      state: 6
    },
    {
      pos: [6, 5, 6],
      state: 3
    },
    {
      pos: [3, 6, 6],
      state: 3
    },
    {
      pos: [4, 6, 6],
      state: 3
    },
    {
      pos: [5, 6, 6],
      state: 3
    },
    {
      pos: [1, 0, 7],
      state: 0
    },
    {
      pos: [2, 0, 7],
      state: 0
    },
    {
      pos: [5, 0, 7],
      state: 0
    },
    {
      pos: [6, 0, 7],
      state: 0
    },
    {
      pos: [7, 0, 7],
      state: 0
    },
    {
      pos: [8, 0, 7],
      state: 0
    },
    {
      pos: [3, 0, 8],
      state: 0
    },
    {
      pos: [4, 0, 8],
      state: 5
    },
    {
      nbt: {
        target_pool: "minecraft:village/taiga/decor",
        final_state: "minecraft:grass_block",
        id: "minecraft:jigsaw",
        attachement_type: "minecraft:bottom"
      },
      pos: [0, 1, 0],
      state: 7
    },
    {
      nbt: {
        target_pool: "minecraft:village/common/cats",
        final_state: "minecraft:grass_block",
        id: "minecraft:jigsaw",
        attachement_type: "minecraft:bottom"
      },
      pos: [2, 1, 0],
      state: 7
    },
    {
      nbt: {
        target_pool: "minecraft:village/taiga/streets",
        final_state: "minecraft:air",
        id: "minecraft:jigsaw",
        attachement_type: "minecraft:street"
      },
      pos: [4, 2, 0],
      state: 8
    },
    {
      nbt: {
        target_pool: "minecraft:village/taiga/streets",
        final_state: "minecraft:air",
        id: "minecraft:jigsaw",
        attachement_type: "minecraft:street"
      },
      pos: [0, 2, 4],
      state: 9
    },
    {
      nbt: {
        target_pool: "minecraft:village/taiga/streets",
        final_state: "minecraft:air",
        id: "minecraft:jigsaw",
        attachement_type: "minecraft:street"
      },
      pos: [8, 2, 4],
      state: 10
    },
    {
      nbt: {
        id: "minecraft:bell"
      },
      pos: [2, 4, 4],
      state: 11
    },
    {
      nbt: {
        target_pool: "minecraft:village/common/cats",
        final_state: "minecraft:grass_block",
        id: "minecraft:jigsaw",
        attachement_type: "minecraft:bottom"
      },
      pos: [0, 1, 6],
      state: 7
    },
    {
      nbt: {
        target_pool: "minecraft:village/taiga/decor",
        final_state: "minecraft:grass_block",
        id: "minecraft:jigsaw",
        attachement_type: "minecraft:bottom"
      },
      pos: [8, 1, 7],
      state: 7
    },
    {
      nbt: {
        target_pool: "minecraft:village/taiga/streets",
        final_state: "minecraft:air",
        id: "minecraft:jigsaw",
        attachement_type: "minecraft:street"
      },
      pos: [4, 2, 8],
      state: 12
    },
    {
      pos: [1, 0, 0],
      state: 13
    },
    {
      pos: [2, 0, 0],
      state: 13
    },
    {
      pos: [6, 0, 0],
      state: 13
    },
    {
      pos: [7, 0, 0],
      state: 13
    },
    {
      pos: [8, 0, 0],
      state: 13
    },
    {
      pos: [1, 1, 0],
      state: 13
    },
    {
      pos: [3, 1, 0],
      state: 14
    },
    {
      pos: [4, 1, 0],
      state: 14
    },
    {
      pos: [5, 1, 0],
      state: 14
    },
    {
      pos: [6, 1, 0],
      state: 13
    },
    {
      pos: [7, 1, 0],
      state: 13
    },
    {
      pos: [8, 1, 0],
      state: 13
    },
    {
      pos: [0, 2, 0],
      state: 13
    },
    {
      pos: [1, 2, 0],
      state: 13
    },
    {
      pos: [2, 2, 0],
      state: 13
    },
    {
      pos: [3, 2, 0],
      state: 13
    },
    {
      pos: [5, 2, 0],
      state: 13
    },
    {
      pos: [6, 2, 0],
      state: 13
    },
    {
      pos: [7, 2, 0],
      state: 13
    },
    {
      pos: [8, 2, 0],
      state: 13
    },
    {
      pos: [0, 3, 0],
      state: 13
    },
    {
      pos: [1, 3, 0],
      state: 13
    },
    {
      pos: [2, 3, 0],
      state: 13
    },
    {
      pos: [3, 3, 0],
      state: 13
    },
    {
      pos: [4, 3, 0],
      state: 13
    },
    {
      pos: [5, 3, 0],
      state: 13
    },
    {
      pos: [6, 3, 0],
      state: 13
    },
    {
      pos: [7, 3, 0],
      state: 13
    },
    {
      pos: [8, 3, 0],
      state: 13
    },
    {
      pos: [0, 4, 0],
      state: 13
    },
    {
      pos: [1, 4, 0],
      state: 13
    },
    {
      pos: [2, 4, 0],
      state: 13
    },
    {
      pos: [3, 4, 0],
      state: 13
    },
    {
      pos: [4, 4, 0],
      state: 13
    },
    {
      pos: [5, 4, 0],
      state: 13
    },
    {
      pos: [6, 4, 0],
      state: 13
    },
    {
      pos: [7, 4, 0],
      state: 13
    },
    {
      pos: [8, 4, 0],
      state: 13
    },
    {
      pos: [0, 5, 0],
      state: 13
    },
    {
      pos: [1, 5, 0],
      state: 13
    },
    {
      pos: [2, 5, 0],
      state: 13
    },
    {
      pos: [3, 5, 0],
      state: 13
    },
    {
      pos: [4, 5, 0],
      state: 13
    },
    {
      pos: [5, 5, 0],
      state: 13
    },
    {
      pos: [6, 5, 0],
      state: 13
    },
    {
      pos: [7, 5, 0],
      state: 13
    },
    {
      pos: [8, 5, 0],
      state: 13
    },
    {
      pos: [0, 6, 0],
      state: 13
    },
    {
      pos: [1, 6, 0],
      state: 13
    },
    {
      pos: [2, 6, 0],
      state: 13
    },
    {
      pos: [3, 6, 0],
      state: 13
    },
    {
      pos: [4, 6, 0],
      state: 13
    },
    {
      pos: [5, 6, 0],
      state: 13
    },
    {
      pos: [6, 6, 0],
      state: 13
    },
    {
      pos: [7, 6, 0],
      state: 13
    },
    {
      pos: [8, 6, 0],
      state: 13
    },
    {
      pos: [0, 0, 1],
      state: 13
    },
    {
      pos: [8, 0, 1],
      state: 13
    },
    {
      pos: [1, 1, 1],
      state: 14
    },
    {
      pos: [2, 1, 1],
      state: 14
    },
    {
      pos: [3, 1, 1],
      state: 14
    },
    {
      pos: [4, 1, 1],
      state: 14
    },
    {
      pos: [5, 1, 1],
      state: 14
    },
    {
      pos: [6, 1, 1],
      state: 14
    },
    {
      pos: [7, 1, 1],
      state: 14
    },
    {
      pos: [0, 0, 2],
      state: 13
    },
    {
      pos: [2, 0, 2],
      state: 14
    },
    {
      pos: [3, 0, 2],
      state: 14
    },
    {
      pos: [4, 0, 2],
      state: 14
    },
    {
      pos: [5, 0, 2],
      state: 14
    },
    {
      pos: [6, 0, 2],
      state: 14
    },
    {
      pos: [8, 0, 2],
      state: 13
    },
    {
      pos: [1, 1, 2],
      state: 14
    },
    {
      pos: [7, 1, 2],
      state: 14
    },
    {
      pos: [2, 3, 2],
      state: 15
    },
    {
      pos: [6, 3, 2],
      state: 15
    },
    {
      pos: [2, 4, 2],
      state: 15
    },
    {
      pos: [6, 4, 2],
      state: 15
    },
    {
      pos: [3, 5, 2],
      state: 16
    },
    {
      pos: [4, 5, 2],
      state: 16
    },
    {
      pos: [5, 5, 2],
      state: 16
    },
    {
      pos: [2, 0, 3],
      state: 14
    },
    {
      pos: [6, 0, 3],
      state: 14
    },
    {
      pos: [0, 1, 3],
      state: 14
    },
    {
      pos: [1, 1, 3],
      state: 14
    },
    {
      pos: [3, 1, 3],
      state: 17
    },
    {
      pos: [4, 1, 3],
      state: 18
    },
    {
      pos: [5, 1, 3],
      state: 18
    },
    {
      pos: [7, 1, 3],
      state: 14
    },
    {
      pos: [8, 1, 3],
      state: 14
    },
    {
      pos: [3, 2, 3],
      state: 18
    },
    {
      pos: [4, 2, 3],
      state: 18
    },
    {
      pos: [5, 2, 3],
      state: 18
    },
    {
      pos: [2, 0, 4],
      state: 14
    },
    {
      pos: [6, 0, 4],
      state: 14
    },
    {
      pos: [0, 1, 4],
      state: 14
    },
    {
      pos: [1, 1, 4],
      state: 14
    },
    {
      pos: [3, 1, 4],
      state: 17
    },
    {
      pos: [4, 1, 4],
      state: 18
    },
    {
      pos: [5, 1, 4],
      state: 18
    },
    {
      pos: [7, 1, 4],
      state: 14
    },
    {
      pos: [8, 1, 4],
      state: 14
    },
    {
      pos: [3, 2, 4],
      state: 18
    },
    {
      pos: [4, 2, 4],
      state: 18
    },
    {
      pos: [5, 2, 4],
      state: 18
    },
    {
      pos: [1, 0, 5],
      state: 14
    },
    {
      pos: [2, 0, 5],
      state: 14
    },
    {
      pos: [6, 0, 5],
      state: 14
    },
    {
      pos: [0, 1, 5],
      state: 14
    },
    {
      pos: [1, 1, 5],
      state: 14
    },
    {
      pos: [3, 1, 5],
      state: 17
    },
    {
      pos: [4, 1, 5],
      state: 17
    },
    {
      pos: [5, 1, 5],
      state: 17
    },
    {
      pos: [7, 1, 5],
      state: 14
    },
    {
      pos: [8, 1, 5],
      state: 14
    },
    {
      pos: [3, 2, 5],
      state: 18
    },
    {
      pos: [4, 2, 5],
      state: 18
    },
    {
      pos: [5, 2, 5],
      state: 18
    },
    {
      pos: [0, 0, 6],
      state: 13
    },
    {
      pos: [2, 0, 6],
      state: 14
    },
    {
      pos: [3, 0, 6],
      state: 14
    },
    {
      pos: [4, 0, 6],
      state: 14
    },
    {
      pos: [5, 0, 6],
      state: 14
    },
    {
      pos: [6, 0, 6],
      state: 14
    },
    {
      pos: [8, 0, 6],
      state: 13
    },
    {
      pos: [1, 1, 6],
      state: 14
    },
    {
      pos: [7, 1, 6],
      state: 14
    },
    {
      pos: [2, 3, 6],
      state: 15
    },
    {
      pos: [6, 3, 6],
      state: 15
    },
    {
      pos: [2, 4, 6],
      state: 15
    },
    {
      pos: [6, 4, 6],
      state: 15
    },
    {
      pos: [3, 5, 6],
      state: 16
    },
    {
      pos: [4, 5, 6],
      state: 16
    },
    {
      pos: [5, 5, 6],
      state: 16
    },
    {
      pos: [0, 0, 7],
      state: 13
    },
    {
      pos: [3, 0, 7],
      state: 14
    },
    {
      pos: [4, 0, 7],
      state: 18
    },
    {
      pos: [1, 1, 7],
      state: 14
    },
    {
      pos: [2, 1, 7],
      state: 14
    },
    {
      pos: [3, 1, 7],
      state: 14
    },
    {
      pos: [4, 1, 7],
      state: 14
    },
    {
      pos: [5, 1, 7],
      state: 14
    },
    {
      pos: [6, 1, 7],
      state: 14
    },
    {
      pos: [7, 1, 7],
      state: 14
    },
    {
      pos: [0, 0, 8],
      state: 13
    },
    {
      pos: [1, 0, 8],
      state: 13
    },
    {
      pos: [2, 0, 8],
      state: 13
    },
    {
      pos: [5, 0, 8],
      state: 13
    },
    {
      pos: [6, 0, 8],
      state: 13
    },
    {
      pos: [7, 0, 8],
      state: 13
    },
    {
      pos: [8, 0, 8],
      state: 13
    },
    {
      pos: [3, 1, 8],
      state: 14
    },
    {
      pos: [4, 1, 8],
      state: 14
    },
    {
      pos: [5, 1, 8],
      state: 14
    }
  ],
  palette: [
    {
      Properties: {
        snowy: "false"
      },
      Name: "minecraft:grass_block"
    },
    {
      Name: "minecraft:cobblestone"
    },
    {
      Name: "minecraft:mossy_cobblestone"
    },
    {
      Properties: {
        axis: "z"
      },
      Name: "minecraft:spruce_log"
    },
    {
      Properties: {
        axis: "x"
      },
      Name: "minecraft:spruce_log"
    },
    {
      Name: "minecraft:dirt"
    },
    {
      Properties: {
        axis: "y"
      },
      Name: "minecraft:spruce_log"
    },
    {
      Properties: {
        facing: "up"
      },
      Name: "minecraft:jigsaw"
    },
    {
      Properties: {
        facing: "north"
      },
      Name: "minecraft:jigsaw"
    },
    {
      Properties: {
        facing: "west"
      },
      Name: "minecraft:jigsaw"
    },
    {
      Properties: {
        facing: "east"
      },
      Name: "minecraft:jigsaw"
    },
    {
      Properties: {
        attachment: "ceiling",
        facing: "east"
      },
      Name: "minecraft:bell"
    },
    {
      Properties: {
        facing: "south"
      },
      Name: "minecraft:jigsaw"
    },
    {
      Name: "minecraft:air"
    },
    {
      Name: "minecraft:grass_path"
    },
    {
      Properties: {
        east: "false",
        waterlogged: "false",
        south: "false",
        north: "false",
        west: "false"
      },
      Name: "minecraft:spruce_fence"
    },
    {
      Properties: {
        east: "true",
        waterlogged: "false",
        south: "false",
        north: "false",
        west: "true"
      },
      Name: "minecraft:spruce_fence"
    },
    {
      Properties: {
        level: "8"
      },
      Name: "minecraft:water"
    },
    {
      Properties: {
        level: "0"
      },
      Name: "minecraft:water"
    }
  ],
  DataVersion: 1930
}