{
  size: [5, 6, 5],
  entities: [],
  blocks: [
    {
      pos: [0, 0, 0],
      state: 0
    },
    {
      pos: [1, 0, 0],
      state: 0
    },
    {
      pos: [2, 0, 0],
      state: 0
    },
    {
      pos: [3, 0, 0],
      state: 0
    },
    {
      pos: [4, 0, 0],
      state: 0
    },
    {
      pos: [0, 1, 0],
      state: 1
    },
    {
      pos: [1, 1, 0],
      state: 2
    },
    {
      pos: [2, 1, 0],
      state: 2
    },
    {
      pos: [3, 1, 0],
      state: 2
    },
    {
      pos: [4, 1, 0],
      state: 1
    },
    {
      pos: [0, 2, 0],
      state: 2
    },
    {
      pos: [1, 2, 0],
      state: 2
    },
    {
      pos: [2, 2, 0],
      state: 2
    },
    {
      pos: [3, 2, 0],
      state: 2
    },
    {
      pos: [4, 2, 0],
      state: 2
    },
    {
      pos: [0, 3, 0],
      state: 2
    },
    {
      pos: [1, 3, 0],
      state: 2
    },
    {
      pos: [2, 3, 0],
      state: 2
    },
    {
      pos: [3, 3, 0],
      state: 2
    },
    {
      pos: [4, 3, 0],
      state: 2
    },
    {
      pos: [1, 4, 0],
      state: 2
    },
    {
      pos: [2, 4, 0],
      state: 2
    },
    {
      pos: [3, 4, 0],
      state: 2
    },
    {
      pos: [0, 0, 1],
      state: 0
    },
    {
      pos: [1, 0, 1],
      state: 2
    },
    {
      pos: [2, 0, 1],
      state: 2
    },
    {
      pos: [3, 0, 1],
      state: 2
    },
    {
      pos: [4, 0, 1],
      state: 0
    },
    {
      pos: [0, 1, 1],
      state: 2
    },
    {
      pos: [4, 1, 1],
      state: 2
    },
    {
      pos: [0, 2, 1],
      state: 2
    },
    {
      pos: [4, 2, 1],
      state: 2
    },
    {
      pos: [0, 3, 1],
      state: 2
    },
    {
      pos: [4, 3, 1],
      state: 2
    },
    {
      pos: [0, 4, 1],
      state: 2
    },
    {
      pos: [4, 4, 1],
      state: 2
    },
    {
      pos: [0, 0, 2],
      state: 2
    },
    {
      pos: [1, 0, 2],
      state: 2
    },
    {
      pos: [3, 0, 2],
      state: 2
    },
    {
      pos: [4, 0, 2],
      state: 0
    },
    {
      pos: [4, 1, 2],
      state: 1
    },
    {
      pos: [0, 3, 2],
      state: 3
    },
    {
      pos: [0, 4, 2],
      state: 2
    },
    {
      pos: [4, 4, 2],
      state: 2
    },
    {
      pos: [0, 0, 3],
      state: 0
    },
    {
      pos: [1, 0, 3],
      state: 2
    },
    {
      pos: [2, 0, 3],
      state: 2
    },
    {
      pos: [3, 0, 3],
      state: 2
    },
    {
      pos: [4, 0, 3],
      state: 0
    },
    {
      pos: [4, 1, 3],
      state: 2
    },
    {
      pos: [0, 2, 3],
      state: 2
    },
    {
      pos: [4, 2, 3],
      state: 2
    },
    {
      pos: [0, 3, 3],
      state: 2
    },
    {
      pos: [4, 3, 3],
      state: 2
    },
    {
      pos: [0, 4, 3],
      state: 2
    },
    {
      pos: [4, 4, 3],
      state: 2
    },
    {
      pos: [0, 0, 4],
      state: 0
    },
    {
      pos: [1, 0, 4],
      state: 0
    },
    {
      pos: [2, 0, 4],
      state: 0
    },
    {
      pos: [3, 0, 4],
      state: 0
    },
    {
      pos: [4, 0, 4],
      state: 0
    },
    {
      pos: [0, 1, 4],
      state: 1
    },
    {
      pos: [1, 1, 4],
      state: 2
    },
    {
      pos: [2, 1, 4],
      state: 2
    },
    {
      pos: [3, 1, 4],
      state: 2
    },
    {
      pos: [4, 1, 4],
      state: 1
    },
    {
      pos: [0, 2, 4],
      state: 2
    },
    {
      pos: [1, 2, 4],
      state: 2
    },
    {
      pos: [2, 2, 4],
      state: 2
    },
    {
      pos: [3, 2, 4],
      state: 2
    },
    {
      pos: [4, 2, 4],
      state: 2
    },
    {
      pos: [0, 3, 4],
      state: 2
    },
    {
      pos: [1, 3, 4],
      state: 2
    },
    {
      pos: [2, 3, 4],
      state: 2
    },
    {
      pos: [3, 3, 4],
      state: 2
    },
    {
      pos: [4, 3, 4],
      state: 2
    },
    {
      pos: [1, 4, 4],
      state: 2
    },
    {
      pos: [2, 4, 4],
      state: 2
    },
    {
      pos: [3, 4, 4],
      state: 2
    },
    {
      nbt: {
        target_pool: "minecraft:village/desert/zombie/villagers",
        final_state: "minecraft:smooth_sandstone",
        id: "minecraft:jigsaw",
        attachement_type: "minecraft:bottom"
      },
      pos: [2, 0, 2],
      state: 4
    },
    {
      nbt: {
        target_pool: "minecraft:empty",
        final_state: "minecraft:smooth_sandstone",
        id: "minecraft:jigsaw",
        attachement_type: "minecraft:building_entrance"
      },
      pos: [0, 1, 3],
      state: 5
    },
    {
      nbt: {
        id: "minecraft:bed"
      },
      pos: [2, 1, 3],
      state: 6
    },
    {
      nbt: {
        id: "minecraft:bed"
      },
      pos: [3, 1, 3],
      state: 7
    },
    {
      pos: [0, 4, 0],
      state: 8
    },
    {
      pos: [4, 4, 0],
      state: 8
    },
    {
      pos: [0, 5, 0],
      state: 9
    },
    {
      pos: [1, 5, 0],
      state: 8
    },
    {
      pos: [2, 5, 0],
      state: 8
    },
    {
      pos: [3, 5, 0],
      state: 8
    },
    {
      pos: [4, 5, 0],
      state: 9
    },
    {
      pos: [1, 1, 1],
      state: 9
    },
    {
      pos: [2, 1, 1],
      state: 9
    },
    {
      pos: [3, 1, 1],
      state: 10
    },
    {
      pos: [1, 2, 1],
      state: 9
    },
    {
      pos: [2, 2, 1],
      state: 9
    },
    {
      pos: [3, 2, 1],
      state: 9
    },
    {
      pos: [1, 3, 1],
      state: 9
    },
    {
      pos: [2, 3, 1],
      state: 9
    },
    {
      pos: [3, 3, 1],
      state: 9
    },
    {
      pos: [1, 4, 1],
      state: 9
    },
    {
      pos: [2, 4, 1],
      state: 9
    },
    {
      pos: [3, 4, 1],
      state: 9
    },
    {
      pos: [0, 5, 1],
      state: 8
    },
    {
      pos: [1, 5, 1],
      state: 8
    },
    {
      pos: [2, 5, 1],
      state: 8
    },
    {
      pos: [3, 5, 1],
      state: 8
    },
    {
      pos: [4, 5, 1],
      state: 8
    },
    {
      pos: [0, 1, 2],
      state: 11
    },
    {
      pos: [1, 1, 2],
      state: 9
    },
    {
      pos: [2, 1, 2],
      state: 9
    },
    {
      pos: [3, 1, 2],
      state: 9
    },
    {
      pos: [0, 2, 2],
      state: 12
    },
    {
      pos: [1, 2, 2],
      state: 9
    },
    {
      pos: [2, 2, 2],
      state: 9
    },
    {
      pos: [3, 2, 2],
      state: 9
    },
    {
      pos: [4, 2, 2],
      state: 13
    },
    {
      pos: [1, 3, 2],
      state: 9
    },
    {
      pos: [2, 3, 2],
      state: 9
    },
    {
      pos: [3, 3, 2],
      state: 9
    },
    {
      pos: [4, 3, 2],
      state: 14
    },
    {
      pos: [1, 4, 2],
      state: 15
    },
    {
      pos: [2, 4, 2],
      state: 9
    },
    {
      pos: [3, 4, 2],
      state: 9
    },
    {
      pos: [0, 5, 2],
      state: 8
    },
    {
      pos: [1, 5, 2],
      state: 8
    },
    {
      pos: [2, 5, 2],
      state: 8
    },
    {
      pos: [3, 5, 2],
      state: 8
    },
    {
      pos: [4, 5, 2],
      state: 8
    },
    {
      pos: [1, 1, 3],
      state: 9
    },
    {
      pos: [1, 2, 3],
      state: 9
    },
    {
      pos: [2, 2, 3],
      state: 9
    },
    {
      pos: [3, 2, 3],
      state: 9
    },
    {
      pos: [1, 3, 3],
      state: 9
    },
    {
      pos: [2, 3, 3],
      state: 9
    },
    {
      pos: [3, 3, 3],
      state: 9
    },
    {
      pos: [1, 4, 3],
      state: 9
    },
    {
      pos: [2, 4, 3],
      state: 9
    },
    {
      pos: [3, 4, 3],
      state: 9
    },
    {
      pos: [0, 5, 3],
      state: 8
    },
    {
      pos: [1, 5, 3],
      state: 8
    },
    {
      pos: [2, 5, 3],
      state: 8
    },
    {
      pos: [3, 5, 3],
      state: 8
    },
    {
      pos: [4, 5, 3],
      state: 8
    },
    {
      pos: [0, 4, 4],
      state: 8
    },
    {
      pos: [4, 4, 4],
      state: 8
    },
    {
      pos: [0, 5, 4],
      state: 9
    },
    {
      pos: [1, 5, 4],
      state: 8
    },
    {
      pos: [2, 5, 4],
      state: 8
    },
    {
      pos: [3, 5, 4],
      state: 8
    },
    {
      pos: [4, 5, 4],
      state: 9
    }
  ],
  palette: [
    {
      Name: "minecraft:sand"
    },
    {
      Name: "minecraft:sandstone"
    },
    {
      Name: "minecraft:smooth_sandstone"
    },
    {
      Properties: {
        waterlogged: "false",
        type: "double"
      },
      Name: "minecraft:sandstone_slab"
    },
    {
      Properties: {
        facing: "up"
      },
      Name: "minecraft:jigsaw"
    },
    {
      Properties: {
        facing: "west"
      },
      Name: "minecraft:jigsaw"
    },
    {
      Properties: {
        part: "foot",
        facing: "east",
        occupied: "false"
      },
      Name: "minecraft:cyan_bed"
    },
    {
      Properties: {
        part: "head",
        facing: "east",
        occupied: "false"
      },
      Name: "minecraft:cyan_bed"
    },
    {
      Properties: {
        waterlogged: "false",
        type: "bottom"
      },
      Name: "minecraft:sandstone_slab"
    },
    {
      Name: "minecraft:air"
    },
    {
      Properties: {
        half: "bottom",
        waterlogged: "false",
        shape: "straight",
        facing: "east"
      },
      Name: "minecraft:smooth_sandstone_stairs"
    },
    {
      Properties: {
        hinge: "left",
        half: "lower",
        powered: "false",
        facing: "west",
        open: "false"
      },
      Name: "minecraft:jungle_door"
    },
    {
      Properties: {
        hinge: "left",
        half: "upper",
        powered: "false",
        facing: "west",
        open: "false"
      },
      Name: "minecraft:jungle_door"
    },
    {
      Name: "minecraft:potted_cactus"
    },
    {
      Properties: {
        waterlogged: "false",
        type: "top"
      },
      Name: "minecraft:sandstone_slab"
    },
    {
      Properties: {
        facing: "east"
      },
      Name: "minecraft:wall_torch"
    }
  ],
  DataVersion: 1915
}