{
  size: [8, 5, 15],
  entities: [],
  blocks: [
    {
      pos: [0, 0, 0],
      state: 0
    },
    {
      pos: [1, 0, 0],
      state: 0
    },
    {
      pos: [2, 0, 0],
      state: 0
    },
    {
      pos: [3, 0, 0],
      state: 0
    },
    {
      pos: [7, 0, 0],
      state: 0
    },
    {
      pos: [1, 4, 0],
      state: 1
    },
    {
      pos: [2, 4, 0],
      state: 2
    },
    {
      pos: [0, 0, 1],
      state: 0
    },
    {
      pos: [1, 0, 1],
      state: 0
    },
    {
      pos: [2, 0, 1],
      state: 0
    },
    {
      pos: [6, 0, 1],
      state: 0
    },
    {
      pos: [7, 0, 1],
      state: 0
    },
    {
      pos: [0, 1, 1],
      state: 3
    },
    {
      pos: [1, 1, 1],
      state: 3
    },
    {
      pos: [2, 1, 1],
      state: 3
    },
    {
      pos: [3, 1, 1],
      state: 3
    },
    {
      pos: [1, 4, 1],
      state: 2
    },
    {
      pos: [2, 4, 1],
      state: 1
    },
    {
      pos: [0, 0, 2],
      state: 0
    },
    {
      pos: [3, 0, 2],
      state: 0
    },
    {
      pos: [1, 4, 2],
      state: 1
    },
    {
      pos: [2, 4, 2],
      state: 2
    },
    {
      pos: [4, 0, 3],
      state: 0
    },
    {
      pos: [1, 0, 4],
      state: 0
    },
    {
      pos: [5, 0, 4],
      state: 0
    },
    {
      pos: [7, 0, 4],
      state: 0
    },
    {
      pos: [4, 0, 5],
      state: 0
    },
    {
      pos: [6, 0, 5],
      state: 0
    },
    {
      pos: [7, 0, 5],
      state: 0
    },
    {
      pos: [5, 1, 5],
      state: 3
    },
    {
      pos: [2, 0, 6],
      state: 0
    },
    {
      pos: [4, 0, 6],
      state: 0
    },
    {
      pos: [6, 0, 6],
      state: 0
    },
    {
      pos: [7, 0, 6],
      state: 0
    },
    {
      pos: [5, 1, 6],
      state: 3
    },
    {
      pos: [4, 4, 6],
      state: 2
    },
    {
      pos: [5, 4, 6],
      state: 1
    },
    {
      pos: [6, 4, 6],
      state: 2
    },
    {
      pos: [6, 0, 7],
      state: 0
    },
    {
      pos: [7, 0, 7],
      state: 0
    },
    {
      pos: [5, 1, 7],
      state: 3
    },
    {
      pos: [4, 4, 7],
      state: 1
    },
    {
      pos: [5, 4, 7],
      state: 2
    },
    {
      pos: [6, 4, 7],
      state: 1
    },
    {
      pos: [3, 0, 8],
      state: 0
    },
    {
      pos: [4, 0, 8],
      state: 0
    },
    {
      pos: [6, 0, 8],
      state: 0
    },
    {
      pos: [7, 0, 8],
      state: 0
    },
    {
      pos: [5, 1, 8],
      state: 3
    },
    {
      pos: [1, 0, 9],
      state: 0
    },
    {
      pos: [5, 0, 9],
      state: 0
    },
    {
      pos: [6, 0, 9],
      state: 0
    },
    {
      pos: [7, 0, 9],
      state: 0
    },
    {
      pos: [0, 0, 10],
      state: 0
    },
    {
      pos: [1, 0, 10],
      state: 0
    },
    {
      pos: [3, 0, 10],
      state: 0
    },
    {
      pos: [6, 0, 10],
      state: 0
    },
    {
      pos: [7, 0, 10],
      state: 0
    },
    {
      pos: [5, 1, 10],
      state: 3
    },
    {
      pos: [2, 0, 11],
      state: 0
    },
    {
      pos: [3, 0, 11],
      state: 0
    },
    {
      pos: [5, 0, 11],
      state: 0
    },
    {
      pos: [6, 0, 11],
      state: 0
    },
    {
      pos: [7, 0, 11],
      state: 0
    },
    {
      pos: [0, 0, 12],
      state: 0
    },
    {
      pos: [3, 0, 12],
      state: 0
    },
    {
      pos: [6, 0, 12],
      state: 0
    },
    {
      pos: [7, 0, 12],
      state: 0
    },
    {
      pos: [1, 4, 12],
      state: 1
    },
    {
      pos: [2, 4, 12],
      state: 2
    },
    {
      pos: [0, 0, 13],
      state: 0
    },
    {
      pos: [2, 0, 13],
      state: 0
    },
    {
      pos: [3, 0, 13],
      state: 0
    },
    {
      pos: [7, 0, 13],
      state: 0
    },
    {
      pos: [0, 1, 13],
      state: 3
    },
    {
      pos: [1, 1, 13],
      state: 3
    },
    {
      pos: [2, 1, 13],
      state: 3
    },
    {
      pos: [3, 1, 13],
      state: 3
    },
    {
      pos: [1, 4, 13],
      state: 2
    },
    {
      pos: [2, 4, 13],
      state: 1
    },
    {
      pos: [0, 0, 14],
      state: 0
    },
    {
      pos: [1, 0, 14],
      state: 0
    },
    {
      pos: [2, 0, 14],
      state: 0
    },
    {
      pos: [3, 0, 14],
      state: 0
    },
    {
      pos: [4, 0, 14],
      state: 0
    },
    {
      pos: [7, 0, 14],
      state: 0
    },
    {
      pos: [1, 4, 14],
      state: 1
    },
    {
      pos: [2, 4, 14],
      state: 2
    },
    {
      nbt: {
        target_pool: "minecraft:village/plains/streets",
        final_state: "minecraft:air",
        id: "minecraft:jigsaw",
        attachement_type: "minecraft:street"
      },
      pos: [5, 1, 0],
      state: 4
    },
    {
      nbt: {
        target_pool: "minecraft:village/plains/streets",
        final_state: "minecraft:air",
        id: "minecraft:jigsaw",
        attachement_type: "minecraft:street"
      },
      pos: [7, 1, 3],
      state: 5
    },
    {
      nbt: {
        target_pool: "minecraft:village/common/cats",
        final_state: "minecraft:grass_path",
        id: "minecraft:jigsaw",
        attachement_type: "minecraft:bottom"
      },
      pos: [2, 0, 5],
      state: 6
    },
    {
      nbt: {
        target_pool: "minecraft:village/plains/streets",
        final_state: "minecraft:air",
        id: "minecraft:jigsaw",
        attachement_type: "minecraft:street"
      },
      pos: [0, 1, 7],
      state: 7
    },
    {
      nbt: {
        target_pool: "minecraft:village/common/cats",
        final_state: "minecraft:grass_block",
        id: "minecraft:jigsaw",
        attachement_type: "minecraft:bottom"
      },
      pos: [2, 0, 9],
      state: 6
    },
    {
      nbt: {
        id: "minecraft:bell"
      },
      pos: [5, 2, 10],
      state: 8
    },
    {
      nbt: {
        target_pool: "minecraft:village/plains/streets",
        final_state: "minecraft:air",
        id: "minecraft:jigsaw",
        attachement_type: "minecraft:street"
      },
      pos: [5, 1, 14],
      state: 9
    },
    {
      pos: [4, 0, 0],
      state: 10
    },
    {
      pos: [5, 0, 0],
      state: 10
    },
    {
      pos: [6, 0, 0],
      state: 10
    },
    {
      pos: [0, 1, 0],
      state: 11
    },
    {
      pos: [3, 1, 0],
      state: 11
    },
    {
      pos: [0, 2, 0],
      state: 12
    },
    {
      pos: [3, 2, 0],
      state: 12
    },
    {
      pos: [0, 3, 0],
      state: 12
    },
    {
      pos: [3, 3, 0],
      state: 12
    },
    {
      pos: [0, 4, 0],
      state: 13
    },
    {
      pos: [3, 4, 0],
      state: 13
    },
    {
      pos: [3, 0, 1],
      state: 10
    },
    {
      pos: [4, 0, 1],
      state: 10
    },
    {
      pos: [5, 0, 1],
      state: 10
    },
    {
      pos: [0, 4, 1],
      state: 13
    },
    {
      pos: [3, 4, 1],
      state: 13
    },
    {
      pos: [1, 0, 2],
      state: 10
    },
    {
      pos: [2, 0, 2],
      state: 10
    },
    {
      pos: [4, 0, 2],
      state: 10
    },
    {
      pos: [5, 0, 2],
      state: 10
    },
    {
      pos: [6, 0, 2],
      state: 10
    },
    {
      pos: [7, 0, 2],
      state: 10
    },
    {
      pos: [0, 1, 2],
      state: 14
    },
    {
      pos: [3, 1, 2],
      state: 14
    },
    {
      pos: [0, 2, 2],
      state: 12
    },
    {
      pos: [3, 2, 2],
      state: 12
    },
    {
      pos: [0, 3, 2],
      state: 12
    },
    {
      pos: [3, 3, 2],
      state: 12
    },
    {
      pos: [0, 4, 2],
      state: 13
    },
    {
      pos: [3, 4, 2],
      state: 13
    },
    {
      pos: [0, 0, 3],
      state: 10
    },
    {
      pos: [1, 0, 3],
      state: 10
    },
    {
      pos: [2, 0, 3],
      state: 10
    },
    {
      pos: [3, 0, 3],
      state: 10
    },
    {
      pos: [5, 0, 3],
      state: 10
    },
    {
      pos: [6, 0, 3],
      state: 10
    },
    {
      pos: [7, 0, 3],
      state: 10
    },
    {
      pos: [0, 0, 4],
      state: 10
    },
    {
      pos: [2, 0, 4],
      state: 10
    },
    {
      pos: [3, 0, 4],
      state: 10
    },
    {
      pos: [4, 0, 4],
      state: 10
    },
    {
      pos: [6, 0, 4],
      state: 10
    },
    {
      pos: [0, 0, 5],
      state: 10
    },
    {
      pos: [1, 0, 5],
      state: 10
    },
    {
      pos: [3, 0, 5],
      state: 10
    },
    {
      pos: [5, 0, 5],
      state: 10
    },
    {
      pos: [4, 1, 5],
      state: 15
    },
    {
      pos: [6, 1, 5],
      state: 16
    },
    {
      pos: [4, 2, 5],
      state: 12
    },
    {
      pos: [6, 2, 5],
      state: 12
    },
    {
      pos: [4, 3, 5],
      state: 12
    },
    {
      pos: [6, 3, 5],
      state: 12
    },
    {
      pos: [4, 4, 5],
      state: 13
    },
    {
      pos: [5, 4, 5],
      state: 13
    },
    {
      pos: [6, 4, 5],
      state: 13
    },
    {
      pos: [0, 0, 6],
      state: 10
    },
    {
      pos: [1, 0, 6],
      state: 10
    },
    {
      pos: [3, 0, 6],
      state: 10
    },
    {
      pos: [5, 0, 6],
      state: 10
    },
    {
      pos: [0, 0, 7],
      state: 10
    },
    {
      pos: [1, 0, 7],
      state: 10
    },
    {
      pos: [2, 0, 7],
      state: 10
    },
    {
      pos: [3, 0, 7],
      state: 10
    },
    {
      pos: [4, 0, 7],
      state: 10
    },
    {
      pos: [5, 0, 7],
      state: 10
    },
    {
      pos: [6, 1, 7],
      state: 17
    },
    {
      pos: [0, 0, 8],
      state: 10
    },
    {
      pos: [1, 0, 8],
      state: 10
    },
    {
      pos: [2, 0, 8],
      state: 10
    },
    {
      pos: [5, 0, 8],
      state: 10
    },
    {
      pos: [4, 1, 8],
      state: 15
    },
    {
      pos: [6, 1, 8],
      state: 16
    },
    {
      pos: [7, 1, 8],
      state: 17
    },
    {
      pos: [4, 2, 8],
      state: 12
    },
    {
      pos: [6, 2, 8],
      state: 12
    },
    {
      pos: [4, 3, 8],
      state: 12
    },
    {
      pos: [6, 3, 8],
      state: 12
    },
    {
      pos: [4, 4, 8],
      state: 13
    },
    {
      pos: [5, 4, 8],
      state: 13
    },
    {
      pos: [6, 4, 8],
      state: 13
    },
    {
      pos: [0, 0, 9],
      state: 10
    },
    {
      pos: [3, 0, 9],
      state: 10
    },
    {
      pos: [4, 0, 9],
      state: 10
    },
    {
      pos: [2, 0, 10],
      state: 10
    },
    {
      pos: [4, 0, 10],
      state: 10
    },
    {
      pos: [5, 0, 10],
      state: 10
    },
    {
      pos: [3, 1, 10],
      state: 17
    },
    {
      pos: [0, 0, 11],
      state: 10
    },
    {
      pos: [1, 0, 11],
      state: 10
    },
    {
      pos: [4, 0, 11],
      state: 10
    },
    {
      pos: [3, 1, 11],
      state: 17
    },
    {
      pos: [1, 0, 12],
      state: 10
    },
    {
      pos: [2, 0, 12],
      state: 10
    },
    {
      pos: [4, 0, 12],
      state: 10
    },
    {
      pos: [5, 0, 12],
      state: 10
    },
    {
      pos: [0, 1, 12],
      state: 11
    },
    {
      pos: [3, 1, 12],
      state: 11
    },
    {
      pos: [6, 1, 12],
      state: 17
    },
    {
      pos: [0, 2, 12],
      state: 12
    },
    {
      pos: [3, 2, 12],
      state: 12
    },
    {
      pos: [0, 3, 12],
      state: 12
    },
    {
      pos: [3, 3, 12],
      state: 12
    },
    {
      pos: [0, 4, 12],
      state: 13
    },
    {
      pos: [3, 4, 12],
      state: 13
    },
    {
      pos: [1, 0, 13],
      state: 10
    },
    {
      pos: [4, 0, 13],
      state: 10
    },
    {
      pos: [5, 0, 13],
      state: 10
    },
    {
      pos: [6, 0, 13],
      state: 10
    },
    {
      pos: [0, 4, 13],
      state: 13
    },
    {
      pos: [3, 4, 13],
      state: 13
    },
    {
      pos: [5, 0, 14],
      state: 10
    },
    {
      pos: [6, 0, 14],
      state: 10
    },
    {
      pos: [0, 1, 14],
      state: 14
    },
    {
      pos: [3, 1, 14],
      state: 14
    },
    {
      pos: [0, 2, 14],
      state: 12
    },
    {
      pos: [3, 2, 14],
      state: 12
    },
    {
      pos: [0, 3, 14],
      state: 12
    },
    {
      pos: [3, 3, 14],
      state: 12
    },
    {
      pos: [0, 4, 14],
      state: 13
    },
    {
      pos: [3, 4, 14],
      state: 13
    }
  ],
  palette: [
    {
      Properties: {
        snowy: "false"
      },
      Name: "minecraft:grass_block"
    },
    {
      Name: "minecraft:white_wool"
    },
    {
      Name: "minecraft:yellow_wool"
    },
    {
      Name: "minecraft:oak_planks"
    },
    {
      Properties: {
        facing: "north"
      },
      Name: "minecraft:jigsaw"
    },
    {
      Properties: {
        facing: "east"
      },
      Name: "minecraft:jigsaw"
    },
    {
      Properties: {
        facing: "up"
      },
      Name: "minecraft:jigsaw"
    },
    {
      Properties: {
        facing: "west"
      },
      Name: "minecraft:jigsaw"
    },
    {
      Properties: {
        face: "floor",
        facing: "east"
      },
      Name: "minecraft:bell"
    },
    {
      Properties: {
        facing: "south"
      },
      Name: "minecraft:jigsaw"
    },
    {
      Name: "minecraft:grass_path"
    },
    {
      Properties: {
        east: "false",
        waterlogged: "false",
        south: "true",
        north: "false",
        west: "false"
      },
      Name: "minecraft:oak_fence"
    },
    {
      Properties: {
        east: "false",
        waterlogged: "false",
        south: "false",
        north: "false",
        west: "false"
      },
      Name: "minecraft:oak_fence"
    },
    {
      Properties: {
        waterlogged: "false",
        type: "bottom"
      },
      Name: "minecraft:oak_slab"
    },
    {
      Properties: {
        east: "false",
        waterlogged: "false",
        south: "false",
        north: "true",
        west: "false"
      },
      Name: "minecraft:oak_fence"
    },
    {
      Properties: {
        east: "true",
        waterlogged: "false",
        south: "false",
        north: "false",
        west: "false"
      },
      Name: "minecraft:oak_fence"
    },
    {
      Properties: {
        east: "false",
        waterlogged: "false",
        south: "false",
        north: "false",
        west: "true"
      },
      Name: "minecraft:oak_fence"
    },
    {
      Name: "minecraft:grass"
    }
  ],
  DataVersion: 1916
}