{
  size: [5, 5, 5],
  entities: [],
  blocks: [
    {
      pos: [0, 0, 0],
      state: 0
    },
    {
      pos: [1, 0, 0],
      state: 0
    },
    {
      pos: [2, 0, 0],
      state: 1
    },
    {
      pos: [3, 0, 0],
      state: 0
    },
    {
      pos: [4, 0, 0],
      state: 0
    },
    {
      pos: [0, 1, 0],
      state: 2
    },
    {
      pos: [1, 1, 0],
      state: 1
    },
    {
      pos: [3, 1, 0],
      state: 1
    },
    {
      pos: [4, 1, 0],
      state: 2
    },
    {
      pos: [0, 2, 0],
      state: 2
    },
    {
      pos: [1, 2, 0],
      state: 1
    },
    {
      pos: [3, 2, 0],
      state: 1
    },
    {
      pos: [4, 2, 0],
      state: 2
    },
    {
      pos: [0, 3, 0],
      state: 2
    },
    {
      pos: [1, 3, 0],
      state: 1
    },
    {
      pos: [2, 3, 0],
      state: 1
    },
    {
      pos: [3, 3, 0],
      state: 1
    },
    {
      pos: [4, 3, 0],
      state: 2
    },
    {
      pos: [0, 4, 0],
      state: 2
    },
    {
      pos: [4, 4, 0],
      state: 2
    },
    {
      pos: [0, 0, 1],
      state: 0
    },
    {
      pos: [1, 0, 1],
      state: 1
    },
    {
      pos: [2, 0, 1],
      state: 1
    },
    {
      pos: [3, 0, 1],
      state: 1
    },
    {
      pos: [4, 0, 1],
      state: 0
    },
    {
      pos: [0, 1, 1],
      state: 1
    },
    {
      pos: [4, 1, 1],
      state: 1
    },
    {
      pos: [0, 2, 1],
      state: 1
    },
    {
      pos: [4, 2, 1],
      state: 1
    },
    {
      pos: [0, 3, 1],
      state: 1
    },
    {
      pos: [4, 3, 1],
      state: 1
    },
    {
      pos: [0, 0, 2],
      state: 0
    },
    {
      pos: [1, 0, 2],
      state: 1
    },
    {
      pos: [3, 0, 2],
      state: 1
    },
    {
      pos: [4, 0, 2],
      state: 0
    },
    {
      pos: [0, 1, 2],
      state: 1
    },
    {
      pos: [1, 1, 2],
      state: 2
    },
    {
      pos: [4, 1, 2],
      state: 1
    },
    {
      pos: [0, 2, 2],
      state: 1
    },
    {
      pos: [4, 2, 2],
      state: 3
    },
    {
      pos: [0, 0, 3],
      state: 0
    },
    {
      pos: [1, 0, 3],
      state: 1
    },
    {
      pos: [2, 0, 3],
      state: 1
    },
    {
      pos: [3, 0, 3],
      state: 1
    },
    {
      pos: [4, 0, 3],
      state: 0
    },
    {
      pos: [0, 1, 3],
      state: 1
    },
    {
      pos: [3, 1, 3],
      state: 4
    },
    {
      pos: [4, 1, 3],
      state: 1
    },
    {
      pos: [0, 2, 3],
      state: 1
    },
    {
      pos: [4, 2, 3],
      state: 1
    },
    {
      pos: [0, 3, 3],
      state: 1
    },
    {
      pos: [4, 3, 3],
      state: 1
    },
    {
      pos: [0, 0, 4],
      state: 0
    },
    {
      pos: [1, 0, 4],
      state: 0
    },
    {
      pos: [2, 0, 4],
      state: 0
    },
    {
      pos: [3, 0, 4],
      state: 0
    },
    {
      pos: [4, 0, 4],
      state: 0
    },
    {
      pos: [0, 1, 4],
      state: 2
    },
    {
      pos: [1, 1, 4],
      state: 1
    },
    {
      pos: [2, 1, 4],
      state: 1
    },
    {
      pos: [3, 1, 4],
      state: 1
    },
    {
      pos: [4, 1, 4],
      state: 2
    },
    {
      pos: [0, 2, 4],
      state: 2
    },
    {
      pos: [1, 2, 4],
      state: 1
    },
    {
      pos: [2, 2, 4],
      state: 3
    },
    {
      pos: [3, 2, 4],
      state: 1
    },
    {
      pos: [4, 2, 4],
      state: 2
    },
    {
      pos: [0, 3, 4],
      state: 2
    },
    {
      pos: [1, 3, 4],
      state: 1
    },
    {
      pos: [3, 3, 4],
      state: 1
    },
    {
      pos: [4, 3, 4],
      state: 2
    },
    {
      pos: [0, 4, 4],
      state: 2
    },
    {
      pos: [4, 4, 4],
      state: 2
    },
    {
      nbt: {
        id: "minecraft:bed"
      },
      pos: [3, 1, 1],
      state: 5
    },
    {
      nbt: {
        target_pool: "minecraft:village/desert/villagers",
        final_state: "minecraft:smooth_sandstone",
        id: "minecraft:jigsaw",
        attachement_type: "minecraft:bottom"
      },
      pos: [2, 0, 2],
      state: 6
    },
    {
      nbt: {
        id: "minecraft:bed"
      },
      pos: [3, 1, 2],
      state: 7
    },
    {
      pos: [2, 1, 0],
      state: 8
    },
    {
      pos: [2, 2, 0],
      state: 9
    },
    {
      pos: [1, 4, 0],
      state: 10
    },
    {
      pos: [2, 4, 0],
      state: 10
    },
    {
      pos: [3, 4, 0],
      state: 10
    },
    {
      pos: [1, 1, 1],
      state: 11
    },
    {
      pos: [2, 1, 1],
      state: 12
    },
    {
      pos: [1, 2, 1],
      state: 12
    },
    {
      pos: [2, 2, 1],
      state: 12
    },
    {
      pos: [3, 2, 1],
      state: 12
    },
    {
      pos: [1, 3, 1],
      state: 12
    },
    {
      pos: [2, 3, 1],
      state: 13
    },
    {
      pos: [3, 3, 1],
      state: 12
    },
    {
      pos: [0, 4, 1],
      state: 10
    },
    {
      pos: [1, 4, 1],
      state: 14
    },
    {
      pos: [2, 4, 1],
      state: 14
    },
    {
      pos: [3, 4, 1],
      state: 14
    },
    {
      pos: [4, 4, 1],
      state: 10
    },
    {
      pos: [2, 1, 2],
      state: 12
    },
    {
      pos: [1, 2, 2],
      state: 15
    },
    {
      pos: [2, 2, 2],
      state: 12
    },
    {
      pos: [3, 2, 2],
      state: 12
    },
    {
      pos: [0, 3, 2],
      state: 16
    },
    {
      pos: [1, 3, 2],
      state: 12
    },
    {
      pos: [2, 3, 2],
      state: 12
    },
    {
      pos: [3, 3, 2],
      state: 12
    },
    {
      pos: [4, 3, 2],
      state: 16
    },
    {
      pos: [0, 4, 2],
      state: 10
    },
    {
      pos: [1, 4, 2],
      state: 14
    },
    {
      pos: [2, 4, 2],
      state: 14
    },
    {
      pos: [3, 4, 2],
      state: 14
    },
    {
      pos: [4, 4, 2],
      state: 10
    },
    {
      pos: [1, 1, 3],
      state: 17
    },
    {
      pos: [2, 1, 3],
      state: 12
    },
    {
      pos: [1, 2, 3],
      state: 12
    },
    {
      pos: [2, 2, 3],
      state: 12
    },
    {
      pos: [3, 2, 3],
      state: 12
    },
    {
      pos: [1, 3, 3],
      state: 12
    },
    {
      pos: [2, 3, 3],
      state: 12
    },
    {
      pos: [3, 3, 3],
      state: 12
    },
    {
      pos: [0, 4, 3],
      state: 10
    },
    {
      pos: [1, 4, 3],
      state: 14
    },
    {
      pos: [2, 4, 3],
      state: 14
    },
    {
      pos: [3, 4, 3],
      state: 14
    },
    {
      pos: [4, 4, 3],
      state: 10
    },
    {
      pos: [2, 3, 4],
      state: 16
    },
    {
      pos: [1, 4, 4],
      state: 10
    },
    {
      pos: [2, 4, 4],
      state: 10
    },
    {
      pos: [3, 4, 4],
      state: 10
    }
  ],
  palette: [
    {
      Name: "minecraft:sand"
    },
    {
      Name: "minecraft:smooth_sandstone"
    },
    {
      Name: "minecraft:terracotta"
    },
    {
      Properties: {
        waterlogged: "false",
        type: "double"
      },
      Name: "minecraft:smooth_sandstone_slab"
    },
    {
      Name: "minecraft:crafting_table"
    },
    {
      Properties: {
        part: "head",
        facing: "north",
        occupied: "false"
      },
      Name: "minecraft:lime_bed"
    },
    {
      Properties: {
        facing: "up"
      },
      Name: "minecraft:jigsaw"
    },
    {
      Properties: {
        part: "foot",
        facing: "north",
        occupied: "false"
      },
      Name: "minecraft:lime_bed"
    },
    {
      Properties: {
        hinge: "right",
        half: "lower",
        powered: "false",
        facing: "north",
        open: "false"
      },
      Name: "minecraft:jungle_door"
    },
    {
      Properties: {
        hinge: "right",
        half: "upper",
        powered: "false",
        facing: "north",
        open: "false"
      },
      Name: "minecraft:jungle_door"
    },
    {
      Properties: {
        waterlogged: "false",
        type: "bottom"
      },
      Name: "minecraft:sandstone_slab"
    },
    {
      Properties: {
        half: "bottom",
        waterlogged: "false",
        shape: "straight",
        facing: "north"
      },
      Name: "minecraft:sandstone_stairs"
    },
    {
      Name: "minecraft:air"
    },
    {
      Properties: {
        facing: "south"
      },
      Name: "minecraft:wall_torch"
    },
    {
      Properties: {
        waterlogged: "false",
        type: "bottom"
      },
      Name: "minecraft:smooth_sandstone_slab"
    },
    {
      Properties: {
        waterlogged: "false",
        pickles: "2"
      },
      Name: "minecraft:sea_pickle"
    },
    {
      Properties: {
        waterlogged: "false",
        type: "top"
      },
      Name: "minecraft:smooth_sandstone_slab"
    },
    {
      Properties: {
        half: "bottom",
        waterlogged: "false",
        shape: "straight",
        facing: "south"
      },
      Name: "minecraft:sandstone_stairs"
    }
  ],
  DataVersion: 1915
}