{
  size: [8, 8, 11],
  entities: [],
  blocks: [
    {
      pos: [1, 0, 0],
      state: 0
    },
    {
      pos: [2, 0, 0],
      state: 0
    },
    {
      pos: [3, 0, 0],
      state: 0
    },
    {
      pos: [4, 0, 0],
      state: 0
    },
    {
      pos: [5, 0, 0],
      state: 0
    },
    {
      pos: [6, 0, 0],
      state: 0
    },
    {
      pos: [7, 0, 0],
      state: 0
    },
    {
      pos: [5, 1, 0],
      state: 0
    },
    {
      pos: [6, 1, 0],
      state: 0
    },
    {
      pos: [7, 1, 0],
      state: 0
    },
    {
      pos: [7, 2, 0],
      state: 0
    },
    {
      pos: [5, 3, 0],
      state: 0
    },
    {
      pos: [6, 3, 0],
      state: 0
    },
    {
      pos: [7, 3, 0],
      state: 0
    },
    {
      pos: [1, 4, 0],
      state: 0
    },
    {
      pos: [2, 4, 0],
      state: 0
    },
    {
      pos: [3, 4, 0],
      state: 0
    },
    {
      pos: [4, 4, 0],
      state: 0
    },
    {
      pos: [5, 4, 0],
      state: 0
    },
    {
      pos: [6, 4, 0],
      state: 0
    },
    {
      pos: [7, 4, 0],
      state: 0
    },
    {
      pos: [1, 0, 1],
      state: 0
    },
    {
      pos: [2, 0, 1],
      state: 0
    },
    {
      pos: [3, 0, 1],
      state: 0
    },
    {
      pos: [4, 0, 1],
      state: 0
    },
    {
      pos: [5, 0, 1],
      state: 0
    },
    {
      pos: [6, 0, 1],
      state: 0
    },
    {
      pos: [7, 0, 1],
      state: 0
    },
    {
      pos: [5, 1, 1],
      state: 0
    },
    {
      pos: [7, 1, 1],
      state: 0
    },
    {
      pos: [7, 2, 1],
      state: 0
    },
    {
      pos: [5, 3, 1],
      state: 0
    },
    {
      pos: [6, 3, 1],
      state: 0
    },
    {
      pos: [7, 3, 1],
      state: 0
    },
    {
      pos: [1, 4, 1],
      state: 0
    },
    {
      pos: [2, 4, 1],
      state: 0
    },
    {
      pos: [3, 4, 1],
      state: 0
    },
    {
      pos: [4, 4, 1],
      state: 0
    },
    {
      pos: [5, 4, 1],
      state: 0
    },
    {
      pos: [6, 4, 1],
      state: 0
    },
    {
      pos: [7, 4, 1],
      state: 0
    },
    {
      pos: [6, 5, 1],
      state: 0
    },
    {
      pos: [1, 0, 2],
      state: 0
    },
    {
      pos: [2, 0, 2],
      state: 0
    },
    {
      pos: [3, 0, 2],
      state: 0
    },
    {
      pos: [4, 0, 2],
      state: 0
    },
    {
      pos: [5, 0, 2],
      state: 0
    },
    {
      pos: [6, 0, 2],
      state: 0
    },
    {
      pos: [7, 0, 2],
      state: 0
    },
    {
      pos: [5, 1, 2],
      state: 0
    },
    {
      pos: [7, 1, 2],
      state: 0
    },
    {
      pos: [7, 2, 2],
      state: 0
    },
    {
      pos: [5, 3, 2],
      state: 0
    },
    {
      pos: [6, 3, 2],
      state: 0
    },
    {
      pos: [7, 3, 2],
      state: 0
    },
    {
      pos: [1, 4, 2],
      state: 0
    },
    {
      pos: [2, 4, 2],
      state: 0
    },
    {
      pos: [3, 4, 2],
      state: 0
    },
    {
      pos: [4, 4, 2],
      state: 0
    },
    {
      pos: [5, 4, 2],
      state: 0
    },
    {
      pos: [6, 4, 2],
      state: 0
    },
    {
      pos: [7, 4, 2],
      state: 0
    },
    {
      pos: [6, 5, 2],
      state: 0
    },
    {
      pos: [1, 0, 3],
      state: 0
    },
    {
      pos: [2, 0, 3],
      state: 0
    },
    {
      pos: [3, 0, 3],
      state: 0
    },
    {
      pos: [4, 0, 3],
      state: 0
    },
    {
      pos: [5, 0, 3],
      state: 0
    },
    {
      pos: [6, 0, 3],
      state: 0
    },
    {
      pos: [7, 0, 3],
      state: 0
    },
    {
      pos: [4, 1, 3],
      state: 0
    },
    {
      pos: [5, 1, 3],
      state: 0
    },
    {
      pos: [6, 1, 3],
      state: 0
    },
    {
      pos: [7, 1, 3],
      state: 0
    },
    {
      pos: [5, 2, 3],
      state: 0
    },
    {
      pos: [6, 2, 3],
      state: 0
    },
    {
      pos: [7, 2, 3],
      state: 1
    },
    {
      pos: [5, 3, 3],
      state: 0
    },
    {
      pos: [6, 3, 3],
      state: 0
    },
    {
      pos: [7, 3, 3],
      state: 0
    },
    {
      pos: [1, 4, 3],
      state: 0
    },
    {
      pos: [2, 4, 3],
      state: 0
    },
    {
      pos: [3, 4, 3],
      state: 0
    },
    {
      pos: [4, 4, 3],
      state: 0
    },
    {
      pos: [5, 4, 3],
      state: 0
    },
    {
      pos: [6, 4, 3],
      state: 0
    },
    {
      pos: [7, 4, 3],
      state: 0
    },
    {
      pos: [1, 0, 4],
      state: 0
    },
    {
      pos: [2, 0, 4],
      state: 0
    },
    {
      pos: [3, 0, 4],
      state: 0
    },
    {
      pos: [4, 0, 4],
      state: 0
    },
    {
      pos: [5, 0, 4],
      state: 0
    },
    {
      pos: [6, 0, 4],
      state: 0
    },
    {
      pos: [7, 0, 4],
      state: 0
    },
    {
      pos: [4, 1, 4],
      state: 0
    },
    {
      pos: [7, 1, 4],
      state: 0
    },
    {
      pos: [4, 2, 4],
      state: 0
    },
    {
      pos: [4, 3, 4],
      state: 0
    },
    {
      pos: [7, 3, 4],
      state: 0
    },
    {
      pos: [1, 4, 4],
      state: 0
    },
    {
      pos: [2, 4, 4],
      state: 0
    },
    {
      pos: [3, 4, 4],
      state: 0
    },
    {
      pos: [4, 4, 4],
      state: 0
    },
    {
      pos: [5, 4, 4],
      state: 0
    },
    {
      pos: [6, 4, 4],
      state: 0
    },
    {
      pos: [7, 4, 4],
      state: 0
    },
    {
      pos: [1, 0, 5],
      state: 0
    },
    {
      pos: [2, 0, 5],
      state: 0
    },
    {
      pos: [3, 0, 5],
      state: 0
    },
    {
      pos: [4, 0, 5],
      state: 0
    },
    {
      pos: [5, 0, 5],
      state: 0
    },
    {
      pos: [6, 0, 5],
      state: 0
    },
    {
      pos: [7, 0, 5],
      state: 0
    },
    {
      pos: [4, 1, 5],
      state: 2
    },
    {
      pos: [7, 1, 5],
      state: 0
    },
    {
      pos: [4, 2, 5],
      state: 2
    },
    {
      pos: [7, 2, 5],
      state: 1
    },
    {
      pos: [4, 3, 5],
      state: 2
    },
    {
      pos: [7, 3, 5],
      state: 0
    },
    {
      pos: [1, 4, 5],
      state: 0
    },
    {
      pos: [2, 4, 5],
      state: 0
    },
    {
      pos: [3, 4, 5],
      state: 0
    },
    {
      pos: [4, 4, 5],
      state: 0
    },
    {
      pos: [5, 4, 5],
      state: 0
    },
    {
      pos: [6, 4, 5],
      state: 0
    },
    {
      pos: [7, 4, 5],
      state: 0
    },
    {
      pos: [1, 0, 6],
      state: 2
    },
    {
      pos: [2, 0, 6],
      state: 0
    },
    {
      pos: [3, 0, 6],
      state: 0
    },
    {
      pos: [4, 0, 6],
      state: 0
    },
    {
      pos: [5, 0, 6],
      state: 0
    },
    {
      pos: [6, 0, 6],
      state: 0
    },
    {
      pos: [7, 0, 6],
      state: 2
    },
    {
      pos: [1, 1, 6],
      state: 2
    },
    {
      pos: [3, 1, 6],
      state: 3
    },
    {
      pos: [7, 1, 6],
      state: 2
    },
    {
      pos: [1, 2, 6],
      state: 2
    },
    {
      pos: [3, 2, 6],
      state: 3
    },
    {
      pos: [7, 2, 6],
      state: 2
    },
    {
      pos: [1, 3, 6],
      state: 2
    },
    {
      pos: [2, 3, 6],
      state: 3
    },
    {
      pos: [3, 3, 6],
      state: 3
    },
    {
      pos: [7, 3, 6],
      state: 2
    },
    {
      pos: [1, 4, 6],
      state: 2
    },
    {
      pos: [2, 4, 6],
      state: 0
    },
    {
      pos: [3, 4, 6],
      state: 0
    },
    {
      pos: [4, 4, 6],
      state: 0
    },
    {
      pos: [5, 4, 6],
      state: 0
    },
    {
      pos: [6, 4, 6],
      state: 0
    },
    {
      pos: [7, 4, 6],
      state: 2
    },
    {
      pos: [1, 5, 6],
      state: 2
    },
    {
      pos: [7, 5, 6],
      state: 2
    },
    {
      pos: [1, 0, 7],
      state: 0
    },
    {
      pos: [2, 0, 7],
      state: 0
    },
    {
      pos: [3, 0, 7],
      state: 0
    },
    {
      pos: [4, 0, 7],
      state: 0
    },
    {
      pos: [5, 0, 7],
      state: 0
    },
    {
      pos: [6, 0, 7],
      state: 0
    },
    {
      pos: [7, 0, 7],
      state: 0
    },
    {
      pos: [1, 1, 7],
      state: 3
    },
    {
      pos: [7, 1, 7],
      state: 3
    },
    {
      pos: [1, 2, 7],
      state: 3
    },
    {
      pos: [7, 2, 7],
      state: 3
    },
    {
      pos: [1, 3, 7],
      state: 3
    },
    {
      pos: [7, 3, 7],
      state: 3
    },
    {
      pos: [1, 4, 7],
      state: 1
    },
    {
      pos: [2, 4, 7],
      state: 0
    },
    {
      pos: [3, 4, 7],
      state: 0
    },
    {
      pos: [4, 4, 7],
      state: 0
    },
    {
      pos: [5, 4, 7],
      state: 0
    },
    {
      pos: [6, 4, 7],
      state: 0
    },
    {
      pos: [7, 4, 7],
      state: 1
    },
    {
      pos: [1, 5, 7],
      state: 3
    },
    {
      pos: [7, 5, 7],
      state: 3
    },
    {
      pos: [1, 6, 7],
      state: 3
    },
    {
      pos: [7, 6, 7],
      state: 3
    },
    {
      pos: [1, 0, 8],
      state: 0
    },
    {
      pos: [2, 0, 8],
      state: 0
    },
    {
      pos: [3, 0, 8],
      state: 0
    },
    {
      pos: [4, 0, 8],
      state: 0
    },
    {
      pos: [5, 0, 8],
      state: 0
    },
    {
      pos: [6, 0, 8],
      state: 0
    },
    {
      pos: [7, 0, 8],
      state: 0
    },
    {
      pos: [1, 1, 8],
      state: 3
    },
    {
      pos: [6, 1, 8],
      state: 3
    },
    {
      pos: [7, 1, 8],
      state: 3
    },
    {
      pos: [1, 2, 8],
      state: 3
    },
    {
      pos: [7, 2, 8],
      state: 3
    },
    {
      pos: [1, 3, 8],
      state: 3
    },
    {
      pos: [7, 3, 8],
      state: 3
    },
    {
      pos: [1, 4, 8],
      state: 1
    },
    {
      pos: [2, 4, 8],
      state: 0
    },
    {
      pos: [3, 4, 8],
      state: 0
    },
    {
      pos: [4, 4, 8],
      state: 0
    },
    {
      pos: [5, 4, 8],
      state: 0
    },
    {
      pos: [6, 4, 8],
      state: 0
    },
    {
      pos: [7, 4, 8],
      state: 1
    },
    {
      pos: [1, 5, 8],
      state: 3
    },
    {
      pos: [7, 5, 8],
      state: 3
    },
    {
      pos: [1, 6, 8],
      state: 3
    },
    {
      pos: [7, 6, 8],
      state: 3
    },
    {
      pos: [1, 0, 9],
      state: 2
    },
    {
      pos: [2, 0, 9],
      state: 0
    },
    {
      pos: [3, 0, 9],
      state: 0
    },
    {
      pos: [4, 0, 9],
      state: 0
    },
    {
      pos: [5, 0, 9],
      state: 0
    },
    {
      pos: [6, 0, 9],
      state: 0
    },
    {
      pos: [7, 0, 9],
      state: 2
    },
    {
      pos: [1, 1, 9],
      state: 2
    },
    {
      pos: [2, 1, 9],
      state: 3
    },
    {
      pos: [3, 1, 9],
      state: 3
    },
    {
      pos: [4, 1, 9],
      state: 3
    },
    {
      pos: [5, 1, 9],
      state: 3
    },
    {
      pos: [6, 1, 9],
      state: 3
    },
    {
      pos: [7, 1, 9],
      state: 2
    },
    {
      pos: [1, 2, 9],
      state: 2
    },
    {
      pos: [2, 2, 9],
      state: 3
    },
    {
      pos: [4, 2, 9],
      state: 3
    },
    {
      pos: [6, 2, 9],
      state: 3
    },
    {
      pos: [7, 2, 9],
      state: 2
    },
    {
      pos: [1, 3, 9],
      state: 2
    },
    {
      pos: [2, 3, 9],
      state: 3
    },
    {
      pos: [3, 3, 9],
      state: 3
    },
    {
      pos: [4, 3, 9],
      state: 3
    },
    {
      pos: [5, 3, 9],
      state: 3
    },
    {
      pos: [6, 3, 9],
      state: 3
    },
    {
      pos: [7, 3, 9],
      state: 2
    },
    {
      pos: [1, 4, 9],
      state: 2
    },
    {
      pos: [2, 4, 9],
      state: 4
    },
    {
      pos: [3, 4, 9],
      state: 4
    },
    {
      pos: [4, 4, 9],
      state: 4
    },
    {
      pos: [5, 4, 9],
      state: 4
    },
    {
      pos: [6, 4, 9],
      state: 4
    },
    {
      pos: [7, 4, 9],
      state: 2
    },
    {
      pos: [1, 5, 9],
      state: 2
    },
    {
      pos: [2, 5, 9],
      state: 3
    },
    {
      pos: [3, 5, 9],
      state: 3
    },
    {
      pos: [4, 5, 9],
      state: 3
    },
    {
      pos: [5, 5, 9],
      state: 3
    },
    {
      pos: [6, 5, 9],
      state: 3
    },
    {
      pos: [7, 5, 9],
      state: 2
    },
    {
      nbt: {
        target_pool: "minecraft:village/plains/streets",
        final_state: "minecraft:cobblestone_stairs[facing=east,half=bottom,shape=straight,waterlogged=false]",
        id: "minecraft:jigsaw",
        attachement_type: "minecraft:building_entrance"
      },
      pos: [0, 0, 3],
      state: 5
    },
    {
      nbt: {
        CookTime: 0s,
        BurnTime: 0s,
        Items: [],
        RecipesUsedSize: 0s,
        id: "minecraft:furnace",
        CookTimeTotal: 0s,
        Lock: ""
      },
      pos: [4, 2, 3],
      state: 6
    },
    {
      nbt: {
        CookTime: 0s,
        BurnTime: 0s,
        Items: [],
        RecipesUsedSize: 0s,
        id: "minecraft:furnace",
        CookTimeTotal: 0s,
        Lock: ""
      },
      pos: [4, 3, 3],
      state: 6
    },
    {
      nbt: {
        LootTable: "minecraft:chests/village_weaponsmith",
        id: "minecraft:chest",
        Lock: "",
        LootTableSeed: 0L
      },
      pos: [6, 1, 4],
      state: 7
    },
    {
      pos: [0, 0, 0],
      state: 8
    },
    {
      pos: [0, 1, 0],
      state: 8
    },
    {
      pos: [1, 1, 0],
      state: 9
    },
    {
      pos: [2, 1, 0],
      state: 8
    },
    {
      pos: [3, 1, 0],
      state: 8
    },
    {
      pos: [4, 1, 0],
      state: 8
    },
    {
      pos: [0, 2, 0],
      state: 8
    },
    {
      pos: [1, 2, 0],
      state: 9
    },
    {
      pos: [2, 2, 0],
      state: 8
    },
    {
      pos: [3, 2, 0],
      state: 8
    },
    {
      pos: [4, 2, 0],
      state: 8
    },
    {
      pos: [5, 2, 0],
      state: 10
    },
    {
      pos: [6, 2, 0],
      state: 11
    },
    {
      pos: [0, 3, 0],
      state: 8
    },
    {
      pos: [1, 3, 0],
      state: 9
    },
    {
      pos: [2, 3, 0],
      state: 8
    },
    {
      pos: [3, 3, 0],
      state: 8
    },
    {
      pos: [4, 3, 0],
      state: 8
    },
    {
      pos: [0, 4, 0],
      state: 8
    },
    {
      pos: [0, 5, 0],
      state: 8
    },
    {
      pos: [1, 5, 0],
      state: 12
    },
    {
      pos: [2, 5, 0],
      state: 12
    },
    {
      pos: [3, 5, 0],
      state: 12
    },
    {
      pos: [4, 5, 0],
      state: 12
    },
    {
      pos: [5, 5, 0],
      state: 12
    },
    {
      pos: [6, 5, 0],
      state: 12
    },
    {
      pos: [7, 5, 0],
      state: 12
    },
    {
      pos: [0, 6, 0],
      state: 8
    },
    {
      pos: [1, 6, 0],
      state: 8
    },
    {
      pos: [2, 6, 0],
      state: 8
    },
    {
      pos: [3, 6, 0],
      state: 8
    },
    {
      pos: [4, 6, 0],
      state: 8
    },
    {
      pos: [5, 6, 0],
      state: 8
    },
    {
      pos: [6, 6, 0],
      state: 8
    },
    {
      pos: [7, 6, 0],
      state: 8
    },
    {
      pos: [0, 7, 0],
      state: 8
    },
    {
      pos: [1, 7, 0],
      state: 8
    },
    {
      pos: [2, 7, 0],
      state: 8
    },
    {
      pos: [3, 7, 0],
      state: 8
    },
    {
      pos: [4, 7, 0],
      state: 8
    },
    {
      pos: [5, 7, 0],
      state: 8
    },
    {
      pos: [6, 7, 0],
      state: 8
    },
    {
      pos: [7, 7, 0],
      state: 8
    },
    {
      pos: [0, 0, 1],
      state: 13
    },
    {
      pos: [0, 1, 1],
      state: 8
    },
    {
      pos: [1, 1, 1],
      state: 8
    },
    {
      pos: [2, 1, 1],
      state: 14
    },
    {
      pos: [3, 1, 1],
      state: 8
    },
    {
      pos: [4, 1, 1],
      state: 8
    },
    {
      pos: [6, 1, 1],
      state: 15
    },
    {
      pos: [0, 2, 1],
      state: 8
    },
    {
      pos: [1, 2, 1],
      state: 8
    },
    {
      pos: [2, 2, 1],
      state: 8
    },
    {
      pos: [3, 2, 1],
      state: 8
    },
    {
      pos: [4, 2, 1],
      state: 8
    },
    {
      pos: [5, 2, 1],
      state: 8
    },
    {
      pos: [6, 2, 1],
      state: 8
    },
    {
      pos: [0, 3, 1],
      state: 8
    },
    {
      pos: [1, 3, 1],
      state: 8
    },
    {
      pos: [2, 3, 1],
      state: 8
    },
    {
      pos: [3, 3, 1],
      state: 8
    },
    {
      pos: [4, 3, 1],
      state: 8
    },
    {
      pos: [0, 4, 1],
      state: 8
    },
    {
      pos: [0, 5, 1],
      state: 8
    },
    {
      pos: [1, 5, 1],
      state: 12
    },
    {
      pos: [2, 5, 1],
      state: 8
    },
    {
      pos: [3, 5, 1],
      state: 8
    },
    {
      pos: [4, 5, 1],
      state: 8
    },
    {
      pos: [5, 5, 1],
      state: 8
    },
    {
      pos: [7, 5, 1],
      state: 12
    },
    {
      pos: [0, 6, 1],
      state: 8
    },
    {
      pos: [1, 6, 1],
      state: 8
    },
    {
      pos: [2, 6, 1],
      state: 8
    },
    {
      pos: [3, 6, 1],
      state: 8
    },
    {
      pos: [4, 6, 1],
      state: 8
    },
    {
      pos: [5, 6, 1],
      state: 8
    },
    {
      pos: [6, 6, 1],
      state: 16
    },
    {
      pos: [7, 6, 1],
      state: 8
    },
    {
      pos: [0, 7, 1],
      state: 8
    },
    {
      pos: [1, 7, 1],
      state: 8
    },
    {
      pos: [2, 7, 1],
      state: 8
    },
    {
      pos: [3, 7, 1],
      state: 8
    },
    {
      pos: [4, 7, 1],
      state: 8
    },
    {
      pos: [5, 7, 1],
      state: 8
    },
    {
      pos: [6, 7, 1],
      state: 8
    },
    {
      pos: [7, 7, 1],
      state: 8
    },
    {
      pos: [0, 0, 2],
      state: 13
    },
    {
      pos: [0, 1, 2],
      state: 8
    },
    {
      pos: [1, 1, 2],
      state: 8
    },
    {
      pos: [2, 1, 2],
      state: 8
    },
    {
      pos: [3, 1, 2],
      state: 8
    },
    {
      pos: [4, 1, 2],
      state: 8
    },
    {
      pos: [6, 1, 2],
      state: 15
    },
    {
      pos: [0, 2, 2],
      state: 8
    },
    {
      pos: [1, 2, 2],
      state: 8
    },
    {
      pos: [2, 2, 2],
      state: 8
    },
    {
      pos: [3, 2, 2],
      state: 8
    },
    {
      pos: [4, 2, 2],
      state: 8
    },
    {
      pos: [5, 2, 2],
      state: 8
    },
    {
      pos: [6, 2, 2],
      state: 8
    },
    {
      pos: [0, 3, 2],
      state: 8
    },
    {
      pos: [1, 3, 2],
      state: 8
    },
    {
      pos: [2, 3, 2],
      state: 8
    },
    {
      pos: [3, 3, 2],
      state: 8
    },
    {
      pos: [4, 3, 2],
      state: 8
    },
    {
      pos: [0, 4, 2],
      state: 8
    },
    {
      pos: [0, 5, 2],
      state: 8
    },
    {
      pos: [1, 5, 2],
      state: 12
    },
    {
      pos: [2, 5, 2],
      state: 8
    },
    {
      pos: [3, 5, 2],
      state: 8
    },
    {
      pos: [4, 5, 2],
      state: 8
    },
    {
      pos: [5, 5, 2],
      state: 8
    },
    {
      pos: [7, 5, 2],
      state: 12
    },
    {
      pos: [0, 6, 2],
      state: 8
    },
    {
      pos: [1, 6, 2],
      state: 8
    },
    {
      pos: [2, 6, 2],
      state: 8
    },
    {
      pos: [3, 6, 2],
      state: 8
    },
    {
      pos: [4, 6, 2],
      state: 8
    },
    {
      pos: [5, 6, 2],
      state: 8
    },
    {
      pos: [6, 6, 2],
      state: 8
    },
    {
      pos: [7, 6, 2],
      state: 8
    },
    {
      pos: [0, 7, 2],
      state: 8
    },
    {
      pos: [1, 7, 2],
      state: 8
    },
    {
      pos: [2, 7, 2],
      state: 8
    },
    {
      pos: [3, 7, 2],
      state: 8
    },
    {
      pos: [4, 7, 2],
      state: 8
    },
    {
      pos: [5, 7, 2],
      state: 8
    },
    {
      pos: [6, 7, 2],
      state: 8
    },
    {
      pos: [7, 7, 2],
      state: 8
    },
    {
      pos: [0, 1, 3],
      state: 8
    },
    {
      pos: [1, 1, 3],
      state: 8
    },
    {
      pos: [2, 1, 3],
      state: 8
    },
    {
      pos: [3, 1, 3],
      state: 8
    },
    {
      pos: [0, 2, 3],
      state: 8
    },
    {
      pos: [1, 2, 3],
      state: 8
    },
    {
      pos: [2, 2, 3],
      state: 8
    },
    {
      pos: [3, 2, 3],
      state: 8
    },
    {
      pos: [0, 3, 3],
      state: 8
    },
    {
      pos: [1, 3, 3],
      state: 8
    },
    {
      pos: [2, 3, 3],
      state: 8
    },
    {
      pos: [3, 3, 3],
      state: 8
    },
    {
      pos: [0, 4, 3],
      state: 8
    },
    {
      pos: [0, 5, 3],
      state: 8
    },
    {
      pos: [1, 5, 3],
      state: 12
    },
    {
      pos: [2, 5, 3],
      state: 8
    },
    {
      pos: [3, 5, 3],
      state: 8
    },
    {
      pos: [4, 5, 3],
      state: 8
    },
    {
      pos: [5, 5, 3],
      state: 8
    },
    {
      pos: [6, 5, 3],
      state: 8
    },
    {
      pos: [7, 5, 3],
      state: 12
    },
    {
      pos: [0, 6, 3],
      state: 8
    },
    {
      pos: [1, 6, 3],
      state: 8
    },
    {
      pos: [2, 6, 3],
      state: 8
    },
    {
      pos: [3, 6, 3],
      state: 8
    },
    {
      pos: [4, 6, 3],
      state: 8
    },
    {
      pos: [5, 6, 3],
      state: 8
    },
    {
      pos: [6, 6, 3],
      state: 8
    },
    {
      pos: [7, 6, 3],
      state: 8
    },
    {
      pos: [0, 7, 3],
      state: 8
    },
    {
      pos: [1, 7, 3],
      state: 8
    },
    {
      pos: [2, 7, 3],
      state: 8
    },
    {
      pos: [3, 7, 3],
      state: 8
    },
    {
      pos: [4, 7, 3],
      state: 8
    },
    {
      pos: [5, 7, 3],
      state: 8
    },
    {
      pos: [6, 7, 3],
      state: 8
    },
    {
      pos: [7, 7, 3],
      state: 8
    },
    {
      pos: [0, 0, 4],
      state: 8
    },
    {
      pos: [0, 1, 4],
      state: 8
    },
    {
      pos: [1, 1, 4],
      state: 9
    },
    {
      pos: [2, 1, 4],
      state: 8
    },
    {
      pos: [3, 1, 4],
      state: 8
    },
    {
      pos: [5, 1, 4],
      state: 8
    },
    {
      pos: [0, 2, 4],
      state: 8
    },
    {
      pos: [1, 2, 4],
      state: 9
    },
    {
      pos: [2, 2, 4],
      state: 8
    },
    {
      pos: [3, 2, 4],
      state: 8
    },
    {
      pos: [5, 2, 4],
      state: 8
    },
    {
      pos: [6, 2, 4],
      state: 8
    },
    {
      pos: [7, 2, 4],
      state: 17
    },
    {
      pos: [0, 3, 4],
      state: 8
    },
    {
      pos: [1, 3, 4],
      state: 9
    },
    {
      pos: [2, 3, 4],
      state: 8
    },
    {
      pos: [3, 3, 4],
      state: 8
    },
    {
      pos: [5, 3, 4],
      state: 8
    },
    {
      pos: [6, 3, 4],
      state: 8
    },
    {
      pos: [0, 4, 4],
      state: 8
    },
    {
      pos: [0, 5, 4],
      state: 8
    },
    {
      pos: [1, 5, 4],
      state: 12
    },
    {
      pos: [2, 5, 4],
      state: 8
    },
    {
      pos: [3, 5, 4],
      state: 8
    },
    {
      pos: [4, 5, 4],
      state: 8
    },
    {
      pos: [5, 5, 4],
      state: 8
    },
    {
      pos: [6, 5, 4],
      state: 8
    },
    {
      pos: [7, 5, 4],
      state: 12
    },
    {
      pos: [0, 6, 4],
      state: 8
    },
    {
      pos: [1, 6, 4],
      state: 8
    },
    {
      pos: [2, 6, 4],
      state: 8
    },
    {
      pos: [3, 6, 4],
      state: 8
    },
    {
      pos: [4, 6, 4],
      state: 8
    },
    {
      pos: [5, 6, 4],
      state: 8
    },
    {
      pos: [6, 6, 4],
      state: 8
    },
    {
      pos: [7, 6, 4],
      state: 8
    },
    {
      pos: [0, 7, 4],
      state: 8
    },
    {
      pos: [1, 7, 4],
      state: 8
    },
    {
      pos: [2, 7, 4],
      state: 8
    },
    {
      pos: [3, 7, 4],
      state: 8
    },
    {
      pos: [4, 7, 4],
      state: 8
    },
    {
      pos: [5, 7, 4],
      state: 8
    },
    {
      pos: [6, 7, 4],
      state: 8
    },
    {
      pos: [7, 7, 4],
      state: 8
    },
    {
      pos: [0, 0, 5],
      state: 8
    },
    {
      pos: [0, 1, 5],
      state: 8
    },
    {
      pos: [1, 1, 5],
      state: 8
    },
    {
      pos: [2, 1, 5],
      state: 8
    },
    {
      pos: [3, 1, 5],
      state: 8
    },
    {
      pos: [5, 1, 5],
      state: 8
    },
    {
      pos: [6, 1, 5],
      state: 8
    },
    {
      pos: [0, 2, 5],
      state: 8
    },
    {
      pos: [1, 2, 5],
      state: 8
    },
    {
      pos: [2, 2, 5],
      state: 8
    },
    {
      pos: [3, 2, 5],
      state: 18
    },
    {
      pos: [5, 2, 5],
      state: 8
    },
    {
      pos: [6, 2, 5],
      state: 8
    },
    {
      pos: [0, 3, 5],
      state: 8
    },
    {
      pos: [1, 3, 5],
      state: 8
    },
    {
      pos: [2, 3, 5],
      state: 8
    },
    {
      pos: [3, 3, 5],
      state: 8
    },
    {
      pos: [5, 3, 5],
      state: 8
    },
    {
      pos: [6, 3, 5],
      state: 8
    },
    {
      pos: [0, 4, 5],
      state: 8
    },
    {
      pos: [0, 5, 5],
      state: 19
    },
    {
      pos: [1, 5, 5],
      state: 19
    },
    {
      pos: [2, 5, 5],
      state: 19
    },
    {
      pos: [3, 5, 5],
      state: 19
    },
    {
      pos: [4, 5, 5],
      state: 19
    },
    {
      pos: [5, 5, 5],
      state: 19
    },
    {
      pos: [6, 5, 5],
      state: 19
    },
    {
      pos: [7, 5, 5],
      state: 19
    },
    {
      pos: [0, 6, 5],
      state: 8
    },
    {
      pos: [1, 6, 5],
      state: 8
    },
    {
      pos: [2, 6, 5],
      state: 8
    },
    {
      pos: [3, 6, 5],
      state: 8
    },
    {
      pos: [4, 6, 5],
      state: 8
    },
    {
      pos: [5, 6, 5],
      state: 8
    },
    {
      pos: [6, 6, 5],
      state: 8
    },
    {
      pos: [7, 6, 5],
      state: 8
    },
    {
      pos: [0, 7, 5],
      state: 8
    },
    {
      pos: [1, 7, 5],
      state: 8
    },
    {
      pos: [2, 7, 5],
      state: 8
    },
    {
      pos: [3, 7, 5],
      state: 8
    },
    {
      pos: [4, 7, 5],
      state: 8
    },
    {
      pos: [5, 7, 5],
      state: 8
    },
    {
      pos: [6, 7, 5],
      state: 8
    },
    {
      pos: [7, 7, 5],
      state: 8
    },
    {
      pos: [0, 0, 6],
      state: 8
    },
    {
      pos: [0, 1, 6],
      state: 8
    },
    {
      pos: [2, 1, 6],
      state: 20
    },
    {
      pos: [4, 1, 6],
      state: 8
    },
    {
      pos: [5, 1, 6],
      state: 8
    },
    {
      pos: [6, 1, 6],
      state: 8
    },
    {
      pos: [0, 2, 6],
      state: 8
    },
    {
      pos: [2, 2, 6],
      state: 21
    },
    {
      pos: [4, 2, 6],
      state: 8
    },
    {
      pos: [5, 2, 6],
      state: 8
    },
    {
      pos: [6, 2, 6],
      state: 8
    },
    {
      pos: [0, 3, 6],
      state: 8
    },
    {
      pos: [4, 3, 6],
      state: 8
    },
    {
      pos: [5, 3, 6],
      state: 8
    },
    {
      pos: [6, 3, 6],
      state: 8
    },
    {
      pos: [0, 4, 6],
      state: 8
    },
    {
      pos: [0, 5, 6],
      state: 22
    },
    {
      pos: [2, 5, 6],
      state: 8
    },
    {
      pos: [3, 5, 6],
      state: 8
    },
    {
      pos: [4, 5, 6],
      state: 8
    },
    {
      pos: [5, 5, 6],
      state: 8
    },
    {
      pos: [6, 5, 6],
      state: 8
    },
    {
      pos: [0, 6, 6],
      state: 19
    },
    {
      pos: [1, 6, 6],
      state: 19
    },
    {
      pos: [2, 6, 6],
      state: 19
    },
    {
      pos: [3, 6, 6],
      state: 19
    },
    {
      pos: [4, 6, 6],
      state: 19
    },
    {
      pos: [5, 6, 6],
      state: 19
    },
    {
      pos: [6, 6, 6],
      state: 19
    },
    {
      pos: [7, 6, 6],
      state: 19
    },
    {
      pos: [0, 7, 6],
      state: 8
    },
    {
      pos: [1, 7, 6],
      state: 8
    },
    {
      pos: [2, 7, 6],
      state: 8
    },
    {
      pos: [3, 7, 6],
      state: 8
    },
    {
      pos: [4, 7, 6],
      state: 8
    },
    {
      pos: [5, 7, 6],
      state: 8
    },
    {
      pos: [6, 7, 6],
      state: 8
    },
    {
      pos: [7, 7, 6],
      state: 8
    },
    {
      pos: [0, 0, 7],
      state: 8
    },
    {
      pos: [0, 1, 7],
      state: 8
    },
    {
      pos: [2, 1, 7],
      state: 8
    },
    {
      pos: [3, 1, 7],
      state: 8
    },
    {
      pos: [4, 1, 7],
      state: 8
    },
    {
      pos: [5, 1, 7],
      state: 9
    },
    {
      pos: [6, 1, 7],
      state: 23
    },
    {
      pos: [0, 2, 7],
      state: 8
    },
    {
      pos: [2, 2, 7],
      state: 8
    },
    {
      pos: [3, 2, 7],
      state: 8
    },
    {
      pos: [4, 2, 7],
      state: 8
    },
    {
      pos: [5, 2, 7],
      state: 24
    },
    {
      pos: [6, 2, 7],
      state: 8
    },
    {
      pos: [0, 3, 7],
      state: 8
    },
    {
      pos: [2, 3, 7],
      state: 8
    },
    {
      pos: [3, 3, 7],
      state: 8
    },
    {
      pos: [4, 3, 7],
      state: 8
    },
    {
      pos: [5, 3, 7],
      state: 8
    },
    {
      pos: [6, 3, 7],
      state: 8
    },
    {
      pos: [0, 4, 7],
      state: 8
    },
    {
      pos: [0, 5, 7],
      state: 8
    },
    {
      pos: [2, 5, 7],
      state: 8
    },
    {
      pos: [3, 5, 7],
      state: 8
    },
    {
      pos: [4, 5, 7],
      state: 8
    },
    {
      pos: [5, 5, 7],
      state: 8
    },
    {
      pos: [6, 5, 7],
      state: 8
    },
    {
      pos: [0, 6, 7],
      state: 22
    },
    {
      pos: [2, 6, 7],
      state: 8
    },
    {
      pos: [3, 6, 7],
      state: 8
    },
    {
      pos: [4, 6, 7],
      state: 8
    },
    {
      pos: [5, 6, 7],
      state: 8
    },
    {
      pos: [6, 6, 7],
      state: 8
    },
    {
      pos: [0, 7, 7],
      state: 19
    },
    {
      pos: [1, 7, 7],
      state: 19
    },
    {
      pos: [2, 7, 7],
      state: 19
    },
    {
      pos: [3, 7, 7],
      state: 19
    },
    {
      pos: [4, 7, 7],
      state: 19
    },
    {
      pos: [5, 7, 7],
      state: 19
    },
    {
      pos: [6, 7, 7],
      state: 19
    },
    {
      pos: [7, 7, 7],
      state: 19
    },
    {
      pos: [0, 0, 8],
      state: 8
    },
    {
      pos: [0, 1, 8],
      state: 8
    },
    {
      pos: [2, 1, 8],
      state: 8
    },
    {
      pos: [3, 1, 8],
      state: 8
    },
    {
      pos: [4, 1, 8],
      state: 8
    },
    {
      pos: [5, 1, 8],
      state: 19
    },
    {
      pos: [0, 2, 8],
      state: 8
    },
    {
      pos: [2, 2, 8],
      state: 8
    },
    {
      pos: [3, 2, 8],
      state: 8
    },
    {
      pos: [4, 2, 8],
      state: 8
    },
    {
      pos: [5, 2, 8],
      state: 8
    },
    {
      pos: [6, 2, 8],
      state: 25
    },
    {
      pos: [0, 3, 8],
      state: 8
    },
    {
      pos: [2, 3, 8],
      state: 8
    },
    {
      pos: [3, 3, 8],
      state: 8
    },
    {
      pos: [4, 3, 8],
      state: 8
    },
    {
      pos: [5, 3, 8],
      state: 8
    },
    {
      pos: [6, 3, 8],
      state: 8
    },
    {
      pos: [0, 4, 8],
      state: 8
    },
    {
      pos: [0, 5, 8],
      state: 8
    },
    {
      pos: [2, 5, 8],
      state: 8
    },
    {
      pos: [3, 5, 8],
      state: 8
    },
    {
      pos: [4, 5, 8],
      state: 8
    },
    {
      pos: [5, 5, 8],
      state: 8
    },
    {
      pos: [6, 5, 8],
      state: 8
    },
    {
      pos: [0, 6, 8],
      state: 26
    },
    {
      pos: [2, 6, 8],
      state: 8
    },
    {
      pos: [3, 6, 8],
      state: 8
    },
    {
      pos: [4, 6, 8],
      state: 8
    },
    {
      pos: [5, 6, 8],
      state: 8
    },
    {
      pos: [6, 6, 8],
      state: 8
    },
    {
      pos: [0, 7, 8],
      state: 27
    },
    {
      pos: [1, 7, 8],
      state: 27
    },
    {
      pos: [2, 7, 8],
      state: 27
    },
    {
      pos: [3, 7, 8],
      state: 27
    },
    {
      pos: [4, 7, 8],
      state: 27
    },
    {
      pos: [5, 7, 8],
      state: 27
    },
    {
      pos: [6, 7, 8],
      state: 27
    },
    {
      pos: [7, 7, 8],
      state: 27
    },
    {
      pos: [0, 0, 9],
      state: 8
    },
    {
      pos: [0, 1, 9],
      state: 8
    },
    {
      pos: [0, 2, 9],
      state: 8
    },
    {
      pos: [3, 2, 9],
      state: 28
    },
    {
      pos: [5, 2, 9],
      state: 28
    },
    {
      pos: [0, 3, 9],
      state: 8
    },
    {
      pos: [0, 4, 9],
      state: 8
    },
    {
      pos: [0, 5, 9],
      state: 26
    },
    {
      pos: [0, 6, 9],
      state: 27
    },
    {
      pos: [1, 6, 9],
      state: 27
    },
    {
      pos: [2, 6, 9],
      state: 27
    },
    {
      pos: [3, 6, 9],
      state: 27
    },
    {
      pos: [4, 6, 9],
      state: 27
    },
    {
      pos: [5, 6, 9],
      state: 27
    },
    {
      pos: [6, 6, 9],
      state: 27
    },
    {
      pos: [7, 6, 9],
      state: 27
    },
    {
      pos: [0, 7, 9],
      state: 8
    },
    {
      pos: [1, 7, 9],
      state: 8
    },
    {
      pos: [2, 7, 9],
      state: 8
    },
    {
      pos: [3, 7, 9],
      state: 8
    },
    {
      pos: [4, 7, 9],
      state: 8
    },
    {
      pos: [5, 7, 9],
      state: 8
    },
    {
      pos: [6, 7, 9],
      state: 8
    },
    {
      pos: [7, 7, 9],
      state: 8
    },
    {
      pos: [0, 0, 10],
      state: 8
    },
    {
      pos: [1, 0, 10],
      state: 8
    },
    {
      pos: [2, 0, 10],
      state: 8
    },
    {
      pos: [3, 0, 10],
      state: 8
    },
    {
      pos: [4, 0, 10],
      state: 8
    },
    {
      pos: [5, 0, 10],
      state: 8
    },
    {
      pos: [6, 0, 10],
      state: 8
    },
    {
      pos: [7, 0, 10],
      state: 8
    },
    {
      pos: [0, 1, 10],
      state: 8
    },
    {
      pos: [1, 1, 10],
      state: 8
    },
    {
      pos: [2, 1, 10],
      state: 8
    },
    {
      pos: [3, 1, 10],
      state: 8
    },
    {
      pos: [4, 1, 10],
      state: 8
    },
    {
      pos: [5, 1, 10],
      state: 8
    },
    {
      pos: [6, 1, 10],
      state: 8
    },
    {
      pos: [7, 1, 10],
      state: 8
    },
    {
      pos: [0, 2, 10],
      state: 8
    },
    {
      pos: [1, 2, 10],
      state: 8
    },
    {
      pos: [2, 2, 10],
      state: 8
    },
    {
      pos: [3, 2, 10],
      state: 8
    },
    {
      pos: [4, 2, 10],
      state: 8
    },
    {
      pos: [5, 2, 10],
      state: 8
    },
    {
      pos: [6, 2, 10],
      state: 8
    },
    {
      pos: [7, 2, 10],
      state: 8
    },
    {
      pos: [0, 3, 10],
      state: 8
    },
    {
      pos: [1, 3, 10],
      state: 8
    },
    {
      pos: [2, 3, 10],
      state: 8
    },
    {
      pos: [3, 3, 10],
      state: 8
    },
    {
      pos: [4, 3, 10],
      state: 8
    },
    {
      pos: [5, 3, 10],
      state: 8
    },
    {
      pos: [6, 3, 10],
      state: 8
    },
    {
      pos: [7, 3, 10],
      state: 8
    },
    {
      pos: [0, 4, 10],
      state: 8
    },
    {
      pos: [1, 4, 10],
      state: 8
    },
    {
      pos: [2, 4, 10],
      state: 8
    },
    {
      pos: [3, 4, 10],
      state: 8
    },
    {
      pos: [4, 4, 10],
      state: 8
    },
    {
      pos: [5, 4, 10],
      state: 8
    },
    {
      pos: [6, 4, 10],
      state: 8
    },
    {
      pos: [7, 4, 10],
      state: 8
    },
    {
      pos: [0, 5, 10],
      state: 27
    },
    {
      pos: [1, 5, 10],
      state: 27
    },
    {
      pos: [2, 5, 10],
      state: 27
    },
    {
      pos: [3, 5, 10],
      state: 27
    },
    {
      pos: [4, 5, 10],
      state: 27
    },
    {
      pos: [5, 5, 10],
      state: 27
    },
    {
      pos: [6, 5, 10],
      state: 27
    },
    {
      pos: [7, 5, 10],
      state: 27
    },
    {
      pos: [0, 6, 10],
      state: 8
    },
    {
      pos: [1, 6, 10],
      state: 8
    },
    {
      pos: [2, 6, 10],
      state: 8
    },
    {
      pos: [3, 6, 10],
      state: 8
    },
    {
      pos: [4, 6, 10],
      state: 8
    },
    {
      pos: [5, 6, 10],
      state: 8
    },
    {
      pos: [6, 6, 10],
      state: 8
    },
    {
      pos: [7, 6, 10],
      state: 8
    },
    {
      pos: [0, 7, 10],
      state: 8
    },
    {
      pos: [1, 7, 10],
      state: 8
    },
    {
      pos: [2, 7, 10],
      state: 8
    },
    {
      pos: [3, 7, 10],
      state: 8
    },
    {
      pos: [4, 7, 10],
      state: 8
    },
    {
      pos: [5, 7, 10],
      state: 8
    },
    {
      pos: [6, 7, 10],
      state: 8
    },
    {
      pos: [7, 7, 10],
      state: 8
    }
  ],
  palette: [
    {
      Name: "minecraft:cobblestone"
    },
    {
      Properties: {
        axis: "z"
      },
      Name: "minecraft:oak_log"
    },
    {
      Properties: {
        axis: "y"
      },
      Name: "minecraft:oak_log"
    },
    {
      Name: "minecraft:oak_planks"
    },
    {
      Properties: {
        axis: "x"
      },
      Name: "minecraft:oak_log"
    },
    {
      Properties: {
        facing: "west"
      },
      Name: "minecraft:jigsaw"
    },
    {
      Properties: {
        lit: "false",
        facing: "west"
      },
      Name: "minecraft:furnace"
    },
    {
      Properties: {
        waterlogged: "false",
        facing: "south",
        type: "single"
      },
      Name: "minecraft:chest"
    },
    {
      Name: "minecraft:air"
    },
    {
      Properties: {
        east: "false",
        waterlogged: "false",
        south: "false",
        north: "false",
        west: "false"
      },
      Name: "minecraft:oak_fence"
    },
    {
      Properties: {
        east: "true",
        waterlogged: "false",
        south: "false",
        north: "false",
        west: "false"
      },
      Name: "minecraft:iron_bars"
    },
    {
      Properties: {
        east: "true",
        waterlogged: "false",
        south: "false",
        north: "false",
        west: "true"
      },
      Name: "minecraft:iron_bars"
    },
    {
      Properties: {
        waterlogged: "false",
        type: "bottom"
      },
      Name: "minecraft:smooth_stone_slab"
    },
    {
      Properties: {
        half: "bottom",
        waterlogged: "false",
        shape: "straight",
        facing: "east"
      },
      Name: "minecraft:cobblestone_stairs"
    },
    {
      Properties: {
        face: "floor",
        facing: "east"
      },
      Name: "minecraft:grindstone"
    },
    {
      Properties: {
        level: "0"
      },
      Name: "minecraft:lava"
    },
    {
      Properties: {
        east: "false",
        waterlogged: "false",
        south: "false",
        north: "false",
        west: "false",
        up: "true"
      },
      Name: "minecraft:cobblestone_wall"
    },
    {
      Properties: {
        east: "false",
        waterlogged: "false",
        south: "true",
        north: "true",
        west: "false"
      },
      Name: "minecraft:glass_pane"
    },
    {
      Properties: {
        facing: "north"
      },
      Name: "minecraft:wall_torch"
    },
    {
      Properties: {
        half: "bottom",
        waterlogged: "false",
        shape: "straight",
        facing: "south"
      },
      Name: "minecraft:oak_stairs"
    },
    {
      Properties: {
        hinge: "right",
        half: "lower",
        powered: "false",
        facing: "south",
        open: "false"
      },
      Name: "minecraft:oak_door"
    },
    {
      Properties: {
        hinge: "right",
        half: "upper",
        powered: "false",
        facing: "south",
        open: "false"
      },
      Name: "minecraft:oak_door"
    },
    {
      Properties: {
        half: "top",
        waterlogged: "false",
        shape: "straight",
        facing: "north"
      },
      Name: "minecraft:oak_stairs"
    },
    {
      Properties: {
        half: "bottom",
        waterlogged: "false",
        shape: "straight",
        facing: "east"
      },
      Name: "minecraft:oak_stairs"
    },
    {
      Properties: {
        powered: "false"
      },
      Name: "minecraft:oak_pressure_plate"
    },
    {
      Properties: {
        facing: "west"
      },
      Name: "minecraft:wall_torch"
    },
    {
      Properties: {
        half: "top",
        waterlogged: "false",
        shape: "straight",
        facing: "south"
      },
      Name: "minecraft:oak_stairs"
    },
    {
      Properties: {
        half: "bottom",
        waterlogged: "false",
        shape: "straight",
        facing: "north"
      },
      Name: "minecraft:oak_stairs"
    },
    {
      Properties: {
        east: "true",
        waterlogged: "false",
        south: "false",
        north: "false",
        west: "true"
      },
      Name: "minecraft:glass_pane"
    }
  ],
  DataVersion: 1910
}