{
  size: [7, 7, 7],
  entities: [],
  blocks: [
    {
      pos: [2, 0, 2],
      state: 0
    },
    {
      pos: [4, 0, 2],
      state: 0
    },
    {
      pos: [2, 4, 2],
      state: 1
    },
    {
      pos: [3, 4, 2],
      state: 2
    },
    {
      pos: [4, 4, 2],
      state: 2
    },
    {
      pos: [2, 4, 3],
      state: 1
    },
    {
      pos: [3, 4, 3],
      state: 1
    },
    {
      pos: [4, 4, 3],
      state: 1
    },
    {
      pos: [3, 5, 3],
      state: 1
    },
    {
      pos: [2, 0, 4],
      state: 0
    },
    {
      pos: [4, 0, 4],
      state: 0
    },
    {
      pos: [2, 4, 4],
      state: 1
    },
    {
      pos: [3, 4, 4],
      state: 2
    },
    {
      pos: [4, 4, 4],
      state: 1
    },
    {
      nbt: {
        target_pool: "minecraft:village/snowy/streets",
        final_state: "minecraft:air",
        id: "minecraft:jigsaw",
        attachement_type: "minecraft:street"
      },
      pos: [3, 1, 0],
      state: 3
    },
    {
      nbt: {
        target_pool: "minecraft:village/snowy/streets",
        final_state: "minecraft:air",
        id: "minecraft:jigsaw",
        attachement_type: "minecraft:street"
      },
      pos: [0, 1, 3],
      state: 4
    },
    {
      nbt: {
        target_pool: "minecraft:village/snowy/streets",
        final_state: "minecraft:air",
        id: "minecraft:jigsaw",
        attachement_type: "minecraft:street"
      },
      pos: [6, 1, 3],
      state: 5
    },
    {
      nbt: {
        id: "minecraft:bell"
      },
      pos: [3, 3, 3],
      state: 6
    },
    {
      nbt: {
        target_pool: "minecraft:empty",
        final_state: "minecraft:air",
        id: "minecraft:jigsaw",
        attachement_type: "minecraft:empty"
      },
      pos: [5, 3, 3],
      state: 7
    },
    {
      nbt: {
        target_pool: "minecraft:village/snowy/streets",
        final_state: "minecraft:air",
        id: "minecraft:jigsaw",
        attachement_type: "minecraft:street"
      },
      pos: [3, 1, 6],
      state: 8
    },
    {
      pos: [2, 0, 0],
      state: 9
    },
    {
      pos: [3, 0, 0],
      state: 9
    },
    {
      pos: [4, 0, 0],
      state: 9
    },
    {
      pos: [0, 1, 0],
      state: 10
    },
    {
      pos: [1, 1, 0],
      state: 10
    },
    {
      pos: [2, 1, 0],
      state: 10
    },
    {
      pos: [4, 1, 0],
      state: 10
    },
    {
      pos: [5, 1, 0],
      state: 10
    },
    {
      pos: [6, 1, 0],
      state: 10
    },
    {
      pos: [0, 2, 0],
      state: 10
    },
    {
      pos: [1, 2, 0],
      state: 10
    },
    {
      pos: [2, 2, 0],
      state: 10
    },
    {
      pos: [3, 2, 0],
      state: 10
    },
    {
      pos: [4, 2, 0],
      state: 10
    },
    {
      pos: [5, 2, 0],
      state: 10
    },
    {
      pos: [6, 2, 0],
      state: 10
    },
    {
      pos: [0, 3, 0],
      state: 10
    },
    {
      pos: [1, 3, 0],
      state: 10
    },
    {
      pos: [2, 3, 0],
      state: 10
    },
    {
      pos: [3, 3, 0],
      state: 10
    },
    {
      pos: [4, 3, 0],
      state: 10
    },
    {
      pos: [5, 3, 0],
      state: 10
    },
    {
      pos: [6, 3, 0],
      state: 10
    },
    {
      pos: [0, 4, 0],
      state: 10
    },
    {
      pos: [1, 4, 0],
      state: 10
    },
    {
      pos: [2, 4, 0],
      state: 10
    },
    {
      pos: [3, 4, 0],
      state: 10
    },
    {
      pos: [4, 4, 0],
      state: 10
    },
    {
      pos: [5, 4, 0],
      state: 10
    },
    {
      pos: [6, 4, 0],
      state: 10
    },
    {
      pos: [0, 5, 0],
      state: 10
    },
    {
      pos: [1, 5, 0],
      state: 10
    },
    {
      pos: [2, 5, 0],
      state: 10
    },
    {
      pos: [3, 5, 0],
      state: 10
    },
    {
      pos: [4, 5, 0],
      state: 10
    },
    {
      pos: [5, 5, 0],
      state: 10
    },
    {
      pos: [6, 5, 0],
      state: 10
    },
    {
      pos: [0, 6, 0],
      state: 10
    },
    {
      pos: [1, 6, 0],
      state: 10
    },
    {
      pos: [2, 6, 0],
      state: 10
    },
    {
      pos: [3, 6, 0],
      state: 10
    },
    {
      pos: [4, 6, 0],
      state: 10
    },
    {
      pos: [5, 6, 0],
      state: 10
    },
    {
      pos: [6, 6, 0],
      state: 10
    },
    {
      pos: [1, 0, 1],
      state: 9
    },
    {
      pos: [2, 0, 1],
      state: 9
    },
    {
      pos: [3, 0, 1],
      state: 9
    },
    {
      pos: [4, 0, 1],
      state: 9
    },
    {
      pos: [5, 0, 1],
      state: 9
    },
    {
      pos: [0, 1, 1],
      state: 10
    },
    {
      pos: [1, 1, 1],
      state: 10
    },
    {
      pos: [2, 1, 1],
      state: 10
    },
    {
      pos: [3, 1, 1],
      state: 10
    },
    {
      pos: [4, 1, 1],
      state: 10
    },
    {
      pos: [5, 1, 1],
      state: 10
    },
    {
      pos: [6, 1, 1],
      state: 10
    },
    {
      pos: [0, 2, 1],
      state: 10
    },
    {
      pos: [1, 2, 1],
      state: 10
    },
    {
      pos: [2, 2, 1],
      state: 10
    },
    {
      pos: [3, 2, 1],
      state: 10
    },
    {
      pos: [4, 2, 1],
      state: 10
    },
    {
      pos: [5, 2, 1],
      state: 10
    },
    {
      pos: [6, 2, 1],
      state: 10
    },
    {
      pos: [0, 3, 1],
      state: 10
    },
    {
      pos: [1, 3, 1],
      state: 10
    },
    {
      pos: [2, 3, 1],
      state: 10
    },
    {
      pos: [3, 3, 1],
      state: 7
    },
    {
      pos: [4, 3, 1],
      state: 10
    },
    {
      pos: [5, 3, 1],
      state: 10
    },
    {
      pos: [6, 3, 1],
      state: 10
    },
    {
      pos: [0, 4, 1],
      state: 10
    },
    {
      pos: [1, 4, 1],
      state: 10
    },
    {
      pos: [2, 4, 1],
      state: 10
    },
    {
      pos: [3, 4, 1],
      state: 11
    },
    {
      pos: [4, 4, 1],
      state: 10
    },
    {
      pos: [5, 4, 1],
      state: 10
    },
    {
      pos: [6, 4, 1],
      state: 10
    },
    {
      pos: [0, 5, 1],
      state: 10
    },
    {
      pos: [1, 5, 1],
      state: 10
    },
    {
      pos: [2, 5, 1],
      state: 10
    },
    {
      pos: [3, 5, 1],
      state: 10
    },
    {
      pos: [4, 5, 1],
      state: 10
    },
    {
      pos: [5, 5, 1],
      state: 10
    },
    {
      pos: [6, 5, 1],
      state: 10
    },
    {
      pos: [0, 6, 1],
      state: 10
    },
    {
      pos: [1, 6, 1],
      state: 10
    },
    {
      pos: [2, 6, 1],
      state: 10
    },
    {
      pos: [3, 6, 1],
      state: 10
    },
    {
      pos: [4, 6, 1],
      state: 10
    },
    {
      pos: [5, 6, 1],
      state: 10
    },
    {
      pos: [6, 6, 1],
      state: 10
    },
    {
      pos: [0, 0, 2],
      state: 9
    },
    {
      pos: [1, 0, 2],
      state: 9
    },
    {
      pos: [3, 0, 2],
      state: 9
    },
    {
      pos: [5, 0, 2],
      state: 9
    },
    {
      pos: [6, 0, 2],
      state: 9
    },
    {
      pos: [0, 1, 2],
      state: 10
    },
    {
      pos: [1, 1, 2],
      state: 10
    },
    {
      pos: [2, 1, 2],
      state: 12
    },
    {
      pos: [3, 1, 2],
      state: 10
    },
    {
      pos: [4, 1, 2],
      state: 12
    },
    {
      pos: [5, 1, 2],
      state: 10
    },
    {
      pos: [6, 1, 2],
      state: 10
    },
    {
      pos: [0, 2, 2],
      state: 10
    },
    {
      pos: [1, 2, 2],
      state: 10
    },
    {
      pos: [2, 2, 2],
      state: 12
    },
    {
      pos: [3, 2, 2],
      state: 10
    },
    {
      pos: [4, 2, 2],
      state: 12
    },
    {
      pos: [5, 2, 2],
      state: 10
    },
    {
      pos: [6, 2, 2],
      state: 10
    },
    {
      pos: [0, 3, 2],
      state: 10
    },
    {
      pos: [1, 3, 2],
      state: 10
    },
    {
      pos: [2, 3, 2],
      state: 12
    },
    {
      pos: [3, 3, 2],
      state: 10
    },
    {
      pos: [4, 3, 2],
      state: 12
    },
    {
      pos: [5, 3, 2],
      state: 10
    },
    {
      pos: [6, 3, 2],
      state: 10
    },
    {
      pos: [0, 4, 2],
      state: 10
    },
    {
      pos: [1, 4, 2],
      state: 10
    },
    {
      pos: [5, 4, 2],
      state: 10
    },
    {
      pos: [6, 4, 2],
      state: 10
    },
    {
      pos: [0, 5, 2],
      state: 10
    },
    {
      pos: [1, 5, 2],
      state: 10
    },
    {
      pos: [2, 5, 2],
      state: 10
    },
    {
      pos: [3, 5, 2],
      state: 10
    },
    {
      pos: [4, 5, 2],
      state: 10
    },
    {
      pos: [5, 5, 2],
      state: 10
    },
    {
      pos: [6, 5, 2],
      state: 10
    },
    {
      pos: [0, 6, 2],
      state: 10
    },
    {
      pos: [1, 6, 2],
      state: 10
    },
    {
      pos: [2, 6, 2],
      state: 10
    },
    {
      pos: [3, 6, 2],
      state: 10
    },
    {
      pos: [4, 6, 2],
      state: 10
    },
    {
      pos: [5, 6, 2],
      state: 10
    },
    {
      pos: [6, 6, 2],
      state: 10
    },
    {
      pos: [0, 0, 3],
      state: 9
    },
    {
      pos: [1, 0, 3],
      state: 9
    },
    {
      pos: [2, 0, 3],
      state: 9
    },
    {
      pos: [3, 0, 3],
      state: 9
    },
    {
      pos: [4, 0, 3],
      state: 9
    },
    {
      pos: [5, 0, 3],
      state: 9
    },
    {
      pos: [6, 0, 3],
      state: 9
    },
    {
      pos: [1, 1, 3],
      state: 10
    },
    {
      pos: [2, 1, 3],
      state: 10
    },
    {
      pos: [3, 1, 3],
      state: 10
    },
    {
      pos: [4, 1, 3],
      state: 10
    },
    {
      pos: [5, 1, 3],
      state: 10
    },
    {
      pos: [0, 2, 3],
      state: 10
    },
    {
      pos: [1, 2, 3],
      state: 10
    },
    {
      pos: [2, 2, 3],
      state: 10
    },
    {
      pos: [3, 2, 3],
      state: 10
    },
    {
      pos: [4, 2, 3],
      state: 10
    },
    {
      pos: [5, 2, 3],
      state: 10
    },
    {
      pos: [6, 2, 3],
      state: 10
    },
    {
      pos: [0, 3, 3],
      state: 10
    },
    {
      pos: [1, 3, 3],
      state: 7
    },
    {
      pos: [2, 3, 3],
      state: 10
    },
    {
      pos: [4, 3, 3],
      state: 10
    },
    {
      pos: [6, 3, 3],
      state: 10
    },
    {
      pos: [0, 4, 3],
      state: 10
    },
    {
      pos: [1, 4, 3],
      state: 13
    },
    {
      pos: [5, 4, 3],
      state: 14
    },
    {
      pos: [6, 4, 3],
      state: 10
    },
    {
      pos: [0, 5, 3],
      state: 10
    },
    {
      pos: [1, 5, 3],
      state: 10
    },
    {
      pos: [2, 5, 3],
      state: 10
    },
    {
      pos: [4, 5, 3],
      state: 10
    },
    {
      pos: [5, 5, 3],
      state: 10
    },
    {
      pos: [6, 5, 3],
      state: 10
    },
    {
      pos: [0, 6, 3],
      state: 10
    },
    {
      pos: [1, 6, 3],
      state: 10
    },
    {
      pos: [2, 6, 3],
      state: 10
    },
    {
      pos: [3, 6, 3],
      state: 10
    },
    {
      pos: [4, 6, 3],
      state: 10
    },
    {
      pos: [5, 6, 3],
      state: 10
    },
    {
      pos: [6, 6, 3],
      state: 10
    },
    {
      pos: [0, 0, 4],
      state: 9
    },
    {
      pos: [1, 0, 4],
      state: 9
    },
    {
      pos: [3, 0, 4],
      state: 9
    },
    {
      pos: [5, 0, 4],
      state: 9
    },
    {
      pos: [6, 0, 4],
      state: 9
    },
    {
      pos: [0, 1, 4],
      state: 10
    },
    {
      pos: [1, 1, 4],
      state: 10
    },
    {
      pos: [2, 1, 4],
      state: 12
    },
    {
      pos: [3, 1, 4],
      state: 10
    },
    {
      pos: [4, 1, 4],
      state: 12
    },
    {
      pos: [5, 1, 4],
      state: 10
    },
    {
      pos: [6, 1, 4],
      state: 10
    },
    {
      pos: [0, 2, 4],
      state: 10
    },
    {
      pos: [1, 2, 4],
      state: 10
    },
    {
      pos: [2, 2, 4],
      state: 12
    },
    {
      pos: [3, 2, 4],
      state: 10
    },
    {
      pos: [4, 2, 4],
      state: 12
    },
    {
      pos: [5, 2, 4],
      state: 10
    },
    {
      pos: [6, 2, 4],
      state: 10
    },
    {
      pos: [0, 3, 4],
      state: 10
    },
    {
      pos: [1, 3, 4],
      state: 10
    },
    {
      pos: [2, 3, 4],
      state: 12
    },
    {
      pos: [3, 3, 4],
      state: 10
    },
    {
      pos: [4, 3, 4],
      state: 12
    },
    {
      pos: [5, 3, 4],
      state: 10
    },
    {
      pos: [6, 3, 4],
      state: 10
    },
    {
      pos: [0, 4, 4],
      state: 10
    },
    {
      pos: [1, 4, 4],
      state: 10
    },
    {
      pos: [5, 4, 4],
      state: 10
    },
    {
      pos: [6, 4, 4],
      state: 10
    },
    {
      pos: [0, 5, 4],
      state: 10
    },
    {
      pos: [1, 5, 4],
      state: 10
    },
    {
      pos: [2, 5, 4],
      state: 10
    },
    {
      pos: [3, 5, 4],
      state: 10
    },
    {
      pos: [4, 5, 4],
      state: 10
    },
    {
      pos: [5, 5, 4],
      state: 10
    },
    {
      pos: [6, 5, 4],
      state: 10
    },
    {
      pos: [0, 6, 4],
      state: 10
    },
    {
      pos: [1, 6, 4],
      state: 10
    },
    {
      pos: [2, 6, 4],
      state: 10
    },
    {
      pos: [3, 6, 4],
      state: 10
    },
    {
      pos: [4, 6, 4],
      state: 10
    },
    {
      pos: [5, 6, 4],
      state: 10
    },
    {
      pos: [6, 6, 4],
      state: 10
    },
    {
      pos: [1, 0, 5],
      state: 9
    },
    {
      pos: [2, 0, 5],
      state: 9
    },
    {
      pos: [3, 0, 5],
      state: 9
    },
    {
      pos: [4, 0, 5],
      state: 9
    },
    {
      pos: [5, 0, 5],
      state: 9
    },
    {
      pos: [0, 1, 5],
      state: 10
    },
    {
      pos: [1, 1, 5],
      state: 10
    },
    {
      pos: [2, 1, 5],
      state: 10
    },
    {
      pos: [3, 1, 5],
      state: 10
    },
    {
      pos: [4, 1, 5],
      state: 10
    },
    {
      pos: [5, 1, 5],
      state: 10
    },
    {
      pos: [6, 1, 5],
      state: 10
    },
    {
      pos: [0, 2, 5],
      state: 10
    },
    {
      pos: [1, 2, 5],
      state: 10
    },
    {
      pos: [2, 2, 5],
      state: 10
    },
    {
      pos: [3, 2, 5],
      state: 10
    },
    {
      pos: [4, 2, 5],
      state: 10
    },
    {
      pos: [5, 2, 5],
      state: 10
    },
    {
      pos: [6, 2, 5],
      state: 10
    },
    {
      pos: [0, 3, 5],
      state: 10
    },
    {
      pos: [1, 3, 5],
      state: 10
    },
    {
      pos: [2, 3, 5],
      state: 10
    },
    {
      pos: [3, 3, 5],
      state: 7
    },
    {
      pos: [4, 3, 5],
      state: 10
    },
    {
      pos: [5, 3, 5],
      state: 10
    },
    {
      pos: [6, 3, 5],
      state: 10
    },
    {
      pos: [0, 4, 5],
      state: 10
    },
    {
      pos: [1, 4, 5],
      state: 10
    },
    {
      pos: [2, 4, 5],
      state: 10
    },
    {
      pos: [3, 4, 5],
      state: 15
    },
    {
      pos: [4, 4, 5],
      state: 10
    },
    {
      pos: [5, 4, 5],
      state: 10
    },
    {
      pos: [6, 4, 5],
      state: 10
    },
    {
      pos: [0, 5, 5],
      state: 10
    },
    {
      pos: [1, 5, 5],
      state: 10
    },
    {
      pos: [2, 5, 5],
      state: 10
    },
    {
      pos: [3, 5, 5],
      state: 10
    },
    {
      pos: [4, 5, 5],
      state: 10
    },
    {
      pos: [5, 5, 5],
      state: 10
    },
    {
      pos: [6, 5, 5],
      state: 10
    },
    {
      pos: [0, 6, 5],
      state: 10
    },
    {
      pos: [1, 6, 5],
      state: 10
    },
    {
      pos: [2, 6, 5],
      state: 10
    },
    {
      pos: [3, 6, 5],
      state: 10
    },
    {
      pos: [4, 6, 5],
      state: 10
    },
    {
      pos: [5, 6, 5],
      state: 10
    },
    {
      pos: [6, 6, 5],
      state: 10
    },
    {
      pos: [2, 0, 6],
      state: 9
    },
    {
      pos: [3, 0, 6],
      state: 9
    },
    {
      pos: [4, 0, 6],
      state: 9
    },
    {
      pos: [0, 1, 6],
      state: 10
    },
    {
      pos: [1, 1, 6],
      state: 10
    },
    {
      pos: [2, 1, 6],
      state: 10
    },
    {
      pos: [4, 1, 6],
      state: 10
    },
    {
      pos: [5, 1, 6],
      state: 10
    },
    {
      pos: [6, 1, 6],
      state: 10
    },
    {
      pos: [0, 2, 6],
      state: 10
    },
    {
      pos: [1, 2, 6],
      state: 10
    },
    {
      pos: [2, 2, 6],
      state: 10
    },
    {
      pos: [3, 2, 6],
      state: 10
    },
    {
      pos: [4, 2, 6],
      state: 10
    },
    {
      pos: [5, 2, 6],
      state: 10
    },
    {
      pos: [6, 2, 6],
      state: 10
    },
    {
      pos: [0, 3, 6],
      state: 10
    },
    {
      pos: [1, 3, 6],
      state: 10
    },
    {
      pos: [2, 3, 6],
      state: 10
    },
    {
      pos: [3, 3, 6],
      state: 10
    },
    {
      pos: [4, 3, 6],
      state: 10
    },
    {
      pos: [5, 3, 6],
      state: 10
    },
    {
      pos: [6, 3, 6],
      state: 10
    },
    {
      pos: [0, 4, 6],
      state: 10
    },
    {
      pos: [1, 4, 6],
      state: 10
    },
    {
      pos: [2, 4, 6],
      state: 10
    },
    {
      pos: [3, 4, 6],
      state: 10
    },
    {
      pos: [4, 4, 6],
      state: 10
    },
    {
      pos: [5, 4, 6],
      state: 10
    },
    {
      pos: [6, 4, 6],
      state: 10
    },
    {
      pos: [0, 5, 6],
      state: 10
    },
    {
      pos: [1, 5, 6],
      state: 10
    },
    {
      pos: [2, 5, 6],
      state: 10
    },
    {
      pos: [3, 5, 6],
      state: 10
    },
    {
      pos: [4, 5, 6],
      state: 10
    },
    {
      pos: [5, 5, 6],
      state: 10
    },
    {
      pos: [6, 5, 6],
      state: 10
    },
    {
      pos: [0, 6, 6],
      state: 10
    },
    {
      pos: [1, 6, 6],
      state: 10
    },
    {
      pos: [2, 6, 6],
      state: 10
    },
    {
      pos: [3, 6, 6],
      state: 10
    },
    {
      pos: [4, 6, 6],
      state: 10
    },
    {
      pos: [5, 6, 6],
      state: 10
    },
    {
      pos: [6, 6, 6],
      state: 10
    }
  ],
  palette: [
    {
      Properties: {
        snowy: "false"
      },
      Name: "minecraft:grass_block"
    },
    {
      Properties: {
        axis: "z"
      },
      Name: "minecraft:stripped_spruce_wood"
    },
    {
      Properties: {
        axis: "x"
      },
      Name: "minecraft:stripped_spruce_wood"
    },
    {
      Properties: {
        facing: "north"
      },
      Name: "minecraft:jigsaw"
    },
    {
      Properties: {
        facing: "west"
      },
      Name: "minecraft:jigsaw"
    },
    {
      Properties: {
        facing: "east"
      },
      Name: "minecraft:jigsaw"
    },
    {
      Properties: {
        face: "ceiling",
        facing: "east"
      },
      Name: "minecraft:bell"
    },
    {
      Properties: {
        hanging: "true"
      },
      Name: "minecraft:lantern"
    },
    {
      Properties: {
        facing: "south"
      },
      Name: "minecraft:jigsaw"
    },
    {
      Name: "minecraft:grass_path"
    },
    {
      Name: "minecraft:air"
    },
    {
      Properties: {
        east: "false",
        waterlogged: "false",
        south: "true",
        north: "false",
        west: "false"
      },
      Name: "minecraft:spruce_fence"
    },
    {
      Properties: {
        east: "false",
        waterlogged: "false",
        south: "false",
        north: "false",
        west: "false"
      },
      Name: "minecraft:spruce_fence"
    },
    {
      Properties: {
        east: "true",
        waterlogged: "false",
        south: "false",
        north: "false",
        west: "false"
      },
      Name: "minecraft:spruce_fence"
    },
    {
      Properties: {
        east: "false",
        waterlogged: "false",
        south: "false",
        north: "false",
        west: "true"
      },
      Name: "minecraft:spruce_fence"
    },
    {
      Properties: {
        east: "false",
        waterlogged: "false",
        south: "false",
        north: "true",
        west: "false"
      },
      Name: "minecraft:spruce_fence"
    }
  ],
  DataVersion: 1910
}